Workbook

Sheet תפוקה מצטברת מול אשתקד
D1: שינוי מול אשתקד % | H1: תפוקה מצטברת 07/2025 | L1: תפוקה מצטברת 07/2024
A2: שם סוכן | B2: מפקח | C2: מחלקה | D2: פנסיוני | E2: סיכונים | F2: פיננסים | G2: ניודי פנסיה | H2: פנסיוני | I2: סיכונים | J2: פיננסים | K2: ניודי פנסיה | L2: פנסיוני | M2: סיכונים | N2: פיננסים | O2: ניודי פנסיה
A3: גל אלמגור סוכ | B3: יוסי אביב | C3: ישירים | D3: =IF(H3=0,0%,IF(L3=0,100%,H3/L3-1)) -> 0.75387384 | E3: =IF(I3=0,0%,IF(M3=0,100%,I3/M3-1)) -> -0.66207676 | F3: =IF(J3=0,0%,IF(N3=G29,100%,J3/N3-1)) -> 0.21062612 | G3: =IF(K3=0,0%,IF(O3=H29,100%,K3/O3-1)) -> 0.95230791 | H3: =VLOOKUP(A3,'הכשרה'!A:G,4,0)+VLOOKUP('תפוקה מצטברת מול אשתקד'!A3,'מגדל'!A:G,4,0)+VLOOKUP('תפוקה מצטברת מול אשתקד'!A3,'מנורה'!A:G,4,0)+VLOOKUP('תפוקה מצטברת מול אשתקד'!A3,'איילון'!A:G,4,0)+VLOOKUP('תפוקה מצטברת מול אשתקד'!A3,'הראל'!A:G,4,0)+VLOOKUP('תפוקה מצטברת מול אשתקד'!A3,'הפניקס'!A:G,4,0)+VLOOKUP('תפוקה מצטברת מול אשתקד'!A3,'כלל'!A:G,4,0)+VLOOKUP('תפוקה מצטברת מול אשתקד'!A3,'מור'!A:G,4,0)+VLOOKUP('תפוקה מצטברת מול אשתקד'!A3,'אלטשולר שחם'!A:G,4,0)+VLOOKUP('תפוקה מצטברת מול אשתקד'!A3,'מדיהו '!A:G,4,0)+VLOOKUP('תפוקה מצטברת מול אשתקד'!A3,'אנליסט '!A:G,4,0)+VLOOKUP('תפוקה מצטברת מול אשתקד'!A3,'מיטב דש'!A:G,4,0)+VLOOKUP('תפוקה מצטברת מול אשתקד'!A3,'אינפניטי'!A:G,4,0) -> 7943583.2 | I3: =VLOOKUP(A3,'הכשרה'!A:G,5,0)+VLOOKUP('תפוקה מצטברת מול אשתקד'!A3,'מגדל'!A:G,5,0)+VLOOKUP('תפוקה מצטברת מול אשתקד'!A3,'מנורה'!A:G,5,0)+VLOOKUP('תפוקה מצטברת מול אשתקד'!A3,'איילון'!A:G,5,0)+VLOOKUP('תפוקה מצטברת מול אשתקד'!A3,'הראל'!A:G,5,0)+VLOOKUP('תפוקה מצטברת מול אשתקד'!A3,'הפניקס'!A:G,5,0)+VLOOKUP('תפוקה מצטברת מול אשתקד'!A3,'כלל'!A:G,5,0)+VLOOKUP('תפוקה מצטברת מול אשתקד'!A3,'מור'!A:G,5,0)+VLOOKUP('תפוקה מצטברת מול אשתקד'!A3,'אלטשולר שחם'!A:G,5,0)+VLOOKUP('תפוקה מצטברת מול אשתקד'!A3,'מדיהו '!A:G,5,0)+VLOOKUP('תפוקה מצטברת מול אשתקד'!A3,'אנליסט '!A:G,5,0)+VLOOKUP('תפוקה מצטברת מול אשתקד'!A3,'מיטב דש'!A:G,5,0)+VLOOKUP('תפוקה מצטברת מול אשתקד'!A3,'אינפניטי'!A:G,5,0) -> 284148.82 | J3: =VLOOKUP(A3,'הכשרה'!A:G,6,0)+VLOOKUP('תפוקה מצטברת מול אשתקד'!A3,'מגדל'!A:G,6,0)+VLOOKUP('תפוקה מצטברת מול אשתקד'!A3,'מנורה'!A:G,6,0)+VLOOKUP('תפוקה מצטברת מול אשתקד'!A3,'איילון'!A:G,6,0)+VLOOKUP(A3,'הראל'!A:G,6,0)+VLOOKUP('תפוקה מצטברת מול אשתקד'!A3,'הפניקס'!A:G,6,0)+VLOOKUP('תפוקה מצטברת מול אשתקד'!A3,'כלל'!A:G,6,0)+VLOOKUP('תפוקה מצטברת מול אשתקד'!A3,'מור'!A:G,6,0)+VLOOKUP('תפוקה מצטברת מול אשתקד'!A3,'אלטשולר שחם'!A:G,6,0)+VLOOKUP('תפוקה מצטברת מול אשתקד'!A3,'מדיהו '!A:G,6,0)+VLOOKUP('תפוקה מצטברת מול אשתקד'!A3,'אנליסט '!A:G,6,0)+VLOOKUP('תפוקה מצטברת מול אשתקד'!A3,'מיטב דש'!A:G,6,0)+VLOOKUP('תפוקה מצטברת מול אשתקד'!A3,'אינפניטי'!A:G,6,0) -> 19291898 | K3: =VLOOKUP(A3,'הכשרה'!A:G,7,0)+VLOOKUP('תפוקה מצטברת מול אשתקד'!A3,'מגדל'!A:G,7,0)+VLOOKUP('תפוקה מצטברת מול אשתקד'!A3,'מנורה'!A:G,7,0)+VLOOKUP('תפוקה מצטברת מול אשתקד'!A3,'איילון'!A:G,7,0)+VLOOKUP('תפוקה מצטברת מול אשתקד'!A3,'הראל'!A:G,7,0)+VLOOKUP('תפוקה מצטברת מול אשתקד'!A3,'הפניקס'!A:G,7,0)+VLOOKUP('תפוקה מצטברת מול אשתקד'!A3,'כלל'!A:G,7,0)+VLOOKUP('תפוקה מצטברת מול אשתקד'!A3,'מור'!A:G,7,0)+VLOOKUP('תפוקה מצטברת מול אשתקד'!A3,'אלטשולר שחם'!A:G,7,0)+VLOOKUP('תפוקה מצטברת מול אשתקד'!A3,'מדיהו '!A:K,7,0)+VLOOKUP(A3,'אנליסט '!A:G,7,0)+VLOOKUP('תפוקה מצטברת מול אשתקד'!A3,'מיטב דש'!A:G,7,0)+VLOOKUP('תפוקה מצטברת מול אשתקד'!A3,'אינפניטי'!A:G,7,0) -> 50754486 | L3: =VLOOKUP(A3,'הכשרה'!A:K,8,0)+VLOOKUP('תפוקה מצטברת מול אשתקד'!A3,'מגדל'!A:K,8,0)+VLOOKUP('תפוקה מצטברת מול אשתקד'!A3,'מנורה'!A:K,8,0)+VLOOKUP('תפוקה מצטברת מול אשתקד'!A3,'איילון'!A:K,8,0)+VLOOKUP('תפוקה מצטברת מול אשתקד'!A3,'הראל'!A:K,8,0)+VLOOKUP('תפוקה מצטברת מול אשתקד'!A3,'הפניקס'!A:K,8,0)+VLOOKUP('תפוקה מצטברת מול אשתקד'!A3,'כלל'!A:K,8,0)+VLOOKUP('תפוקה מצטברת מול אשתקד'!A3,'מור'!A:K,8,0)+VLOOKUP('תפוקה מצטברת מול אשתקד'!A3,'אלטשולר שחם'!A:K,8,0)+VLOOKUP('תפוקה מצטברת מול אשתקד'!A3,'מדיהו '!A:K,8,0)+VLOOKUP('תפוקה מצטברת מול אשתקד'!A3,'אנליסט '!A:K,8,0)+VLOOKUP('תפוקה מצטברת מול אשתקד'!A3,'מיטב דש'!A:K,8,0)+VLOOKUP('תפוקה מצטברת מול אשתקד'!A3,'אינפניטי'!A:K,8,0) -> 4529164.5 | M3: =VLOOKUP(A3,'הכשרה'!A:K,9,0)+VLOOKUP('תפוקה מצטברת מול אשתקד'!A3,'מגדל'!A:K,9,0)+VLOOKUP('תפוקה מצטברת מול אשתקד'!A3,'מנורה'!A:K,9,0)+VLOOKUP('תפוקה מצטברת מול אשתקד'!A3,'איילון'!A:K,9,0)+VLOOKUP('תפוקה מצטברת מול אשתקד'!A3,'הראל'!A:K,9,0)+VLOOKUP('תפוקה מצטברת מול אשתקד'!A3,'הפניקס'!A:K,9,0)+VLOOKUP('תפוקה מצטברת מול אשתקד'!A3,'כלל'!A:K,9,0)+VLOOKUP('תפוקה מצטברת מול אשתקד'!A3,'מור'!A:K,9,0)+VLOOKUP('תפוקה מצטברת מול אשתקד'!A3,'אלטשולר שחם'!A:K,9,0)+VLOOKUP('תפוקה מצטברת מול אשתקד'!A3,'מדיהו '!A:K,9,0)+VLOOKUP('תפוקה מצטברת מול אשתקד'!A3,'אנליסט '!A:K,9,0)+VLOOKUP('תפוקה מצטברת מול אשתקד'!A3,'מיטב דש'!A:K,9,0)+VLOOKUP('תפוקה מצטברת מול אשתקד'!A3,'אינפניטי'!A:K,9,0) -> 840867.93 | N3: =VLOOKUP(A3,'הכשרה'!A:K,10,0)+VLOOKUP('תפוקה מצטברת מול אשתקד'!A3,'מגדל'!A:K,10,0)+VLOOKUP('תפוקה מצטברת מול אשתקד'!A3,'מנורה'!A:K,10,0)+VLOOKUP('תפוקה מצטברת מול אשתקד'!A3,'איילון'!A:K,10,0)+VLOOKUP('תפוקה מצטברת מול אשתקד'!A3,'הראל'!A:K,10,0)+VLOOKUP('תפוקה מצטברת מול אשתקד'!A3,'הפניקס'!A:K,10,0)+VLOOKUP('תפוקה מצטברת מול אשתקד'!A3,'כלל'!A:K,10,0)+VLOOKUP('תפוקה מצטברת מול אשתקד'!A3,'מור'!A:K,10,0)+VLOOKUP('תפוקה מצטברת מול אשתקד'!A3,'אלטשולר שחם'!A:K,10,0)+VLOOKUP('תפוקה מצטברת מול אשתקד'!A3,'מדיהו '!A:K,10,0)+VLOOKUP('תפוקה מצטברת מול אשתקד'!A3,'אנליסט '!A:K,10,0)+VLOOKUP('תפוקה מצטברת מול אשתקד'!A3,'מיטב דש'!A:K,10,0)+VLOOKUP('תפוקה מצטברת מול אשתקד'!A3,'אינפניטי'!A:K,10,0) -> 15935471 | O3: =VLOOKUP(A3,'הכשרה'!A:K,11,0)+VLOOKUP('תפוקה מצטברת מול אשתקד'!A3,'מגדל'!A:K,11,0)+VLOOKUP('תפוקה מצטברת מול אשתקד'!A3,'מנורה'!A:K,11,0)+VLOOKUP('תפוקה מצטברת מול אשתקד'!A3,'איילון'!A:K,11,0)+VLOOKUP('תפוקה מצטברת מול אשתקד'!A3,'הראל'!A:K,11,0)+VLOOKUP('תפוקה מצטברת מול אשתקד'!A3,'הפניקס'!A:K,11,0)+VLOOKUP('תפוקה מצטברת מול אשתקד'!A3,'כלל'!A:K,11,0)+VLOOKUP('תפוקה מצטברת מול אשתקד'!A3,'מור'!A:K,11,0)+VLOOKUP('תפוקה מצטברת מול אשתקד'!A3,'אלטשולר שחם'!A:K,11,0)+VLOOKUP('תפוקה מצטברת מול אשתקד'!A3,'מדיהו '!A:K,11,0)+VLOOKUP('תפוקה מצטברת מול אשתקד'!A3,'אנליסט '!A:K,11,0)+VLOOKUP('תפוקה מצטברת מול אשתקד'!A3,'מיטב דש'!A:K,11,0)+VLOOKUP('תפוקה מצטברת מול אשתקד'!A3,'אינפניטי'!A:K,11,0) -> 25997172
A4: דניאלה אביב | B4: יוסי אביב | C4: ישירים | D4: =IF(H4=0,0%,IF(L4=0,100%,H4/L4-1)) -> -0.43877468 | E4: =IF(I4=0,0%,IF(M4=0,100%,I4/M4-1)) -> -0.42272162 | F4: =IF(J4=0,0%,IF(N4=0,100%,J4/N4-1)) -> -0.49415328 | G4: =IF(K4=0,0%,IF(O4=H30,100%,K4/O4-1)) -> -0.83586763 | H4: =VLOOKUP(A4,'הכשרה'!A:G,4,0)+VLOOKUP('תפוקה מצטברת מול אשתקד'!A4,'מגדל'!A:G,4,0)+VLOOKUP('תפוקה מצטברת מול אשתקד'!A4,'מנורה'!A:G,4,0)+VLOOKUP('תפוקה מצטברת מול אשתקד'!A4,'איילון'!A:G,4,0)+VLOOKUP('תפוקה מצטברת מול אשתקד'!A4,'הראל'!A:G,4,0)+VLOOKUP('תפוקה מצטברת מול אשתקד'!A4,'הפניקס'!A:G,4,0)+VLOOKUP('תפוקה מצטברת מול אשתקד'!A4,'כלל'!A:G,4,0)+VLOOKUP('תפוקה מצטברת מול אשתקד'!A4,'מור'!A:G,4,0)+VLOOKUP('תפוקה מצטברת מול אשתקד'!A4,'אלטשולר שחם'!A:G,4,0)+VLOOKUP('תפוקה מצטברת מול אשתקד'!A4,'מדיהו '!A:G,4,0)+VLOOKUP('תפוקה מצטברת מול אשתקד'!A4,'אנליסט '!A:G,4,0)+VLOOKUP('תפוקה מצטברת מול אשתקד'!A4,'מיטב דש'!A:G,4,0)+VLOOKUP('תפוקה מצטברת מול אשתקד'!A4,'אינפניטי'!A:G,4,0) -> 430369.65 | I4: =VLOOKUP(A4,'הכשרה'!A:G,5,0)+VLOOKUP('תפוקה מצטברת מול אשתקד'!A4,'מגדל'!A:G,5,0)+VLOOKUP('תפוקה מצטברת מול אשתקד'!A4,'מנורה'!A:G,5,0)+VLOOKUP('תפוקה מצטברת מול אשתקד'!A4,'איילון'!A:G,5,0)+VLOOKUP('תפוקה מצטברת מול אשתקד'!A4,'הראל'!A:G,5,0)+VLOOKUP('תפוקה מצטברת מול אשתקד'!A4,'הפניקס'!A:G,5,0)+VLOOKUP('תפוקה מצטברת מול אשתקד'!A4,'כלל'!A:G,5,0)+VLOOKUP('תפוקה מצטברת מול אשתקד'!A4,'מור'!A:G,5,0)+VLOOKUP('תפוקה מצטברת מול אשתקד'!A4,'אלטשולר שחם'!A:G,5,0)+VLOOKUP('תפוקה מצטברת מול אשתקד'!A4,'מדיהו '!A:G,5,0)+VLOOKUP('תפוקה מצטברת מול אשתקד'!A4,'אנליסט '!A:G,5,0)+VLOOKUP('תפוקה מצטברת מול אשתקד'!A4,'מיטב דש'!A:G,5,0)+VLOOKUP('תפוקה מצטברת מול אשתקד'!A4,'אינפניטי'!A:G,5,0) -> 3951.3062 | J4: =VLOOKUP(A4,'הכשרה'!A:G,6,0)+VLOOKUP('תפוקה מצטברת מול אשתקד'!A4,'מגדל'!A:G,6,0)+VLOOKUP('תפוקה מצטברת מול אשתקד'!A4,'מנורה'!A:G,6,0)+VLOOKUP('תפוקה מצטברת מול אשתקד'!A4,'איילון'!A:G,6,0)+VLOOKUP(A4,'הראל'!A:G,6,0)+VLOOKUP('תפוקה מצטברת מול אשתקד'!A4,'הפניקס'!A:G,6,0)+VLOOKUP('תפוקה מצטברת מול אשתקד'!A4,'כלל'!A:G,6,0)+VLOOKUP('תפוקה מצטברת מול אשתקד'!A4,'מור'!A:G,6,0)+VLOOKUP('תפוקה מצטברת מול אשתקד'!A4,'אלטשולר שחם'!A:G,6,0)+VLOOKUP('תפוקה מצטברת מול אשתקד'!A4,'מדיהו '!A:G,6,0)+VLOOKUP('תפוקה מצטברת מול אשתקד'!A4,'אנליסט '!A:G,6,0)+VLOOKUP('תפוקה מצטברת מול אשתקד'!A4,'מיטב דש'!A:G,6,0)+VLOOKUP('תפוקה מצטברת מול אשתקד'!A4,'אינפניטי'!A:G,6,0) -> 2919925 | K4: =VLOOKUP(A4,'הכשרה'!A:G,7,0)+VLOOKUP('תפוקה מצטברת מול אשתקד'!A4,'מגדל'!A:G,7,0)+VLOOKUP('תפוקה מצטברת מול אשתקד'!A4,'מנורה'!A:G,7,0)+VLOOKUP('תפוקה מצטברת מול אשתקד'!A4,'איילון'!A:G,7,0)+VLOOKUP('תפוקה מצטברת מול אשתקד'!A4,'הראל'!A:G,7,0)+VLOOKUP('תפוקה מצטברת מול אשתקד'!A4,'הפניקס'!A:G,7,0)+VLOOKUP('תפוקה מצטברת מול אשתקד'!A4,'כלל'!A:G,7,0)+VLOOKUP('תפוקה מצטברת מול אשתקד'!A4,'מור'!A:G,7,0)+VLOOKUP('תפוקה מצטברת מול אשתקד'!A4,'אלטשולר שחם'!A:G,7,0)+VLOOKUP('תפוקה מצטברת מול אשתקד'!A4,'מדיהו '!A:K,7,0)+VLOOKUP(A4,'אנליסט '!A:G,7,0)+VLOOKUP('תפוקה מצטברת מול אשתקד'!A4,'מיטב דש'!A:G,7,0)+VLOOKUP('תפוקה מצטברת מול אשתקד'!A4,'אינפניטי'!A:G,7,0) -> 1041834.2 | L4: =VLOOKUP(A4,'הכשרה'!A:K,8,0)+VLOOKUP('תפוקה מצטברת מול אשתקד'!A4,'מגדל'!A:K,8,0)+VLOOKUP('תפוקה מצטברת מול אשתקד'!A4,'מנורה'!A:K,8,0)+VLOOKUP('תפוקה מצטברת מול אשתקד'!A4,'איילון'!A:K,8,0)+VLOOKUP('תפוקה מצטברת מול אשתקד'!A4,'הראל'!A:K,8,0)+VLOOKUP('תפוקה מצטברת מול אשתקד'!A4,'הפניקס'!A:K,8,0)+VLOOKUP('תפוקה מצטברת מול אשתקד'!A4,'כלל'!A:K,8,0)+VLOOKUP('תפוקה מצטברת מול אשתקד'!A4,'מור'!A:K,8,0)+VLOOKUP('תפוקה מצטברת מול אשתקד'!A4,'אלטשולר שחם'!A:K,8,0)+VLOOKUP('תפוקה מצטברת מול אשתקד'!A4,'מדיהו '!A:K,8,0)+VLOOKUP('תפוקה מצטברת מול אשתקד'!A4,'אנליסט '!A:K,8,0)+VLOOKUP('תפוקה מצטברת מול אשתקד'!A4,'מיטב דש'!A:K,8,0)+VLOOKUP('תפוקה מצטברת מול אשתקד'!A4,'אינפניטי'!A:K,8,0) -> 766839.34 | M4: =VLOOKUP(A4,'הכשרה'!A:K,9,0)+VLOOKUP('תפוקה מצטברת מול אשתקד'!A4,'מגדל'!A:K,9,0)+VLOOKUP('תפוקה מצטברת מול אשתקד'!A4,'מנורה'!A:K,9,0)+VLOOKUP('תפוקה מצטברת מול אשתקד'!A4,'איילון'!A:K,9,0)+VLOOKUP('תפוקה מצטברת מול אשתקד'!A4,'הראל'!A:K,9,0)+VLOOKUP('תפוקה מצטברת מול אשתקד'!A4,'הפניקס'!A:K,9,0)+VLOOKUP('תפוקה מצטברת מול אשתקד'!A4,'כלל'!A:K,9,0)+VLOOKUP('תפוקה מצטברת מול אשתקד'!A4,'מור'!A:K,9,0)+VLOOKUP('תפוקה מצטברת מול אשתקד'!A4,'אלטשולר שחם'!A:K,9,0)+VLOOKUP('תפוקה מצטברת מול אשתקד'!A4,'מדיהו '!A:K,9,0)+VLOOKUP('תפוקה מצטברת מול אשתקד'!A4,'אנליסט '!A:K,9,0)+VLOOKUP('תפוקה מצטברת מול אשתקד'!A4,'מיטב דש'!A:K,9,0)+VLOOKUP('תפוקה מצטברת מול אשתקד'!A4,'אינפניטי'!A:K,9,0) -> 6844.7154 | N4: =VLOOKUP(A4,'הכשרה'!A:K,10,0)+VLOOKUP('תפוקה מצטברת מול אשתקד'!A4,'מגדל'!A:K,10,0)+VLOOKUP('תפוקה מצטברת מול אשתקד'!A4,'מנורה'!A:K,10,0)+VLOOKUP('תפוקה מצטברת מול אשתקד'!A4,'איילון'!A:K,10,0)+VLOOKUP('תפוקה מצטברת מול אשתקד'!A4,'הראל'!A:K,10,0)+VLOOKUP('תפוקה מצטברת מול אשתקד'!A4,'הפניקס'!A:K,10,0)+VLOOKUP('תפוקה מצטברת מול אשתקד'!A4,'כלל'!A:K,10,0)+VLOOKUP('תפוקה מצטברת מול אשתקד'!A4,'מור'!A:K,10,0)+VLOOKUP('תפוקה מצטברת מול אשתקד'!A4,'אלטשולר שחם'!A:K,10,0)+VLOOKUP('תפוקה מצטברת מול אשתקד'!A4,'מדיהו '!A:K,10,0)+VLOOKUP('תפוקה מצטברת מול אשתקד'!A4,'אנליסט '!A:K,10,0)+VLOOKUP('תפוקה מצטברת מול אשתקד'!A4,'מיטב דש'!A:K,10,0)+VLOOKUP('תפוקה מצטברת מול אשתקד'!A4,'אינפניטי'!A:K,10,0) -> 5772351.3 | O4: =VLOOKUP(A4,'הכשרה'!A:K,11,0)+VLOOKUP('תפוקה מצטברת מול אשתקד'!A4,'מגדל'!A:K,11,0)+VLOOKUP('תפוקה מצטברת מול אשתקד'!A4,'מנורה'!A:K,11,0)+VLOOKUP('תפוקה מצטברת מול אשתקד'!A4,'איילון'!A:K,11,0)+VLOOKUP('תפוקה מצטברת מול אשתקד'!A4,'הראל'!A:K,11,0)+VLOOKUP('תפוקה מצטברת מול אשתקד'!A4,'הפניקס'!A:K,11,0)+VLOOKUP('תפוקה מצטברת מול אשתקד'!A4,'כלל'!A:K,11,0)+VLOOKUP('תפוקה מצטברת מול אשתקד'!A4,'מור'!A:K,11,0)+VLOOKUP('תפוקה מצטברת מול אשתקד'!A4,'אלטשולר שחם'!A:K,11,0)+VLOOKUP('תפוקה מצטברת מול אשתקד'!A4,'מדיהו '!A:K,11,0)+VLOOKUP('תפוקה מצטברת מול אשתקד'!A4,'אנליסט '!A:K,11,0)+VLOOKUP('תפוקה מצטברת מול אשתקד'!A4,'מיטב דש'!A:K,11,0)+VLOOKUP('תפוקה מצטברת מול אשתקד'!A4,'אינפניטי'!A:K,11,0) -> 6347524.3
A5: רותי | B5: יוסי אביב | C5: ישירים | D5: =IF(H5=0,0%,IF(L5=0,100%,H5/L5-1)) -> 0 | E5: =IF(I5=0,0%,IF(M5=0,100%,I5/M5-1)) -> 1 | F5: =IF(J5=0,0%,IF(N5=0,100%,J5/N5-1)) -> 1 | G5: =IF(K5=0,0%,IF(O5=H31,100%,K5/O5-1)) -> 0 | H5: =VLOOKUP(A5,'הכשרה'!A:G,4,0)+VLOOKUP('תפוקה מצטברת מול אשתקד'!A5,'מגדל'!A:G,4,0)+VLOOKUP('תפוקה מצטברת מול אשתקד'!A5,'מנורה'!A:G,4,0)+VLOOKUP('תפוקה מצטברת מול אשתקד'!A5,'איילון'!A:G,4,0)+VLOOKUP('תפוקה מצטברת מול אשתקד'!A5,'הראל'!A:G,4,0)+VLOOKUP('תפוקה מצטברת מול אשתקד'!A5,'הפניקס'!A:G,4,0)+VLOOKUP('תפוקה מצטברת מול אשתקד'!A5,'כלל'!A:G,4,0)+VLOOKUP('תפוקה מצטברת מול אשתקד'!A5,'מור'!A:G,4,0)+VLOOKUP('תפוקה מצטברת מול אשתקד'!A5,'אלטשולר שחם'!A:G,4,0)+VLOOKUP('תפוקה מצטברת מול אשתקד'!A5,'מדיהו '!A:G,4,0)+VLOOKUP('תפוקה מצטברת מול אשתקד'!A5,'אנליסט '!A:G,4,0)+VLOOKUP('תפוקה מצטברת מול אשתקד'!A5,'מיטב דש'!A:G,4,0)+VLOOKUP('תפוקה מצטברת מול אשתקד'!A5,'אינפניטי'!A:G,4,0) -> 0 | I5: =VLOOKUP(A5,'הכשרה'!A:G,5,0)+VLOOKUP('תפוקה מצטברת מול אשתקד'!A5,'מגדל'!A:G,5,0)+VLOOKUP('תפוקה מצטברת מול אשתקד'!A5,'מנורה'!A:G,5,0)+VLOOKUP('תפוקה מצטברת מול אשתקד'!A5,'איילון'!A:G,5,0)+VLOOKUP('תפוקה מצטברת מול אשתקד'!A5,'הראל'!A:G,5,0)+VLOOKUP('תפוקה מצטברת מול אשתקד'!A5,'הפניקס'!A:G,5,0)+VLOOKUP('תפוקה מצטברת מול אשתקד'!A5,'כלל'!A:G,5,0)+VLOOKUP('תפוקה מצטברת מול אשתקד'!A5,'מור'!A:G,5,0)+VLOOKUP('תפוקה מצטברת מול אשתקד'!A5,'אלטשולר שחם'!A:G,5,0)+VLOOKUP('תפוקה מצטברת מול אשתקד'!A5,'מדיהו '!A:G,5,0)+VLOOKUP('תפוקה מצטברת מול אשתקד'!A5,'אנליסט '!A:G,5,0)+VLOOKUP('תפוקה מצטברת מול אשתקד'!A5,'מיטב דש'!A:G,5,0)+VLOOKUP('תפוקה מצטברת מול אשתקד'!A5,'אינפניטי'!A:G,5,0) -> 53005.696 | J5: =VLOOKUP(A5,'הכשרה'!A:G,6,0)+VLOOKUP('תפוקה מצטברת מול אשתקד'!A5,'מגדל'!A:G,6,0)+VLOOKUP('תפוקה מצטברת מול אשתקד'!A5,'מנורה'!A:G,6,0)+VLOOKUP('תפוקה מצטברת מול אשתקד'!A5,'איילון'!A:G,6,0)+VLOOKUP(A5,'הראל'!A:G,6,0)+VLOOKUP('תפוקה מצטברת מול אשתקד'!A5,'הפניקס'!A:G,6,0)+VLOOKUP('תפוקה מצטברת מול אשתקד'!A5,'כלל'!A:G,6,0)+VLOOKUP('תפוקה מצטברת מול אשתקד'!A5,'מור'!A:G,6,0)+VLOOKUP('תפוקה מצטברת מול אשתקד'!A5,'אלטשולר שחם'!A:G,6,0)+VLOOKUP('תפוקה מצטברת מול אשתקד'!A5,'מדיהו '!A:G,6,0)+VLOOKUP('תפוקה מצטברת מול אשתקד'!A5,'אנליסט '!A:G,6,0)+VLOOKUP('תפוקה מצטברת מול אשתקד'!A5,'מיטב דש'!A:G,6,0)+VLOOKUP('תפוקה מצטברת מול אשתקד'!A5,'אינפניטי'!A:G,6,0) -> 300000 | K5: =VLOOKUP(A5,'הכשרה'!A:G,7,0)+VLOOKUP('תפוקה מצטברת מול אשתקד'!A5,'מגדל'!A:G,7,0)+VLOOKUP('תפוקה מצטברת מול אשתקד'!A5,'מנורה'!A:G,7,0)+VLOOKUP('תפוקה מצטברת מול אשתקד'!A5,'איילון'!A:G,7,0)+VLOOKUP('תפוקה מצטברת מול אשתקד'!A5,'הראל'!A:G,7,0)+VLOOKUP('תפוקה מצטברת מול אשתקד'!A5,'הפניקס'!A:G,7,0)+VLOOKUP('תפוקה מצטברת מול אשתקד'!A5,'כלל'!A:G,7,0)+VLOOKUP('תפוקה מצטברת מול אשתקד'!A5,'מור'!A:G,7,0)+VLOOKUP('תפוקה מצטברת מול אשתקד'!A5,'אלטשולר שחם'!A:G,7,0)+VLOOKUP('תפוקה מצטברת מול אשתקד'!A5,'מדיהו '!A:K,7,0)+VLOOKUP(A5,'אנליסט '!A:G,7,0)+VLOOKUP('תפוקה מצטברת מול אשתקד'!A5,'מיטב דש'!A:G,7,0)+VLOOKUP('תפוקה מצטברת מול אשתקד'!A5,'אינפניטי'!A:G,7,0) -> 0 | L5: =VLOOKUP(A5,'הכשרה'!A:K,8,0)+VLOOKUP('תפוקה מצטברת מול אשתקד'!A5,'מגדל'!A:K,8,0)+VLOOKUP('תפוקה מצטברת מול אשתקד'!A5,'מנורה'!A:K,8,0)+VLOOKUP('תפוקה מצטברת מול אשתקד'!A5,'איילון'!A:K,8,0)+VLOOKUP('תפוקה מצטברת מול אשתקד'!A5,'הראל'!A:K,8,0)+VLOOKUP('תפוקה מצטברת מול אשתקד'!A5,'הפניקס'!A:K,8,0)+VLOOKUP('תפוקה מצטברת מול אשתקד'!A5,'כלל'!A:K,8,0)+VLOOKUP('תפוקה מצטברת מול אשתקד'!A5,'מור'!A:K,8,0)+VLOOKUP('תפוקה מצטברת מול אשתקד'!A5,'אלטשולר שחם'!A:K,8,0)+VLOOKUP('תפוקה מצטברת מול אשתקד'!A5,'מדיהו '!A:K,8,0)+VLOOKUP('תפוקה מצטברת מול אשתקד'!A5,'אנליסט '!A:K,8,0)+VLOOKUP('תפוקה מצטברת מול אשתקד'!A5,'מיטב דש'!A:K,8,0)+VLOOKUP('תפוקה מצטברת מול אשתקד'!A5,'אינפניטי'!A:K,8,0) -> 0 | M5: =VLOOKUP(A5,'הכשרה'!A:K,9,0)+VLOOKUP('תפוקה מצטברת מול אשתקד'!A5,'מגדל'!A:K,9,0)+VLOOKUP('תפוקה מצטברת מול אשתקד'!A5,'מנורה'!A:K,9,0)+VLOOKUP('תפוקה מצטברת מול אשתקד'!A5,'איילון'!A:K,9,0)+VLOOKUP('תפוקה מצטברת מול אשתקד'!A5,'הראל'!A:K,9,0)+VLOOKUP('תפוקה מצטברת מול אשתקד'!A5,'הפניקס'!A:K,9,0)+VLOOKUP('תפוקה מצטברת מול אשתקד'!A5,'כלל'!A:K,9,0)+VLOOKUP('תפוקה מצטברת מול אשתקד'!A5,'מור'!A:K,9,0)+VLOOKUP('תפוקה מצטברת מול אשתקד'!A5,'אלטשולר שחם'!A:K,9,0)+VLOOKUP('תפוקה מצטברת מול אשתקד'!A5,'מדיהו '!A:K,9,0)+VLOOKUP('תפוקה מצטברת מול אשתקד'!A5,'אנליסט '!A:K,9,0)+VLOOKUP('תפוקה מצטברת מול אשתקד'!A5,'מיטב דש'!A:K,9,0)+VLOOKUP('תפוקה מצטברת מול אשתקד'!A5,'אינפניטי'!A:K,9,0) -> 0 | N5: =VLOOKUP(A5,'הכשרה'!A:K,10,0)+VLOOKUP('תפוקה מצטברת מול אשתקד'!A5,'מגדל'!A:K,10,0)+VLOOKUP('תפוקה מצטברת מול אשתקד'!A5,'מנורה'!A:K,10,0)+VLOOKUP('תפוקה מצטברת מול אשתקד'!A5,'איילון'!A:K,10,0)+VLOOKUP('תפוקה מצטברת מול אשתקד'!A5,'הראל'!A:K,10,0)+VLOOKUP('תפוקה מצטברת מול אשתקד'!A5,'הפניקס'!A:K,10,0)+VLOOKUP('תפוקה מצטברת מול אשתקד'!A5,'כלל'!A:K,10,0)+VLOOKUP('תפוקה מצטברת מול אשתקד'!A5,'מור'!A:K,10,0)+VLOOKUP('תפוקה מצטברת מול אשתקד'!A5,'אלטשולר שחם'!A:K,10,0)+VLOOKUP('תפוקה מצטברת מול אשתקד'!A5,'מדיהו '!A:K,10,0)+VLOOKUP('תפוקה מצטברת מול אשתקד'!A5,'אנליסט '!A:K,10,0)+VLOOKUP('תפוקה מצטברת מול אשתקד'!A5,'מיטב דש'!A:K,10,0)+VLOOKUP('תפוקה מצטברת מול אשתקד'!A5,'אינפניטי'!A:K,10,0) -> 0 | O5: =VLOOKUP(A5,'הכשרה'!A:K,11,0)+VLOOKUP('תפוקה מצטברת מול אשתקד'!A5,'מגדל'!A:K,11,0)+VLOOKUP('תפוקה מצטברת מול אשתקד'!A5,'מנורה'!A:K,11,0)+VLOOKUP('תפוקה מצטברת מול אשתקד'!A5,'איילון'!A:K,11,0)+VLOOKUP('תפוקה מצטברת מול אשתקד'!A5,'הראל'!A:K,11,0)+VLOOKUP('תפוקה מצטברת מול אשתקד'!A5,'הפניקס'!A:K,11,0)+VLOOKUP('תפוקה מצטברת מול אשתקד'!A5,'כלל'!A:K,11,0)+VLOOKUP('תפוקה מצטברת מול אשתקד'!A5,'מור'!A:K,11,0)+VLOOKUP('תפוקה מצטברת מול אשתקד'!A5,'אלטשולר שחם'!A:K,11,0)+VLOOKUP('תפוקה מצטברת מול אשתקד'!A5,'מדיהו '!A:K,11,0)+VLOOKUP('תפוקה מצטברת מול אשתקד'!A5,'אנליסט '!A:K,11,0)+VLOOKUP('תפוקה מצטברת מול אשתקד'!A5,'מיטב דש'!A:K,11,0)+VLOOKUP('תפוקה מצטברת מול אשתקד'!A5,'אינפניטי'!A:K,11,0) -> 0
A6: אילנית | B6: יוסי אביב | C6: ישירים | D6: =IF(H6=0,0%,IF(L6=0,100%,H6/L6-1)) -> 1 | E6: =IF(I6=0,0%,IF(M6=0,100%,I6/M6-1)) -> 1 | F6: =IF(J6=0,0%,IF(N6=0,100%,J6/N6-1)) -> 1 | G6: 1 | H6: =VLOOKUP(A6,'הכשרה'!A:G,4,0)+VLOOKUP('תפוקה מצטברת מול אשתקד'!A6,'מגדל'!A:G,4,0)+VLOOKUP('תפוקה מצטברת מול אשתקד'!A6,'מנורה'!A:G,4,0)+VLOOKUP('תפוקה מצטברת מול אשתקד'!A6,'איילון'!A:G,4,0)+VLOOKUP('תפוקה מצטברת מול אשתקד'!A6,'הראל'!A:G,4,0)+VLOOKUP('תפוקה מצטברת מול אשתקד'!A6,'הפניקס'!A:G,4,0)+VLOOKUP('תפוקה מצטברת מול אשתקד'!A6,'כלל'!A:G,4,0)+VLOOKUP('תפוקה מצטברת מול אשתקד'!A6,'מור'!A:G,4,0)+VLOOKUP('תפוקה מצטברת מול אשתקד'!A6,'אלטשולר שחם'!A:G,4,0)+VLOOKUP('תפוקה מצטברת מול אשתקד'!A6,'מדיהו '!A:G,4,0)+VLOOKUP('תפוקה מצטברת מול אשתקד'!A6,'אנליסט '!A:G,4,0)+VLOOKUP('תפוקה מצטברת מול אשתקד'!A6,'מיטב דש'!A:G,4,0)+VLOOKUP('תפוקה מצטברת מול אשתקד'!A6,'אינפניטי'!A:G,4,0) -> 94229.891 | I6: =VLOOKUP(A6,'הכשרה'!A:G,5,0)+VLOOKUP('תפוקה מצטברת מול אשתקד'!A6,'מגדל'!A:G,5,0)+VLOOKUP('תפוקה מצטברת מול אשתקד'!A6,'מנורה'!A:G,5,0)+VLOOKUP('תפוקה מצטברת מול אשתקד'!A6,'איילון'!A:G,5,0)+VLOOKUP('תפוקה מצטברת מול אשתקד'!A6,'הראל'!A:G,5,0)+VLOOKUP('תפוקה מצטברת מול אשתקד'!A6,'הפניקס'!A:G,5,0)+VLOOKUP('תפוקה מצטברת מול אשתקד'!A6,'כלל'!A:G,5,0)+VLOOKUP('תפוקה מצטברת מול אשתקד'!A6,'מור'!A:G,5,0)+VLOOKUP('תפוקה מצטברת מול אשתקד'!A6,'אלטשולר שחם'!A:G,5,0)+VLOOKUP('תפוקה מצטברת מול אשתקד'!A6,'מדיהו '!A:G,5,0)+VLOOKUP('תפוקה מצטברת מול אשתקד'!A6,'אנליסט '!A:G,5,0)+VLOOKUP('תפוקה מצטברת מול אשתקד'!A6,'מיטב דש'!A:G,5,0)+VLOOKUP('תפוקה מצטברת מול אשתקד'!A6,'אינפניטי'!A:G,5,0) -> 40998.678 | J6: =VLOOKUP(A6,'הכשרה'!A:G,6,0)+VLOOKUP('תפוקה מצטברת מול אשתקד'!A6,'מגדל'!A:G,6,0)+VLOOKUP('תפוקה מצטברת מול אשתקד'!A6,'מנורה'!A:G,6,0)+VLOOKUP('תפוקה מצטברת מול אשתקד'!A6,'איילון'!A:G,6,0)+VLOOKUP(A6,'הראל'!A:G,6,0)+VLOOKUP('תפוקה מצטברת מול אשתקד'!A6,'הפניקס'!A:G,6,0)+VLOOKUP('תפוקה מצטברת מול אשתקד'!A6,'כלל'!A:G,6,0)+VLOOKUP('תפוקה מצטברת מול אשתקד'!A6,'מור'!A:G,6,0)+VLOOKUP('תפוקה מצטברת מול אשתקד'!A6,'אלטשולר שחם'!A:G,6,0)+VLOOKUP('תפוקה מצטברת מול אשתקד'!A6,'מדיהו '!A:G,6,0)+VLOOKUP('תפוקה מצטברת מול אשתקד'!A6,'אנליסט '!A:G,6,0)+VLOOKUP('תפוקה מצטברת מול אשתקד'!A6,'מיטב דש'!A:G,6,0)+VLOOKUP('תפוקה מצטברת מול אשתקד'!A6,'אינפניטי'!A:G,6,0) -> 785770.34 | K6: =VLOOKUP(A6,'הכשרה'!A:G,7,0)+VLOOKUP('תפוקה מצטברת מול אשתקד'!A6,'מגדל'!A:G,7,0)+VLOOKUP('תפוקה מצטברת מול אשתקד'!A6,'מנורה'!A:G,7,0)+VLOOKUP('תפוקה מצטברת מול אשתקד'!A6,'איילון'!A:G,7,0)+VLOOKUP('תפוקה מצטברת מול אשתקד'!A6,'הראל'!A:G,7,0)+VLOOKUP('תפוקה מצטברת מול אשתקד'!A6,'הפניקס'!A:G,7,0)+VLOOKUP('תפוקה מצטברת מול אשתקד'!A6,'כלל'!A:G,7,0)+VLOOKUP('תפוקה מצטברת מול אשתקד'!A6,'מור'!A:G,7,0)+VLOOKUP('תפוקה מצטברת מול אשתקד'!A6,'אלטשולר שחם'!A:G,7,0)+VLOOKUP('תפוקה מצטברת מול אשתקד'!A6,'מדיהו '!A:K,7,0)+VLOOKUP(A6,'אנליסט '!A:G,7,0)+VLOOKUP('תפוקה מצטברת מול אשתקד'!A6,'מיטב דש'!A:G,7,0)+VLOOKUP('תפוקה מצטברת מול אשתקד'!A6,'אינפניטי'!A:G,7,0) -> 937262.66 | L6: =VLOOKUP(A6,'הכשרה'!A:K,8,0)+VLOOKUP('תפוקה מצטברת מול אשתקד'!A6,'מגדל'!A:K,8,0)+VLOOKUP('תפוקה מצטברת מול אשתקד'!A6,'מנורה'!A:K,8,0)+VLOOKUP('תפוקה מצטברת מול אשתקד'!A6,'איילון'!A:K,8,0)+VLOOKUP('תפוקה מצטברת מול אשתקד'!A6,'הראל'!A:K,8,0)+VLOOKUP('תפוקה מצטברת מול אשתקד'!A6,'הפניקס'!A:K,8,0)+VLOOKUP('תפוקה מצטברת מול אשתקד'!A6,'כלל'!A:K,8,0)+VLOOKUP('תפוקה מצטברת מול אשתקד'!A6,'מור'!A:K,8,0)+VLOOKUP('תפוקה מצטברת מול אשתקד'!A6,'אלטשולר שחם'!A:K,8,0)+VLOOKUP('תפוקה מצטברת מול אשתקד'!A6,'מדיהו '!A:K,8,0)+VLOOKUP('תפוקה מצטברת מול אשתקד'!A6,'אנליסט '!A:K,8,0)+VLOOKUP('תפוקה מצטברת מול אשתקד'!A6,'מיטב דש'!A:K,8,0)+VLOOKUP('תפוקה מצטברת מול אשתקד'!A6,'אינפניטי'!A:K,8,0) -> 0 | M6: =VLOOKUP(A6,'הכשרה'!A:K,9,0)+VLOOKUP('תפוקה מצטברת מול אשתקד'!A6,'מגדל'!A:K,9,0)+VLOOKUP('תפוקה מצטברת מול אשתקד'!A6,'מנורה'!A:K,9,0)+VLOOKUP('תפוקה מצטברת מול אשתקד'!A6,'איילון'!A:K,9,0)+VLOOKUP('תפוקה מצטברת מול אשתקד'!A6,'הראל'!A:K,9,0)+VLOOKUP('תפוקה מצטברת מול אשתקד'!A6,'הפניקס'!A:K,9,0)+VLOOKUP('תפוקה מצטברת מול אשתקד'!A6,'כלל'!A:K,9,0)+VLOOKUP('תפוקה מצטברת מול אשתקד'!A6,'מור'!A:K,9,0)+VLOOKUP('תפוקה מצטברת מול אשתקד'!A6,'אלטשולר שחם'!A:K,9,0)+VLOOKUP('תפוקה מצטברת מול אשתקד'!A6,'מדיהו '!A:K,9,0)+VLOOKUP('תפוקה מצטברת מול אשתקד'!A6,'אנליסט '!A:K,9,0)+VLOOKUP('תפוקה מצטברת מול אשתקד'!A6,'מיטב דש'!A:K,9,0)+VLOOKUP('תפוקה מצטברת מול אשתקד'!A6,'אינפניטי'!A:K,9,0) -> 0 | N6: =VLOOKUP(A6,'הכשרה'!A:K,10,0)+VLOOKUP('תפוקה מצטברת מול אשתקד'!A6,'מגדל'!A:K,10,0)+VLOOKUP('תפוקה מצטברת מול אשתקד'!A6,'מנורה'!A:K,10,0)+VLOOKUP('תפוקה מצטברת מול אשתקד'!A6,'איילון'!A:K,10,0)+VLOOKUP('תפוקה מצטברת מול אשתקד'!A6,'הראל'!A:K,10,0)+VLOOKUP('תפוקה מצטברת מול אשתקד'!A6,'הפניקס'!A:K,10,0)+VLOOKUP('תפוקה מצטברת מול אשתקד'!A6,'כלל'!A:K,10,0)+VLOOKUP('תפוקה מצטברת מול אשתקד'!A6,'מור'!A:K,10,0)+VLOOKUP('תפוקה מצטברת מול אשתקד'!A6,'אלטשולר שחם'!A:K,10,0)+VLOOKUP('תפוקה מצטברת מול אשתקד'!A6,'מדיהו '!A:K,10,0)+VLOOKUP('תפוקה מצטברת מול אשתקד'!A6,'אנליסט '!A:K,10,0)+VLOOKUP('תפוקה מצטברת מול אשתקד'!A6,'מיטב דש'!A:K,10,0)+VLOOKUP('תפוקה מצטברת מול אשתקד'!A6,'אינפניטי'!A:K,10,0) -> 0 | O6: =VLOOKUP(A6,'הכשרה'!A:K,11,0)+VLOOKUP('תפוקה מצטברת מול אשתקד'!A6,'מגדל'!A:K,11,0)+VLOOKUP('תפוקה מצטברת מול אשתקד'!A6,'מנורה'!A:K,11,0)+VLOOKUP('תפוקה מצטברת מול אשתקד'!A6,'איילון'!A:K,11,0)+VLOOKUP('תפוקה מצטברת מול אשתקד'!A6,'הראל'!A:K,11,0)+VLOOKUP('תפוקה מצטברת מול אשתקד'!A6,'הפניקס'!A:K,11,0)+VLOOKUP('תפוקה מצטברת מול אשתקד'!A6,'כלל'!A:K,11,0)+VLOOKUP('תפוקה מצטברת מול אשתקד'!A6,'מור'!A:K,11,0)+VLOOKUP('תפוקה מצטברת מול אשתקד'!A6,'אלטשולר שחם'!A:K,11,0)+VLOOKUP('תפוקה מצטברת מול אשתקד'!A6,'מדיהו '!A:K,11,0)+VLOOKUP('תפוקה מצטברת מול אשתקד'!A6,'אנליסט '!A:K,11,0)+VLOOKUP('תפוקה מצטברת מול אשתקד'!A6,'מיטב דש'!A:K,11,0)+VLOOKUP('תפוקה מצטברת מול אשתקד'!A6,'אינפניטי'!A:K,11,0) -> 0
A7: דני פחימה | B7: יוסי אביב | C7: ישירים | D7: =IF(H7=0,0%,IF(L7=0,100%,H7/L7-1)) -> -0.51184377 | E7: =IF(I7=0,0%,IF(M7=0,100%,I7/M7-1)) -> -0.57839059 | F7: =IF(J7=0,0%,IF(N7=0,100%,J7/N7-1)) -> 0.15942432 | G7: =IF(K7=0,0%,IF(O7=H74,100%,K7/O7-1)) -> -0.49768728 | H7: =VLOOKUP(A7,'הכשרה'!A:G,4,0)+VLOOKUP('תפוקה מצטברת מול אשתקד'!A7,'מגדל'!A:G,4,0)+VLOOKUP('תפוקה מצטברת מול אשתקד'!A7,'מנורה'!A:G,4,0)+VLOOKUP('תפוקה מצטברת מול אשתקד'!A7,'איילון'!A:G,4,0)+VLOOKUP('תפוקה מצטברת מול אשתקד'!A7,'הראל'!A:G,4,0)+VLOOKUP('תפוקה מצטברת מול אשתקד'!A7,'הפניקס'!A:G,4,0)+VLOOKUP('תפוקה מצטברת מול אשתקד'!A7,'כלל'!A:G,4,0)+VLOOKUP('תפוקה מצטברת מול אשתקד'!A7,'מור'!A:G,4,0)+VLOOKUP('תפוקה מצטברת מול אשתקד'!A7,'אלטשולר שחם'!A:G,4,0)+VLOOKUP('תפוקה מצטברת מול אשתקד'!A7,'מדיהו '!A:G,4,0)+VLOOKUP('תפוקה מצטברת מול אשתקד'!A7,'אנליסט '!A:G,4,0)+VLOOKUP('תפוקה מצטברת מול אשתקד'!A7,'מיטב דש'!A:G,4,0)+VLOOKUP('תפוקה מצטברת מול אשתקד'!A7,'אינפניטי'!A:G,4,0) -> 19388.55 | I7: =VLOOKUP(A7,'הכשרה'!A:G,5,0)+VLOOKUP('תפוקה מצטברת מול אשתקד'!A7,'מגדל'!A:G,5,0)+VLOOKUP('תפוקה מצטברת מול אשתקד'!A7,'מנורה'!A:G,5,0)+VLOOKUP('תפוקה מצטברת מול אשתקד'!A7,'איילון'!A:G,5,0)+VLOOKUP('תפוקה מצטברת מול אשתקד'!A7,'הראל'!A:G,5,0)+VLOOKUP('תפוקה מצטברת מול אשתקד'!A7,'הפניקס'!A:G,5,0)+VLOOKUP('תפוקה מצטברת מול אשתקד'!A7,'כלל'!A:G,5,0)+VLOOKUP('תפוקה מצטברת מול אשתקד'!A7,'מור'!A:G,5,0)+VLOOKUP('תפוקה מצטברת מול אשתקד'!A7,'אלטשולר שחם'!A:G,5,0)+VLOOKUP('תפוקה מצטברת מול אשתקד'!A7,'מדיהו '!A:G,5,0)+VLOOKUP('תפוקה מצטברת מול אשתקד'!A7,'אנליסט '!A:G,5,0)+VLOOKUP('תפוקה מצטברת מול אשתקד'!A7,'מיטב דש'!A:G,5,0)+VLOOKUP('תפוקה מצטברת מול אשתקד'!A7,'אינפניטי'!A:G,5,0) -> 1778.28 | J7: =VLOOKUP(A7,'הכשרה'!A:G,6,0)+VLOOKUP('תפוקה מצטברת מול אשתקד'!A7,'מגדל'!A:G,6,0)+VLOOKUP('תפוקה מצטברת מול אשתקד'!A7,'מנורה'!A:G,6,0)+VLOOKUP('תפוקה מצטברת מול אשתקד'!A7,'איילון'!A:G,6,0)+VLOOKUP(A7,'הראל'!A:G,6,0)+VLOOKUP('תפוקה מצטברת מול אשתקד'!A7,'הפניקס'!A:G,6,0)+VLOOKUP('תפוקה מצטברת מול אשתקד'!A7,'כלל'!A:G,6,0)+VLOOKUP('תפוקה מצטברת מול אשתקד'!A7,'מור'!A:G,6,0)+VLOOKUP('תפוקה מצטברת מול אשתקד'!A7,'אלטשולר שחם'!A:G,6,0)+VLOOKUP('תפוקה מצטברת מול אשתקד'!A7,'מדיהו '!A:G,6,0)+VLOOKUP('תפוקה מצטברת מול אשתקד'!A7,'אנליסט '!A:G,6,0)+VLOOKUP('תפוקה מצטברת מול אשתקד'!A7,'מיטב דש'!A:G,6,0)+VLOOKUP('תפוקה מצטברת מול אשתקד'!A7,'אינפניטי'!A:G,6,0) -> 12228.97 | K7: =VLOOKUP(A7,'הכשרה'!A:G,7,0)+VLOOKUP('תפוקה מצטברת מול אשתקד'!A7,'מגדל'!A:G,7,0)+VLOOKUP('תפוקה מצטברת מול אשתקד'!A7,'מנורה'!A:G,7,0)+VLOOKUP('תפוקה מצטברת מול אשתקד'!A7,'איילון'!A:G,7,0)+VLOOKUP('תפוקה מצטברת מול אשתקד'!A7,'הראל'!A:G,7,0)+VLOOKUP('תפוקה מצטברת מול אשתקד'!A7,'הפניקס'!A:G,7,0)+VLOOKUP('תפוקה מצטברת מול אשתקד'!A7,'כלל'!A:G,7,0)+VLOOKUP('תפוקה מצטברת מול אשתקד'!A7,'מור'!A:G,7,0)+VLOOKUP('תפוקה מצטברת מול אשתקד'!A7,'אלטשולר שחם'!A:G,7,0)+VLOOKUP('תפוקה מצטברת מול אשתקד'!A7,'מדיהו '!A:K,7,0)+VLOOKUP(A7,'אנליסט '!A:G,7,0)+VLOOKUP('תפוקה מצטברת מול אשתקד'!A7,'מיטב דש'!A:G,7,0)+VLOOKUP('תפוקה מצטברת מול אשתקד'!A7,'אינפניטי'!A:G,7,0) -> 53154.27 | L7: =VLOOKUP(A7,'הכשרה'!A:K,8,0)+VLOOKUP('תפוקה מצטברת מול אשתקד'!A7,'מגדל'!A:K,8,0)+VLOOKUP('תפוקה מצטברת מול אשתקד'!A7,'מנורה'!A:K,8,0)+VLOOKUP('תפוקה מצטברת מול אשתקד'!A7,'איילון'!A:K,8,0)+VLOOKUP('תפוקה מצטברת מול אשתקד'!A7,'הראל'!A:K,8,0)+VLOOKUP('תפוקה מצטברת מול אשתקד'!A7,'הפניקס'!A:K,8,0)+VLOOKUP('תפוקה מצטברת מול אשתקד'!A7,'כלל'!A:K,8,0)+VLOOKUP('תפוקה מצטברת מול אשתקד'!A7,'מור'!A:K,8,0)+VLOOKUP('תפוקה מצטברת מול אשתקד'!A7,'אלטשולר שחם'!A:K,8,0)+VLOOKUP('תפוקה מצטברת מול אשתקד'!A7,'מדיהו '!A:K,8,0)+VLOOKUP('תפוקה מצטברת מול אשתקד'!A7,'אנליסט '!A:K,8,0)+VLOOKUP('תפוקה מצטברת מול אשתקד'!A7,'מיטב דש'!A:K,8,0)+VLOOKUP('תפוקה מצטברת מול אשתקד'!A7,'אינפניטי'!A:K,8,0) -> 39717.92 | M7: =VLOOKUP(A7,'הכשרה'!A:K,9,0)+VLOOKUP('תפוקה מצטברת מול אשתקד'!A7,'מגדל'!A:K,9,0)+VLOOKUP('תפוקה מצטברת מול אשתקד'!A7,'מנורה'!A:K,9,0)+VLOOKUP('תפוקה מצטברת מול אשתקד'!A7,'איילון'!A:K,9,0)+VLOOKUP('תפוקה מצטברת מול אשתקד'!A7,'הראל'!A:K,9,0)+VLOOKUP('תפוקה מצטברת מול אשתקד'!A7,'הפניקס'!A:K,9,0)+VLOOKUP('תפוקה מצטברת מול אשתקד'!A7,'כלל'!A:K,9,0)+VLOOKUP('תפוקה מצטברת מול אשתקד'!A7,'מור'!A:K,9,0)+VLOOKUP('תפוקה מצטברת מול אשתקד'!A7,'אלטשולר שחם'!A:K,9,0)+VLOOKUP('תפוקה מצטברת מול אשתקד'!A7,'מדיהו '!A:K,9,0)+VLOOKUP('תפוקה מצטברת מול אשתקד'!A7,'אנליסט '!A:K,9,0)+VLOOKUP('תפוקה מצטברת מול אשתקד'!A7,'מיטב דש'!A:K,9,0)+VLOOKUP('תפוקה מצטברת מול אשתקד'!A7,'אינפניטי'!A:K,9,0) -> 4217.8375 | N7: =VLOOKUP(A7,'הכשרה'!A:K,10,0)+VLOOKUP('תפוקה מצטברת מול אשתקד'!A7,'מגדל'!A:K,10,0)+VLOOKUP('תפוקה מצטברת מול אשתקד'!A7,'מנורה'!A:K,10,0)+VLOOKUP('תפוקה מצטברת מול אשתקד'!A7,'איילון'!A:K,10,0)+VLOOKUP('תפוקה מצטברת מול אשתקד'!A7,'הראל'!A:K,10,0)+VLOOKUP('תפוקה מצטברת מול אשתקד'!A7,'הפניקס'!A:K,10,0)+VLOOKUP('תפוקה מצטברת מול אשתקד'!A7,'כלל'!A:K,10,0)+VLOOKUP('תפוקה מצטברת מול אשתקד'!A7,'מור'!A:K,10,0)+VLOOKUP('תפוקה מצטברת מול אשתקד'!A7,'אלטשולר שחם'!A:K,10,0)+VLOOKUP('תפוקה מצטברת מול אשתקד'!A7,'מדיהו '!A:K,10,0)+VLOOKUP('תפוקה מצטברת מול אשתקד'!A7,'אנליסט '!A:K,10,0)+VLOOKUP('תפוקה מצטברת מול אשתקד'!A7,'מיטב דש'!A:K,10,0)+VLOOKUP('תפוקה מצטברת מול אשתקד'!A7,'אינפניטי'!A:K,10,0) -> 10547.45 | O7: =VLOOKUP(A7,'הכשרה'!A:K,11,0)+VLOOKUP('תפוקה מצטברת מול אשתקד'!A7,'מגדל'!A:K,11,0)+VLOOKUP('תפוקה מצטברת מול אשתקד'!A7,'מנורה'!A:K,11,0)+VLOOKUP('תפוקה מצטברת מול אשתקד'!A7,'איילון'!A:K,11,0)+VLOOKUP('תפוקה מצטברת מול אשתקד'!A7,'הראל'!A:K,11,0)+VLOOKUP('תפוקה מצטברת מול אשתקד'!A7,'הפניקס'!A:K,11,0)+VLOOKUP('תפוקה מצטברת מול אשתקד'!A7,'כלל'!A:K,11,0)+VLOOKUP('תפוקה מצטברת מול אשתקד'!A7,'מור'!A:K,11,0)+VLOOKUP('תפוקה מצטברת מול אשתקד'!A7,'אלטשולר שחם'!A:K,11,0)+VLOOKUP('תפוקה מצטברת מול אשתקד'!A7,'מדיהו '!A:K,11,0)+VLOOKUP('תפוקה מצטברת מול אשתקד'!A7,'אנליסט '!A:K,11,0)+VLOOKUP('תפוקה מצטברת מול אשתקד'!A7,'מיטב דש'!A:K,11,0)+VLOOKUP('תפוקה מצטברת מול אשתקד'!A7,'אינפניטי'!A:K,11,0) -> 105819.08
A8: סה"כ ישיר | D8: =IF(H8=0,0%,IF(L8=0,100%,H8/L8-1)) -> 0.59070724 | E8: =IF(I8=0,0%,IF(M8=0,100%,I8/M8-1)) -> -0.54939659 | F8: =IF(J8=0,0%,IF(N8=0,100%,J8/N8-1)) -> 0.07327677 | G8: =IF(K8=0,0%,IF(O8=H75,100%,K8/O8-1)) -> 0.62668405 | H8: =SUM(H3:H7) -> 8487571.3 | I8: =SUM(I3:I7) -> 383882.78 | J8: =SUM(J3:J7) -> 23309822 | K8: =SUM(K3:K7) -> 52786737 | L8: =SUM(L3:L7) -> 5335721.8 | M8: =SUM(M3:M7) -> 851930.49 | N8: =SUM(N3:N7) -> 21718370 | O8: =SUM(O3:O7) -> 32450516
A9: בראשית סוכנות לביטוח | B9: יוסי אביב | C9: שותפים | D9: =IF(H9=0,0%,IF(L9=0,100%,H9/L9-1)) -> 13.008987 | E9: =IF(I9=0,0%,IF(M9=0,100%,I9/M9-1)) -> 0.67705477 | F9: =IF(J9=0,0%,IF(N9=0,100%,J9/N9-1)) -> 0 | G9: =IF(K9=0,0%,IF(O9=H33,100%,K9/O9-1)) -> -0.59458265 | H9: =VLOOKUP(A9,'הכשרה'!A:G,4,0)+VLOOKUP('תפוקה מצטברת מול אשתקד'!A9,'מגדל'!A:G,4,0)+VLOOKUP('תפוקה מצטברת מול אשתקד'!A9,'מנורה'!A:G,4,0)+VLOOKUP('תפוקה מצטברת מול אשתקד'!A9,'איילון'!A:G,4,0)+VLOOKUP('תפוקה מצטברת מול אשתקד'!A9,'הראל'!A:G,4,0)+VLOOKUP('תפוקה מצטברת מול אשתקד'!A9,'הפניקס'!A:G,4,0)+VLOOKUP('תפוקה מצטברת מול אשתקד'!A9,'כלל'!A:G,4,0)+VLOOKUP('תפוקה מצטברת מול אשתקד'!A9,'מור'!A:G,4,0)+VLOOKUP('תפוקה מצטברת מול אשתקד'!A9,'אלטשולר שחם'!A:G,4,0)+VLOOKUP('תפוקה מצטברת מול אשתקד'!A9,'מדיהו '!A:G,4,0)+VLOOKUP('תפוקה מצטברת מול אשתקד'!A9,'אנליסט '!A:G,4,0)+VLOOKUP('תפוקה מצטברת מול אשתקד'!A9,'מיטב דש'!A:G,4,0)+VLOOKUP('תפוקה מצטברת מול אשתקד'!A9,'אינפניטי'!A:G,4,0) -> 37973.945 | I9: =VLOOKUP(A9,'הכשרה'!A:G,5,0)+VLOOKUP('תפוקה מצטברת מול אשתקד'!A9,'מגדל'!A:G,5,0)+VLOOKUP('תפוקה מצטברת מול אשתקד'!A9,'מנורה'!A:G,5,0)+VLOOKUP('תפוקה מצטברת מול אשתקד'!A9,'איילון'!A:G,5,0)+VLOOKUP('תפוקה מצטברת מול אשתקד'!A9,'הראל'!A:G,5,0)+VLOOKUP('תפוקה מצטברת מול אשתקד'!A9,'הפניקס'!A:G,5,0)+VLOOKUP('תפוקה מצטברת מול אשתקד'!A9,'כלל'!A:G,5,0)+VLOOKUP('תפוקה מצטברת מול אשתקד'!A9,'מור'!A:G,5,0)+VLOOKUP('תפוקה מצטברת מול אשתקד'!A9,'אלטשולר שחם'!A:G,5,0)+VLOOKUP('תפוקה מצטברת מול אשתקד'!A9,'מדיהו '!A:G,5,0)+VLOOKUP('תפוקה מצטברת מול אשתקד'!A9,'אנליסט '!A:G,5,0)+VLOOKUP('תפוקה מצטברת מול אשתקד'!A9,'מיטב דש'!A:G,5,0)+VLOOKUP('תפוקה מצטברת מול אשתקד'!A9,'אינפניטי'!A:G,5,0) -> 1173.13 | J9: =VLOOKUP(A9,'הכשרה'!A:G,6,0)+VLOOKUP('תפוקה מצטברת מול אשתקד'!A9,'מגדל'!A:G,6,0)+VLOOKUP('תפוקה מצטברת מול אשתקד'!A9,'מנורה'!A:G,6,0)+VLOOKUP('תפוקה מצטברת מול אשתקד'!A9,'איילון'!A:G,6,0)+VLOOKUP(A9,'הראל'!A:G,6,0)+VLOOKUP('תפוקה מצטברת מול אשתקד'!A9,'הפניקס'!A:G,6,0)+VLOOKUP('תפוקה מצטברת מול אשתקד'!A9,'כלל'!A:G,6,0)+VLOOKUP('תפוקה מצטברת מול אשתקד'!A9,'מור'!A:G,6,0)+VLOOKUP('תפוקה מצטברת מול אשתקד'!A9,'אלטשולר שחם'!A:G,6,0)+VLOOKUP('תפוקה מצטברת מול אשתקד'!A9,'מדיהו '!A:G,6,0)+VLOOKUP('תפוקה מצטברת מול אשתקד'!A9,'אנליסט '!A:G,6,0)+VLOOKUP('תפוקה מצטברת מול אשתקד'!A9,'מיטב דש'!A:G,6,0)+VLOOKUP('תפוקה מצטברת מול אשתקד'!A9,'אינפניטי'!A:G,6,0) -> 0 | K9: =VLOOKUP(A9,'הכשרה'!A:G,7,0)+VLOOKUP('תפוקה מצטברת מול אשתקד'!A9,'מגדל'!A:G,7,0)+VLOOKUP('תפוקה מצטברת מול אשתקד'!A9,'מנורה'!A:G,7,0)+VLOOKUP('תפוקה מצטברת מול אשתקד'!A9,'איילון'!A:G,7,0)+VLOOKUP('תפוקה מצטברת מול אשתקד'!A9,'הראל'!A:G,7,0)+VLOOKUP('תפוקה מצטברת מול אשתקד'!A9,'הפניקס'!A:G,7,0)+VLOOKUP('תפוקה מצטברת מול אשתקד'!A9,'כלל'!A:G,7,0)+VLOOKUP('תפוקה מצטברת מול אשתקד'!A9,'מור'!A:G,7,0)+VLOOKUP('תפוקה מצטברת מול אשתקד'!A9,'אלטשולר שחם'!A:G,7,0)+VLOOKUP('תפוקה מצטברת מול אשתקד'!A9,'מדיהו '!A:K,7,0)+VLOOKUP(A9,'אנליסט '!A:G,7,0)+VLOOKUP('תפוקה מצטברת מול אשתקד'!A9,'מיטב דש'!A:G,7,0)+VLOOKUP('תפוקה מצטברת מול אשתקד'!A9,'אינפניטי'!A:G,7,0) -> -321158.48 | L9: =VLOOKUP(A9,'הכשרה'!A:K,8,0)+VLOOKUP('תפוקה מצטברת מול אשתקד'!A9,'מגדל'!A:K,8,0)+VLOOKUP('תפוקה מצטברת מול אשתקד'!A9,'מנורה'!A:K,8,0)+VLOOKUP('תפוקה מצטברת מול אשתקד'!A9,'איילון'!A:K,8,0)+VLOOKUP('תפוקה מצטברת מול אשתקד'!A9,'הראל'!A:K,8,0)+VLOOKUP('תפוקה מצטברת מול אשתקד'!A9,'הפניקס'!A:K,8,0)+VLOOKUP('תפוקה מצטברת מול אשתקד'!A9,'כלל'!A:K,8,0)+VLOOKUP('תפוקה מצטברת מול אשתקד'!A9,'מור'!A:K,8,0)+VLOOKUP('תפוקה מצטברת מול אשתקד'!A9,'אלטשולר שחם'!A:K,8,0)+VLOOKUP('תפוקה מצטברת מול אשתקד'!A9,'מדיהו '!A:K,8,0)+VLOOKUP('תפוקה מצטברת מול אשתקד'!A9,'אנליסט '!A:K,8,0)+VLOOKUP('תפוקה מצטברת מול אשתקד'!A9,'מיטב דש'!A:K,8,0)+VLOOKUP('תפוקה מצטברת מול אשתקד'!A9,'אינפניטי'!A:K,8,0) -> 2710.6846 | M9: =VLOOKUP(A9,'הכשרה'!A:K,9,0)+VLOOKUP('תפוקה מצטברת מול אשתקד'!A9,'מגדל'!A:K,9,0)+VLOOKUP('תפוקה מצטברת מול אשתקד'!A9,'מנורה'!A:K,9,0)+VLOOKUP('תפוקה מצטברת מול אשתקד'!A9,'איילון'!A:K,9,0)+VLOOKUP('תפוקה מצטברת מול אשתקד'!A9,'הראל'!A:K,9,0)+VLOOKUP('תפוקה מצטברת מול אשתקד'!A9,'הפניקס'!A:K,9,0)+VLOOKUP('תפוקה מצטברת מול אשתקד'!A9,'כלל'!A:K,9,0)+VLOOKUP('תפוקה מצטברת מול אשתקד'!A9,'מור'!A:K,9,0)+VLOOKUP('תפוקה מצטברת מול אשתקד'!A9,'אלטשולר שחם'!A:K,9,0)+VLOOKUP('תפוקה מצטברת מול אשתקד'!A9,'מדיהו '!A:K,9,0)+VLOOKUP('תפוקה מצטברת מול אשתקד'!A9,'אנליסט '!A:K,9,0)+VLOOKUP('תפוקה מצטברת מול אשתקד'!A9,'מיטב דש'!A:K,9,0)+VLOOKUP('תפוקה מצטברת מול אשתקד'!A9,'אינפניטי'!A:K,9,0) -> 699.518 | N9: =VLOOKUP(A9,'הכשרה'!A:K,10,0)+VLOOKUP('תפוקה מצטברת מול אשתקד'!A9,'מגדל'!A:K,10,0)+VLOOKUP('תפוקה מצטברת מול אשתקד'!A9,'מנורה'!A:K,10,0)+VLOOKUP('תפוקה מצטברת מול אשתקד'!A9,'איילון'!A:K,10,0)+VLOOKUP('תפוקה מצטברת מול אשתקד'!A9,'הראל'!A:K,10,0)+VLOOKUP('תפוקה מצטברת מול אשתקד'!A9,'הפניקס'!A:K,10,0)+VLOOKUP('תפוקה מצטברת מול אשתקד'!A9,'כלל'!A:K,10,0)+VLOOKUP('תפוקה מצטברת מול אשתקד'!A9,'מור'!A:K,10,0)+VLOOKUP('תפוקה מצטברת מול אשתקד'!A9,'אלטשולר שחם'!A:K,10,0)+VLOOKUP('תפוקה מצטברת מול אשתקד'!A9,'מדיהו '!A:K,10,0)+VLOOKUP('תפוקה מצטברת מול אשתקד'!A9,'אנליסט '!A:K,10,0)+VLOOKUP('תפוקה מצטברת מול אשתקד'!A9,'מיטב דש'!A:K,10,0)+VLOOKUP('תפוקה מצטברת מול אשתקד'!A9,'אינפניטי'!A:K,10,0) -> 0 | O9: =VLOOKUP(A9,'הכשרה'!A:K,11,0)+VLOOKUP('תפוקה מצטברת מול אשתקד'!A9,'מגדל'!A:K,11,0)+VLOOKUP('תפוקה מצטברת מול אשתקד'!A9,'מנורה'!A:K,11,0)+VLOOKUP('תפוקה מצטברת מול אשתקד'!A9,'איילון'!A:K,11,0)+VLOOKUP('תפוקה מצטברת מול אשתקד'!A9,'הראל'!A:K,11,0)+VLOOKUP('תפוקה מצטברת מול אשתקד'!A9,'הפניקס'!A:K,11,0)+VLOOKUP('תפוקה מצטברת מול אשתקד'!A9,'כלל'!A:K,11,0)+VLOOKUP('תפוקה מצטברת מול אשתקד'!A9,'מור'!A:K,11,0)+VLOOKUP('תפוקה מצטברת מול אשתקד'!A9,'אלטשולר שחם'!A:K,11,0)+VLOOKUP('תפוקה מצטברת מול אשתקד'!A9,'מדיהו '!A:K,11,0)+VLOOKUP('תפוקה מצטברת מול אשתקד'!A9,'אנליסט '!A:K,11,0)+VLOOKUP('תפוקה מצטברת מול אשתקד'!A9,'מיטב דש'!A:K,11,0)+VLOOKUP('תפוקה מצטברת מול אשתקד'!A9,'אינפניטי'!A:K,11,0) -> -792167.57
A10: גל אלמגור דאוד סוכ' לב | B10: יוסי אביב | C10: שותפים | D10: =IF(H10=0,0%,IF(L10=0,100%,H10/L10-1)) -> 0.021415244 | E10: =IF(I10=0,0%,IF(M10=0,100%,I10/M10-1)) -> 1.005249 | F10: =IF(J10=0,0%,IF(N10=0,100%,J10/N10-1)) -> 0.26763775 | G10: =IF(K10=0,0%,IF(O10=H34,100%,K10/O10-1)) -> 0.60304406 | H10: =VLOOKUP(A10,'הכשרה'!A:G,4,0)+VLOOKUP('תפוקה מצטברת מול אשתקד'!A10,'מגדל'!A:G,4,0)+VLOOKUP('תפוקה מצטברת מול אשתקד'!A10,'מנורה'!A:G,4,0)+VLOOKUP('תפוקה מצטברת מול אשתקד'!A10,'איילון'!A:G,4,0)+VLOOKUP('תפוקה מצטברת מול אשתקד'!A10,'הראל'!A:G,4,0)+VLOOKUP('תפוקה מצטברת מול אשתקד'!A10,'הפניקס'!A:G,4,0)+VLOOKUP('תפוקה מצטברת מול אשתקד'!A10,'כלל'!A:G,4,0)+VLOOKUP('תפוקה מצטברת מול אשתקד'!A10,'מור'!A:G,4,0)+VLOOKUP('תפוקה מצטברת מול אשתקד'!A10,'אלטשולר שחם'!A:G,4,0)+VLOOKUP('תפוקה מצטברת מול אשתקד'!A10,'מדיהו '!A:G,4,0)+VLOOKUP('תפוקה מצטברת מול אשתקד'!A10,'אנליסט '!A:G,4,0)+VLOOKUP('תפוקה מצטברת מול אשתקד'!A10,'מיטב דש'!A:G,4,0)+VLOOKUP('תפוקה מצטברת מול אשתקד'!A10,'אינפניטי'!A:G,4,0) -> 802630.51 | I10: =VLOOKUP(A10,'הכשרה'!A:G,5,0)+VLOOKUP('תפוקה מצטברת מול אשתקד'!A10,'מגדל'!A:G,5,0)+VLOOKUP('תפוקה מצטברת מול אשתקד'!A10,'מנורה'!A:G,5,0)+VLOOKUP('תפוקה מצטברת מול אשתקד'!A10,'איילון'!A:G,5,0)+VLOOKUP('תפוקה מצטברת מול אשתקד'!A10,'הראל'!A:G,5,0)+VLOOKUP('תפוקה מצטברת מול אשתקד'!A10,'הפניקס'!A:G,5,0)+VLOOKUP('תפוקה מצטברת מול אשתקד'!A10,'כלל'!A:G,5,0)+VLOOKUP('תפוקה מצטברת מול אשתקד'!A10,'מור'!A:G,5,0)+VLOOKUP('תפוקה מצטברת מול אשתקד'!A10,'אלטשולר שחם'!A:G,5,0)+VLOOKUP('תפוקה מצטברת מול אשתקד'!A10,'מדיהו '!A:G,5,0)+VLOOKUP('תפוקה מצטברת מול אשתקד'!A10,'אנליסט '!A:G,5,0)+VLOOKUP('תפוקה מצטברת מול אשתקד'!A10,'מיטב דש'!A:G,5,0)+VLOOKUP('תפוקה מצטברת מול אשתקד'!A10,'אינפניטי'!A:G,5,0) -> 1023238.4 | J10: =VLOOKUP(A10,'הכשרה'!A:G,6,0)+VLOOKUP('תפוקה מצטברת מול אשתקד'!A10,'מגדל'!A:G,6,0)+VLOOKUP('תפוקה מצטברת מול אשתקד'!A10,'מנורה'!A:G,6,0)+VLOOKUP('תפוקה מצטברת מול אשתקד'!A10,'איילון'!A:G,6,0)+VLOOKUP(A10,'הראל'!A:G,6,0)+VLOOKUP('תפוקה מצטברת מול אשתקד'!A10,'הפניקס'!A:G,6,0)+VLOOKUP('תפוקה מצטברת מול אשתקד'!A10,'כלל'!A:G,6,0)+VLOOKUP('תפוקה מצטברת מול אשתקד'!A10,'מור'!A:G,6,0)+VLOOKUP('תפוקה מצטברת מול אשתקד'!A10,'אלטשולר שחם'!A:G,6,0)+VLOOKUP('תפוקה מצטברת מול אשתקד'!A10,'מדיהו '!A:G,6,0)+VLOOKUP('תפוקה מצטברת מול אשתקד'!A10,'אנליסט '!A:G,6,0)+VLOOKUP('תפוקה מצטברת מול אשתקד'!A10,'מיטב דש'!A:G,6,0)+VLOOKUP('תפוקה מצטברת מול אשתקד'!A10,'אינפניטי'!A:G,6,0) -> 336893.64 | K10: =VLOOKUP(A10,'הכשרה'!A:G,7,0)+VLOOKUP('תפוקה מצטברת מול אשתקד'!A10,'מגדל'!A:G,7,0)+VLOOKUP('תפוקה מצטברת מול אשתקד'!A10,'מנורה'!A:G,7,0)+VLOOKUP('תפוקה מצטברת מול אשתקד'!A10,'איילון'!A:G,7,0)+VLOOKUP('תפוקה מצטברת מול אשתקד'!A10,'הראל'!A:G,7,0)+VLOOKUP('תפוקה מצטברת מול אשתקד'!A10,'הפניקס'!A:G,7,0)+VLOOKUP('תפוקה מצטברת מול אשתקד'!A10,'כלל'!A:G,7,0)+VLOOKUP('תפוקה מצטברת מול אשתקד'!A10,'מור'!A:G,7,0)+VLOOKUP('תפוקה מצטברת מול אשתקד'!A10,'אלטשולר שחם'!A:G,7,0)+VLOOKUP('תפוקה מצטברת מול אשתקד'!A10,'מדיהו '!A:K,7,0)+VLOOKUP(A10,'אנליסט '!A:G,7,0)+VLOOKUP('תפוקה מצטברת מול אשתקד'!A10,'מיטב דש'!A:G,7,0)+VLOOKUP('תפוקה מצטברת מול אשתקד'!A10,'אינפניטי'!A:G,7,0) -> 1488051.8 | L10: =VLOOKUP(A10,'הכשרה'!A:K,8,0)+VLOOKUP('תפוקה מצטברת מול אשתקד'!A10,'מגדל'!A:K,8,0)+VLOOKUP('תפוקה מצטברת מול אשתקד'!A10,'מנורה'!A:K,8,0)+VLOOKUP('תפוקה מצטברת מול אשתקד'!A10,'איילון'!A:K,8,0)+VLOOKUP('תפוקה מצטברת מול אשתקד'!A10,'הראל'!A:K,8,0)+VLOOKUP('תפוקה מצטברת מול אשתקד'!A10,'הפניקס'!A:K,8,0)+VLOOKUP('תפוקה מצטברת מול אשתקד'!A10,'כלל'!A:K,8,0)+VLOOKUP('תפוקה מצטברת מול אשתקד'!A10,'מור'!A:K,8,0)+VLOOKUP('תפוקה מצטברת מול אשתקד'!A10,'אלטשולר שחם'!A:K,8,0)+VLOOKUP('תפוקה מצטברת מול אשתקד'!A10,'מדיהו '!A:K,8,0)+VLOOKUP('תפוקה מצטברת מול אשתקד'!A10,'אנליסט '!A:K,8,0)+VLOOKUP('תפוקה מצטברת מול אשתקד'!A10,'מיטב דש'!A:K,8,0)+VLOOKUP('תפוקה מצטברת מול אשתקד'!A10,'אינפניטי'!A:K,8,0) -> 785802.36 | M10: =VLOOKUP(A10,'הכשרה'!A:K,9,0)+VLOOKUP('תפוקה מצטברת מול אשתקד'!A10,'מגדל'!A:K,9,0)+VLOOKUP('תפוקה מצטברת מול אשתקד'!A10,'מנורה'!A:K,9,0)+VLOOKUP('תפוקה מצטברת מול אשתקד'!A10,'איילון'!A:K,9,0)+VLOOKUP('תפוקה מצטברת מול אשתקד'!A10,'הראל'!A:K,9,0)+VLOOKUP('תפוקה מצטברת מול אשתקד'!A10,'הפניקס'!A:K,9,0)+VLOOKUP('תפוקה מצטברת מול אשתקד'!A10,'כלל'!A:K,9,0)+VLOOKUP('תפוקה מצטברת מול אשתקד'!A10,'מור'!A:K,9,0)+VLOOKUP('תפוקה מצטברת מול אשתקד'!A10,'אלטשולר שחם'!A:K,9,0)+VLOOKUP('תפוקה מצטברת מול אשתקד'!A10,'מדיהו '!A:K,9,0)+VLOOKUP('תפוקה מצטברת מול אשתקד'!A10,'אנליסט '!A:K,9,0)+VLOOKUP('תפוקה מצטברת מול אשתקד'!A10,'מיטב דש'!A:K,9,0)+VLOOKUP('תפוקה מצטברת מול אשתקד'!A10,'אינפניטי'!A:K,9,0) -> 510279.99 | N10: =VLOOKUP(A10,'הכשרה'!A:K,10,0)+VLOOKUP('תפוקה מצטברת מול אשתקד'!A10,'מגדל'!A:K,10,0)+VLOOKUP('תפוקה מצטברת מול אשתקד'!A10,'מנורה'!A:K,10,0)+VLOOKUP('תפוקה מצטברת מול אשתקד'!A10,'איילון'!A:K,10,0)+VLOOKUP('תפוקה מצטברת מול אשתקד'!A10,'הראל'!A:K,10,0)+VLOOKUP('תפוקה מצטברת מול אשתקד'!A10,'הפניקס'!A:K,10,0)+VLOOKUP('תפוקה מצטברת מול אשתקד'!A10,'כלל'!A:K,10,0)+VLOOKUP('תפוקה מצטברת מול אשתקד'!A10,'מור'!A:K,10,0)+VLOOKUP('תפוקה מצטברת מול אשתקד'!A10,'אלטשולר שחם'!A:K,10,0)+VLOOKUP('תפוקה מצטברת מול אשתקד'!A10,'מדיהו '!A:K,10,0)+VLOOKUP('תפוקה מצטברת מול אשתקד'!A10,'אנליסט '!A:K,10,0)+VLOOKUP('תפוקה מצטברת מול אשתקד'!A10,'מיטב דש'!A:K,10,0)+VLOOKUP('תפוקה מצטברת מול אשתקד'!A10,'אינפניטי'!A:K,10,0) -> 265764.92 | O10: =VLOOKUP(A10,'הכשרה'!A:K,11,0)+VLOOKUP('תפוקה מצטברת מול אשתקד'!A10,'מגדל'!A:K,11,0)+VLOOKUP('תפוקה מצטברת מול אשתקד'!A10,'מנורה'!A:K,11,0)+VLOOKUP('תפוקה מצטברת מול אשתקד'!A10,'איילון'!A:K,11,0)+VLOOKUP('תפוקה מצטברת מול אשתקד'!A10,'הראל'!A:K,11,0)+VLOOKUP('תפוקה מצטברת מול אשתקד'!A10,'הפניקס'!A:K,11,0)+VLOOKUP('תפוקה מצטברת מול אשתקד'!A10,'כלל'!A:K,11,0)+VLOOKUP('תפוקה מצטברת מול אשתקד'!A10,'מור'!A:K,11,0)+VLOOKUP('תפוקה מצטברת מול אשתקד'!A10,'אלטשולר שחם'!A:K,11,0)+VLOOKUP('תפוקה מצטברת מול אשתקד'!A10,'מדיהו '!A:K,11,0)+VLOOKUP('תפוקה מצטברת מול אשתקד'!A10,'אנליסט '!A:K,11,0)+VLOOKUP('תפוקה מצטברת מול אשתקד'!A10,'מיטב דש'!A:K,11,0)+VLOOKUP('תפוקה מצטברת מול אשתקד'!A10,'אינפניטי'!A:K,11,0) -> 928266.34
A11: גל אלמגור -וייס סוכנות | B11: יוסי אביב | C11: שותפים | D11: =IF(H11=0,0%,IF(L11=0,100%,H11/L11-1)) -> -0.39273436 | E11: =IF(I11=0,0%,IF(M11=0,100%,I11/M11-1)) -> -0.50106264 | F11: =IF(J11=0,0%,IF(N11=0,100%,J11/N11-1)) -> 2.3072486 | G11: =IF(K11=0,0%,IF(O11=H35,100%,K11/O11-1)) -> -1.215931 | H11: =VLOOKUP(A11,'הכשרה'!A:G,4,0)+VLOOKUP('תפוקה מצטברת מול אשתקד'!A11,'מגדל'!A:G,4,0)+VLOOKUP('תפוקה מצטברת מול אשתקד'!A11,'מנורה'!A:G,4,0)+VLOOKUP('תפוקה מצטברת מול אשתקד'!A11,'איילון'!A:G,4,0)+VLOOKUP('תפוקה מצטברת מול אשתקד'!A11,'הראל'!A:G,4,0)+VLOOKUP('תפוקה מצטברת מול אשתקד'!A11,'הפניקס'!A:G,4,0)+VLOOKUP('תפוקה מצטברת מול אשתקד'!A11,'כלל'!A:G,4,0)+VLOOKUP('תפוקה מצטברת מול אשתקד'!A11,'מור'!A:G,4,0)+VLOOKUP('תפוקה מצטברת מול אשתקד'!A11,'אלטשולר שחם'!A:G,4,0)+VLOOKUP('תפוקה מצטברת מול אשתקד'!A11,'מדיהו '!A:G,4,0)+VLOOKUP('תפוקה מצטברת מול אשתקד'!A11,'אנליסט '!A:G,4,0)+VLOOKUP('תפוקה מצטברת מול אשתקד'!A11,'מיטב דש'!A:G,4,0)+VLOOKUP('תפוקה מצטברת מול אשתקד'!A11,'אינפניטי'!A:G,4,0) -> 139802.97 | I11: =VLOOKUP(A11,'הכשרה'!A:G,5,0)+VLOOKUP('תפוקה מצטברת מול אשתקד'!A11,'מגדל'!A:G,5,0)+VLOOKUP('תפוקה מצטברת מול אשתקד'!A11,'מנורה'!A:G,5,0)+VLOOKUP('תפוקה מצטברת מול אשתקד'!A11,'איילון'!A:G,5,0)+VLOOKUP('תפוקה מצטברת מול אשתקד'!A11,'הראל'!A:G,5,0)+VLOOKUP('תפוקה מצטברת מול אשתקד'!A11,'הפניקס'!A:G,5,0)+VLOOKUP('תפוקה מצטברת מול אשתקד'!A11,'כלל'!A:G,5,0)+VLOOKUP('תפוקה מצטברת מול אשתקד'!A11,'מור'!A:G,5,0)+VLOOKUP('תפוקה מצטברת מול אשתקד'!A11,'אלטשולר שחם'!A:G,5,0)+VLOOKUP('תפוקה מצטברת מול אשתקד'!A11,'מדיהו '!A:G,5,0)+VLOOKUP('תפוקה מצטברת מול אשתקד'!A11,'אנליסט '!A:G,5,0)+VLOOKUP('תפוקה מצטברת מול אשתקד'!A11,'מיטב דש'!A:G,5,0)+VLOOKUP('תפוקה מצטברת מול אשתקד'!A11,'אינפניטי'!A:G,5,0) -> 40596.432 | J11: =VLOOKUP(A11,'הכשרה'!A:G,6,0)+VLOOKUP('תפוקה מצטברת מול אשתקד'!A11,'מגדל'!A:G,6,0)+VLOOKUP('תפוקה מצטברת מול אשתקד'!A11,'מנורה'!A:G,6,0)+VLOOKUP('תפוקה מצטברת מול אשתקד'!A11,'איילון'!A:G,6,0)+VLOOKUP(A11,'הראל'!A:G,6,0)+VLOOKUP('תפוקה מצטברת מול אשתקד'!A11,'הפניקס'!A:G,6,0)+VLOOKUP('תפוקה מצטברת מול אשתקד'!A11,'כלל'!A:G,6,0)+VLOOKUP('תפוקה מצטברת מול אשתקד'!A11,'מור'!A:G,6,0)+VLOOKUP('תפוקה מצטברת מול אשתקד'!A11,'אלטשולר שחם'!A:G,6,0)+VLOOKUP('תפוקה מצטברת מול אשתקד'!A11,'מדיהו '!A:G,6,0)+VLOOKUP('תפוקה מצטברת מול אשתקד'!A11,'אנליסט '!A:G,6,0)+VLOOKUP('תפוקה מצטברת מול אשתקד'!A11,'מיטב דש'!A:G,6,0)+VLOOKUP('תפוקה מצטברת מול אשתקד'!A11,'אינפניטי'!A:G,6,0) -> 899639.48 | K11: =VLOOKUP(A11,'הכשרה'!A:G,7,0)+VLOOKUP('תפוקה מצטברת מול אשתקד'!A11,'מגדל'!A:G,7,0)+VLOOKUP('תפוקה מצטברת מול אשתקד'!A11,'מנורה'!A:G,7,0)+VLOOKUP('תפוקה מצטברת מול אשתקד'!A11,'איילון'!A:G,7,0)+VLOOKUP('תפוקה מצטברת מול אשתקד'!A11,'הראל'!A:G,7,0)+VLOOKUP('תפוקה מצטברת מול אשתקד'!A11,'הפניקס'!A:G,7,0)+VLOOKUP('תפוקה מצטברת מול אשתקד'!A11,'כלל'!A:G,7,0)+VLOOKUP('תפוקה מצטברת מול אשתקד'!A11,'מור'!A:G,7,0)+VLOOKUP('תפוקה מצטברת מול אשתקד'!A11,'אלטשולר שחם'!A:G,7,0)+VLOOKUP('תפוקה מצטברת מול אשתקד'!A11,'מדיהו '!A:K,7,0)+VLOOKUP(A11,'אנליסט '!A:G,7,0)+VLOOKUP('תפוקה מצטברת מול אשתקד'!A11,'מיטב דש'!A:G,7,0)+VLOOKUP('תפוקה מצטברת מול אשתקד'!A11,'אינפניטי'!A:G,7,0) -> 81331.63 | L11: =VLOOKUP(A11,'הכשרה'!A:K,8,0)+VLOOKUP('תפוקה מצטברת מול אשתקד'!A11,'מגדל'!A:K,8,0)+VLOOKUP('תפוקה מצטברת מול אשתקד'!A11,'מנורה'!A:K,8,0)+VLOOKUP('תפוקה מצטברת מול אשתקד'!A11,'איילון'!A:K,8,0)+VLOOKUP('תפוקה מצטברת מול אשתקד'!A11,'הראל'!A:K,8,0)+VLOOKUP('תפוקה מצטברת מול אשתקד'!A11,'הפניקס'!A:K,8,0)+VLOOKUP('תפוקה מצטברת מול אשתקד'!A11,'כלל'!A:K,8,0)+VLOOKUP('תפוקה מצטברת מול אשתקד'!A11,'מור'!A:K,8,0)+VLOOKUP('תפוקה מצטברת מול אשתקד'!A11,'אלטשולר שחם'!A:K,8,0)+VLOOKUP('תפוקה מצטברת מול אשתקד'!A11,'מדיהו '!A:K,8,0)+VLOOKUP('תפוקה מצטברת מול אשתקד'!A11,'אנליסט '!A:K,8,0)+VLOOKUP('תפוקה מצטברת מול אשתקד'!A11,'מיטב דש'!A:K,8,0)+VLOOKUP('תפוקה מצטברת מול אשתקד'!A11,'אינפניטי'!A:K,8,0) -> 230217.16 | M11: =VLOOKUP(A11,'הכשרה'!A:K,9,0)+VLOOKUP('תפוקה מצטברת מול אשתקד'!A11,'מגדל'!A:K,9,0)+VLOOKUP('תפוקה מצטברת מול אשתקד'!A11,'מנורה'!A:K,9,0)+VLOOKUP('תפוקה מצטברת מול אשתקד'!A11,'איילון'!A:K,9,0)+VLOOKUP('תפוקה מצטברת מול אשתקד'!A11,'הראל'!A:K,9,0)+VLOOKUP('תפוקה מצטברת מול אשתקד'!A11,'הפניקס'!A:K,9,0)+VLOOKUP('תפוקה מצטברת מול אשתקד'!A11,'כלל'!A:K,9,0)+VLOOKUP('תפוקה מצטברת מול אשתקד'!A11,'מור'!A:K,9,0)+VLOOKUP('תפוקה מצטברת מול אשתקד'!A11,'אלטשולר שחם'!A:K,9,0)+VLOOKUP('תפוקה מצטברת מול אשתקד'!A11,'מדיהו '!A:K,9,0)+VLOOKUP('תפוקה מצטברת מול אשתקד'!A11,'אנליסט '!A:K,9,0)+VLOOKUP('תפוקה מצטברת מול אשתקד'!A11,'מיטב דש'!A:K,9,0)+VLOOKUP('תפוקה מצטברת מול אשתקד'!A11,'אינפניטי'!A:K,9,0) -> 81365.79 | N11: =VLOOKUP(A11,'הכשרה'!A:K,10,0)+VLOOKUP('תפוקה מצטברת מול אשתקד'!A11,'מגדל'!A:K,10,0)+VLOOKUP('תפוקה מצטברת מול אשתקד'!A11,'מנורה'!A:K,10,0)+VLOOKUP('תפוקה מצטברת מול אשתקד'!A11,'איילון'!A:K,10,0)+VLOOKUP('תפוקה מצטברת מול אשתקד'!A11,'הראל'!A:K,10,0)+VLOOKUP('תפוקה מצטברת מול אשתקד'!A11,'הפניקס'!A:K,10,0)+VLOOKUP('תפוקה מצטברת מול אשתקד'!A11,'כלל'!A:K,10,0)+VLOOKUP('תפוקה מצטברת מול אשתקד'!A11,'מור'!A:K,10,0)+VLOOKUP('תפוקה מצטברת מול אשתקד'!A11,'אלטשולר שחם'!A:K,10,0)+VLOOKUP('תפוקה מצטברת מול אשתקד'!A11,'מדיהו '!A:K,10,0)+VLOOKUP('תפוקה מצטברת מול אשתקד'!A11,'אנליסט '!A:K,10,0)+VLOOKUP('תפוקה מצטברת מול אשתקד'!A11,'מיטב דש'!A:K,10,0)+VLOOKUP('תפוקה מצטברת מול אשתקד'!A11,'אינפניטי'!A:K,10,0) -> 272020.52 | O11: =VLOOKUP(A11,'הכשרה'!A:K,11,0)+VLOOKUP('תפוקה מצטברת מול אשתקד'!A11,'מגדל'!A:K,11,0)+VLOOKUP('תפוקה מצטברת מול אשתקד'!A11,'מנורה'!A:K,11,0)+VLOOKUP('תפוקה מצטברת מול אשתקד'!A11,'איילון'!A:K,11,0)+VLOOKUP('תפוקה מצטברת מול אשתקד'!A11,'הראל'!A:K,11,0)+VLOOKUP('תפוקה מצטברת מול אשתקד'!A11,'הפניקס'!A:K,11,0)+VLOOKUP('תפוקה מצטברת מול אשתקד'!A11,'כלל'!A:K,11,0)+VLOOKUP('תפוקה מצטברת מול אשתקד'!A11,'מור'!A:K,11,0)+VLOOKUP('תפוקה מצטברת מול אשתקד'!A11,'אלטשולר שחם'!A:K,11,0)+VLOOKUP('תפוקה מצטברת מול אשתקד'!A11,'מדיהו '!A:K,11,0)+VLOOKUP('תפוקה מצטברת מול אשתקד'!A11,'אנליסט '!A:K,11,0)+VLOOKUP('תפוקה מצטברת מול אשתקד'!A11,'מיטב דש'!A:K,11,0)+VLOOKUP('תפוקה מצטברת מול אשתקד'!A11,'אינפניטי'!A:K,11,0) -> -376655.71
A12: גל אלמגור דרום סוכ ל | B12: יוסי אביב | C12: שותפים | D12: =IF(H12=0,0%,IF(L12=0,100%,H12/L12-1)) -> 1627.821 | E12: =IF(I12=0,0%,IF(M12=0,100%,I12/M12-1)) -> 39.421966 | F12: =IF(J12=0,0%,IF(N12=0,100%,J12/N12-1)) -> 1 | G12: =IF(K12=0,0%,IF(O12=H36,100%,K12/O12-1)) -> -3.3197653 | H12: =VLOOKUP(A12,'הכשרה'!A:G,4,0)+VLOOKUP('תפוקה מצטברת מול אשתקד'!A12,'מגדל'!A:G,4,0)+VLOOKUP('תפוקה מצטברת מול אשתקד'!A12,'מנורה'!A:G,4,0)+VLOOKUP('תפוקה מצטברת מול אשתקד'!A12,'איילון'!A:G,4,0)+VLOOKUP('תפוקה מצטברת מול אשתקד'!A12,'הראל'!A:G,4,0)+VLOOKUP('תפוקה מצטברת מול אשתקד'!A12,'הפניקס'!A:G,4,0)+VLOOKUP('תפוקה מצטברת מול אשתקד'!A12,'כלל'!A:G,4,0)+VLOOKUP('תפוקה מצטברת מול אשתקד'!A12,'מור'!A:G,4,0)+VLOOKUP('תפוקה מצטברת מול אשתקד'!A12,'אלטשולר שחם'!A:G,4,0)+VLOOKUP('תפוקה מצטברת מול אשתקד'!A12,'מדיהו '!A:G,4,0)+VLOOKUP('תפוקה מצטברת מול אשתקד'!A12,'אנליסט '!A:G,4,0)+VLOOKUP('תפוקה מצטברת מול אשתקד'!A12,'מיטב דש'!A:G,4,0)+VLOOKUP('תפוקה מצטברת מול אשתקד'!A12,'אינפניטי'!A:G,4,0) -> 225510.27 | I12: =VLOOKUP(A12,'הכשרה'!A:G,5,0)+VLOOKUP('תפוקה מצטברת מול אשתקד'!A12,'מגדל'!A:G,5,0)+VLOOKUP('תפוקה מצטברת מול אשתקד'!A12,'מנורה'!A:G,5,0)+VLOOKUP('תפוקה מצטברת מול אשתקד'!A12,'איילון'!A:G,5,0)+VLOOKUP('תפוקה מצטברת מול אשתקד'!A12,'הראל'!A:G,5,0)+VLOOKUP('תפוקה מצטברת מול אשתקד'!A12,'הפניקס'!A:G,5,0)+VLOOKUP('תפוקה מצטברת מול אשתקד'!A12,'כלל'!A:G,5,0)+VLOOKUP('תפוקה מצטברת מול אשתקד'!A12,'מור'!A:G,5,0)+VLOOKUP('תפוקה מצטברת מול אשתקד'!A12,'אלטשולר שחם'!A:G,5,0)+VLOOKUP('תפוקה מצטברת מול אשתקד'!A12,'מדיהו '!A:G,5,0)+VLOOKUP('תפוקה מצטברת מול אשתקד'!A12,'אנליסט '!A:G,5,0)+VLOOKUP('תפוקה מצטברת מול אשתקד'!A12,'מיטב דש'!A:G,5,0)+VLOOKUP('תפוקה מצטברת מול אשתקד'!A12,'אינפניטי'!A:G,5,0) -> 16003.137 | J12: =VLOOKUP(A12,'הכשרה'!A:G,6,0)+VLOOKUP('תפוקה מצטברת מול אשתקד'!A12,'מגדל'!A:G,6,0)+VLOOKUP('תפוקה מצטברת מול אשתקד'!A12,'מנורה'!A:G,6,0)+VLOOKUP('תפוקה מצטברת מול אשתקד'!A12,'איילון'!A:G,6,0)+VLOOKUP(A12,'הראל'!A:G,6,0)+VLOOKUP('תפוקה מצטברת מול אשתקד'!A12,'הפניקס'!A:G,6,0)+VLOOKUP('תפוקה מצטברת מול אשתקד'!A12,'כלל'!A:G,6,0)+VLOOKUP('תפוקה מצטברת מול אשתקד'!A12,'מור'!A:G,6,0)+VLOOKUP('תפוקה מצטברת מול אשתקד'!A12,'אלטשולר שחם'!A:G,6,0)+VLOOKUP('תפוקה מצטברת מול אשתקד'!A12,'מדיהו '!A:G,6,0)+VLOOKUP('תפוקה מצטברת מול אשתקד'!A12,'אנליסט '!A:G,6,0)+VLOOKUP('תפוקה מצטברת מול אשתקד'!A12,'מיטב דש'!A:G,6,0)+VLOOKUP('תפוקה מצטברת מול אשתקד'!A12,'אינפניטי'!A:G,6,0) -> 1814271.1 | K12: =VLOOKUP(A12,'הכשרה'!A:G,7,0)+VLOOKUP('תפוקה מצטברת מול אשתקד'!A12,'מגדל'!A:G,7,0)+VLOOKUP('תפוקה מצטברת מול אשתקד'!A12,'מנורה'!A:G,7,0)+VLOOKUP('תפוקה מצטברת מול אשתקד'!A12,'איילון'!A:G,7,0)+VLOOKUP('תפוקה מצטברת מול אשתקד'!A12,'הראל'!A:G,7,0)+VLOOKUP('תפוקה מצטברת מול אשתקד'!A12,'הפניקס'!A:G,7,0)+VLOOKUP('תפוקה מצטברת מול אשתקד'!A12,'כלל'!A:G,7,0)+VLOOKUP('תפוקה מצטברת מול אשתקד'!A12,'מור'!A:G,7,0)+VLOOKUP('תפוקה מצטברת מול אשתקד'!A12,'אלטשולר שחם'!A:G,7,0)+VLOOKUP('תפוקה מצטברת מול אשתקד'!A12,'מדיהו '!A:K,7,0)+VLOOKUP(A12,'אנליסט '!A:G,7,0)+VLOOKUP('תפוקה מצטברת מול אשתקד'!A12,'מיטב דש'!A:G,7,0)+VLOOKUP('תפוקה מצטברת מול אשתקד'!A12,'אינפניטי'!A:G,7,0) -> 542020.65 | L12: =VLOOKUP(A12,'הכשרה'!A:K,8,0)+VLOOKUP('תפוקה מצטברת מול אשתקד'!A12,'מגדל'!A:K,8,0)+VLOOKUP('תפוקה מצטברת מול אשתקד'!A12,'מנורה'!A:K,8,0)+VLOOKUP('תפוקה מצטברת מול אשתקד'!A12,'איילון'!A:K,8,0)+VLOOKUP('תפוקה מצטברת מול אשתקד'!A12,'הראל'!A:K,8,0)+VLOOKUP('תפוקה מצטברת מול אשתקד'!A12,'הפניקס'!A:K,8,0)+VLOOKUP('תפוקה מצטברת מול אשתקד'!A12,'כלל'!A:K,8,0)+VLOOKUP('תפוקה מצטברת מול אשתקד'!A12,'מור'!A:K,8,0)+VLOOKUP('תפוקה מצטברת מול אשתקד'!A12,'אלטשולר שחם'!A:K,8,0)+VLOOKUP('תפוקה מצטברת מול אשתקד'!A12,'מדיהו '!A:K,8,0)+VLOOKUP('תפוקה מצטברת מול אשתקד'!A12,'אנליסט '!A:K,8,0)+VLOOKUP('תפוקה מצטברת מול אשתקד'!A12,'מיטב דש'!A:K,8,0)+VLOOKUP('תפוקה מצטברת מול אשתקד'!A12,'אינפניטי'!A:K,8,0) -> 138.45 | M12: =VLOOKUP(A12,'הכשרה'!A:K,9,0)+VLOOKUP('תפוקה מצטברת מול אשתקד'!A12,'מגדל'!A:K,9,0)+VLOOKUP('תפוקה מצטברת מול אשתקד'!A12,'מנורה'!A:K,9,0)+VLOOKUP('תפוקה מצטברת מול אשתקד'!A12,'איילון'!A:K,9,0)+VLOOKUP('תפוקה מצטברת מול אשתקד'!A12,'הראל'!A:K,9,0)+VLOOKUP('תפוקה מצטברת מול אשתקד'!A12,'הפניקס'!A:K,9,0)+VLOOKUP('תפוקה מצטברת מול אשתקד'!A12,'כלל'!A:K,9,0)+VLOOKUP('תפוקה מצטברת מול אשתקד'!A12,'מור'!A:K,9,0)+VLOOKUP('תפוקה מצטברת מול אשתקד'!A12,'אלטשולר שחם'!A:K,9,0)+VLOOKUP('תפוקה מצטברת מול אשתקד'!A12,'מדיהו '!A:K,9,0)+VLOOKUP('תפוקה מצטברת מול אשתקד'!A12,'אנליסט '!A:K,9,0)+VLOOKUP('תפוקה מצטברת מול אשתקד'!A12,'מיטב דש'!A:K,9,0)+VLOOKUP('תפוקה מצטברת מול אשתקד'!A12,'אינפניטי'!A:K,9,0) -> 395.902 | N12: =VLOOKUP(A12,'הכשרה'!A:K,10,0)+VLOOKUP('תפוקה מצטברת מול אשתקד'!A12,'מגדל'!A:K,10,0)+VLOOKUP('תפוקה מצטברת מול אשתקד'!A12,'מנורה'!A:K,10,0)+VLOOKUP('תפוקה מצטברת מול אשתקד'!A12,'איילון'!A:K,10,0)+VLOOKUP('תפוקה מצטברת מול אשתקד'!A12,'הראל'!A:K,10,0)+VLOOKUP('תפוקה מצטברת מול אשתקד'!A12,'הפניקס'!A:K,10,0)+VLOOKUP('תפוקה מצטברת מול אשתקד'!A12,'כלל'!A:K,10,0)+VLOOKUP('תפוקה מצטברת מול אשתקד'!A12,'מור'!A:K,10,0)+VLOOKUP('תפוקה מצטברת מול אשתקד'!A12,'אלטשולר שחם'!A:K,10,0)+VLOOKUP('תפוקה מצטברת מול אשתקד'!A12,'מדיהו '!A:K,10,0)+VLOOKUP('תפוקה מצטברת מול אשתקד'!A12,'אנליסט '!A:K,10,0)+VLOOKUP('תפוקה מצטברת מול אשתקד'!A12,'מיטב דש'!A:K,10,0)+VLOOKUP('תפוקה מצטברת מול אשתקד'!A12,'אינפניטי'!A:K,10,0) -> 0 | O12: =VLOOKUP(A12,'הכשרה'!A:K,11,0)+VLOOKUP('תפוקה מצטברת מול אשתקד'!A12,'מגדל'!A:K,11,0)+VLOOKUP('תפוקה מצטברת מול אשתקד'!A12,'מנורה'!A:K,11,0)+VLOOKUP('תפוקה מצטברת מול אשתקד'!A12,'איילון'!A:K,11,0)+VLOOKUP('תפוקה מצטברת מול אשתקד'!A12,'הראל'!A:K,11,0)+VLOOKUP('תפוקה מצטברת מול אשתקד'!A12,'הפניקס'!A:K,11,0)+VLOOKUP('תפוקה מצטברת מול אשתקד'!A12,'כלל'!A:K,11,0)+VLOOKUP('תפוקה מצטברת מול אשתקד'!A12,'מור'!A:K,11,0)+VLOOKUP('תפוקה מצטברת מול אשתקד'!A12,'אלטשולר שחם'!A:K,11,0)+VLOOKUP('תפוקה מצטברת מול אשתקד'!A12,'מדיהו '!A:K,11,0)+VLOOKUP('תפוקה מצטברת מול אשתקד'!A12,'אנליסט '!A:K,11,0)+VLOOKUP('תפוקה מצטברת מול אשתקד'!A12,'מיטב דש'!A:K,11,0)+VLOOKUP('תפוקה מצטברת מול אשתקד'!A12,'אינפניטי'!A:K,11,0) -> -233653.23
A13: משה שטרן גל אלמגור | B13: יוסי אביב | C13: שותפים | D13: =IF(H13=0,0%,IF(L13=0,100%,H13/L13-1)) -> 1 | E13: =IF(I13=0,0%,IF(M13=0,100%,I13/M13-1)) -> -0.32909281 | F13: =IF(J13=0,0%,IF(N13=0,100%,J13/N13-1)) -> -0.99760108 | G13: =IF(K13=0,0%,IF(O13=H37,100%,K13/O13-1)) -> -1.0274995 | H13: =VLOOKUP(A13,'הכשרה'!A:G,4,0)+VLOOKUP('תפוקה מצטברת מול אשתקד'!A13,'מגדל'!A:G,4,0)+VLOOKUP('תפוקה מצטברת מול אשתקד'!A13,'מנורה'!A:G,4,0)+VLOOKUP('תפוקה מצטברת מול אשתקד'!A13,'איילון'!A:G,4,0)+VLOOKUP('תפוקה מצטברת מול אשתקד'!A13,'הראל'!A:G,4,0)+VLOOKUP('תפוקה מצטברת מול אשתקד'!A13,'הפניקס'!A:G,4,0)+VLOOKUP('תפוקה מצטברת מול אשתקד'!A13,'כלל'!A:G,4,0)+VLOOKUP('תפוקה מצטברת מול אשתקד'!A13,'מור'!A:G,4,0)+VLOOKUP('תפוקה מצטברת מול אשתקד'!A13,'אלטשולר שחם'!A:G,4,0)+VLOOKUP('תפוקה מצטברת מול אשתקד'!A13,'מדיהו '!A:G,4,0)+VLOOKUP('תפוקה מצטברת מול אשתקד'!A13,'אנליסט '!A:G,4,0)+VLOOKUP('תפוקה מצטברת מול אשתקד'!A13,'מיטב דש'!A:G,4,0)+VLOOKUP('תפוקה מצטברת מול אשתקד'!A13,'אינפניטי'!A:G,4,0) -> 66506.982 | I13: =VLOOKUP(A13,'הכשרה'!A:G,5,0)+VLOOKUP('תפוקה מצטברת מול אשתקד'!A13,'מגדל'!A:G,5,0)+VLOOKUP('תפוקה מצטברת מול אשתקד'!A13,'מנורה'!A:G,5,0)+VLOOKUP('תפוקה מצטברת מול אשתקד'!A13,'איילון'!A:G,5,0)+VLOOKUP('תפוקה מצטברת מול אשתקד'!A13,'הראל'!A:G,5,0)+VLOOKUP('תפוקה מצטברת מול אשתקד'!A13,'הפניקס'!A:G,5,0)+VLOOKUP('תפוקה מצטברת מול אשתקד'!A13,'כלל'!A:G,5,0)+VLOOKUP('תפוקה מצטברת מול אשתקד'!A13,'מור'!A:G,5,0)+VLOOKUP('תפוקה מצטברת מול אשתקד'!A13,'אלטשולר שחם'!A:G,5,0)+VLOOKUP('תפוקה מצטברת מול אשתקד'!A13,'מדיהו '!A:G,5,0)+VLOOKUP('תפוקה מצטברת מול אשתקד'!A13,'אנליסט '!A:G,5,0)+VLOOKUP('תפוקה מצטברת מול אשתקד'!A13,'מיטב דש'!A:G,5,0)+VLOOKUP('תפוקה מצטברת מול אשתקד'!A13,'אינפניטי'!A:G,5,0) -> 142979.02 | J13: =VLOOKUP(A13,'הכשרה'!A:G,6,0)+VLOOKUP('תפוקה מצטברת מול אשתקד'!A13,'מגדל'!A:G,6,0)+VLOOKUP('תפוקה מצטברת מול אשתקד'!A13,'מנורה'!A:G,6,0)+VLOOKUP('תפוקה מצטברת מול אשתקד'!A13,'איילון'!A:G,6,0)+VLOOKUP(A13,'הראל'!A:G,6,0)+VLOOKUP('תפוקה מצטברת מול אשתקד'!A13,'הפניקס'!A:G,6,0)+VLOOKUP('תפוקה מצטברת מול אשתקד'!A13,'כלל'!A:G,6,0)+VLOOKUP('תפוקה מצטברת מול אשתקד'!A13,'מור'!A:G,6,0)+VLOOKUP('תפוקה מצטברת מול אשתקד'!A13,'אלטשולר שחם'!A:G,6,0)+VLOOKUP('תפוקה מצטברת מול אשתקד'!A13,'מדיהו '!A:G,6,0)+VLOOKUP('תפוקה מצטברת מול אשתקד'!A13,'אנליסט '!A:G,6,0)+VLOOKUP('תפוקה מצטברת מול אשתקד'!A13,'מיטב דש'!A:G,6,0)+VLOOKUP('תפוקה מצטברת מול אשתקד'!A13,'אינפניטי'!A:G,6,0) -> 2349.83 | K13: =VLOOKUP(A13,'הכשרה'!A:G,7,0)+VLOOKUP('תפוקה מצטברת מול אשתקד'!A13,'מגדל'!A:G,7,0)+VLOOKUP('תפוקה מצטברת מול אשתקד'!A13,'מנורה'!A:G,7,0)+VLOOKUP('תפוקה מצטברת מול אשתקד'!A13,'איילון'!A:G,7,0)+VLOOKUP('תפוקה מצטברת מול אשתקד'!A13,'הראל'!A:G,7,0)+VLOOKUP('תפוקה מצטברת מול אשתקד'!A13,'הפניקס'!A:G,7,0)+VLOOKUP('תפוקה מצטברת מול אשתקד'!A13,'כלל'!A:G,7,0)+VLOOKUP('תפוקה מצטברת מול אשתקד'!A13,'מור'!A:G,7,0)+VLOOKUP('תפוקה מצטברת מול אשתקד'!A13,'אלטשולר שחם'!A:G,7,0)+VLOOKUP('תפוקה מצטברת מול אשתקד'!A13,'מדיהו '!A:K,7,0)+VLOOKUP(A13,'אנליסט '!A:G,7,0)+VLOOKUP('תפוקה מצטברת מול אשתקד'!A13,'מיטב דש'!A:G,7,0)+VLOOKUP('תפוקה מצטברת מול אשתקד'!A13,'אינפניטי'!A:G,7,0) -> -4433.24 | L13: =VLOOKUP(A13,'הכשרה'!A:K,8,0)+VLOOKUP('תפוקה מצטברת מול אשתקד'!A13,'מגדל'!A:K,8,0)+VLOOKUP('תפוקה מצטברת מול אשתקד'!A13,'מנורה'!A:K,8,0)+VLOOKUP('תפוקה מצטברת מול אשתקד'!A13,'איילון'!A:K,8,0)+VLOOKUP('תפוקה מצטברת מול אשתקד'!A13,'הראל'!A:K,8,0)+VLOOKUP('תפוקה מצטברת מול אשתקד'!A13,'הפניקס'!A:K,8,0)+VLOOKUP('תפוקה מצטברת מול אשתקד'!A13,'כלל'!A:K,8,0)+VLOOKUP('תפוקה מצטברת מול אשתקד'!A13,'מור'!A:K,8,0)+VLOOKUP('תפוקה מצטברת מול אשתקד'!A13,'אלטשולר שחם'!A:K,8,0)+VLOOKUP('תפוקה מצטברת מול אשתקד'!A13,'מדיהו '!A:K,8,0)+VLOOKUP('תפוקה מצטברת מול אשתקד'!A13,'אנליסט '!A:K,8,0)+VLOOKUP('תפוקה מצטברת מול אשתקד'!A13,'מיטב דש'!A:K,8,0)+VLOOKUP('תפוקה מצטברת מול אשתקד'!A13,'אינפניטי'!A:K,8,0) -> 0 | M13: =VLOOKUP(A13,'הכשרה'!A:K,9,0)+VLOOKUP('תפוקה מצטברת מול אשתקד'!A13,'מגדל'!A:K,9,0)+VLOOKUP('תפוקה מצטברת מול אשתקד'!A13,'מנורה'!A:K,9,0)+VLOOKUP('תפוקה מצטברת מול אשתקד'!A13,'איילון'!A:K,9,0)+VLOOKUP('תפוקה מצטברת מול אשתקד'!A13,'הראל'!A:K,9,0)+VLOOKUP('תפוקה מצטברת מול אשתקד'!A13,'הפניקס'!A:K,9,0)+VLOOKUP('תפוקה מצטברת מול אשתקד'!A13,'כלל'!A:K,9,0)+VLOOKUP('תפוקה מצטברת מול אשתקד'!A13,'מור'!A:K,9,0)+VLOOKUP('תפוקה מצטברת מול אשתקד'!A13,'אלטשולר שחם'!A:K,9,0)+VLOOKUP('תפוקה מצטברת מול אשתקד'!A13,'מדיהו '!A:K,9,0)+VLOOKUP('תפוקה מצטברת מול אשתקד'!A13,'אנליסט '!A:K,9,0)+VLOOKUP('תפוקה מצטברת מול אשתקד'!A13,'מיטב דש'!A:K,9,0)+VLOOKUP('תפוקה מצטברת מול אשתקד'!A13,'אינפניטי'!A:K,9,0) -> 213112.96 | N13: =VLOOKUP(A13,'הכשרה'!A:K,10,0)+VLOOKUP('תפוקה מצטברת מול אשתקד'!A13,'מגדל'!A:K,10,0)+VLOOKUP('תפוקה מצטברת מול אשתקד'!A13,'מנורה'!A:K,10,0)+VLOOKUP('תפוקה מצטברת מול אשתקד'!A13,'איילון'!A:K,10,0)+VLOOKUP('תפוקה מצטברת מול אשתקד'!A13,'הראל'!A:K,10,0)+VLOOKUP('תפוקה מצטברת מול אשתקד'!A13,'הפניקס'!A:K,10,0)+VLOOKUP('תפוקה מצטברת מול אשתקד'!A13,'כלל'!A:K,10,0)+VLOOKUP('תפוקה מצטברת מול אשתקד'!A13,'מור'!A:K,10,0)+VLOOKUP('תפוקה מצטברת מול אשתקד'!A13,'אלטשולר שחם'!A:K,10,0)+VLOOKUP('תפוקה מצטברת מול אשתקד'!A13,'מדיהו '!A:K,10,0)+VLOOKUP('תפוקה מצטברת מול אשתקד'!A13,'אנליסט '!A:K,10,0)+VLOOKUP('תפוקה מצטברת מול אשתקד'!A13,'מיטב דש'!A:K,10,0)+VLOOKUP('תפוקה מצטברת מול אשתקד'!A13,'אינפניטי'!A:K,10,0) -> 979535.58 | O13: =VLOOKUP(A13,'הכשרה'!A:K,11,0)+VLOOKUP('תפוקה מצטברת מול אשתקד'!A13,'מגדל'!A:K,11,0)+VLOOKUP('תפוקה מצטברת מול אשתקד'!A13,'מנורה'!A:K,11,0)+VLOOKUP('תפוקה מצטברת מול אשתקד'!A13,'איילון'!A:K,11,0)+VLOOKUP('תפוקה מצטברת מול אשתקד'!A13,'הראל'!A:K,11,0)+VLOOKUP('תפוקה מצטברת מול אשתקד'!A13,'הפניקס'!A:K,11,0)+VLOOKUP('תפוקה מצטברת מול אשתקד'!A13,'כלל'!A:K,11,0)+VLOOKUP('תפוקה מצטברת מול אשתקד'!A13,'מור'!A:K,11,0)+VLOOKUP('תפוקה מצטברת מול אשתקד'!A13,'אלטשולר שחם'!A:K,11,0)+VLOOKUP('תפוקה מצטברת מול אשתקד'!A13,'מדיהו '!A:K,11,0)+VLOOKUP('תפוקה מצטברת מול אשתקד'!A13,'אנליסט '!A:K,11,0)+VLOOKUP('תפוקה מצטברת מול אשתקד'!A13,'מיטב דש'!A:K,11,0)+VLOOKUP('תפוקה מצטברת מול אשתקד'!A13,'אינפניטי'!A:K,11,0) -> 161211.56
