Workbook

Sheet דוח הנהלה
A2: תפוקה חודשית לפי קבוצות | O2: עולים בולטים
A3: קבוצה | B3: תפוקה חודשית 01/2025 | F3: השגת יעדים חודשי % | O3: סוכן | P3: שינוי % מול תקופה חופפת אשתקד | Q3: עליה מול תקופה חופפת אשתקד | R3: תפוקה מצטברת - 2025
B4: פנסיוני | C4: סיכונים | D4: פיננסים | E4: ניודי פנסיה | F4: פנסיוני | G4: סיכונים | H4: פיננסים | I4: ניודי פנסיה
A5: ישירים | B5: ='תפוקה מול יעד חודשי'!L8 -> 1129325.5 | C5: ='תפוקה מול יעד חודשי'!M8 -> 430756.29 | D5: ='תפוקה מול יעד חודשי'!N8 -> 3418786 | E5: ='תפוקה מול יעד חודשי'!O8 -> 7238176 | F5: ='תפוקה מול יעד חודשי'!D5 -> 0 | G5: ='תפוקה מול יעד חודשי'!E5 -> 0.37003158 | H5: ='תפוקה מול יעד חודשי'!F5 -> 0 | I5: ='תפוקה מול יעד חודשי'!G5 -> 0
A6: חברות בת | B6: ='תפוקה מול יעד חודשי'!L8 -> 1129325.5 | C6: ='תפוקה מול יעד חודשי'!M21 -> 276135.67 | D6: ='תפוקה מול יעד חודשי'!N21 -> 1343239 | E6: ='תפוקה מול יעד חודשי'!O21 -> 399567.57 | F6: ='תפוקה מול יעד חודשי'!D13 -> 0 | G6: ='תפוקה מול יעד חודשי'!E13 -> -0.74851415 | H6: ='תפוקה מול יעד חודשי'!F13 -> 0 | I6: ='תפוקה מול יעד חודשי'!G13 -> 0
A7: סוכני פרימיום | B7: ='תפוקה מול יעד חודשי'!L71 -> 579517.98 | C7: ='תפוקה מול יעד חודשי'!M71 -> 838553.7 | D7: ='תפוקה מול יעד חודשי'!N71 -> 3159084.2 | E7: ='תפוקה מול יעד חודשי'!O71 -> 5778612.3 | F7: ='תפוקה מול יעד חודשי'!D70 -> -0.675891 | G7: ='תפוקה מול יעד חודשי'!E70 -> 48.372039 | H7: ='תפוקה מול יעד חודשי'!F70 -> 0.0099075362 | I7: ='תפוקה מול יעד חודשי'!G70 -> 0
A8: סוכנים ערן | B8: ='תפוקה מול יעד חודשי'!L54 -> 613484.09 | C8: ='תפוקה מול יעד חודשי'!M54 -> 309510.9 | D8: ='תפוקה מול יעד חודשי'!N54 -> 1910393.7 | E8: ='תפוקה מול יעד חודשי'!O54 -> 2348418.5 | F8: ='תפוקה מול יעד חודשי'!D71 -> -0.43184512 | G8: ='תפוקה מול יעד חודשי'!E71 -> 5.7899085 | H8: ='תפוקה מול יעד חודשי'!F71 -> -0.53281807 | I8: ='תפוקה מול יעד חודשי'!G71 -> 0.6749601
A9: סוכנים איתי | B9: ='תפוקה מול יעד חודשי'!L62 -> 570943.95 | C9: ='תפוקה מול יעד חודשי'!M62 -> 33882.161 | D9: ='תפוקה מול יעד חודשי'!N62 -> 1619801.2 | E9: ='תפוקה מול יעד חודשי'!O62 -> 618203.73 | F9: ='תפוקה מול יעד חודשי'!D72 -> -0.60697749 | G9: ='תפוקה מול יעד חודשי'!E72 -> 1.2517002 | H9: ='תפוקה מול יעד חודשי'!F72 -> -0.62022671 | I9: ='תפוקה מול יעד חודשי'!G72 -> -0.44987381
A10: סה"כ מכירות | B10: =SUM(B5:B8) -> 3451653.1 | C10: =SUM(C5:C8) -> 1854956.6 | D10: =SUM(D5:D8) -> 9831502.9 | E10: =SUM(E5:E8) -> 15764774 | F10: ='תפוקה מול יעד חודשי'!D71 -> -0.43184512 | G10: ='תפוקה מול יעד חודשי'!E71 -> 5.7899085 | H10: ='תפוקה מול יעד חודשי'!F71 -> -0.53281807 | I10: ='תפוקה מול יעד חודשי'!G71 -> 0.6749601
A14: תפוקה מצטברת לפי קבוצות | O14: יורדים בולטים
A15: קבוצה | B15: תפוקה מצטברת 01/2025 | F15: שינוי מול אשתקד % | J15: השגת יעדים מצטבר % | O15: סוכן | P15: שינוי % מול תקופה חופפת אשתקד | Q15: ירידה מול תקופה חופפת אשתקד | R15: תפוקה מצטברת - 2025
B16: פנסיוני | C16: סיכונים | D16: פיננסים | E16: ניודי פנסיה | F16: פנסיוני | G16: סיכונים | H16: פיננסים | I16: ניודי פנסיה | J16: פנסיוני | K16: סיכונים | L16: פיננסים | M16: ניודי פנסיה
A17: ישירים | B17: ='תפוקה מצטברת מול אשתקד'!H8 -> 1129325.5 | C17: ='תפוקה מצטברת מול אשתקד'!I8 -> 430756.29 | D17: ='תפוקה מצטברת מול אשתקד'!J8 -> 3418786 | E17: ='תפוקה מצטברת מול אשתקד'!K8 -> 7238176 | F17: ='תפוקה מצטברת מול אשתקד'!D8 -> -0.85736407 | G17: ='תפוקה מצטברת מול אשתקד'!E8 -> -0.25834773 | H17: ='תפוקה מצטברת מול אשתקד'!F8 -> -0.84705929 | I17: ='תפוקה מצטברת מול אשתקד'!G8 -> -0.85003467 | J17: ='תפוקה מצטברת מול יעד מצטבר'!D8 -> -0.94208587 | K17: ='תפוקה מצטברת מול יעד מצטבר'!E8 -> -0.66864901 | L17: ='תפוקה מצטברת מול יעד מצטבר'!F8 -> 1.6298354 | M17: ='תפוקה מצטברת מול יעד מצטבר'!G8 -> 4.5678277
A18: חברות בת | B18: ='תפוקה מצטברת מול אשתקד'!H21 -> 358596.73 | C18: ='תפוקה מצטברת מול אשתקד'!I21 -> 276135.67 | D18: ='תפוקה מצטברת מול אשתקד'!J21 -> 1343239 | E18: ='תפוקה מצטברת מול אשתקד'!K21 -> 399567.57 | F18: ='תפוקה מצטברת מול אשתקד'!D21 -> -0.84720074 | G18: ='תפוקה מצטברת מול אשתקד'!E21 -> -0.56793629 | H18: ='תפוקה מצטברת מול אשתקד'!F21 -> -0.94158332 | I18: ='תפוקה מצטברת מול אשתקד'!G21 -> -0.97041889 | J18: ='תפוקה מצטברת מול יעד מצטבר'!D21 -> -0.95402606 | K18: ='תפוקה מצטברת מול יעד מצטבר'!E21 -> -0.89579786 | L18: ='תפוקה מצטברת מול יעד מצטבר'!F21 -> -0.97742455 | M18: ='תפוקה מצטברת מול יעד מצטבר'!G21 -> -0.86221808
A19: סוכני פרימיום | B19: ='תפוקה מצטברת מול אשתקד'!H71 -> 2258651 | C19: ='תפוקה מצטברת מול אשתקד'!I71 -> 838553.7 | D19: ='תפוקה מצטברת מול אשתקד'!J71 -> 6837572 | E19: ='תפוקה מצטברת מול אשתקד'!K71 -> 14476352 | F19: ='תפוקה מצטברת מול אשתקד'!D71 -> -0.85736407 | G19: ='תפוקה מצטברת מול אשתקד'!E71 -> -0.27811239 | H19: ='תפוקה מצטברת מול אשתקד'!F71 -> -0.84705929 | I19: ='תפוקה מצטברת מול אשתקד'!G62 -> -0.93504145 | J19: ='תפוקה מצטברת מול יעד מצטבר'!D62 -> -0.99979052 | K19: ='תפוקה מצטברת מול יעד מצטבר'!E62 -> -0.96506994 | L19: ='תפוקה מצטברת מול יעד מצטבר'!F62 -> -0.94214996 | M19: ='תפוקה מצטברת מול יעד מצטבר'!G62 -> -0.36267657
A20: סוכנים ערן | B20: ='תפוקה מצטברת מול אשתקד'!H54 -> 613484.09 | C20: ='תפוקה מצטברת מול אשתקד'!I54 -> 309510.9 | D20: ='תפוקה מצטברת מול אשתקד'!J54 -> 1910393.7 | E20: ='תפוקה מצטברת מול אשתקד'!K54 -> 2348418.5 | F20: ='תפוקה מצטברת מול אשתקד'!D72 -> -0.86443093 | G20: ='תפוקה מצטברת מול אשתקד'!E72 -> -0.45917206 | H20: ='תפוקה מצטברת מול אשתקד'!F72 -> -0.86026621 | I20: ='תפוקה מצטברת מול אשתקד'!G71 -> -0.85003467 | J20: ='תפוקה מצטברת מול יעד מצטבר'!D71 -> -0.93182141 | K20: ='תפוקה מצטברת מול יעד מצטבר'!E71 -> -0.3549587 | L20: ='תפוקה מצטברת מול יעד מצטבר'!F71 -> -0.93744388 | M20: ='תפוקה מצטברת מול יעד מצטבר'!G71 -> 3.4450864
A21: סוכנים איתי | B21: ='תפוקה מצטברת מול אשתקד'!H62 -> 570943.95 | C21: ='תפוקה מצטברת מול אשתקד'!I62 -> 33882.161 | D21: ='תפוקה מצטברת מול אשתקד'!J62 -> 1619801.2 | E21: ='תפוקה מצטברת מול אשתקד'!K62 -> 618203.73 | F21: ='תפוקה מצטברת מול אשתקד'!D73 -> 0 | G21: ='תפוקה מצטברת מול אשתקד'!E73 -> 0 | H21: ='תפוקה מצטברת מול אשתקד'!F73 -> 0 | I21: ='תפוקה מצטברת מול אשתקד'!G72 -> -0.87410193 | J21: ='תפוקה מצטברת מול יעד מצטבר'!D72 -> -0.99825125 | K21: ='תפוקה מצטברת מול יעד מצטבר'!E72 -> -0.72326073 | L21: ='תפוקה מצטברת מול יעד מצטבר'!F72 -> -0.90402296 | M21: ='תפוקה מצטברת מול יעד מצטבר'!G72 -> 2.4022568
A22: סה"כ מכירות | B22: =SUM(B17:B21) -> 4931001.3 | C22: =SUM(C17:C21) -> 1888838.7 | D22: =SUM(D17:D20) -> 13509991 | E22: =SUM(E17:E20) -> 24462514 | F22: ='תפוקה מצטברת מול אשתקד'!D72 -> -0.86443093 | G22: ='תפוקה מצטברת מול אשתקד'!E72 -> -0.45917206 | H22: ='תפוקה מצטברת מול אשתקד'!F72 -> -0.86026621 | I22: ='תפוקה מצטברת מול יעד מצטבר'!D71 -> -0.93182141 | J22: ='תפוקה מצטברת מול יעד מצטבר'!D72 -> -0.99825125 | K22: ='תפוקה מצטברת מול יעד מצטבר'!E72 -> -0.72326073 | L22: ='תפוקה מצטברת מול יעד מצטבר'!F72 -> -0.90402296 | M22: ='תפוקה מצטברת מול יעד מצטבר'!G72 -> 2.4022568
A25: תפוקה מצטברת לפי מפקחים
A26: מפקח | B26: תפוקה מצטברת 01/2025 | F26: שינוי מול אשתקד % | J26: השגת יעדים מצטבר % | N26: תפוקה מצטברת 01/2024 | R26: יעדים מצטבר
B27: פנסיוני | C27: סיכונים | D27: פיננסים | E27: ניודי פנסיה | F27: פנסיוני | G27: סיכונים | H27: פיננסים | I27: ניודי פנסיה | J27: פנסיוני | K27: סיכונים | L27: פיננסים | M27: ניודי פנסיה | N27: פנסיוני | O27: סיכונים | P27: פיננסים | Q27: ניודי פנסיה | R27: פנסיוני | S27: סיכונים | T27: פיננסים | U27: ניודי פנסיה
A28: ערן גירוני | B28: =SUMIF('תפוקה מצטברת מול אשתקד'!$B:$B,'דוח הנהלה'!A28,'תפוקה מצטברת מול אשתקד'!$H:$H) -> 1177504.6 | C28: =SUMIF('תפוקה מצטברת מול אשתקד'!$B:$B,'דוח הנהלה'!B28,'תפוקה מצטברת מול אשתקד'!$H:$H) -> 0 | D28: =SUMIF('תפוקה מצטברת מול אשתקד'!$B:$B,'דוח הנהלה'!C28,'תפוקה מצטברת מול אשתקד'!$H:$H) -> 0 | E28: =SUMIF('תפוקה מצטברת מול אשתקד'!$B:$B,'דוח הנהלה'!D28,'תפוקה מצטברת מול אשתקד'!$H:$H) -> 0 | F28: =(B28-N28)/N28 -> -0.91029112 | G28: =(C28-O28)/O28 -> -1 | H28: =(D28-P28)/P28 -> #DIV/0! | I28: =(E28-Q28)/Q28 -> #DIV/0! | J28: =(B28-R28)/R28 -> #VALUE! | K28: =(C28-S28)/S28 -> #VALUE! | L28: =(D28-T28)/T28 -> #VALUE! | M28: =(E28-U28)/U28 -> #VALUE! | N28: =SUMIF('תפוקה מצטברת מול אשתקד'!$B:$B,'דוח הנהלה'!A28,'תפוקה מצטברת מול אשתקד'!$L:$L) -> 13125842 | O28: =SUMIF('תפוקה מצטברת מול אשתקד'!$B:$B,'דוח הנהלה'!A28,'תפוקה מצטברת מול אשתקד'!$I:$I) -> 1146188.7 | R28: =SUMIF([1]גיליון1!$B:$B,A28,[1]גיליון1!$I:$I) -> #VALUE! | S28: =SUMIF([1]גיליון1!$B:$B,A28,[1]גיליון1!$J:$J) -> #VALUE! | T28: =SUMIF([1]גיליון1!$B:$B,A28,[1]גיליון1!$K:$K) -> #VALUE! | U28: =SUMIF([1]גיליון1!$B:$B,A28,[1]גיליון1!$L:$L) -> #VALUE!
A29: לא מפוקחים | B29: =SUMIF('תפוקה מצטברת מול אשתקד'!B:B,'דוח הנהלה'!A29,'תפוקה מצטברת מול אשתקד'!H:H) -> 15497.42 | C29: =SUMIF('תפוקה מצטברת מול אשתקד'!C:C,'דוח הנהלה'!B29,'תפוקה מצטברת מול אשתקד'!I:I) -> 0 | F29: =(B29-N29)/N29 -> -0.67532249 | G29: =(C29-O29)/O29 -> #DIV/0! | H29: =(D29-P29)/P29 -> #DIV/0! | I29: =(E29-Q29)/Q29 -> #DIV/0! | J29: =(B29-R29)/R29 -> #VALUE! | K29: =(C29-S29)/S29 -> #VALUE! | L29: =(D29-T29)/T29 -> #VALUE! | M29: =(E29-U29)/U29 -> #VALUE! | N29: =SUMIF('תפוקה מצטברת מול אשתקד'!$B:$B,'דוח הנהלה'!A29,'תפוקה מצטברת מול אשתקד'!$L:$L) -> 47731.732 | O29: =SUMIF('תפוקה מצטברת מול אשתקד'!$B:$B,'דוח הנהלה'!A29,'תפוקה מצטברת מול אשתקד'!$I:$I) -> 0 | P29: =SUMIF('תפוקה מצטברת מול אשתקד'!$B:$B,'דוח הנהלה'!C29,'תפוקה מצטברת מול אשתקד'!$L:$L) -> 0 | Q29: =SUMIF('תפוקה מצטברת מול אשתקד'!$B:$B,'דוח הנהלה'!D29,'תפוקה מצטברת מול אשתקד'!$L:$L) -> 0 | R29: =SUMIF([1]גיליון1!$B:$B,A29,[1]גיליון1!$I:$I) -> #VALUE! | S29: =SUMIF([1]גיליון1!$B:$B,A29,[1]גיליון1!$J:$J) -> #VALUE! | T29: =SUMIF([1]גיליון1!$B:$B,A29,[1]גיליון1!$K:$K) -> #VALUE! | U29: =SUMIF([1]גיליון1!$B:$B,A29,[1]גיליון1!$L:$L) -> #VALUE!
A30: יוסי אביב | B30: =SUMIF('תפוקה מצטברת מול אשתקד'!B:B,'דוח הנהלה'!A30,'תפוקה מצטברת מול אשתקד'!H:H) -> 1487922.2 | C30: =SUMIF('תפוקה מצטברת מול אשתקד'!C:C,'דוח הנהלה'!B30,'תפוקה מצטברת מול אשתקד'!I:I) -> 0 | F30: =(B30-N30)/N30 -> -0.86484558 | G30: =(C30-O30)/O30 -> -1 | H30: =(D30-P30)/P30 -> #DIV/0! | I30: =(E30-Q30)/Q30 -> #DIV/0! | J30: =(B30-R30)/R30 -> #VALUE! | K30: =(C30-S30)/S30 -> #VALUE! | L30: =(D30-T30)/T30 -> #VALUE! | M30: =(E30-U30)/U30 -> #VALUE! | N30: =SUMIF('תפוקה מצטברת מול אשתקד'!$B:$B,'דוח הנהלה'!A30,'תפוקה מצטברת מול אשתקד'!$L:$L) -> 11009054 | O30: =SUMIF('תפוקה מצטברת מול אשתקד'!$B:$B,'דוח הנהלה'!A30,'תפוקה מצטברת מול אשתקד'!$I:$I) -> 708767.81 | P30: =SUMIF('תפוקה מצטברת מול אשתקד'!$B:$B,'דוח הנהלה'!C30,'תפוקה מצטברת מול אשתקד'!$L:$L) -> 0 | Q30: =SUMIF('תפוקה מצטברת מול אשתקד'!$B:$B,'דוח הנהלה'!D30,'תפוקה מצטברת מול אשתקד'!$L:$L) -> 0 | R30: =SUMIF([1]גיליון1!$B:$B,A30,[1]גיליון1!$I:$I) -> #VALUE! | S30: =SUMIF([1]גיליון1!$B:$B,A30,[1]גיליון1!$J:$J) -> #VALUE! | T30: =SUMIF([1]גיליון1!$B:$B,A30,[1]גיליון1!$K:$K) -> #VALUE! | U30: =SUMIF([1]גיליון1!$B:$B,A30,[1]גיליון1!$L:$L) -> #VALUE!
A31: איתי אדן | B31: =SUMIF('תפוקה מצטברת מול אשתקד'!B:B,'דוח הנהלה'!A31,'תפוקה מצטברת מול אשתקד'!H:H) -> 570943.95 | C31: =SUMIF('תפוקה מצטברת מול אשתקד'!C:C,'דוח הנהלה'!B31,'תפוקה מצטברת מול אשתקד'!I:I) -> 0 | F31: =(B31-N31)/N31 -> -0.77015315 | G31: =(C31-O31)/O31 -> -1 | H31: =(D31-P31)/P31 -> #DIV/0! | I31: =(E31-Q31)/Q31 -> #DIV/0! | J31: =(B31-R31)/R31 -> #VALUE! | K31: =(C31-S31)/S31 -> #VALUE! | L31: =(D31-T31)/T31 -> #VALUE! | M31: =(E31-U31)/U31 -> #VALUE! | N31: =SUMIF('תפוקה מצטברת מול אשתקד'!$B:$B,'דוח הנהלה'!A31,'תפוקה מצטברת מול אשתקד'!$L:$L) -> 2484019 | O31: =SUMIF('תפוקה מצטברת מול אשתקד'!$B:$B,'דוח הנהלה'!A31,'תפוקה מצטברת מול אשתקד'!$I:$I) -> 33882.161 | P31: =SUMIF('תפוקה מצטברת מול אשתקד'!$B:$B,'דוח הנהלה'!C31,'תפוקה מצטברת מול אשתקד'!$L:$L) -> 0 | Q31: =SUMIF('תפוקה מצטברת מול אשתקד'!$B:$B,'דוח הנהלה'!D31,'תפוקה מצטברת מול אשתקד'!$L:$L) -> 0 | R31: =SUMIF([1]גיליון1!$B:$B,A31,[1]גיליון1!$I:$I) -> #VALUE! | S31: =SUMIF([1]גיליון1!$B:$B,A31,[1]גיליון1!$J:$J) -> #VALUE! | T31: =SUMIF([1]גיליון1!$B:$B,A31,[1]גיליון1!$K:$K) -> #VALUE! | U31: =SUMIF([1]גיליון1!$B:$B,A31,[1]גיליון1!$L:$L) -> #VALUE!
B32: =SUM(B28:B30) -> 2680924.3 | C32: =SUM(C28:C30) -> 0 | D32: =SUM(D28:D30) -> 0 | E32: =SUM(E28:E30) -> 0 | F32: =(B32-N32)/N32 -> -0.88913842 | G32: =(C32-O32)/O32 -> -1 | H32: =(D32-P32)/P32 -> #DIV/0! | I32: =(B32-R32)/R32 -> #VALUE! | J32: =(B32-R32)/R32 -> #VALUE! | K32: =(C32-S32)/S32 -> #VALUE! | L32: =(D32-T32)/T32 -> #VALUE! | M32: =(E32-U32)/U32 -> #VALUE! | N32: =SUM(N28:N30) -> 24182628 | O32: =SUM(O28:O31) -> 1888838.7 | P32: =SUM(P28:P30) -> 0 | Q32: =SUM(Q28:Q30) -> 0 | R32: =SUM(R28:R30) -> #VALUE! | S32: =SUM(S28:S30) -> #VALUE! | T32: =SUM(T28:T30) -> #VALUE! | U32: =SUM(U28:U30) -> #VALUE!
A36: תפוקה מצטברת לפי חברות
A37: קבוצה | B37: תפוקה מצטברת 01/2025 | F37: שינוי מול אשתקד %
B38: פנסיוני | C38: סיכונים | D38: פיננסים | E38: ניודי פנסיה | F38: פנסיוני | G38: סיכונים | H38: פיננסים | I38: ניודי פנסיה
A39: מנורה | B39: =מנורה!D72 -> 715891.55 | C39: =מנורה!E72 -> 73695.035 | D39: =מנורה!F72 -> 759970.83 | E39: =מנורה!G72 -> 0 | F39: =מנורה!D72/מנורה!H72-1 -> 0.13451985 | G39: =מנורה!E72/מנורה!I72-1 -> 0.56839112 | H39: =מנורה!F72/מנורה!J72-1 -> -0.79874433 | I39: =מנורה!G72/מנורה!K72-1 -> -1
A40: מגדל | B40: =מגדל!D72 -> 1315337.8 | C40: =מגדל!E72 -> 118705.91 | D40: =מגדל!F72 -> 4124762.6 | E40: =מגדל!G72 -> 9525267 | F40: =מגדל!D72/מגדל!H72-1 -> -0.92899604 | G40: =מגדל!E72/מגדל!I72-1 -> -0.88424931 | H40: =מגדל!F72/מגדל!J72-1 -> -0.92876154 | I40: =מגדל!G72/מגדל!K72-1 -> -0.91654563
A41: כלל | B41: =כלל!D72 -> 614276.76 | C41: =כלל!E72 -> 158927.33 | D41: =כלל!F72 -> 2474449.6 | E41: =כלל!G72 -> 4995148.8 | F41: =כלל!D72/כלל!H72-1 -> -0.23934366 | G41: =כלל!E72/כלל!I72-1 -> -0.035103592 | H41: =כלל!F72/כלל!J72-1 -> 0.47913562 | I41: =מגדל!G73/מגדל!K73-1 -> #DIV/0!
A42: אלטשולר שחם | B42: ='אלטשולר שחם'!D72 -> 0 | C42: ='אלטשולר שחם'!E72 -> 0 | D42: ='אלטשולר שחם'!F72 -> 0 | E42: ='אלטשולר שחם'!G72 -> 0 | F42: ='אלטשולר שחם'!D72/'אלטשולר שחם'!H72-1 -> #DIV/0! | G42: 0 | H42: ='אלטשולר שחם'!F72/'אלטשולר שחם'!J72-1 -> -1 | I42: 0
A43: מור | B43: =מור!D72 -> 0 | C43: =מור!E72 -> 0 | D43: =מור!F72 -> 344469 | E43: =מור!G72 -> 0 | F43: 0 | G43: 0 | H43: =מור!F72/מור!J72-1 -> -0.96659622 | I43: 0
A44: הראל | B44: =הראל!D72 -> 410818.22 | C44: =הראל!E72 -> 107147.88 | D44: =הראל!F72 -> 630744.51 | E44: =הראל!G72 -> 0 | F44: =הראל!D72/הראל!H72-1 -> -0.89478666 | G44: =הראל!E72/הראל!I72-1 -> -0.92976682 | H44: =הראל!F72/הראל!J72-1 -> -0.70629892 | I44: =הראל!G72/הראל!K72-1 -> -1
A45: הפניקס | B45: =הפניקס!D72 -> 189287.03 | C45: =הפניקס!E72 -> 1314115.3 | D45: =הפניקס!F72 -> 1039952.5 | E45: =הפניקס!G72 -> 101779 | F45: =הפניקס!D72/הפניקס!H72-1 -> -0.93236377 | G45: =הפניקס!E72/הפניקס!I72-1 -> 2.8874348 | H45: =הפניקס!F72/הפניקס!J72-1 -> -0.92922704 | I45: =הפניקס!G72/הפניקס!K72-1 -> -0.99037849
A46: איילון | B46: =איילון!D72 -> 0 | C46: =איילון!E72 -> 64133.56 | D46: =איילון!F72 -> 0 | E46: =איילון!G72 -> 0 | F46: 1 | G46: =איילון!E72/איילון!I72-1 -> 0.19949666 | H46: 0 | I46: 0
A47: הכשרה | B47: =הכשרה!D72 -> 6186.95 | C47: =הכשרה!E72 -> 20332.21 | D47: =הכשרה!F72 -> 0 | E47: =הכשרה!G72 -> 1760783.3 | F47: 0 | G47: =הכשרה!E72/הכשרה!I72-1 -> 0.88069651 | H47: 1 | I47: 0
A48: מדיהו | B48: ='מדיהו '!D72 -> 0 | C48: ='מדיהו '!E72 -> 2157 | D48: ='מדיהו '!F72 -> 0 | E48: ='מדיהו '!G72 -> 0 | F48: 0 | G48: ='מדיהו '!E72/'מדיהו '!I72-1 -> #DIV/0! | H48: 0%0 | I48: 0
A49: אנליסט | B49: ='אנליסט '!D72 -> 0 | C49: ='אנליסט '!E72 -> 0 | D49: ='אנליסט '!F72 -> 2076955 | E49: ='אנליסט '!G72 -> 0 | F49: 0 | G49: 0 | H49: 0 | I49: 0
...

Sheet תפוקה מצטברת מול אשתקד
D1: שינוי מול אשתקד % | H1: תפוקה מצטברת 01/2025 | L1: תפוקה מצטברת 01/2024
A2: שם סוכן | B2: מפקח | C2: מחלקה | D2: פנסיוני | E2: סיכונים | F2: פיננסים | G2: ניודי פנסיה | H2: פנסיוני | I2: סיכונים | J2: פיננסים | K2: ניודי פנסיה | L2: פנסיוני | M2: סיכונים | N2: פיננסים | O2: ניודי פנסיה
A3: גל אלמגור סוכ | B3: יוסי אביב | C3: ישירים | D3: =IF(H3=0,0%,IF(L3=0,100%,H3/L3-1)) -> -0.81703052 | E3: =IF(I3=0,0%,IF(M3=0,100%,I3/M3-1)) -> -0.71514745 | F3: =IF(J3=0,0%,IF(N3=G28,100%,J3/N3-1)) -> -0.66415457 | G3: =IF(K3=0,0%,IF(O3=H28,100%,K3/O3-1)) -> -0.81135804 | H3: =VLOOKUP(A3,הכשרה!A:G,4,0)+VLOOKUP('תפוקה מצטברת מול אשתקד'!A3,מגדל!A:G,4,0)+VLOOKUP('תפוקה מצטברת מול אשתקד'!A3,מנורה!A:G,4,0)+VLOOKUP('תפוקה מצטברת מול אשתקד'!A3,איילון!A:G,4,0)+VLOOKUP('תפוקה מצטברת מול אשתקד'!A3,הראל!A:G,4,0)+VLOOKUP('תפוקה מצטברת מול אשתקד'!A3,הפניקס!A:G,4,0)+VLOOKUP('תפוקה מצטברת מול אשתקד'!A3,כלל!A:G,4,0)+VLOOKUP('תפוקה מצטברת מול אשתקד'!A3,מור!A:G,4,0)+VLOOKUP('תפוקה מצטברת מול אשתקד'!A3,'אלטשולר שחם'!A:G,4,0)+VLOOKUP('תפוקה מצטברת מול אשתקד'!A3,'מדיהו '!A:G,4,0)+VLOOKUP('תפוקה מצטברת מול אשתקד'!A3,'אנליסט '!A:G,4,0)+VLOOKUP('תפוקה מצטברת מול אשתקד'!A3,'מיטב דש'!A:G,4,0)+VLOOKUP('תפוקה מצטברת מול אשתקד'!A3,אינפניטי!A:G,4,0) -> 1072519.2 | I3: =VLOOKUP(A3,הכשרה!A:G,5,0)+VLOOKUP('תפוקה מצטברת מול אשתקד'!A3,מגדל!A:G,5,0)+VLOOKUP('תפוקה מצטברת מול אשתקד'!A3,מנורה!A:G,5,0)+VLOOKUP('תפוקה מצטברת מול אשתקד'!A3,איילון!A:G,5,0)+VLOOKUP('תפוקה מצטברת מול אשתקד'!A3,הראל!A:G,5,0)+VLOOKUP('תפוקה מצטברת מול אשתקד'!A3,הפניקס!A:G,5,0)+VLOOKUP('תפוקה מצטברת מול אשתקד'!A3,כלל!A:G,5,0)+VLOOKUP('תפוקה מצטברת מול אשתקד'!A3,מור!A:G,5,0)+VLOOKUP('תפוקה מצטברת מול אשתקד'!A3,'אלטשולר שחם'!A:G,5,0)+VLOOKUP('תפוקה מצטברת מול אשתקד'!A3,'מדיהו '!A:G,5,0)+VLOOKUP('תפוקה מצטברת מול אשתקד'!A3,'אנליסט '!A:G,5,0)+VLOOKUP('תפוקה מצטברת מול אשתקד'!A3,'מיטב דש'!A:G,5,0)+VLOOKUP('תפוקה מצטברת מול אשתקד'!A3,אינפניטי!A:G,5,0) -> 133701.09 | J3: =VLOOKUP(A3,הכשרה!A:G,6,0)+VLOOKUP('תפוקה מצטברת מול אשתקד'!A3,מגדל!A:G,6,0)+VLOOKUP('תפוקה מצטברת מול אשתקד'!A3,מנורה!A:G,6,0)+VLOOKUP('תפוקה מצטברת מול אשתקד'!A3,איילון!A:G,6,0)+VLOOKUP(A3,הראל!A:G,6,0)+VLOOKUP('תפוקה מצטברת מול אשתקד'!A3,הפניקס!A:G,6,0)+VLOOKUP('תפוקה מצטברת מול אשתקד'!A3,כלל!A:G,6,0)+VLOOKUP('תפוקה מצטברת מול אשתקד'!A3,מור!A:G,6,0)+VLOOKUP('תפוקה מצטברת מול אשתקד'!A3,'אלטשולר שחם'!A:G,6,0)+VLOOKUP('תפוקה מצטברת מול אשתקד'!A3,'מדיהו '!A:G,6,0)+VLOOKUP('תפוקה מצטברת מול אשתקד'!A3,'אנליסט '!A:G,6,0)+VLOOKUP('תפוקה מצטברת מול אשתקד'!A3,'מיטב דש'!A:G,6,0)+VLOOKUP('תפוקה מצטברת מול אשתקד'!A3,אינפניטי!A:G,6,0) -> 3139560.5 | K3: =VLOOKUP(A3,הכשרה!A:G,7,0)+VLOOKUP('תפוקה מצטברת מול אשתקד'!A3,מגדל!A:G,7,0)+VLOOKUP('תפוקה מצטברת מול אשתקד'!A3,מנורה!A:G,7,0)+VLOOKUP('תפוקה מצטברת מול אשתקד'!A3,איילון!A:G,7,0)+VLOOKUP('תפוקה מצטברת מול אשתקד'!A3,הראל!A:G,7,0)+VLOOKUP('תפוקה מצטברת מול אשתקד'!A3,הפניקס!A:G,7,0)+VLOOKUP('תפוקה מצטברת מול אשתקד'!A3,כלל!A:G,7,0)+VLOOKUP('תפוקה מצטברת מול אשתקד'!A3,מור!A:G,7,0)+VLOOKUP('תפוקה מצטברת מול אשתקד'!A3,'אלטשולר שחם'!A:G,7,0)+VLOOKUP('תפוקה מצטברת מול אשתקד'!A3,'מדיהו '!A:K,7,0)+VLOOKUP(A3,'אנליסט '!A:G,7,0)+VLOOKUP('תפוקה מצטברת מול אשתקד'!A3,'מיטב דש'!A:G,7,0)+VLOOKUP('תפוקה מצטברת מול אשתקד'!A3,אינפניטי!A:G,7,0) -> 7043528.8 | L3: =VLOOKUP(A3,הכשרה!A:K,8,0)+VLOOKUP('תפוקה מצטברת מול אשתקד'!A3,מגדל!A:K,8,0)+VLOOKUP('תפוקה מצטברת מול אשתקד'!A3,מנורה!A:K,8,0)+VLOOKUP('תפוקה מצטברת מול אשתקד'!A3,איילון!A:K,8,0)+VLOOKUP('תפוקה מצטברת מול אשתקד'!A3,הראל!A:K,8,0)+VLOOKUP('תפוקה מצטברת מול אשתקד'!A3,הפניקס!A:K,8,0)+VLOOKUP('תפוקה מצטברת מול אשתקד'!A3,כלל!A:K,8,0)+VLOOKUP('תפוקה מצטברת מול אשתקד'!A3,מור!A:K,8,0)+VLOOKUP('תפוקה מצטברת מול אשתקד'!A3,'אלטשולר שחם'!A:K,8,0)+VLOOKUP('תפוקה מצטברת מול אשתקד'!A3,'מדיהו '!A:K,8,0)+VLOOKUP('תפוקה מצטברת מול אשתקד'!A3,'אנליסט '!A:K,8,0)+VLOOKUP('תפוקה מצטברת מול אשתקד'!A3,'מיטב דש'!A:K,8,0)+VLOOKUP('תפוקה מצטברת מול אשתקד'!A3,אינפניטי!A:K,8,0) -> 5861738.7 | M3: =VLOOKUP(A3,הכשרה!A:K,9,0)+VLOOKUP('תפוקה מצטברת מול אשתקד'!A3,מגדל!A:K,9,0)+VLOOKUP('תפוקה מצטברת מול אשתקד'!A3,מנורה!A:K,9,0)+VLOOKUP('תפוקה מצטברת מול אשתקד'!A3,איילון!A:K,9,0)+VLOOKUP('תפוקה מצטברת מול אשתקד'!A3,הראל!A:K,9,0)+VLOOKUP('תפוקה מצטברת מול אשתקד'!A3,הפניקס!A:K,9,0)+VLOOKUP('תפוקה מצטברת מול אשתקד'!A3,כלל!A:K,9,0)+VLOOKUP('תפוקה מצטברת מול אשתקד'!A3,מור!A:K,9,0)+VLOOKUP('תפוקה מצטברת מול אשתקד'!A3,'אלטשולר שחם'!A:K,9,0)+VLOOKUP('תפוקה מצטברת מול אשתקד'!A3,'מדיהו '!A:K,9,0)+VLOOKUP('תפוקה מצטברת מול אשתקד'!A3,'אנליסט '!A:K,9,0)+VLOOKUP('תפוקה מצטברת מול אשתקד'!A3,'מיטב דש'!A:K,9,0)+VLOOKUP('תפוקה מצטברת מול אשתקד'!A3,אינפניטי!A:K,9,0) -> 469369.47 | N3: =VLOOKUP(A3,הכשרה!A:K,10,0)+VLOOKUP('תפוקה מצטברת מול אשתקד'!A3,מגדל!A:K,10,0)+VLOOKUP('תפוקה מצטברת מול אשתקד'!A3,מנורה!A:K,10,0)+VLOOKUP('תפוקה מצטברת מול אשתקד'!A3,איילון!A:K,10,0)+VLOOKUP('תפוקה מצטברת מול אשתקד'!A3,הראל!A:K,10,0)+VLOOKUP('תפוקה מצטברת מול אשתקד'!A3,הפניקס!A:K,10,0)+VLOOKUP('תפוקה מצטברת מול אשתקד'!A3,כלל!A:K,10,0)+VLOOKUP('תפוקה מצטברת מול אשתקד'!A3,מור!A:K,10,0)+VLOOKUP('תפוקה מצטברת מול אשתקד'!A3,'אלטשולר שחם'!A:K,10,0)+VLOOKUP('תפוקה מצטברת מול אשתקד'!A3,'מדיהו '!A:K,10,0)+VLOOKUP('תפוקה מצטברת מול אשתקד'!A3,'אנליסט '!A:K,10,0)+VLOOKUP('תפוקה מצטברת מול אשתקד'!A3,'מיטב דש'!A:K,10,0)+VLOOKUP('תפוקה מצטברת מול אשתקד'!A3,אינפניטי!A:K,10,0) -> 9348230.5 | O3: =VLOOKUP(A3,הכשרה!A:K,11,0)+VLOOKUP('תפוקה מצטברת מול אשתקד'!A3,מגדל!A:K,11,0)+VLOOKUP('תפוקה מצטברת מול אשתקד'!A3,מנורה!A:K,11,0)+VLOOKUP('תפוקה מצטברת מול אשתקד'!A3,איילון!A:K,11,0)+VLOOKUP('תפוקה מצטברת מול אשתקד'!A3,הראל!A:K,11,0)+VLOOKUP('תפוקה מצטברת מול אשתקד'!A3,הפניקס!A:K,11,0)+VLOOKUP('תפוקה מצטברת מול אשתקד'!A3,כלל!A:K,11,0)+VLOOKUP('תפוקה מצטברת מול אשתקד'!A3,מור!A:K,11,0)+VLOOKUP('תפוקה מצטברת מול אשתקד'!A3,'אלטשולר שחם'!A:K,11,0)+VLOOKUP('תפוקה מצטברת מול אשתקד'!A3,'מדיהו '!A:K,11,0)+VLOOKUP('תפוקה מצטברת מול אשתקד'!A3,'אנליסט '!A:K,11,0)+VLOOKUP('תפוקה מצטברת מול אשתקד'!A3,'מיטב דש'!A:K,11,0)+VLOOKUP('תפוקה מצטברת מול אשתקד'!A3,אינפניטי!A:K,11,0) -> 37338080
A4: דניאלה אביב | B4: יוסי אביב | C4: ישירים | D4: =IF(H4=0,0%,IF(L4=0,100%,H4/L4-1)) -> -0.99129882 | E4: =IF(I4=0,0%,IF(M4=0,100%,I4/M4-1)) -> 25.109473 | F4: =IF(J4=0,0%,IF(N4=0,100%,J4/N4-1)) -> -0.97756751 | G4: =IF(K4=0,0%,IF(O4=H29,100%,K4/O4-1)) -> -1.0006861 | H4: =VLOOKUP(A4,הכשרה!A:G,4,0)+VLOOKUP('תפוקה מצטברת מול אשתקד'!A4,מגדל!A:G,4,0)+VLOOKUP('תפוקה מצטברת מול אשתקד'!A4,מנורה!A:G,4,0)+VLOOKUP('תפוקה מצטברת מול אשתקד'!A4,איילון!A:G,4,0)+VLOOKUP('תפוקה מצטברת מול אשתקד'!A4,הראל!A:G,4,0)+VLOOKUP('תפוקה מצטברת מול אשתקד'!A4,הפניקס!A:G,4,0)+VLOOKUP('תפוקה מצטברת מול אשתקד'!A4,כלל!A:G,4,0)+VLOOKUP('תפוקה מצטברת מול אשתקד'!A4,מור!A:G,4,0)+VLOOKUP('תפוקה מצטברת מול אשתקד'!A4,'אלטשולר שחם'!A:G,4,0)+VLOOKUP('תפוקה מצטברת מול אשתקד'!A4,'מדיהו '!A:G,4,0)+VLOOKUP('תפוקה מצטברת מול אשתקד'!A4,'אנליסט '!A:G,4,0)+VLOOKUP('תפוקה מצטברת מול אשתקד'!A4,'מיטב דש'!A:G,4,0)+VLOOKUP('תפוקה מצטברת מול אשתקד'!A4,אינפניטי!A:G,4,0) -> 17268.48 | I4: =VLOOKUP(A4,הכשרה!A:G,5,0)+VLOOKUP('תפוקה מצטברת מול אשתקד'!A4,מגדל!A:G,5,0)+VLOOKUP('תפוקה מצטברת מול אשתקד'!A4,מנורה!A:G,5,0)+VLOOKUP('תפוקה מצטברת מול אשתקד'!A4,איילון!A:G,5,0)+VLOOKUP('תפוקה מצטברת מול אשתקד'!A4,הראל!A:G,5,0)+VLOOKUP('תפוקה מצטברת מול אשתקד'!A4,הפניקס!A:G,5,0)+VLOOKUP('תפוקה מצטברת מול אשתקד'!A4,כלל!A:G,5,0)+VLOOKUP('תפוקה מצטברת מול אשתקד'!A4,מור!A:G,5,0)+VLOOKUP('תפוקה מצטברת מול אשתקד'!A4,'אלטשולר שחם'!A:G,5,0)+VLOOKUP('תפוקה מצטברת מול אשתקד'!A4,'מדיהו '!A:G,5,0)+VLOOKUP('תפוקה מצטברת מול אשתקד'!A4,'אנליסט '!A:G,5,0)+VLOOKUP('תפוקה מצטברת מול אשתקד'!A4,'מיטב דש'!A:G,5,0)+VLOOKUP('תפוקה מצטברת מול אשתקד'!A4,אינפניטי!A:G,5,0) -> 250000 | J4: =VLOOKUP(A4,הכשרה!A:G,6,0)+VLOOKUP('תפוקה מצטברת מול אשתקד'!A4,מגדל!A:G,6,0)+VLOOKUP('תפוקה מצטברת מול אשתקד'!A4,מנורה!A:G,6,0)+VLOOKUP('תפוקה מצטברת מול אשתקד'!A4,איילון!A:G,6,0)+VLOOKUP(A4,הראל!A:G,6,0)+VLOOKUP('תפוקה מצטברת מול אשתקד'!A4,הפניקס!A:G,6,0)+VLOOKUP('תפוקה מצטברת מול אשתקד'!A4,כלל!A:G,6,0)+VLOOKUP('תפוקה מצטברת מול אשתקד'!A4,מור!A:G,6,0)+VLOOKUP('תפוקה מצטברת מול אשתקד'!A4,'אלטשולר שחם'!A:G,6,0)+VLOOKUP('תפוקה מצטברת מול אשתקד'!A4,'מדיהו '!A:G,6,0)+VLOOKUP('תפוקה מצטברת מול אשתקד'!A4,'אנליסט '!A:G,6,0)+VLOOKUP('תפוקה מצטברת מול אשתקד'!A4,'מיטב דש'!A:G,6,0)+VLOOKUP('תפוקה מצטברת מול אשתקד'!A4,אינפניטי!A:G,6,0) -> 272225.52 | K4: =VLOOKUP(A4,הכשרה!A:G,7,0)+VLOOKUP('תפוקה מצטברת מול אשתקד'!A4,מגדל!A:G,7,0)+VLOOKUP('תפוקה מצטברת מול אשתקד'!A4,מנורה!A:G,7,0)+VLOOKUP('תפוקה מצטברת מול אשתקד'!A4,איילון!A:G,7,0)+VLOOKUP('תפוקה מצטברת מול אשתקד'!A4,הראל!A:G,7,0)+VLOOKUP('תפוקה מצטברת מול אשתקד'!A4,הפניקס!A:G,7,0)+VLOOKUP('תפוקה מצטברת מול אשתקד'!A4,כלל!A:G,7,0)+VLOOKUP('תפוקה מצטברת מול אשתקד'!A4,מור!A:G,7,0)+VLOOKUP('תפוקה מצטברת מול אשתקד'!A4,'אלטשולר שחם'!A:G,7,0)+VLOOKUP('תפוקה מצטברת מול אשתקד'!A4,'מדיהו '!A:K,7,0)+VLOOKUP(A4,'אנליסט '!A:G,7,0)+VLOOKUP('תפוקה מצטברת מול אשתקד'!A4,'מיטב דש'!A:G,7,0)+VLOOKUP('תפוקה מצטברת מול אשתקד'!A4,אינפניטי!A:G,7,0) -> -7407.02 | L4: =VLOOKUP(A4,הכשרה!A:K,8,0)+VLOOKUP('תפוקה מצטברת מול אשתקד'!A4,מגדל!A:K,8,0)+VLOOKUP('תפוקה מצטברת מול אשתקד'!A4,מנורה!A:K,8,0)+VLOOKUP('תפוקה מצטברת מול אשתקד'!A4,איילון!A:K,8,0)+VLOOKUP('תפוקה מצטברת מול אשתקד'!A4,הראל!A:K,8,0)+VLOOKUP('תפוקה מצטברת מול אשתקד'!A4,הפניקס!A:K,8,0)+VLOOKUP('תפוקה מצטברת מול אשתקד'!A4,כלל!A:K,8,0)+VLOOKUP('תפוקה מצטברת מול אשתקד'!A4,מור!A:K,8,0)+VLOOKUP('תפוקה מצטברת מול אשתקד'!A4,'אלטשולר שחם'!A:K,8,0)+VLOOKUP('תפוקה מצטברת מול אשתקד'!A4,'מדיהו '!A:K,8,0)+VLOOKUP('תפוקה מצטברת מול אשתקד'!A4,'אנליסט '!A:K,8,0)+VLOOKUP('תפוקה מצטברת מול אשתקד'!A4,'מיטב דש'!A:K,8,0)+VLOOKUP('תפוקה מצטברת מול אשתקד'!A4,אינפניטי!A:K,8,0) -> 1984613.5 | M4: =VLOOKUP(A4,הכשרה!A:K,9,0)+VLOOKUP('תפוקה מצטברת מול אשתקד'!A4,מגדל!A:K,9,0)+VLOOKUP('תפוקה מצטברת מול אשתקד'!A4,מנורה!A:K,9,0)+VLOOKUP('תפוקה מצטברת מול אשתקד'!A4,איילון!A:K,9,0)+VLOOKUP('תפוקה מצטברת מול אשתקד'!A4,הראל!A:K,9,0)+VLOOKUP('תפוקה מצטברת מול אשתקד'!A4,הפניקס!A:K,9,0)+VLOOKUP('תפוקה מצטברת מול אשתקד'!A4,כלל!A:K,9,0)+VLOOKUP('תפוקה מצטברת מול אשתקד'!A4,מור!A:K,9,0)+VLOOKUP('תפוקה מצטברת מול אשתקד'!A4,'אלטשולר שחם'!A:K,9,0)+VLOOKUP('תפוקה מצטברת מול אשתקד'!A4,'מדיהו '!A:K,9,0)+VLOOKUP('תפוקה מצטברת מול אשתקד'!A4,'אנליסט '!A:K,9,0)+VLOOKUP('תפוקה מצטברת מול אשתקד'!A4,'מיטב דש'!A:K,9,0)+VLOOKUP('תפוקה מצטברת מול אשתקד'!A4,אינפניטי!A:K,9,0) -> 9575.0687 | N4: =VLOOKUP(A4,הכשרה!A:K,10,0)+VLOOKUP('תפוקה מצטברת מול אשתקד'!A4,מגדל!A:K,10,0)+VLOOKUP('תפוקה מצטברת מול אשתקד'!A4,מנורה!A:K,10,0)+VLOOKUP('תפוקה מצטברת מול אשתקד'!A4,איילון!A:K,10,0)+VLOOKUP('תפוקה מצטברת מול אשתקד'!A4,הראל!A:K,10,0)+VLOOKUP('תפוקה מצטברת מול אשתקד'!A4,הפניקס!A:K,10,0)+VLOOKUP('תפוקה מצטברת מול אשתקד'!A4,כלל!A:K,10,0)+VLOOKUP('תפוקה מצטברת מול אשתקד'!A4,מור!A:K,10,0)+VLOOKUP('תפוקה מצטברת מול אשתקד'!A4,'אלטשולר שחם'!A:K,10,0)+VLOOKUP('תפוקה מצטברת מול אשתקד'!A4,'מדיהו '!A:K,10,0)+VLOOKUP('תפוקה מצטברת מול אשתקד'!A4,'אנליסט '!A:K,10,0)+VLOOKUP('תפוקה מצטברת מול אשתקד'!A4,'מיטב דש'!A:K,10,0)+VLOOKUP('תפוקה מצטברת מול אשתקד'!A4,אינפניטי!A:K,10,0) -> 12135322 | O4: =VLOOKUP(A4,הכשרה!A:K,11,0)+VLOOKUP('תפוקה מצטברת מול אשתקד'!A4,מגדל!A:K,11,0)+VLOOKUP('תפוקה מצטברת מול אשתקד'!A4,מנורה!A:K,11,0)+VLOOKUP('תפוקה מצטברת מול אשתקד'!A4,איילון!A:K,11,0)+VLOOKUP('תפוקה מצטברת מול אשתקד'!A4,הראל!A:K,11,0)+VLOOKUP('תפוקה מצטברת מול אשתקד'!A4,הפניקס!A:K,11,0)+VLOOKUP('תפוקה מצטברת מול אשתקד'!A4,כלל!A:K,11,0)+VLOOKUP('תפוקה מצטברת מול אשתקד'!A4,מור!A:K,11,0)+VLOOKUP('תפוקה מצטברת מול אשתקד'!A4,'אלטשולר שחם'!A:K,11,0)+VLOOKUP('תפוקה מצטברת מול אשתקד'!A4,'מדיהו '!A:K,11,0)+VLOOKUP('תפוקה מצטברת מול אשתקד'!A4,'אנליסט '!A:K,11,0)+VLOOKUP('תפוקה מצטברת מול אשתקד'!A4,'מיטב דש'!A:K,11,0)+VLOOKUP('תפוקה מצטברת מול אשתקד'!A4,אינפניטי!A:K,11,0) -> 10795633
A5: רותי | B5: יוסי אביב | C5: ישירים | D5: =IF(H5=0,0%,IF(L5=0,100%,H5/L5-1)) -> 0 | E5: =IF(I5=0,0%,IF(M5=0,100%,I5/M5-1)) -> -0.45965967 | F5: =IF(J5=0,0%,IF(N5=0,100%,J5/N5-1)) -> 0 | G5: =IF(K5=0,0%,IF(O5=H30,100%,K5/O5-1)) -> 0 | H5: =VLOOKUP(A5,הכשרה!A:G,4,0)+VLOOKUP('תפוקה מצטברת מול אשתקד'!A5,מגדל!A:G,4,0)+VLOOKUP('תפוקה מצטברת מול אשתקד'!A5,מנורה!A:G,4,0)+VLOOKUP('תפוקה מצטברת מול אשתקד'!A5,איילון!A:G,4,0)+VLOOKUP('תפוקה מצטברת מול אשתקד'!A5,הראל!A:G,4,0)+VLOOKUP('תפוקה מצטברת מול אשתקד'!A5,הפניקס!A:G,4,0)+VLOOKUP('תפוקה מצטברת מול אשתקד'!A5,כלל!A:G,4,0)+VLOOKUP('תפוקה מצטברת מול אשתקד'!A5,מור!A:G,4,0)+VLOOKUP('תפוקה מצטברת מול אשתקד'!A5,'אלטשולר שחם'!A:G,4,0)+VLOOKUP('תפוקה מצטברת מול אשתקד'!A5,'מדיהו '!A:G,4,0)+VLOOKUP('תפוקה מצטברת מול אשתקד'!A5,'אנליסט '!A:G,4,0)+VLOOKUP('תפוקה מצטברת מול אשתקד'!A5,'מיטב דש'!A:G,4,0)+VLOOKUP('תפוקה מצטברת מול אשתקד'!A5,אינפניטי!A:G,4,0) -> 0 | I5: =VLOOKUP(A5,הכשרה!A:G,5,0)+VLOOKUP('תפוקה מצטברת מול אשתקד'!A5,מגדל!A:G,5,0)+VLOOKUP('תפוקה מצטברת מול אשתקד'!A5,מנורה!A:G,5,0)+VLOOKUP('תפוקה מצטברת מול אשתקד'!A5,איילון!A:G,5,0)+VLOOKUP('תפוקה מצטברת מול אשתקד'!A5,הראל!A:G,5,0)+VLOOKUP('תפוקה מצטברת מול אשתקד'!A5,הפניקס!A:G,5,0)+VLOOKUP('תפוקה מצטברת מול אשתקד'!A5,כלל!A:G,5,0)+VLOOKUP('תפוקה מצטברת מול אשתקד'!A5,מור!A:G,5,0)+VLOOKUP('תפוקה מצטברת מול אשתקד'!A5,'אלטשולר שחם'!A:G,5,0)+VLOOKUP('תפוקה מצטברת מול אשתקד'!A5,'מדיהו '!A:G,5,0)+VLOOKUP('תפוקה מצטברת מול אשתקד'!A5,'אנליסט '!A:G,5,0)+VLOOKUP('תפוקה מצטברת מול אשתקד'!A5,'מיטב דש'!A:G,5,0)+VLOOKUP('תפוקה מצטברת מול אשתקד'!A5,אינפניטי!A:G,5,0) -> 39045.9 | J5: =VLOOKUP(A5,הכשרה!A:G,6,0)+VLOOKUP('תפוקה מצטברת מול אשתקד'!A5,מגדל!A:G,6,0)+VLOOKUP('תפוקה מצטברת מול אשתקד'!A5,מנורה!A:G,6,0)+VLOOKUP('תפוקה מצטברת מול אשתקד'!A5,איילון!A:G,6,0)+VLOOKUP(A5,הראל!A:G,6,0)+VLOOKUP('תפוקה מצטברת מול אשתקד'!A5,הפניקס!A:G,6,0)+VLOOKUP('תפוקה מצטברת מול אשתקד'!A5,כלל!A:G,6,0)+VLOOKUP('תפוקה מצטברת מול אשתקד'!A5,מור!A:G,6,0)+VLOOKUP('תפוקה מצטברת מול אשתקד'!A5,'אלטשולר שחם'!A:G,6,0)+VLOOKUP('תפוקה מצטברת מול אשתקד'!A5,'מדיהו '!A:G,6,0)+VLOOKUP('תפוקה מצטברת מול אשתקד'!A5,'אנליסט '!A:G,6,0)+VLOOKUP('תפוקה מצטברת מול אשתקד'!A5,'מיטב דש'!A:G,6,0)+VLOOKUP('תפוקה מצטברת מול אשתקד'!A5,אינפניטי!A:G,6,0) -> 0 | K5: =VLOOKUP(A5,הכשרה!A:G,7,0)+VLOOKUP('תפוקה מצטברת מול אשתקד'!A5,מגדל!A:G,7,0)+VLOOKUP('תפוקה מצטברת מול אשתקד'!A5,מנורה!A:G,7,0)+VLOOKUP('תפוקה מצטברת מול אשתקד'!A5,איילון!A:G,7,0)+VLOOKUP('תפוקה מצטברת מול אשתקד'!A5,הראל!A:G,7,0)+VLOOKUP('תפוקה מצטברת מול אשתקד'!A5,הפניקס!A:G,7,0)+VLOOKUP('תפוקה מצטברת מול אשתקד'!A5,כלל!A:G,7,0)+VLOOKUP('תפוקה מצטברת מול אשתקד'!A5,מור!A:G,7,0)+VLOOKUP('תפוקה מצטברת מול אשתקד'!A5,'אלטשולר שחם'!A:G,7,0)+VLOOKUP('תפוקה מצטברת מול אשתקד'!A5,'מדיהו '!A:K,7,0)+VLOOKUP(A5,'אנליסט '!A:G,7,0)+VLOOKUP('תפוקה מצטברת מול אשתקד'!A5,'מיטב דש'!A:G,7,0)+VLOOKUP('תפוקה מצטברת מול אשתקד'!A5,אינפניטי!A:G,7,0) -> 0 | L5: =VLOOKUP(A5,הכשרה!A:K,8,0)+VLOOKUP('תפוקה מצטברת מול אשתקד'!A5,מגדל!A:K,8,0)+VLOOKUP('תפוקה מצטברת מול אשתקד'!A5,מנורה!A:K,8,0)+VLOOKUP('תפוקה מצטברת מול אשתקד'!A5,איילון!A:K,8,0)+VLOOKUP('תפוקה מצטברת מול אשתקד'!A5,הראל!A:K,8,0)+VLOOKUP('תפוקה מצטברת מול אשתקד'!A5,הפניקס!A:K,8,0)+VLOOKUP('תפוקה מצטברת מול אשתקד'!A5,כלל!A:K,8,0)+VLOOKUP('תפוקה מצטברת מול אשתקד'!A5,מור!A:K,8,0)+VLOOKUP('תפוקה מצטברת מול אשתקד'!A5,'אלטשולר שחם'!A:K,8,0)+VLOOKUP('תפוקה מצטברת מול אשתקד'!A5,'מדיהו '!A:K,8,0)+VLOOKUP('תפוקה מצטברת מול אשתקד'!A5,'אנליסט '!A:K,8,0)+VLOOKUP('תפוקה מצטברת מול אשתקד'!A5,'מיטב דש'!A:K,8,0)+VLOOKUP('תפוקה מצטברת מול אשתקד'!A5,אינפניטי!A:K,8,0) -> 0 | M5: =VLOOKUP(A5,הכשרה!A:K,9,0)+VLOOKUP('תפוקה מצטברת מול אשתקד'!A5,מגדל!A:K,9,0)+VLOOKUP('תפוקה מצטברת מול אשתקד'!A5,מנורה!A:K,9,0)+VLOOKUP('תפוקה מצטברת מול אשתקד'!A5,איילון!A:K,9,0)+VLOOKUP('תפוקה מצטברת מול אשתקד'!A5,הראל!A:K,9,0)+VLOOKUP('תפוקה מצטברת מול אשתקד'!A5,הפניקס!A:K,9,0)+VLOOKUP('תפוקה מצטברת מול אשתקד'!A5,כלל!A:K,9,0)+VLOOKUP('תפוקה מצטברת מול אשתקד'!A5,מור!A:K,9,0)+VLOOKUP('תפוקה מצטברת מול אשתקד'!A5,'אלטשולר שחם'!A:K,9,0)+VLOOKUP('תפוקה מצטברת מול אשתקד'!A5,'מדיהו '!A:K,9,0)+VLOOKUP('תפוקה מצטברת מול אשתקד'!A5,'אנליסט '!A:K,9,0)+VLOOKUP('תפוקה מצטברת מול אשתקד'!A5,'מיטב דש'!A:K,9,0)+VLOOKUP('תפוקה מצטברת מול אשתקד'!A5,אינפניטי!A:K,9,0) -> 72261.68 | N5: =VLOOKUP(A5,הכשרה!A:K,10,0)+VLOOKUP('תפוקה מצטברת מול אשתקד'!A5,מגדל!A:K,10,0)+VLOOKUP('תפוקה מצטברת מול אשתקד'!A5,מנורה!A:K,10,0)+VLOOKUP('תפוקה מצטברת מול אשתקד'!A5,איילון!A:K,10,0)+VLOOKUP('תפוקה מצטברת מול אשתקד'!A5,הראל!A:K,10,0)+VLOOKUP('תפוקה מצטברת מול אשתקד'!A5,הפניקס!A:K,10,0)+VLOOKUP('תפוקה מצטברת מול אשתקד'!A5,כלל!A:K,10,0)+VLOOKUP('תפוקה מצטברת מול אשתקד'!A5,מור!A:K,10,0)+VLOOKUP('תפוקה מצטברת מול אשתקד'!A5,'אלטשולר שחם'!A:K,10,0)+VLOOKUP('תפוקה מצטברת מול אשתקד'!A5,'מדיהו '!A:K,10,0)+VLOOKUP('תפוקה מצטברת מול אשתקד'!A5,'אנליסט '!A:K,10,0)+VLOOKUP('תפוקה מצטברת מול אשתקד'!A5,'מיטב דש'!A:K,10,0)+VLOOKUP('תפוקה מצטברת מול אשתקד'!A5,אינפניטי!A:K,10,0) -> 0 | O5: =VLOOKUP(A5,הכשרה!A:K,11,0)+VLOOKUP('תפוקה מצטברת מול אשתקד'!A5,מגדל!A:K,11,0)+VLOOKUP('תפוקה מצטברת מול אשתקד'!A5,מנורה!A:K,11,0)+VLOOKUP('תפוקה מצטברת מול אשתקד'!A5,איילון!A:K,11,0)+VLOOKUP('תפוקה מצטברת מול אשתקד'!A5,הראל!A:K,11,0)+VLOOKUP('תפוקה מצטברת מול אשתקד'!A5,הפניקס!A:K,11,0)+VLOOKUP('תפוקה מצטברת מול אשתקד'!A5,כלל!A:K,11,0)+VLOOKUP('תפוקה מצטברת מול אשתקד'!A5,מור!A:K,11,0)+VLOOKUP('תפוקה מצטברת מול אשתקד'!A5,'אלטשולר שחם'!A:K,11,0)+VLOOKUP('תפוקה מצטברת מול אשתקד'!A5,'מדיהו '!A:K,11,0)+VLOOKUP('תפוקה מצטברת מול אשתקד'!A5,'אנליסט '!A:K,11,0)+VLOOKUP('תפוקה מצטברת מול אשתקד'!A5,'מיטב דש'!A:K,11,0)+VLOOKUP('תפוקה מצטברת מול אשתקד'!A5,אינפניטי!A:K,11,0) -> 0
A6: אילנית | B6: יוסי אביב | C6: ישירים | D6: =IF(H6=0,0%,IF(L6=0,100%,H6/L6-1)) -> 0.32486175 | E6: =IF(I6=0,0%,IF(M6=0,100%,I6/M6-1)) -> -0.70802319 | F6: =IF(J6=0,0%,IF(N6=0,100%,J6/N6-1)) -> -0.99154364 | G6: =IF(K6=0,0%,IF(O6=H31,100%,K6/O6-1)) -> 1 | H6: =VLOOKUP(A6,הכשרה!A:G,4,0)+VLOOKUP('תפוקה מצטברת מול אשתקד'!A6,מגדל!A:G,4,0)+VLOOKUP('תפוקה מצטברת מול אשתקד'!A6,מנורה!A:G,4,0)+VLOOKUP('תפוקה מצטברת מול אשתקד'!A6,איילון!A:G,4,0)+VLOOKUP('תפוקה מצטברת מול אשתקד'!A6,הראל!A:G,4,0)+VLOOKUP('תפוקה מצטברת מול אשתקד'!A6,הפניקס!A:G,4,0)+VLOOKUP('תפוקה מצטברת מול אשתקד'!A6,כלל!A:G,4,0)+VLOOKUP('תפוקה מצטברת מול אשתקד'!A6,מור!A:G,4,0)+VLOOKUP('תפוקה מצטברת מול אשתקד'!A6,'אלטשולר שחם'!A:G,4,0)+VLOOKUP('תפוקה מצטברת מול אשתקד'!A6,'מדיהו '!A:G,4,0)+VLOOKUP('תפוקה מצטברת מול אשתקד'!A6,'אנליסט '!A:G,4,0)+VLOOKUP('תפוקה מצטברת מול אשתקד'!A6,'מיטב דש'!A:G,4,0)+VLOOKUP('תפוקה מצטברת מול אשתקד'!A6,אינפניטי!A:G,4,0) -> 39537.783 | I6: =VLOOKUP(A6,הכשרה!A:G,5,0)+VLOOKUP('תפוקה מצטברת מול אשתקד'!A6,מגדל!A:G,5,0)+VLOOKUP('תפוקה מצטברת מול אשתקד'!A6,מנורה!A:G,5,0)+VLOOKUP('תפוקה מצטברת מול אשתקד'!A6,איילון!A:G,5,0)+VLOOKUP('תפוקה מצטברת מול אשתקד'!A6,הראל!A:G,5,0)+VLOOKUP('תפוקה מצטברת מול אשתקד'!A6,הפניקס!A:G,5,0)+VLOOKUP('תפוקה מצטברת מול אשתקד'!A6,כלל!A:G,5,0)+VLOOKUP('תפוקה מצטברת מול אשתקד'!A6,מור!A:G,5,0)+VLOOKUP('תפוקה מצטברת מול אשתקד'!A6,'אלטשולר שחם'!A:G,5,0)+VLOOKUP('תפוקה מצטברת מול אשתקד'!A6,'מדיהו '!A:G,5,0)+VLOOKUP('תפוקה מצטברת מול אשתקד'!A6,'אנליסט '!A:G,5,0)+VLOOKUP('תפוקה מצטברת מול אשתקד'!A6,'מיטב דש'!A:G,5,0)+VLOOKUP('תפוקה מצטברת מול אשתקד'!A6,אינפניטי!A:G,5,0) -> 8009.3 | J6: =VLOOKUP(A6,הכשרה!A:G,6,0)+VLOOKUP('תפוקה מצטברת מול אשתקד'!A6,מגדל!A:G,6,0)+VLOOKUP('תפוקה מצטברת מול אשתקד'!A6,מנורה!A:G,6,0)+VLOOKUP('תפוקה מצטברת מול אשתקד'!A6,איילון!A:G,6,0)+VLOOKUP(A6,הראל!A:G,6,0)+VLOOKUP('תפוקה מצטברת מול אשתקד'!A6,הפניקס!A:G,6,0)+VLOOKUP('תפוקה מצטברת מול אשתקד'!A6,כלל!A:G,6,0)+VLOOKUP('תפוקה מצטברת מול אשתקד'!A6,מור!A:G,6,0)+VLOOKUP('תפוקה מצטברת מול אשתקד'!A6,'אלטשולר שחם'!A:G,6,0)+VLOOKUP('תפוקה מצטברת מול אשתקד'!A6,'מדיהו '!A:G,6,0)+VLOOKUP('תפוקה מצטברת מול אשתקד'!A6,'אנליסט '!A:G,6,0)+VLOOKUP('תפוקה מצטברת מול אשתקד'!A6,'מיטב דש'!A:G,6,0)+VLOOKUP('תפוקה מצטברת מול אשתקד'!A6,אינפניטי!A:G,6,0) -> 7000 | K6: =VLOOKUP(A6,הכשרה!A:G,7,0)+VLOOKUP('תפוקה מצטברת מול אשתקד'!A6,מגדל!A:G,7,0)+VLOOKUP('תפוקה מצטברת מול אשתקד'!A6,מנורה!A:G,7,0)+VLOOKUP('תפוקה מצטברת מול אשתקד'!A6,איילון!A:G,7,0)+VLOOKUP('תפוקה מצטברת מול אשתקד'!A6,הראל!A:G,7,0)+VLOOKUP('תפוקה מצטברת מול אשתקד'!A6,הפניקס!A:G,7,0)+VLOOKUP('תפוקה מצטברת מול אשתקד'!A6,כלל!A:G,7,0)+VLOOKUP('תפוקה מצטברת מול אשתקד'!A6,מור!A:G,7,0)+VLOOKUP('תפוקה מצטברת מול אשתקד'!A6,'אלטשולר שחם'!A:G,7,0)+VLOOKUP('תפוקה מצטברת מול אשתקד'!A6,'מדיהו '!A:K,7,0)+VLOOKUP(A6,'אנליסט '!A:G,7,0)+VLOOKUP('תפוקה מצטברת מול אשתקד'!A6,'מיטב דש'!A:G,7,0)+VLOOKUP('תפוקה מצטברת מול אשתקד'!A6,אינפניטי!A:G,7,0) -> 202054.22 | L6: =VLOOKUP(A6,הכשרה!A:K,8,0)+VLOOKUP('תפוקה מצטברת מול אשתקד'!A6,מגדל!A:K,8,0)+VLOOKUP('תפוקה מצטברת מול אשתקד'!A6,מנורה!A:K,8,0)+VLOOKUP('תפוקה מצטברת מול אשתקד'!A6,איילון!A:K,8,0)+VLOOKUP('תפוקה מצטברת מול אשתקד'!A6,הראל!A:K,8,0)+VLOOKUP('תפוקה מצטברת מול אשתקד'!A6,הפניקס!A:K,8,0)+VLOOKUP('תפוקה מצטברת מול אשתקד'!A6,כלל!A:K,8,0)+VLOOKUP('תפוקה מצטברת מול אשתקד'!A6,מור!A:K,8,0)+VLOOKUP('תפוקה מצטברת מול אשתקד'!A6,'אלטשולר שחם'!A:K,8,0)+VLOOKUP('תפוקה מצטברת מול אשתקד'!A6,'מדיהו '!A:K,8,0)+VLOOKUP('תפוקה מצטברת מול אשתקד'!A6,'אנליסט '!A:K,8,0)+VLOOKUP('תפוקה מצטברת מול אשתקד'!A6,'מיטב דש'!A:K,8,0)+VLOOKUP('תפוקה מצטברת מול אשתקד'!A6,אינפניטי!A:K,8,0) -> 29842.95 | M6: =VLOOKUP(A6,הכשרה!A:K,9,0)+VLOOKUP('תפוקה מצטברת מול אשתקד'!A6,מגדל!A:K,9,0)+VLOOKUP('תפוקה מצטברת מול אשתקד'!A6,מנורה!A:K,9,0)+VLOOKUP('תפוקה מצטברת מול אשתקד'!A6,איילון!A:K,9,0)+VLOOKUP('תפוקה מצטברת מול אשתקד'!A6,הראל!A:K,9,0)+VLOOKUP('תפוקה מצטברת מול אשתקד'!A6,הפניקס!A:K,9,0)+VLOOKUP('תפוקה מצטברת מול אשתקד'!A6,כלל!A:K,9,0)+VLOOKUP('תפוקה מצטברת מול אשתקד'!A6,מור!A:K,9,0)+VLOOKUP('תפוקה מצטברת מול אשתקד'!A6,'אלטשולר שחם'!A:K,9,0)+VLOOKUP('תפוקה מצטברת מול אשתקד'!A6,'מדיהו '!A:K,9,0)+VLOOKUP('תפוקה מצטברת מול אשתקד'!A6,'אנליסט '!A:K,9,0)+VLOOKUP('תפוקה מצטברת מול אשתקד'!A6,'מיטב דש'!A:K,9,0)+VLOOKUP('תפוקה מצטברת מול אשתקד'!A6,אינפניטי!A:K,9,0) -> 27431.288 | N6: =VLOOKUP(A6,הכשרה!A:K,10,0)+VLOOKUP('תפוקה מצטברת מול אשתקד'!A6,מגדל!A:K,10,0)+VLOOKUP('תפוקה מצטברת מול אשתקד'!A6,מנורה!A:K,10,0)+VLOOKUP('תפוקה מצטברת מול אשתקד'!A6,איילון!A:K,10,0)+VLOOKUP('תפוקה מצטברת מול אשתקד'!A6,הראל!A:K,10,0)+VLOOKUP('תפוקה מצטברת מול אשתקד'!A6,הפניקס!A:K,10,0)+VLOOKUP('תפוקה מצטברת מול אשתקד'!A6,כלל!A:K,10,0)+VLOOKUP('תפוקה מצטברת מול אשתקד'!A6,מור!A:K,10,0)+VLOOKUP('תפוקה מצטברת מול אשתקד'!A6,'אלטשולר שחם'!A:K,10,0)+VLOOKUP('תפוקה מצטברת מול אשתקד'!A6,'מדיהו '!A:K,10,0)+VLOOKUP('תפוקה מצטברת מול אשתקד'!A6,'אנליסט '!A:K,10,0)+VLOOKUP('תפוקה מצטברת מול אשתקד'!A6,'מיטב דש'!A:K,10,0)+VLOOKUP('תפוקה מצטברת מול אשתקד'!A6,אינפניטי!A:K,10,0) -> 827779.17 | O6: =VLOOKUP(A6,הכשרה!A:K,11,0)+VLOOKUP('תפוקה מצטברת מול אשתקד'!A6,מגדל!A:K,11,0)+VLOOKUP('תפוקה מצטברת מול אשתקד'!A6,מנורה!A:K,11,0)+VLOOKUP('תפוקה מצטברת מול אשתקד'!A6,איילון!A:K,11,0)+VLOOKUP('תפוקה מצטברת מול אשתקד'!A6,הראל!A:K,11,0)+VLOOKUP('תפוקה מצטברת מול אשתקד'!A6,הפניקס!A:K,11,0)+VLOOKUP('תפוקה מצטברת מול אשתקד'!A6,כלל!A:K,11,0)+VLOOKUP('תפוקה מצטברת מול אשתקד'!A6,מור!A:K,11,0)+VLOOKUP('תפוקה מצטברת מול אשתקד'!A6,'אלטשולר שחם'!A:K,11,0)+VLOOKUP('תפוקה מצטברת מול אשתקד'!A6,'מדיהו '!A:K,11,0)+VLOOKUP('תפוקה מצטברת מול אשתקד'!A6,'אנליסט '!A:K,11,0)+VLOOKUP('תפוקה מצטברת מול אשתקד'!A6,'מיטב דש'!A:K,11,0)+VLOOKUP('תפוקה מצטברת מול אשתקד'!A6,אינפניטי!A:K,11,0) -> 0
A7: דני פחימה | B7: יוסי אביב | C7: ישירים | D7: =IF(H7=0,0%,IF(L7=0,100%,H7/L7-1)) -> 0 | E7: =IF(I7=0,0%,IF(M7=0,100%,I7/M7-1)) -> 0 | F7: =IF(J7=0,0%,IF(N7=0,100%,J7/N7-1)) -> 0 | G7: =IF(K7=0,0%,IF(O7=H70,100%,K7/O7-1)) -> 0 | H7: =VLOOKUP(A7,הכשרה!A:G,4,0)+VLOOKUP('תפוקה מצטברת מול אשתקד'!A7,מגדל!A:G,4,0)+VLOOKUP('תפוקה מצטברת מול אשתקד'!A7,מנורה!A:G,4,0)+VLOOKUP('תפוקה מצטברת מול אשתקד'!A7,איילון!A:G,4,0)+VLOOKUP('תפוקה מצטברת מול אשתקד'!A7,הראל!A:G,4,0)+VLOOKUP('תפוקה מצטברת מול אשתקד'!A7,הפניקס!A:G,4,0)+VLOOKUP('תפוקה מצטברת מול אשתקד'!A7,כלל!A:G,4,0)+VLOOKUP('תפוקה מצטברת מול אשתקד'!A7,מור!A:G,4,0)+VLOOKUP('תפוקה מצטברת מול אשתקד'!A7,'אלטשולר שחם'!A:G,4,0)+VLOOKUP('תפוקה מצטברת מול אשתקד'!A7,'מדיהו '!A:G,4,0)+VLOOKUP('תפוקה מצטברת מול אשתקד'!A7,'אנליסט '!A:G,4,0)+VLOOKUP('תפוקה מצטברת מול אשתקד'!A7,'מיטב דש'!A:G,4,0)+VLOOKUP('תפוקה מצטברת מול אשתקד'!A7,אינפניטי!A:G,4,0) -> 0 | I7: =VLOOKUP(A7,הכשרה!A:G,5,0)+VLOOKUP('תפוקה מצטברת מול אשתקד'!A7,מגדל!A:G,5,0)+VLOOKUP('תפוקה מצטברת מול אשתקד'!A7,מנורה!A:G,5,0)+VLOOKUP('תפוקה מצטברת מול אשתקד'!A7,איילון!A:G,5,0)+VLOOKUP('תפוקה מצטברת מול אשתקד'!A7,הראל!A:G,5,0)+VLOOKUP('תפוקה מצטברת מול אשתקד'!A7,הפניקס!A:G,5,0)+VLOOKUP('תפוקה מצטברת מול אשתקד'!A7,כלל!A:G,5,0)+VLOOKUP('תפוקה מצטברת מול אשתקד'!A7,מור!A:G,5,0)+VLOOKUP('תפוקה מצטברת מול אשתקד'!A7,'אלטשולר שחם'!A:G,5,0)+VLOOKUP('תפוקה מצטברת מול אשתקד'!A7,'מדיהו '!A:G,5,0)+VLOOKUP('תפוקה מצטברת מול אשתקד'!A7,'אנליסט '!A:G,5,0)+VLOOKUP('תפוקה מצטברת מול אשתקד'!A7,'מיטב דש'!A:G,5,0)+VLOOKUP('תפוקה מצטברת מול אשתקד'!A7,אינפניטי!A:G,5,0) -> 0 | J7: =VLOOKUP(A7,הכשרה!A:G,6,0)+VLOOKUP('תפוקה מצטברת מול אשתקד'!A7,מגדל!A:G,6,0)+VLOOKUP('תפוקה מצטברת מול אשתקד'!A7,מנורה!A:G,6,0)+VLOOKUP('תפוקה מצטברת מול אשתקד'!A7,איילון!A:G,6,0)+VLOOKUP(A7,הראל!A:G,6,0)+VLOOKUP('תפוקה מצטברת מול אשתקד'!A7,הפניקס!A:G,6,0)+VLOOKUP('תפוקה מצטברת מול אשתקד'!A7,כלל!A:G,6,0)+VLOOKUP('תפוקה מצטברת מול אשתקד'!A7,מור!A:G,6,0)+VLOOKUP('תפוקה מצטברת מול אשתקד'!A7,'אלטשולר שחם'!A:G,6,0)+VLOOKUP('תפוקה מצטברת מול אשתקד'!A7,'מדיהו '!A:G,6,0)+VLOOKUP('תפוקה מצטברת מול אשתקד'!A7,'אנליסט '!A:G,6,0)+VLOOKUP('תפוקה מצטברת מול אשתקד'!A7,'מיטב דש'!A:G,6,0)+VLOOKUP('תפוקה מצטברת מול אשתקד'!A7,אינפניטי!A:G,6,0) -> 0 | K7: =VLOOKUP(A7,הכשרה!A:G,7,0)+VLOOKUP('תפוקה מצטברת מול אשתקד'!A7,מגדל!A:G,7,0)+VLOOKUP('תפוקה מצטברת מול אשתקד'!A7,מנורה!A:G,7,0)+VLOOKUP('תפוקה מצטברת מול אשתקד'!A7,איילון!A:G,7,0)+VLOOKUP('תפוקה מצטברת מול אשתקד'!A7,הראל!A:G,7,0)+VLOOKUP('תפוקה מצטברת מול אשתקד'!A7,הפניקס!A:G,7,0)+VLOOKUP('תפוקה מצטברת מול אשתקד'!A7,כלל!A:G,7,0)+VLOOKUP('תפוקה מצטברת מול אשתקד'!A7,מור!A:G,7,0)+VLOOKUP('תפוקה מצטברת מול אשתקד'!A7,'אלטשולר שחם'!A:G,7,0)+VLOOKUP('תפוקה מצטברת מול אשתקד'!A7,'מדיהו '!A:K,7,0)+VLOOKUP(A7,'אנליסט '!A:G,7,0)+VLOOKUP('תפוקה מצטברת מול אשתקד'!A7,'מיטב דש'!A:G,7,0)+VLOOKUP('תפוקה מצטברת מול אשתקד'!A7,אינפניטי!A:G,7,0) -> 0 | L7: =VLOOKUP(A7,הכשרה!A:K,8,0)+VLOOKUP('תפוקה מצטברת מול אשתקד'!A7,מגדל!A:K,8,0)+VLOOKUP('תפוקה מצטברת מול אשתקד'!A7,מנורה!A:K,8,0)+VLOOKUP('תפוקה מצטברת מול אשתקד'!A7,איילון!A:K,8,0)+VLOOKUP('תפוקה מצטברת מול אשתקד'!A7,הראל!A:K,8,0)+VLOOKUP('תפוקה מצטברת מול אשתקד'!A7,הפניקס!A:K,8,0)+VLOOKUP('תפוקה מצטברת מול אשתקד'!A7,כלל!A:K,8,0)+VLOOKUP('תפוקה מצטברת מול אשתקד'!A7,מור!A:K,8,0)+VLOOKUP('תפוקה מצטברת מול אשתקד'!A7,'אלטשולר שחם'!A:K,8,0)+VLOOKUP('תפוקה מצטברת מול אשתקד'!A7,'מדיהו '!A:K,8,0)+VLOOKUP('תפוקה מצטברת מול אשתקד'!A7,'אנליסט '!A:K,8,0)+VLOOKUP('תפוקה מצטברת מול אשתקד'!A7,'מיטב דש'!A:K,8,0)+VLOOKUP('תפוקה מצטברת מול אשתקד'!A7,אינפניטי!A:K,8,0) -> 41343.48 | M7: =VLOOKUP(A7,הכשרה!A:K,9,0)+VLOOKUP('תפוקה מצטברת מול אשתקד'!A7,מגדל!A:K,9,0)+VLOOKUP('תפוקה מצטברת מול אשתקד'!A7,מנורה!A:K,9,0)+VLOOKUP('תפוקה מצטברת מול אשתקד'!A7,איילון!A:K,9,0)+VLOOKUP('תפוקה מצטברת מול אשתקד'!A7,הראל!A:K,9,0)+VLOOKUP('תפוקה מצטברת מול אשתקד'!A7,הפניקס!A:K,9,0)+VLOOKUP('תפוקה מצטברת מול אשתקד'!A7,כלל!A:K,9,0)+VLOOKUP('תפוקה מצטברת מול אשתקד'!A7,מור!A:K,9,0)+VLOOKUP('תפוקה מצטברת מול אשתקד'!A7,'אלטשולר שחם'!A:K,9,0)+VLOOKUP('תפוקה מצטברת מול אשתקד'!A7,'מדיהו '!A:K,9,0)+VLOOKUP('תפוקה מצטברת מול אשתקד'!A7,'אנליסט '!A:K,9,0)+VLOOKUP('תפוקה מצטברת מול אשתקד'!A7,'מיטב דש'!A:K,9,0)+VLOOKUP('תפוקה מצטברת מול אשתקד'!A7,אינפניטי!A:K,9,0) -> 2168.7634 | N7: =VLOOKUP(A7,הכשרה!A:K,10,0)+VLOOKUP('תפוקה מצטברת מול אשתקד'!A7,מגדל!A:K,10,0)+VLOOKUP('תפוקה מצטברת מול אשתקד'!A7,מנורה!A:K,10,0)+VLOOKUP('תפוקה מצטברת מול אשתקד'!A7,איילון!A:K,10,0)+VLOOKUP('תפוקה מצטברת מול אשתקד'!A7,הראל!A:K,10,0)+VLOOKUP('תפוקה מצטברת מול אשתקד'!A7,הפניקס!A:K,10,0)+VLOOKUP('תפוקה מצטברת מול אשתקד'!A7,כלל!A:K,10,0)+VLOOKUP('תפוקה מצטברת מול אשתקד'!A7,מור!A:K,10,0)+VLOOKUP('תפוקה מצטברת מול אשתקד'!A7,'אלטשולר שחם'!A:K,10,0)+VLOOKUP('תפוקה מצטברת מול אשתקד'!A7,'מדיהו '!A:K,10,0)+VLOOKUP('תפוקה מצטברת מול אשתקד'!A7,'אנליסט '!A:K,10,0)+VLOOKUP('תפוקה מצטברת מול אשתקד'!A7,'מיטב דש'!A:K,10,0)+VLOOKUP('תפוקה מצטברת מול אשתקד'!A7,אינפניטי!A:K,10,0) -> 42338.01 | O7: =VLOOKUP(A7,הכשרה!A:K,11,0)+VLOOKUP('תפוקה מצטברת מול אשתקד'!A7,מגדל!A:K,11,0)+VLOOKUP('תפוקה מצטברת מול אשתקד'!A7,מנורה!A:K,11,0)+VLOOKUP('תפוקה מצטברת מול אשתקד'!A7,איילון!A:K,11,0)+VLOOKUP('תפוקה מצטברת מול אשתקד'!A7,הראל!A:K,11,0)+VLOOKUP('תפוקה מצטברת מול אשתקד'!A7,הפניקס!A:K,11,0)+VLOOKUP('תפוקה מצטברת מול אשתקד'!A7,כלל!A:K,11,0)+VLOOKUP('תפוקה מצטברת מול אשתקד'!A7,מור!A:K,11,0)+VLOOKUP('תפוקה מצטברת מול אשתקד'!A7,'אלטשולר שחם'!A:K,11,0)+VLOOKUP('תפוקה מצטברת מול אשתקד'!A7,'מדיהו '!A:K,11,0)+VLOOKUP('תפוקה מצטברת מול אשתקד'!A7,'אנליסט '!A:K,11,0)+VLOOKUP('תפוקה מצטברת מול אשתקד'!A7,'מיטב דש'!A:K,11,0)+VLOOKUP('תפוקה מצטברת מול אשתקד'!A7,אינפניטי!A:K,11,0) -> 131949.32
A8: סה"כ ישיר | D8: =IF(H8=0,0%,IF(L8=0,100%,H8/L8-1)) -> -0.85736407 | E8: =IF(I8=0,0%,IF(M8=0,100%,I8/M8-1)) -> -0.25834773 | F8: =IF(J8=0,0%,IF(N8=0,100%,J8/N8-1)) -> -0.84705929 | G8: =IF(K8=0,0%,IF(O8=H71,100%,K8/O8-1)) -> -0.85003467 | H8: =VLOOKUP(A8,הכשרה!A:G,4,0)+VLOOKUP('תפוקה מצטברת מול אשתקד'!A8,מגדל!A:G,4,0)+VLOOKUP('תפוקה מצטברת מול אשתקד'!A8,מנורה!A:G,4,0)+VLOOKUP('תפוקה מצטברת מול אשתקד'!A8,איילון!A:G,4,0)+VLOOKUP('תפוקה מצטברת מול אשתקד'!A8,הראל!A:G,4,0)+VLOOKUP('תפוקה מצטברת מול אשתקד'!A8,הפניקס!A:G,4,0)+VLOOKUP('תפוקה מצטברת מול אשתקד'!A8,כלל!A:G,4,0)+VLOOKUP('תפוקה מצטברת מול אשתקד'!A8,מור!A:G,4,0)+VLOOKUP('תפוקה מצטברת מול אשתקד'!A8,'אלטשולר שחם'!A:G,4,0)+VLOOKUP('תפוקה מצטברת מול אשתקד'!A8,'מדיהו '!A:G,4,0)+VLOOKUP('תפוקה מצטברת מול אשתקד'!A8,'אנליסט '!A:G,4,0)+VLOOKUP('תפוקה מצטברת מול אשתקד'!A8,'מיטב דש'!A:G,4,0)+VLOOKUP('תפוקה מצטברת מול אשתקד'!A8,אינפניטי!A:G,4,0) -> 1129325.5 | I8: =SUM(I3:I7) -> 430756.29 | J8: =SUM(J3:J7) -> 3418786 | K8: =SUM(K3:K7) -> 7238176 | L8: =SUM(L3:L7) -> 7917538.6 | M8: =SUM(M3:M7) -> 580806.27 | N8: =SUM(N3:N7) -> 22353669 | O8: =SUM(O3:O7) -> 48265663
A9: בראשית סוכנות לביטוח | B9: יוסי אביב | C9: שותפים | D9: =IF(H9=0,0%,IF(L9=0,100%,H9/L9-1)) -> 1 | E9: =IF(I9=0,0%,IF(M9=0,100%,I9/M9-1)) -> 0 | F9: =IF(J9=0,0%,IF(N9=0,100%,J9/N9-1)) -> 0 | G9: =IF(K9=0,0%,IF(O9=H32,100%,K9/O9-1)) -> 1 | H9: =VLOOKUP(A9,הכשרה!A:G,4,0)+VLOOKUP('תפוקה מצטברת מול אשתקד'!A9,מגדל!A:G,4,0)+VLOOKUP('תפוקה מצטברת מול אשתקד'!A9,מנורה!A:G,4,0)+VLOOKUP('תפוקה מצטברת מול אשתקד'!A9,איילון!A:G,4,0)+VLOOKUP('תפוקה מצטברת מול אשתקד'!A9,הראל!A:G,4,0)+VLOOKUP('תפוקה מצטברת מול אשתקד'!A9,הפניקס!A:G,4,0)+VLOOKUP('תפוקה מצטברת מול אשתקד'!A9,כלל!A:G,4,0)+VLOOKUP('תפוקה מצטברת מול אשתקד'!A9,מור!A:G,4,0)+VLOOKUP('תפוקה מצטברת מול אשתקד'!A9,'אלטשולר שחם'!A:G,4,0)+VLOOKUP('תפוקה מצטברת מול אשתקד'!A9,'מדיהו '!A:G,4,0)+VLOOKUP('תפוקה מצטברת מול אשתקד'!A9,'אנליסט '!A:G,4,0)+VLOOKUP('תפוקה מצטברת מול אשתקד'!A9,'מיטב דש'!A:G,4,0)+VLOOKUP('תפוקה מצטברת מול אשתקד'!A9,אינפניטי!A:G,4,0) -> 3973.8196 | I9: =VLOOKUP(A9,הכשרה!A:G,5,0)+VLOOKUP('תפוקה מצטברת מול אשתקד'!A9,מגדל!A:G,5,0)+VLOOKUP('תפוקה מצטברת מול אשתקד'!A9,מנורה!A:G,5,0)+VLOOKUP('תפוקה מצטברת מול אשתקד'!A9,איילון!A:G,5,0)+VLOOKUP('תפוקה מצטברת מול אשתקד'!A9,הראל!A:G,5,0)+VLOOKUP('תפוקה מצטברת מול אשתקד'!A9,הפניקס!A:G,5,0)+VLOOKUP('תפוקה מצטברת מול אשתקד'!A9,כלל!A:G,5,0)+VLOOKUP('תפוקה מצטברת מול אשתקד'!A9,מור!A:G,5,0)+VLOOKUP('תפוקה מצטברת מול אשתקד'!A9,'אלטשולר שחם'!A:G,5,0)+VLOOKUP('תפוקה מצטברת מול אשתקד'!A9,'מדיהו '!A:G,5,0)+VLOOKUP('תפוקה מצטברת מול אשתקד'!A9,'אנליסט '!A:G,5,0)+VLOOKUP('תפוקה מצטברת מול אשתקד'!A9,'מיטב דש'!A:G,5,0)+VLOOKUP('תפוקה מצטברת מול אשתקד'!A9,אינפניטי!A:G,5,0) -> 0 | J9: =VLOOKUP(A9,הכשרה!A:G,6,0)+VLOOKUP('תפוקה מצטברת מול אשתקד'!A9,מגדל!A:G,6,0)+VLOOKUP('תפוקה מצטברת מול אשתקד'!A9,מנורה!A:G,6,0)+VLOOKUP('תפוקה מצטברת מול אשתקד'!A9,איילון!A:G,6,0)+VLOOKUP(A9,הראל!A:G,6,0)+VLOOKUP('תפוקה מצטברת מול אשתקד'!A9,הפניקס!A:G,6,0)+VLOOKUP('תפוקה מצטברת מול אשתקד'!A9,כלל!A:G,6,0)+VLOOKUP('תפוקה מצטברת מול אשתקד'!A9,מור!A:G,6,0)+VLOOKUP('תפוקה מצטברת מול אשתקד'!A9,'אלטשולר שחם'!A:G,6,0)+VLOOKUP('תפוקה מצטברת מול אשתקד'!A9,'מדיהו '!A:G,6,0)+VLOOKUP('תפוקה מצטברת מול אשתקד'!A9,'אנליסט '!A:G,6,0)+VLOOKUP('תפוקה מצטברת מול אשתקד'!A9,'מיטב דש'!A:G,6,0)+VLOOKUP('תפוקה מצטברת מול אשתקד'!A9,אינפניטי!A:G,6,0) -> 0 | K9: =VLOOKUP(A9,הכשרה!A:G,7,0)+VLOOKUP('תפוקה מצטברת מול אשתקד'!A9,מגדל!A:G,7,0)+VLOOKUP('תפוקה מצטברת מול אשתקד'!A9,מנורה!A:G,7,0)+VLOOKUP('תפוקה מצטברת מול אשתקד'!A9,איילון!A:G,7,0)+VLOOKUP('תפוקה מצטברת מול אשתקד'!A9,הראל!A:G,7,0)+VLOOKUP('תפוקה מצטברת מול אשתקד'!A9,הפניקס!A:G,7,0)+VLOOKUP('תפוקה מצטברת מול אשתקד'!A9,כלל!A:G,7,0)+VLOOKUP('תפוקה מצטברת מול אשתקד'!A9,מור!A:G,7,0)+VLOOKUP('תפוקה מצטברת מול אשתקד'!A9,'אלטשולר שחם'!A:G,7,0)+VLOOKUP('תפוקה מצטברת מול אשתקד'!A9,'מדיהו '!A:K,7,0)+VLOOKUP(A9,'אנליסט '!A:G,7,0)+VLOOKUP('תפוקה מצטברת מול אשתקד'!A9,'מיטב דש'!A:G,7,0)+VLOOKUP('תפוקה מצטברת מול אשתקד'!A9,אינפניטי!A:G,7,0) -> -133113.14 | L9: =VLOOKUP(A9,הכשרה!A:K,8,0)+VLOOKUP('תפוקה מצטברת מול אשתקד'!A9,מגדל!A:K,8,0)+VLOOKUP('תפוקה מצטברת מול אשתקד'!A9,מנורה!A:K,8,0)+VLOOKUP('תפוקה מצטברת מול אשתקד'!A9,איילון!A:K,8,0)+VLOOKUP('תפוקה מצטברת מול אשתקד'!A9,הראל!A:K,8,0)+VLOOKUP('תפוקה מצטברת מול אשתקד'!A9,הפניקס!A:K,8,0)+VLOOKUP('תפוקה מצטברת מול אשתקד'!A9,כלל!A:K,8,0)+VLOOKUP('תפוקה מצטברת מול אשתקד'!A9,מור!A:K,8,0)+VLOOKUP('תפוקה מצטברת מול אשתקד'!A9,'אלטשולר שחם'!A:K,8,0)+VLOOKUP('תפוקה מצטברת מול אשתקד'!A9,'מדיהו '!A:K,8,0)+VLOOKUP('תפוקה מצטברת מול אשתקד'!A9,'אנליסט '!A:K,8,0)+VLOOKUP('תפוקה מצטברת מול אשתקד'!A9,'מיטב דש'!A:K,8,0)+VLOOKUP('תפוקה מצטברת מול אשתקד'!A9,אינפניטי!A:K,8,0) -> 0 | M9: =VLOOKUP(A9,הכשרה!A:K,9,0)+VLOOKUP('תפוקה מצטברת מול אשתקד'!A9,מגדל!A:K,9,0)+VLOOKUP('תפוקה מצטברת מול אשתקד'!A9,מנורה!A:K,9,0)+VLOOKUP('תפוקה מצטברת מול אשתקד'!A9,איילון!A:K,9,0)+VLOOKUP('תפוקה מצטברת מול אשתקד'!A9,הראל!A:K,9,0)+VLOOKUP('תפוקה מצטברת מול אשתקד'!A9,הפניקס!A:K,9,0)+VLOOKUP('תפוקה מצטברת מול אשתקד'!A9,כלל!A:K,9,0)+VLOOKUP('תפוקה מצטברת מול אשתקד'!A9,מור!A:K,9,0)+VLOOKUP('תפוקה מצטברת מול אשתקד'!A9,'אלטשולר שחם'!A:K,9,0)+VLOOKUP('תפוקה מצטברת מול אשתקד'!A9,'מדיהו '!A:K,9,0)+VLOOKUP('תפוקה מצטברת מול אשתקד'!A9,'אנליסט '!A:K,9,0)+VLOOKUP('תפוקה מצטברת מול אשתקד'!A9,'מיטב דש'!A:K,9,0)+VLOOKUP('תפוקה מצטברת מול אשתקד'!A9,אינפניטי!A:K,9,0) -> 83.03 | N9: =VLOOKUP(A9,הכשרה!A:K,10,0)+VLOOKUP('תפוקה מצטברת מול אשתקד'!A9,מגדל!A:K,10,0)+VLOOKUP('תפוקה מצטברת מול אשתקד'!A9,מנורה!A:K,10,0)+VLOOKUP('תפוקה מצטברת מול אשתקד'!A9,איילון!A:K,10,0)+VLOOKUP('תפוקה מצטברת מול אשתקד'!A9,הראל!A:K,10,0)+VLOOKUP('תפוקה מצטברת מול אשתקד'!A9,הפניקס!A:K,10,0)+VLOOKUP('תפוקה מצטברת מול אשתקד'!A9,כלל!A:K,10,0)+VLOOKUP('תפוקה מצטברת מול אשתקד'!A9,מור!A:K,10,0)+VLOOKUP('תפוקה מצטברת מול אשתקד'!A9,'אלטשולר שחם'!A:K,10,0)+VLOOKUP('תפוקה מצטברת מול אשתקד'!A9,'מדיהו '!A:K,10,0)+VLOOKUP('תפוקה מצטברת מול אשתקד'!A9,'אנליסט '!A:K,10,0)+VLOOKUP('תפוקה מצטברת מול אשתקד'!A9,'מיטב דש'!A:K,10,0)+VLOOKUP('תפוקה מצטברת מול אשתקד'!A9,אינפניטי!A:K,10,0) -> 0 | O9: =VLOOKUP(A9,הכשרה!A:K,11,0)+VLOOKUP('תפוקה מצטברת מול אשתקד'!A9,מגדל!A:K,11,0)+VLOOKUP('תפוקה מצטברת מול אשתקד'!A9,מנורה!A:K,11,0)+VLOOKUP('תפוקה מצטברת מול אשתקד'!A9,איילון!A:K,11,0)+VLOOKUP('תפוקה מצטברת מול אשתקד'!A9,הראל!A:K,11,0)+VLOOKUP('תפוקה מצטברת מול אשתקד'!A9,הפניקס!A:K,11,0)+VLOOKUP('תפוקה מצטברת מול אשתקד'!A9,כלל!A:K,11,0)+VLOOKUP('תפוקה מצטברת מול אשתקד'!A9,מור!A:K,11,0)+VLOOKUP('תפוקה מצטברת מול אשתקד'!A9,'אלטשולר שחם'!A:K,11,0)+VLOOKUP('תפוקה מצטברת מול אשתקד'!A9,'מדיהו '!A:K,11,0)+VLOOKUP('תפוקה מצטברת מול אשתקד'!A9,'אנליסט '!A:K,11,0)+VLOOKUP('תפוקה מצטברת מול אשתקד'!A9,'מיטב דש'!A:K,11,0)+VLOOKUP('תפוקה מצטברת מול אשתקד'!A9,אינפניטי!A:K,11,0) -> 0
A10: גל אלמגור דאוד סוכ' לב | B10: יוסי אביב | C10: שותפים | D10: =IF(H10=0,0%,IF(L10=0,100%,H10/L10-1)) -> -0.52114265 | E10: =IF(I10=0,0%,IF(M10=0,100%,I10/M10-1)) -> -0.73012604 | F10: =IF(J10=0,0%,IF(N10=0,100%,J10/N10-1)) -> -0.2014158 | G10: =IF(K10=0,0%,IF(O10=H33,100%,K10/O10-1)) -> -0.31092524 | H10: =VLOOKUP(A10,הכשרה!A:G,4,0)+VLOOKUP('תפוקה מצטברת מול אשתקד'!A10,מגדל!A:G,4,0)+VLOOKUP('תפוקה מצטברת מול אשתקד'!A10,מנורה!A:G,4,0)+VLOOKUP('תפוקה מצטברת מול אשתקד'!A10,איילון!A:G,4,0)+VLOOKUP('תפוקה מצטברת מול אשתקד'!A10,הראל!A:G,4,0)+VLOOKUP('תפוקה מצטברת מול אשתקד'!A10,הפניקס!A:G,4,0)+VLOOKUP('תפוקה מצטברת מול אשתקד'!A10,כלל!A:G,4,0)+VLOOKUP('תפוקה מצטברת מול אשתקד'!A10,מור!A:G,4,0)+VLOOKUP('תפוקה מצטברת מול אשתקד'!A10,'אלטשולר שחם'!A:G,4,0)+VLOOKUP('תפוקה מצטברת מול אשתקד'!A10,'מדיהו '!A:G,4,0)+VLOOKUP('תפוקה מצטברת מול אשתקד'!A10,'אנליסט '!A:G,4,0)+VLOOKUP('תפוקה מצטברת מול אשתקד'!A10,'מיטב דש'!A:G,4,0)+VLOOKUP('תפוקה מצטברת מול אשתקד'!A10,אינפניטי!A:G,4,0) -> 40911.521 | I10: =VLOOKUP(A10,הכשרה!A:G,5,0)+VLOOKUP('תפוקה מצטברת מול אשתקד'!A10,מגדל!A:G,5,0)+VLOOKUP('תפוקה מצטברת מול אשתקד'!A10,מנורה!A:G,5,0)+VLOOKUP('תפוקה מצטברת מול אשתקד'!A10,איילון!A:G,5,0)+VLOOKUP('תפוקה מצטברת מול אשתקד'!A10,הראל!A:G,5,0)+VLOOKUP('תפוקה מצטברת מול אשתקד'!A10,הפניקס!A:G,5,0)+VLOOKUP('תפוקה מצטברת מול אשתקד'!A10,כלל!A:G,5,0)+VLOOKUP('תפוקה מצטברת מול אשתקד'!A10,מור!A:G,5,0)+VLOOKUP('תפוקה מצטברת מול אשתקד'!A10,'אלטשולר שחם'!A:G,5,0)+VLOOKUP('תפוקה מצטברת מול אשתקד'!A10,'מדיהו '!A:G,5,0)+VLOOKUP('תפוקה מצטברת מול אשתקד'!A10,'אנליסט '!A:G,5,0)+VLOOKUP('תפוקה מצטברת מול אשתקד'!A10,'מיטב דש'!A:G,5,0)+VLOOKUP('תפוקה מצטברת מול אשתקד'!A10,אינפניטי!A:G,5,0) -> 87907.635 | J10: =VLOOKUP(A10,הכשרה!A:G,6,0)+VLOOKUP('תפוקה מצטברת מול אשתקד'!A10,מגדל!A:G,6,0)+VLOOKUP('תפוקה מצטברת מול אשתקד'!A10,מנורה!A:G,6,0)+VLOOKUP('תפוקה מצטברת מול אשתקד'!A10,איילון!A:G,6,0)+VLOOKUP(A10,הראל!A:G,6,0)+VLOOKUP('תפוקה מצטברת מול אשתקד'!A10,הפניקס!A:G,6,0)+VLOOKUP('תפוקה מצטברת מול אשתקד'!A10,כלל!A:G,6,0)+VLOOKUP('תפוקה מצטברת מול אשתקד'!A10,מור!A:G,6,0)+VLOOKUP('תפוקה מצטברת מול אשתקד'!A10,'אלטשולר שחם'!A:G,6,0)+VLOOKUP('תפוקה מצטברת מול אשתקד'!A10,'מדיהו '!A:G,6,0)+VLOOKUP('תפוקה מצטברת מול אשתקד'!A10,'אנליסט '!A:G,6,0)+VLOOKUP('תפוקה מצטברת מול אשתקד'!A10,'מיטב דש'!A:G,6,0)+VLOOKUP('תפוקה מצטברת מול אשתקד'!A10,אינפניטי!A:G,6,0) -> 65973 | K10: =VLOOKUP(A10,הכשרה!A:G,7,0)+VLOOKUP('תפוקה מצטברת מול אשתקד'!A10,מגדל!A:G,7,0)+VLOOKUP('תפוקה מצטברת מול אשתקד'!A10,מנורה!A:G,7,0)+VLOOKUP('תפוקה מצטברת מול אשתקד'!A10,איילון!A:G,7,0)+VLOOKUP('תפוקה מצטברת מול אשתקד'!A10,הראל!A:G,7,0)+VLOOKUP('תפוקה מצטברת מול אשתקד'!A10,הפניקס!A:G,7,0)+VLOOKUP('תפוקה מצטברת מול אשתקד'!A10,כלל!A:G,7,0)+VLOOKUP('תפוקה מצטברת מול אשתקד'!A10,מור!A:G,7,0)+VLOOKUP('תפוקה מצטברת מול אשתקד'!A10,'אלטשולר שחם'!A:G,7,0)+VLOOKUP('תפוקה מצטברת מול אשתקד'!A10,'מדיהו '!A:K,7,0)+VLOOKUP(A10,'אנליסט '!A:G,7,0)+VLOOKUP('תפוקה מצטברת מול אשתקד'!A10,'מיטב דש'!A:G,7,0)+VLOOKUP('תפוקה מצטברת מול אשתקד'!A10,אינפניטי!A:G,7,0) -> 231357.75 | L10: =VLOOKUP(A10,הכשרה!A:K,8,0)+VLOOKUP('תפוקה מצטברת מול אשתקד'!A10,מגדל!A:K,8,0)+VLOOKUP('תפוקה מצטברת מול אשתקד'!A10,מנורה!A:K,8,0)+VLOOKUP('תפוקה מצטברת מול אשתקד'!A10,איילון!A:K,8,0)+VLOOKUP('תפוקה מצטברת מול אשתקד'!A10,הראל!A:K,8,0)+VLOOKUP('תפוקה מצטברת מול אשתקד'!A10,הפניקס!A:K,8,0)+VLOOKUP('תפוקה מצטברת מול אשתקד'!A10,כלל!A:K,8,0)+VLOOKUP('תפוקה מצטברת מול אשתקד'!A10,מור!A:K,8,0)+VLOOKUP('תפוקה מצטברת מול אשתקד'!A10,'אלטשולר שחם'!A:K,8,0)+VLOOKUP('תפוקה מצטברת מול אשתקד'!A10,'מדיהו '!A:K,8,0)+VLOOKUP('תפוקה מצטברת מול אשתקד'!A10,'אנליסט '!A:K,8,0)+VLOOKUP('תפוקה מצטברת מול אשתקד'!A10,'מיטב דש'!A:K,8,0)+VLOOKUP('תפוקה מצטברת מול אשתקד'!A10,אינפניטי!A:K,8,0) -> 85435.718 | M10: =VLOOKUP(A10,הכשרה!A:K,9,0)+VLOOKUP('תפוקה מצטברת מול אשתקד'!A10,מגדל!A:K,9,0)+VLOOKUP('תפוקה מצטברת מול אשתקד'!A10,מנורה!A:K,9,0)+VLOOKUP('תפוקה מצטברת מול אשתקד'!A10,איילון!A:K,9,0)+VLOOKUP('תפוקה מצטברת מול אשתקד'!A10,הראל!A:K,9,0)+VLOOKUP('תפוקה מצטברת מול אשתקד'!A10,הפניקס!A:K,9,0)+VLOOKUP('תפוקה מצטברת מול אשתקד'!A10,כלל!A:K,9,0)+VLOOKUP('תפוקה מצטברת מול אשתקד'!A10,מור!A:K,9,0)+VLOOKUP('תפוקה מצטברת מול אשתקד'!A10,'אלטשולר שחם'!A:K,9,0)+VLOOKUP('תפוקה מצטברת מול אשתקד'!A10,'מדיהו '!A:K,9,0)+VLOOKUP('תפוקה מצטברת מול אשתקד'!A10,'אנליסט '!A:K,9,0)+VLOOKUP('תפוקה מצטברת מול אשתקד'!A10,'מיטב דש'!A:K,9,0)+VLOOKUP('תפוקה מצטברת מול אשתקד'!A10,אינפניטי!A:K,9,0) -> 325735.9 | N10: =VLOOKUP(A10,הכשרה!A:K,10,0)+VLOOKUP('תפוקה מצטברת מול אשתקד'!A10,מגדל!A:K,10,0)+VLOOKUP('תפוקה מצטברת מול אשתקד'!A10,מנורה!A:K,10,0)+VLOOKUP('תפוקה מצטברת מול אשתקד'!A10,איילון!A:K,10,0)+VLOOKUP('תפוקה מצטברת מול אשתקד'!A10,הראל!A:K,10,0)+VLOOKUP('תפוקה מצטברת מול אשתקד'!A10,הפניקס!A:K,10,0)+VLOOKUP('תפוקה מצטברת מול אשתקד'!A10,כלל!A:K,10,0)+VLOOKUP('תפוקה מצטברת מול אשתקד'!A10,מור!A:K,10,0)+VLOOKUP('תפוקה מצטברת מול אשתקד'!A10,'אלטשולר שחם'!A:K,10,0)+VLOOKUP('תפוקה מצטברת מול אשתקד'!A10,'מדיהו '!A:K,10,0)+VLOOKUP('תפוקה מצטברת מול אשתקד'!A10,'אנליסט '!A:K,10,0)+VLOOKUP('תפוקה מצטברת מול אשתקד'!A10,'מיטב דש'!A:K,10,0)+VLOOKUP('תפוקה מצטברת מול אשתקד'!A10,אינפניטי!A:K,10,0) -> 82612.454 | O10: =VLOOKUP(A10,הכשרה!A:K,11,0)+VLOOKUP('תפוקה מצטברת מול אשתקד'!A10,מגדל!A:K,11,0)+VLOOKUP('תפוקה מצטברת מול אשתקד'!A10,מנורה!A:K,11,0)+VLOOKUP('תפוקה מצטברת מול אשתקד'!A10,איילון!A:K,11,0)+VLOOKUP('תפוקה מצטברת מול אשתקד'!A10,הראל!A:K,11,0)+VLOOKUP('תפוקה מצטברת מול אשתקד'!A10,הפניקס!A:K,11,0)+VLOOKUP('תפוקה מצטברת מול אשתקד'!A10,כלל!A:K,11,0)+VLOOKUP('תפוקה מצטברת מול אשתקד'!A10,מור!A:K,11,0)+VLOOKUP('תפוקה מצטברת מול אשתקד'!A10,'אלטשולר שחם'!A:K,11,0)+VLOOKUP('תפוקה מצטברת מול אשתקד'!A10,'מדיהו '!A:K,11,0)+VLOOKUP('תפוקה מצטברת מול אשתקד'!A10,'אנליסט '!A:K,11,0)+VLOOKUP('תפוקה מצטברת מול אשתקד'!A10,'מיטב דש'!A:K,11,0)+VLOOKUP('תפוקה מצטברת מול אשתקד'!A10,אינפניטי!A:K,11,0) -> 335751.31
