Workbook

Sheet דוח הנהלה
A1: בס"ד
A3: תפוקה מצטברת לפי קבוצות
A4: קבוצה | B4: תפוקה מצטברת 04/2025 | F4: שינוי מול אשתקד % | J4: השגת יעדים מצטבר %
B5: פנסיוני | C5: סיכונים | D5: פיננסים | E5: ניודי פנסיה | F5: פנסיוני | G5: סיכונים | H5: פיננסים | I5: ניודי פנסיה | J5: פנסיוני | K5: סיכונים | L5: פיננסים | M5: ניודי פנסיה
A6: ישירים | B6: ='תפוקה מצטברת מול אשתקד'!H8 -> 4971214.4 | C6: ='תפוקה מצטברת מול אשתקד'!I8 -> 249721.28 | D6: ='תפוקה מצטברת מול אשתקד'!J8 -> 13756636 | E6: ='תפוקה מצטברת מול אשתקד'!K8 -> 30552415 | F6: ='תפוקה מצטברת מול אשתקד'!D8 -> 0.61202352 | G6: ='תפוקה מצטברת מול אשתקד'!E8 -> -0.50690169 | H6: ='תפוקה מצטברת מול אשתקד'!F8 -> 0.0062359067 | I6: ='תפוקה מצטברת מול אשתקד'!G8 -> 0.78430941 | J6: ='תפוקה מצטברת מול יעד מצטבר'!D8 -> -0.23046217 | K6: ='תפוקה מצטברת מול יעד מצטבר'!E8 -> -0.60987146 | L6: ='תפוקה מצטברת מול יעד מצטבר'!F8 -> -0.44538641 | M6: ='תפוקה מצטברת מול יעד מצטבר'!G8 -> -0.20924463
A7: חברות בת | B7: ='תפוקה מצטברת מול אשתקד'!H21 -> 1729903.8 | C7: ='תפוקה מצטברת מול אשתקד'!I21 -> 973341.03 | D7: ='תפוקה מצטברת מול אשתקד'!J21 -> 9163856.1 | E7: ='תפוקה מצטברת מול אשתקד'!K21 -> 4367988.5 | F7: ='תפוקה מצטברת מול אשתקד'!D21 -> 0.037733244 | G7: ='תפוקה מצטברת מול אשתקד'!E21 -> 1.2129242 | H7: ='תפוקה מצטברת מול אשתקד'!F21 -> -0.28322923 | I7: ='תפוקה מצטברת מול אשתקד'!G21 -> -0.29396916 | J7: ='תפוקה מצטברת מול יעד מצטבר'!D21 -> -0.31336675 | K7: ='תפוקה מצטברת מול יעד מצטבר'!E21 -> -0.029957113 | L7: ='תפוקה מצטברת מול יעד מצטבר'!F21 -> -0.44582389 | M7: ='תפוקה מצטברת מול יעד מצטבר'!G21 -> -0.54964548
A8: סוכני פרימיום | B8: ='תפוקה מצטברת מול אשתקד'!H72 -> 3058662.5 | C8: ='תפוקה מצטברת מול אשתקד'!I72 -> 552939.71 | D8: ='תפוקה מצטברת מול אשתקד'!J72 -> 22242288 | E8: ='תפוקה מצטברת מול אשתקד'!K72 -> 25758783 | F8: ='תפוקה מצטברת מול אשתקד'!D72 -> 0.35810556 | G8: ='תפוקה מצטברת מול אשתקד'!E72 -> 0.5313647 | H8: ='תפוקה מצטברת מול אשתקד'!F72 -> 0.34324169 | I8: ='תפוקה מצטברת מול אשתקד'!G63 -> 1.2282085 | J8: ='תפוקה מצטברת מול יעד מצטבר'!D63 -> -0.30554485 | K8: ='תפוקה מצטברת מול יעד מצטבר'!E63 -> -0.58280356 | L8: ='תפוקה מצטברת מול יעד מצטבר'!F63 -> 0.026939247 | M8: ='תפוקה מצטברת מול יעד מצטבר'!G63 -> -0.31739908
A9: סוכנים ערן | B9: ='תפוקה מצטברת מול אשתקד'!H54 -> 3886570.6 | C9: ='תפוקה מצטברת מול אשתקד'!I54 -> 547973.44 | D9: ='תפוקה מצטברת מול אשתקד'!J54 -> 7703723.3 | E9: ='תפוקה מצטברת מול אשתקד'!K54 -> 10716190 | F9: ='תפוקה מצטברת מול אשתקד'!D73 -> 0.24915819 | G9: ='תפוקה מצטברת מול אשתקד'!E73 -> 0.2227391 | H9: ='תפוקה מצטברת מול אשתקד'!F73 -> 0.040234621 | I9: ='תפוקה מצטברת מול אשתקד'!G72 -> 0.6695899 | J9: ='תפוקה מצטברת מול יעד מצטבר'!D72 -> 0.088453268 | K9: ='תפוקה מצטברת מול יעד מצטבר'!E72 -> 0.14149404 | L9: ='תפוקה מצטברת מול יעד מצטבר'!F72 -> 0.41301619 | M9: ='תפוקה מצטברת מול יעד מצטבר'!G72 -> 2.1641587
A10: סוכנים איתי | B10: ='תפוקה מצטברת מול אשתקד'!H63 -> 1704748.5 | C10: ='תפוקה מצטברת מול אשתקד'!I63 -> 161671.96 | D10: ='תפוקה מצטברת מול אשתקד'!J63 -> 7511033.7 | E10: ='תפוקה מצטברת מול אשתקד'!K63 -> 4341341.9 | F10: ='תפוקה מצטברת מול אשתקד'!D74 -> 0 | G10: ='תפוקה מצטברת מול אשתקד'!E74 -> 0 | H10: ='תפוקה מצטברת מול אשתקד'!F74 -> 0 | I10: ='תפוקה מצטברת מול אשתקד'!G73 -> 0.26116741 | J10: ='תפוקה מצטברת מול יעד מצטבר'!D73 -> -0.1366644 | K10: ='תפוקה מצטברת מול יעד מצטבר'!E73 -> -0.22586723 | L10: ='תפוקה מצטברת מול יעד מצטבר'!F73 -> -0.16358385 | M10: ='תפוקה מצטברת מול יעד מצטבר'!G73 -> 0.078161079
A11: סה"כ מכירות | B11: =SUM(B6:B10) -> 15351100 | C11: =SUM(C6:C10) -> 2485647.4 | D11: =SUM(D6:D10) -> 60377536 | E11: =SUM(E6:E10) -> 75736719 | F11: ='תפוקה מצטברת מול אשתקד'!D73 -> 0.24915819 | G11: ='תפוקה מצטברת מול אשתקד'!E73 -> 0.2227391 | H11: ='תפוקה מצטברת מול אשתקד'!F73 -> 0.040234621 | I11: ='תפוקה מצטברת מול יעד מצטבר'!D72 -> 0.088453268 | J11: ='תפוקה מצטברת מול יעד מצטבר'!D73 -> -0.1366644 | K11: ='תפוקה מצטברת מול יעד מצטבר'!E73 -> -0.22586723 | L11: ='תפוקה מצטברת מול יעד מצטבר'!F73 -> -0.16358385 | M11: ='תפוקה מצטברת מול יעד מצטבר'!G73 -> 0.078161079
A14: תפוקה מצטברת לפי מפקחים
A15: מפקח | B15: תפוקה מצטברת 04/2025 | F15: שינוי מול אשתקד % | J15: השגת יעדים מצטבר % | N15: תפוקה מצטברת 03/2024 | R15: יעדים מצטבר
B16: פנסיוני | C16: סיכונים | D16: פיננסים | E16: ניודי פנסיה | F16: פנסיוני | G16: סיכונים | H16: פיננסים | I16: ניודי פנסיה | J16: פנסיוני | K16: סיכונים | L16: פיננסים | M16: ניודי פנסיה | N16: פנסיוני | O16: סיכונים | P16: פיננסים | Q16: ניודי פנסיה | R16: פנסיוני | S16: סיכונים | T16: פיננסים | U16: ניודי פנסיה
A17: ערן גירוני | B17: =SUMIF('תפוקה מצטברת מול אשתקד'!B:B,'דוח הנהלה'!A17,'תפוקה מצטברת מול אשתקד'!H:H) -> 6692818.1 | C17: =SUMIF('תפוקה מצטברת מול אשתקד'!B:B,'דוח הנהלה'!A17,'תפוקה מצטברת מול אשתקד'!I:I) -> 1080538.9 | D17: =SUMIF('תפוקה מצטברת מול אשתקד'!B:B,'דוח הנהלה'!A17,'תפוקה מצטברת מול אשתקד'!J:J) -> 27090782 | E17: =SUMIF('תפוקה מצטברת מול אשתקד'!B:B,'דוח הנהלה'!A17,'תפוקה מצטברת מול אשתקד'!K:K) -> 32913766 | F17: =(B17-N17)/N17 -> 0.14121565 | G17: =(C17-O17)/O17 -> 0.1366577 | H17: =(D17-P17)/P17 -> 0.31432638 | I17: =(E17-Q17)/Q17 -> -0.021687343 | J17: =(B17-R17)/R17 -> 0.13538625 | K17: =(C17-S17)/S17 -> -0.011726357 | L17: =(D17-T17)/T17 -> 0.35224027 | M17: =(E17-U17)/U17 -> 1.4126436 | N17: =SUMIF('תפוקה מצטברת מול אשתקד'!B:B,'דוח הנהלה'!A17,'תפוקה מצטברת מול אשתקד'!L:L) -> 5864639.3 | O17: =SUMIF('תפוקה מצטברת מול אשתקד'!B:B,'דוח הנהלה'!A17,'תפוקה מצטברת מול אשתקד'!M:M) -> 950628.21 | P17: =SUMIF('תפוקה מצטברת מול אשתקד'!B:B,'דוח הנהלה'!A17,'תפוקה מצטברת מול אשתקד'!N:N) -> 20611913 | Q17: =SUMIF('תפוקה מצטברת מול אשתקד'!B:B,'דוח הנהלה'!A17,'תפוקה מצטברת מול אשתקד'!O:O) -> 33643402 | R17: =SUMIF('תפוקה מצטברת מול יעד מצטבר'!B:B,'דוח הנהלה'!A17,'תפוקה מצטברת מול יעד מצטבר'!H:K) -> 5894750 | S17: =SUMIF('תפוקה מצטברת מול יעד מצטבר'!B:B,'דוח הנהלה'!A17,'תפוקה מצטברת מול יעד מצטבר'!I:I) -> 1093360 | T17: =SUMIF('תפוקה מצטברת מול יעד מצטבר'!B:B,'דוח הנהלה'!A17,'תפוקה מצטברת מול יעד מצטבר'!J:J) -> 20034000 | U17: =SUMIF('תפוקה מצטברת מול יעד מצטבר'!B:B,'דוח הנהלה'!A17,'תפוקה מצטברת מול יעד מצטבר'!K:K) -> 13642200
A18: לא מפוקחים | B18: =SUMIF('תפוקה מצטברת מול אשתקד'!B:B,'דוח הנהלה'!A18,'תפוקה מצטברת מול אשתקד'!H:H) -> 24383.77 | C18: =SUMIF('תפוקה מצטברת מול אשתקד'!B:B,'דוח הנהלה'!A18,'תפוקה מצטברת מול אשתקד'!I:I) -> 8908.84 | D18: =SUMIF('תפוקה מצטברת מול אשתקד'!B:B,'דוח הנהלה'!A18,'תפוקה מצטברת מול אשתקד'!J:J) -> 0 | E18: =SUMIF('תפוקה מצטברת מול אשתקד'!B:B,'דוח הנהלה'!A18,'תפוקה מצטברת מול אשתקד'!K:K) -> 0 | F18: =(B18-N18)/N18 -> 194.21071 | G18: =(C18-O18)/O18 -> 9.2624189 | H18: 0 | I18: =(E18-Q18)/Q18 -> -1 | J18: =(B18-R18)/R18 -> -0.81127113 | K18: =(C18-S18)/S18 -> -0.74251908 | L18: =(D18-T18)/T18 -> -1 | M18: =(E18-U18)/U18 -> -1 | N18: =SUMIF('תפוקה מצטברת מול אשתקד'!B:B,'דוח הנהלה'!A18,'תפוקה מצטברת מול אשתקד'!L:L) -> 124.91 | O18: =SUMIF('תפוקה מצטברת מול אשתקד'!B:B,'דוח הנהלה'!A18,'תפוקה מצטברת מול אשתקד'!M:M) -> 868.10332 | P18: =SUMIF('תפוקה מצטברת מול אשתקד'!B:B,'דוח הנהלה'!A18,'תפוקה מצטברת מול אשתקד'!N:N) -> 0 | Q18: =SUMIF('תפוקה מצטברת מול אשתקד'!B:B,'דוח הנהלה'!A18,'תפוקה מצטברת מול אשתקד'!O:O) -> -18603.1 | R18: =SUMIF('תפוקה מצטברת מול יעד מצטבר'!B:B,'דוח הנהלה'!A18,'תפוקה מצטברת מול יעד מצטבר'!H:H) -> 129200 | S18: =SUMIF('תפוקה מצטברת מול יעד מצטבר'!B:B,'דוח הנהלה'!A18,'תפוקה מצטברת מול יעד מצטבר'!I:I) -> 34600 | T18: =SUMIF('תפוקה מצטברת מול יעד מצטבר'!B:B,'דוח הנהלה'!A18,'תפוקה מצטברת מול יעד מצטבר'!J:J) -> 318000 | U18: =SUMIF('תפוקה מצטברת מול יעד מצטבר'!B:B,'דוח הנהלה'!A18,'תפוקה מצטברת מול יעד מצטבר'!K:K) -> 318000
A19: יוסי אביב | B19: =SUMIF('תפוקה מצטברת מול אשתקד'!B:B,'דוח הנהלה'!A19,'תפוקה מצטברת מול אשתקד'!H:H) -> 6929149.5 | C19: =SUMIF('תפוקה מצטברת מול אשתקד'!B:B,'דוח הנהלה'!A19,'תפוקה מצטברת מול אשתקד'!I:I) -> 1234527.8 | D19: =SUMIF('תפוקה מצטברת מול אשתקד'!B:B,'דוח הנהלה'!A19,'תפוקה מצטברת מול אשתקד'!J:J) -> 25775721 | E19: =SUMIF('תפוקה מצטברת מול אשתקד'!B:B,'דוח הנהלה'!A19,'תפוקה מצטברת מול אשתקד'!K:K) -> 38481611 | F19: =(B19-N19)/N19 -> 0.38940088 | G19: =(C19-O19)/O19 -> 0.28289676 | H19: =(D19-P19)/P19 -> -0.16458956 | I19: =(E19-Q19)/Q19 -> 0.5719797 | J19: =(B19-R19)/R19 -> -0.25512239 | K19: =(C19-S19)/S19 -> -0.27183688 | L19: =(D19-T19)/T19 -> -0.42103052 | M19: =(E19-U19)/U19 -> -0.22922705 | N19: =SUMIF('תפוקה מצטברת מול אשתקד'!B:B,'דוח הנהלה'!A19,'תפוקה מצטברת מול אשתקד'!L:L) -> 4987149.2 | O19: =SUMIF('תפוקה מצטברת מול אשתקד'!B:B,'דוח הנהלה'!A19,'תפוקה מצטברת מול אשתקד'!M:M) -> 962297.04 | P19: =SUMIF('תפוקה מצטברת מול אשתקד'!B:B,'דוח הנהלה'!A19,'תפוקה מצטברת מול אשתקד'!N:N) -> 30853961 | Q19: =SUMIF('תפוקה מצטברת מול אשתקד'!B:B,'דוח הנהלה'!A19,'תפוקה מצטברת מול אשתקד'!O:O) -> 24479712 | R19: =SUMIF('תפוקה מצטברת מול יעד מצטבר'!B:B,'דוח הנהלה'!A19,'תפוקה מצטברת מול יעד מצטבר'!H:H) -> 9302400 | S19: =SUMIF('תפוקה מצטברת מול יעד מצטבר'!B:B,'דוח הנהלה'!A19,'תפוקה מצטברת מול יעד מצטבר'!I:I) -> 1695400 | T19: =SUMIF('תפוקה מצטברת מול יעד מצטבר'!B:B,'דוח הנהלה'!A19,'תפוקה מצטברת מול יעד מצטבר'!J:J) -> 44520000 | U19: =SUMIF('תפוקה מצטברת מול יעד מצטבר'!B:B,'דוח הנהלה'!A19,'תפוקה מצטברת מול יעד מצטבר'!K:K) -> 49926000
A20: איתי אדן | B20: =SUMIF('תפוקה מצטברת מול אשתקד'!B:B,'דוח הנהלה'!A20,'תפוקה מצטברת מול אשתקד'!H:H) -> 1704748.5 | C20: =SUMIF('תפוקה מצטברת מול אשתקד'!B:B,'דוח הנהלה'!A20,'תפוקה מצטברת מול אשתקד'!I:I) -> 161671.96 | D20: =SUMIF('תפוקה מצטברת מול אשתקד'!B:B,'דוח הנהלה'!A20,'תפוקה מצטברת מול אשתקד'!J:J) -> 7511033.7 | E20: =SUMIF('תפוקה מצטברת מול אשתקד'!B:B,'דוח הנהלה'!A20,'תפוקה מצטברת מול אשתקד'!K:K) -> 4341341.9 | F20: =(B20-N20)/N20 -> 0.18612442 | G20: =(C20-O20)/O20 -> 0.35792058 | H20: =(D20-P20)/P20 -> 0.1421272 | I20: =(E20-Q20)/Q20 -> 1.2282085 | J20: =(B20-R20)/R20 -> -0.30554485 | K20: =(C20-S20)/S20 -> -0.58280356 | L20: =(D20-T20)/T20 -> 0.026939247 | M20: =(E20-U20)/U20 -> -0.31739908 | N20: =SUMIF('תפוקה מצטברת מול אשתקד'!B:B,'דוח הנהלה'!A20,'תפוקה מצטברת מול אשתקד'!L:L) -> 1437242.6 | O20: =SUMIF('תפוקה מצטברת מול אשתקד'!B:B,'דוח הנהלה'!A20,'תפוקה מצטברת מול אשתקד'!M:M) -> 119058.48 | P20: =SUMIF('תפוקה מצטברת מול אשתקד'!B:B,'דוח הנהלה'!A20,'תפוקה מצטברת מול אשתקד'!N:N) -> 6576354.8 | Q20: =SUMIF('תפוקה מצטברת מול אשתקד'!B:B,'דוח הנהלה'!A20,'תפוקה מצטברת מול אשתקד'!O:O) -> 1948355.4 | R20: =SUMIF('תפוקה מצטברת מול יעד מצטבר'!B:B,'דוח הנהלה'!A20,'תפוקה מצטברת מול יעד מצטבר'!H:H) -> 2454800 | S20: =SUMIF('תפוקה מצטברת מול יעד מצטבר'!B:B,'דוח הנהלה'!A20,'תפוקה מצטברת מול יעד מצטבר'!I:I) -> 387520 | T20: =SUMIF('תפוקה מצטברת מול יעד מצטבר'!B:B,'דוח הנהלה'!A20,'תפוקה מצטברת מול יעד מצטבר'!J:J) -> 7314000 | U20: =SUMIF('תפוקה מצטברת מול יעד מצטבר'!B:B,'דוח הנהלה'!A20,'תפוקה מצטברת מול יעד מצטבר'!K:K) -> 6360000
B21: =SUM(B17:B20) -> 15351100 | C21: =SUM(C17:C20) -> 2485647.4 | D21: =SUM(D17:D20) -> 60377536 | E21: =SUM(E17:E20) -> 75736719 | F21: =(B21-N21)/N21 -> 0.24915819 | G21: =(C21-O21)/O21 -> 0.2227391 | H21: =(D21-P21)/P21 -> 0.040234621 | I21: =(B21-R21)/R21 -> -0.1366644 | J21: =(B21-R21)/R21 -> -0.1366644 | K21: =(C21-S21)/S21 -> -0.22586723 | L21: =(D21-T21)/T21 -> -0.16358385 | M21: =(E21-U21)/U21 -> 0.078161079 | N21: =SUM(N17:N20) -> 12289156 | O21: =SUM(O17:O20) -> 2032851.8 | P21: =SUM(P17:P20) -> 58042229 | Q21: =SUM(Q17:Q20) -> 60052867 | R21: =SUM(R17:R20) -> 17781150 | S21: =SUM(S17:S20) -> 3210880 | T21: =SUM(T17:T20) -> 72186000 | U21: =SUM(U17:U20) -> 70246200
A25: תפוקה מצטברת לפי חברות | R25: עולים בולטים
A26: קבוצה | B26: תפוקה מצטברת 04/2025 | F26: שינוי מול אשתקד % | R26: סוכן | S26: שינוי % מול תקופה חופפת אשתקד | T26: עליה מול תקופה חופפת אשתקד | U26: תפוקה מצטברת - 2024
B27: פנסיוני | C27: סיכונים | D27: פיננסים | E27: ניודי פנסיה | F27: פנסיוני | G27: סיכונים | H27: פיננסים | I27: ניודי פנסיה | R27: שלבי מיסון | S27: 1.137323 | T27: 78835.466 | U27: 148152.15
A28: מנורה | B28: =מנורה!D73 -> 2617873.1 | C28: =מנורה!E73 -> 616397.56 | D28: =מנורה!F73 -> 2852204.7 | E28: =מנורה!G73 -> 1849352.4 | F28: =מנורה!D73/מנורה!H73-1 -> 0.29224758 | G28: =מנורה!E73/מנורה!I73-1 -> 0.79163243 | H28: =מנורה!F73/מנורה!J73-1 -> -0.5479204 | I28: =מנורה!G73/מנורה!K73-1 -> -0.76027044 | R28: בחוס יוסף | S28: 2.4472947 | T28: 70836.194 | U28: 99780.886
A29: מגדל | B29: =מגדל!D73 -> 7895532.8 | C29: =מגדל!E73 -> 462425.51 | D29: =מגדל!F73 -> 26405808 | E29: =מגדל!G73 -> 62528138 | F29: =מגדל!D73/מגדל!H73-1 -> 0.66330596 | G29: =מגדל!E73/מגדל!I73-1 -> 0.40496648 | H29: =מגדל!F73/מגדל!J73-1 -> 0.65838478 | I29: =מגדל!G73/מגדל!K73-1 -> 2.226294 | R29: עאטף עדווי | S29: 1.4313468 | T29: 98727.872 | U29: 167703.38
A30: כלל | B30: =כלל!D73 -> 2378264.6 | C30: =כלל!E73 -> 830227.73 | D30: =כלל!F73 -> 7758922 | E30: =כלל!G73 -> 8637709.5 | F30: =כלל!D73/כלל!H73-1 -> -0.3562939 | G30: =כלל!E73/כלל!I73-1 -> 1.7793655 | H30: =כלל!F73/כלל!J73-1 -> 0.064033313 | I30: =כלל!G73/כלל!K73-1 -> -0.68277304 | R30: לוי חיים | S30: 0.43313709 | T30: 84927.638 | U30: 281003.29
A31: אלטשולר שחם | B31: ='אלטשולר שחם'!D73 -> 0 | C31: ='אלטשולר שחם'!E73 -> 0 | D31: ='אלטשולר שחם'!F73 -> 206323 | E31: ='אלטשולר שחם'!G73 -> 0 | F31: ='אלטשולר שחם'!D73/'אלטשולר שחם'!H73-1 -> #DIV/0! | G31: 0 | H31: ='אלטשולר שחם'!F73/'אלטשולר שחם'!J73-1 -> 1.3674469 | I31: 0 | R31: גרניק בנימין | S31: 1.8176875 | T31: 358872.86 | U31: 556306.61
A32: מור | B32: =מור!D73 -> 0 | C32: =מור!E73 -> 0 | D32: =מור!F73 -> 1268094.1 | E32: =מור!G73 -> 0 | F32: 0 | G32: 0 | H32: =מור!F73/מור!J73-1 -> -0.56661203 | I32: 0
A33: הראל | B33: =הראל!D73 -> 1045368 | C33: =הראל!E73 -> 235759 | D33: =הראל!F73 -> 1742433 | E33: =הראל!G73 -> -1187375 | F33: =הראל!D73/הראל!H73-1 -> -0.27296924 | G33: =הראל!E73/הראל!I73-1 -> -0.48974283 | H33: =הראל!F73/הראל!J73-1 -> -0.592024 | I33: =הראל!G73/הראל!K73-1 -> -1.5346583
A34: הפניקס | B34: =הפניקס!D73 -> 1412831.3 | C34: =הפניקס!E73 -> 132415.92 | D34: =הפניקס!F73 -> 8650364.2 | E34: =הפניקס!G73 -> 3908894 | F34: =הפניקס!D73/הפניקס!H73-1 -> 2.6893037 | G34: =הפניקס!E73/הפניקס!I73-1 -> -0.5240477 | H34: =הפניקס!F73/הפניקס!J73-1 -> 0.68190542 | I34: =הפניקס!G73/הפניקס!K73-1 -> 0.11423737
A35: איילון | B35: =איילון!D73 -> 1230 | C35: =איילון!E73 -> 195412.71 | D35: =איילון!F73 -> 0 | E35: =איילון!G73 -> 0 | F35: 1 | G35: =איילון!E73/איילון!I73-1 -> -0.38303974 | H35: 0 | I35: 0
A36: הכשרה | B36: =הכשרה!D73 -> 0 | C36: =הכשרה!E73 -> 1952 | D36: =הכשרה!F73 -> 0 | E36: =הכשרה!G73 -> 0 | F36: 0 | G36: =הכשרה!E73/הכשרה!I73-1 -> -0.35385634 | H36: 1 | I36: 0 | R36: יורדים בולטים
A37: מדיהו | B37: ='מדיהו '!D73 -> 0 | C37: ='מדיהו '!E73 -> 11057 | D37: ='מדיהו '!F73 -> 0 | E37: ='מדיהו '!G73 -> 0 | F37: 0 | G37: ='מדיהו '!E73/'מדיהו '!I73-1 -> 10.590147 | H37: 0%0 | I37: 0 | R37: סוכן | S37: שינוי % מול תקופה חופפת אשתקד | T37: ירידה מול תקופה חופפת אשתקד | U37: תפוקה מצטברת - 2024
A38: אנליסט | B38: ='אנליסט '!D73 -> 0 | C38: ='אנליסט '!E73 -> 0 | D38: ='אנליסט '!F73 -> 11493387 | E38: ='אנליסט '!G73 -> 0 | F38: 0 | G38: 0 | H38: ='אנליסט '!F73/'אנליסט '!J73-1 -> -0.28573859 | I38: 0 | R38: יעקב ישראל שטרן | S38: -0.71824316 | T38: -22185.601 | U38: 8703.104
A39: מיטב דש | B39: ='מיטב דש'!D73 -> 0 | C39: ='מיטב דש'!E73 -> 0 | D39: ='מיטב דש'!F73 -> 0 | E39: ='מיטב דש'!G73 -> 0 | F39: 0 | G39: 0 | H39: 0 | I39: 0 | R39: דאי דניאל | S39: -0.90399965 | T39: -82260.84 | U39: 8735.7
A40: אינפניטי | B40: =אינפניטי!D73 -> 0 | C40: =אינפניטי!E73 -> 0 | D40: =אינפניטי!F73 -> 0 | E40: =אינפניטי!G73 -> 0 | F40: 0 | G40: 0 | H40: 0 | I40: 0 | R40: דורון ענק הביטוח | S40: -0.28801211 | T40: -26606.002 | U40: 65772.066
A41: סה"כ | B41: =SUM(B28:B40) -> 15351100 | C41: =SUM(C28:C40) -> 2485647.4 | D41: =SUM(D28:D40) -> 60377536 | E41: =SUM(E28:E40) -> 75736719 | F41: =('תפוקה מצטברת מול אשתקד'!H73-'תפוקה מצטברת מול אשתקד'!L73)/'תפוקה מצטברת מול אשתקד'!L73 -> 0.24915819 | G41: =('תפוקה מצטברת מול אשתקד'!I73-'תפוקה מצטברת מול אשתקד'!M73)/'תפוקה מצטברת מול אשתקד'!M73 -> 0.2227391 | H41: =('תפוקה מצטברת מול אשתקד'!J73-'תפוקה מצטברת מול אשתקד'!N73)/'תפוקה מצטברת מול אשתקד'!N73 -> 0.040234621 | I41: =('תפוקה מצטברת מול אשתקד'!K73-'תפוקה מצטברת מול אשתקד'!O73)/'תפוקה מצטברת מול אשתקד'!O73 -> 0.26116741 | R41: סאוסן שלבי | S41: -0.65726719 | T41: -327175.87 | U41: 170606.27
R42: ריזק חלבי | S42: -0.30420571 | T42: -68443.743 | U42: 156547.9

Sheet תפוקה מצטברת מול אשתקד
D1: שינוי מול אשתקד % | H1: תפוקה מצטברת 04/2025 | L1: תפוקה מצטברת 04/2024
A2: שם סוכן | B2: מפקח | C2: מחלקה | D2: פנסיוני | E2: סיכונים | F2: פיננסים | G2: ניודי פנסיה | H2: פנסיוני | I2: סיכונים | J2: פיננסים | K2: ניודי פנסיה | L2: פנסיוני | M2: סיכונים | N2: פיננסים | O2: ניודי פנסיה
A3: גל אלמגור סוכ | B3: יוסי אביב | C3: ישירים | D3: =IF(H3=0,0%,IF(L3=0,100%,H3/L3-1)) -> 0.89012587 | E3: =IF(I3=0,0%,IF(M3=0,100%,I3/M3-1)) -> -0.65543692 | F3: =IF(J3=0,0%,IF(N3=G28,100%,J3/N3-1)) -> 0.43445198 | G3: =IF(K3=0,0%,IF(O3=H28,100%,K3/O3-1)) -> 1.223246 | H3: =VLOOKUP(A3,הכשרה!A:G,4,0)+VLOOKUP('תפוקה מצטברת מול אשתקד'!A3,מגדל!A:G,4,0)+VLOOKUP('תפוקה מצטברת מול אשתקד'!A3,מנורה!A:G,4,0)+VLOOKUP('תפוקה מצטברת מול אשתקד'!A3,איילון!A:G,4,0)+VLOOKUP('תפוקה מצטברת מול אשתקד'!A3,הראל!A:G,4,0)+VLOOKUP('תפוקה מצטברת מול אשתקד'!A3,הפניקס!A:G,4,0)+VLOOKUP('תפוקה מצטברת מול אשתקד'!A3,כלל!A:G,4,0)+VLOOKUP('תפוקה מצטברת מול אשתקד'!A3,מור!A:G,4,0)+VLOOKUP('תפוקה מצטברת מול אשתקד'!A3,'אלטשולר שחם'!A:G,4,0)+VLOOKUP('תפוקה מצטברת מול אשתקד'!A3,'מדיהו '!A:G,4,0)+VLOOKUP('תפוקה מצטברת מול אשתקד'!A3,'אנליסט '!A:G,4,0)+VLOOKUP('תפוקה מצטברת מול אשתקד'!A3,'מיטב דש'!A:G,4,0)+VLOOKUP('תפוקה מצטברת מול אשתקד'!A3,אינפניטי!A:G,4,0) -> 4440627.2 | I3: =VLOOKUP(A3,הכשרה!A:G,5,0)+VLOOKUP('תפוקה מצטברת מול אשתקד'!A3,מגדל!A:G,5,0)+VLOOKUP('תפוקה מצטברת מול אשתקד'!A3,מנורה!A:G,5,0)+VLOOKUP('תפוקה מצטברת מול אשתקד'!A3,איילון!A:G,5,0)+VLOOKUP('תפוקה מצטברת מול אשתקד'!A3,הראל!A:G,5,0)+VLOOKUP('תפוקה מצטברת מול אשתקד'!A3,הפניקס!A:G,5,0)+VLOOKUP('תפוקה מצטברת מול אשתקד'!A3,כלל!A:G,5,0)+VLOOKUP('תפוקה מצטברת מול אשתקד'!A3,מור!A:G,5,0)+VLOOKUP('תפוקה מצטברת מול אשתקד'!A3,'אלטשולר שחם'!A:G,5,0)+VLOOKUP('תפוקה מצטברת מול אשתקד'!A3,'מדיהו '!A:G,5,0)+VLOOKUP('תפוקה מצטברת מול אשתקד'!A3,'אנליסט '!A:G,5,0)+VLOOKUP('תפוקה מצטברת מול אשתקד'!A3,'מיטב דש'!A:G,5,0)+VLOOKUP('תפוקה מצטברת מול אשתקד'!A3,אינפניטי!A:G,5,0) -> 172558.27 | J3: =VLOOKUP(A3,הכשרה!A:G,6,0)+VLOOKUP('תפוקה מצטברת מול אשתקד'!A3,מגדל!A:G,6,0)+VLOOKUP('תפוקה מצטברת מול אשתקד'!A3,מנורה!A:G,6,0)+VLOOKUP('תפוקה מצטברת מול אשתקד'!A3,איילון!A:G,6,0)+VLOOKUP(A3,הראל!A:G,6,0)+VLOOKUP('תפוקה מצטברת מול אשתקד'!A3,הפניקס!A:G,6,0)+VLOOKUP('תפוקה מצטברת מול אשתקד'!A3,כלל!A:G,6,0)+VLOOKUP('תפוקה מצטברת מול אשתקד'!A3,מור!A:G,6,0)+VLOOKUP('תפוקה מצטברת מול אשתקד'!A3,'אלטשולר שחם'!A:G,6,0)+VLOOKUP('תפוקה מצטברת מול אשתקד'!A3,'מדיהו '!A:G,6,0)+VLOOKUP('תפוקה מצטברת מול אשתקד'!A3,'אנליסט '!A:G,6,0)+VLOOKUP('תפוקה מצטברת מול אשתקד'!A3,'מיטב דש'!A:G,6,0)+VLOOKUP('תפוקה מצטברת מול אשתקד'!A3,אינפניטי!A:G,6,0) -> 11317307 | K3: =VLOOKUP(A3,הכשרה!A:G,7,0)+VLOOKUP('תפוקה מצטברת מול אשתקד'!A3,מגדל!A:G,7,0)+VLOOKUP('תפוקה מצטברת מול אשתקד'!A3,מנורה!A:G,7,0)+VLOOKUP('תפוקה מצטברת מול אשתקד'!A3,איילון!A:G,7,0)+VLOOKUP('תפוקה מצטברת מול אשתקד'!A3,הראל!A:G,7,0)+VLOOKUP('תפוקה מצטברת מול אשתקד'!A3,הפניקס!A:G,7,0)+VLOOKUP('תפוקה מצטברת מול אשתקד'!A3,כלל!A:G,7,0)+VLOOKUP('תפוקה מצטברת מול אשתקד'!A3,מור!A:G,7,0)+VLOOKUP('תפוקה מצטברת מול אשתקד'!A3,'אלטשולר שחם'!A:G,7,0)+VLOOKUP('תפוקה מצטברת מול אשתקד'!A3,'מדיהו '!A:K,7,0)+VLOOKUP(A3,'אנליסט '!A:G,7,0)+VLOOKUP('תפוקה מצטברת מול אשתקד'!A3,'מיטב דש'!A:G,7,0)+VLOOKUP('תפוקה מצטברת מול אשתקד'!A3,אינפניטי!A:G,7,0) -> 29172903 | L3: =VLOOKUP(A3,הכשרה!A:K,8,0)+VLOOKUP('תפוקה מצטברת מול אשתקד'!A3,מגדל!A:K,8,0)+VLOOKUP('תפוקה מצטברת מול אשתקד'!A3,מנורה!A:K,8,0)+VLOOKUP('תפוקה מצטברת מול אשתקד'!A3,איילון!A:K,8,0)+VLOOKUP('תפוקה מצטברת מול אשתקד'!A3,הראל!A:K,8,0)+VLOOKUP('תפוקה מצטברת מול אשתקד'!A3,הפניקס!A:K,8,0)+VLOOKUP('תפוקה מצטברת מול אשתקד'!A3,כלל!A:K,8,0)+VLOOKUP('תפוקה מצטברת מול אשתקד'!A3,מור!A:K,8,0)+VLOOKUP('תפוקה מצטברת מול אשתקד'!A3,'אלטשולר שחם'!A:K,8,0)+VLOOKUP('תפוקה מצטברת מול אשתקד'!A3,'מדיהו '!A:K,8,0)+VLOOKUP('תפוקה מצטברת מול אשתקד'!A3,'אנליסט '!A:K,8,0)+VLOOKUP('תפוקה מצטברת מול אשתקד'!A3,'מיטב דש'!A:K,8,0)+VLOOKUP('תפוקה מצטברת מול אשתקד'!A3,אינפניטי!A:K,8,0) -> 2349381.7 | M3: =VLOOKUP(A3,הכשרה!A:K,9,0)+VLOOKUP('תפוקה מצטברת מול אשתקד'!A3,מגדל!A:K,9,0)+VLOOKUP('תפוקה מצטברת מול אשתקד'!A3,מנורה!A:K,9,0)+VLOOKUP('תפוקה מצטברת מול אשתקד'!A3,איילון!A:K,9,0)+VLOOKUP('תפוקה מצטברת מול אשתקד'!A3,הראל!A:K,9,0)+VLOOKUP('תפוקה מצטברת מול אשתקד'!A3,הפניקס!A:K,9,0)+VLOOKUP('תפוקה מצטברת מול אשתקד'!A3,כלל!A:K,9,0)+VLOOKUP('תפוקה מצטברת מול אשתקד'!A3,מור!A:K,9,0)+VLOOKUP('תפוקה מצטברת מול אשתקד'!A3,'אלטשולר שחם'!A:K,9,0)+VLOOKUP('תפוקה מצטברת מול אשתקד'!A3,'מדיהו '!A:K,9,0)+VLOOKUP('תפוקה מצטברת מול אשתקד'!A3,'אנליסט '!A:K,9,0)+VLOOKUP('תפוקה מצטברת מול אשתקד'!A3,'מיטב דש'!A:K,9,0)+VLOOKUP('תפוקה מצטברת מול אשתקד'!A3,אינפניטי!A:K,9,0) -> 500803.14 | N3: =VLOOKUP(A3,הכשרה!A:K,10,0)+VLOOKUP('תפוקה מצטברת מול אשתקד'!A3,מגדל!A:K,10,0)+VLOOKUP('תפוקה מצטברת מול אשתקד'!A3,מנורה!A:K,10,0)+VLOOKUP('תפוקה מצטברת מול אשתקד'!A3,איילון!A:K,10,0)+VLOOKUP('תפוקה מצטברת מול אשתקד'!A3,הראל!A:K,10,0)+VLOOKUP('תפוקה מצטברת מול אשתקד'!A3,הפניקס!A:K,10,0)+VLOOKUP('תפוקה מצטברת מול אשתקד'!A3,כלל!A:K,10,0)+VLOOKUP('תפוקה מצטברת מול אשתקד'!A3,מור!A:K,10,0)+VLOOKUP('תפוקה מצטברת מול אשתקד'!A3,'אלטשולר שחם'!A:K,10,0)+VLOOKUP('תפוקה מצטברת מול אשתקד'!A3,'מדיהו '!A:K,10,0)+VLOOKUP('תפוקה מצטברת מול אשתקד'!A3,'אנליסט '!A:K,10,0)+VLOOKUP('תפוקה מצטברת מול אשתקד'!A3,'מיטב דש'!A:K,10,0)+VLOOKUP('תפוקה מצטברת מול אשתקד'!A3,אינפניטי!A:K,10,0) -> 7889638.1 | O3: =VLOOKUP(A3,הכשרה!A:K,11,0)+VLOOKUP('תפוקה מצטברת מול אשתקד'!A3,מגדל!A:K,11,0)+VLOOKUP('תפוקה מצטברת מול אשתקד'!A3,מנורה!A:K,11,0)+VLOOKUP('תפוקה מצטברת מול אשתקד'!A3,איילון!A:K,11,0)+VLOOKUP('תפוקה מצטברת מול אשתקד'!A3,הראל!A:K,11,0)+VLOOKUP('תפוקה מצטברת מול אשתקד'!A3,הפניקס!A:K,11,0)+VLOOKUP('תפוקה מצטברת מול אשתקד'!A3,כלל!A:K,11,0)+VLOOKUP('תפוקה מצטברת מול אשתקד'!A3,מור!A:K,11,0)+VLOOKUP('תפוקה מצטברת מול אשתקד'!A3,'אלטשולר שחם'!A:K,11,0)+VLOOKUP('תפוקה מצטברת מול אשתקד'!A3,'מדיהו '!A:K,11,0)+VLOOKUP('תפוקה מצטברת מול אשתקד'!A3,'אנליסט '!A:K,11,0)+VLOOKUP('תפוקה מצטברת מול אשתקד'!A3,'מיטב דש'!A:K,11,0)+VLOOKUP('תפוקה מצטברת מול אשתקד'!A3,אינפניטי!A:K,11,0) -> 13121762
A4: דניאלה אביב | B4: יוסי אביב | C4: ישירים | D4: =IF(H4=0,0%,IF(L4=0,100%,H4/L4-1)) -> -0.53964559 | E4: =IF(I4=0,0%,IF(M4=0,100%,I4/M4-1)) -> -0.1937936 | F4: =IF(J4=0,0%,IF(N4=0,100%,J4/N4-1)) -> -0.65796824 | G4: =IF(K4=0,0%,IF(O4=H29,100%,K4/O4-1)) -> -0.69312686 | H4: =VLOOKUP(A4,הכשרה!A:G,4,0)+VLOOKUP('תפוקה מצטברת מול אשתקד'!A4,מגדל!A:G,4,0)+VLOOKUP('תפוקה מצטברת מול אשתקד'!A4,מנורה!A:G,4,0)+VLOOKUP('תפוקה מצטברת מול אשתקד'!A4,איילון!A:G,4,0)+VLOOKUP('תפוקה מצטברת מול אשתקד'!A4,הראל!A:G,4,0)+VLOOKUP('תפוקה מצטברת מול אשתקד'!A4,הפניקס!A:G,4,0)+VLOOKUP('תפוקה מצטברת מול אשתקד'!A4,כלל!A:G,4,0)+VLOOKUP('תפוקה מצטברת מול אשתקד'!A4,מור!A:G,4,0)+VLOOKUP('תפוקה מצטברת מול אשתקד'!A4,'אלטשולר שחם'!A:G,4,0)+VLOOKUP('תפוקה מצטברת מול אשתקד'!A4,'מדיהו '!A:G,4,0)+VLOOKUP('תפוקה מצטברת מול אשתקד'!A4,'אנליסט '!A:G,4,0)+VLOOKUP('תפוקה מצטברת מול אשתקד'!A4,'מיטב דש'!A:G,4,0)+VLOOKUP('תפוקה מצטברת מול אשתקד'!A4,אינפניטי!A:G,4,0) -> 320033.34 | I4: =VLOOKUP(A4,הכשרה!A:G,5,0)+VLOOKUP('תפוקה מצטברת מול אשתקד'!A4,מגדל!A:G,5,0)+VLOOKUP('תפוקה מצטברת מול אשתקד'!A4,מנורה!A:G,5,0)+VLOOKUP('תפוקה מצטברת מול אשתקד'!A4,איילון!A:G,5,0)+VLOOKUP('תפוקה מצטברת מול אשתקד'!A4,הראל!A:G,5,0)+VLOOKUP('תפוקה מצטברת מול אשתקד'!A4,הפניקס!A:G,5,0)+VLOOKUP('תפוקה מצטברת מול אשתקד'!A4,כלל!A:G,5,0)+VLOOKUP('תפוקה מצטברת מול אשתקד'!A4,מור!A:G,5,0)+VLOOKUP('תפוקה מצטברת מול אשתקד'!A4,'אלטשולר שחם'!A:G,5,0)+VLOOKUP('תפוקה מצטברת מול אשתקד'!A4,'מדיהו '!A:G,5,0)+VLOOKUP('תפוקה מצטברת מול אשתקד'!A4,'אנליסט '!A:G,5,0)+VLOOKUP('תפוקה מצטברת מול אשתקד'!A4,'מיטב דש'!A:G,5,0)+VLOOKUP('תפוקה מצטברת מול אשתקד'!A4,אינפניטי!A:G,5,0) -> 3936.0592 | J4: =VLOOKUP(A4,הכשרה!A:G,6,0)+VLOOKUP('תפוקה מצטברת מול אשתקד'!A4,מגדל!A:G,6,0)+VLOOKUP('תפוקה מצטברת מול אשתקד'!A4,מנורה!A:G,6,0)+VLOOKUP('תפוקה מצטברת מול אשתקד'!A4,איילון!A:G,6,0)+VLOOKUP(A4,הראל!A:G,6,0)+VLOOKUP('תפוקה מצטברת מול אשתקד'!A4,הפניקס!A:G,6,0)+VLOOKUP('תפוקה מצטברת מול אשתקד'!A4,כלל!A:G,6,0)+VLOOKUP('תפוקה מצטברת מול אשתקד'!A4,מור!A:G,6,0)+VLOOKUP('תפוקה מצטברת מול אשתקד'!A4,'אלטשולר שחם'!A:G,6,0)+VLOOKUP('תפוקה מצטברת מול אשתקד'!A4,'מדיהו '!A:G,6,0)+VLOOKUP('תפוקה מצטברת מול אשתקד'!A4,'אנליסט '!A:G,6,0)+VLOOKUP('תפוקה מצטברת מול אשתקד'!A4,'מיטב דש'!A:G,6,0)+VLOOKUP('תפוקה מצטברת מול אשתקד'!A4,אינפניטי!A:G,6,0) -> 1974049 | K4: =VLOOKUP(A4,הכשרה!A:G,7,0)+VLOOKUP('תפוקה מצטברת מול אשתקד'!A4,מגדל!A:G,7,0)+VLOOKUP('תפוקה מצטברת מול אשתקד'!A4,מנורה!A:G,7,0)+VLOOKUP('תפוקה מצטברת מול אשתקד'!A4,איילון!A:G,7,0)+VLOOKUP('תפוקה מצטברת מול אשתקד'!A4,הראל!A:G,7,0)+VLOOKUP('תפוקה מצטברת מול אשתקד'!A4,הפניקס!A:G,7,0)+VLOOKUP('תפוקה מצטברת מול אשתקד'!A4,כלל!A:G,7,0)+VLOOKUP('תפוקה מצטברת מול אשתקד'!A4,מור!A:G,7,0)+VLOOKUP('תפוקה מצטברת מול אשתקד'!A4,'אלטשולר שחם'!A:G,7,0)+VLOOKUP('תפוקה מצטברת מול אשתקד'!A4,'מדיהו '!A:K,7,0)+VLOOKUP(A4,'אנליסט '!A:G,7,0)+VLOOKUP('תפוקה מצטברת מול אשתקד'!A4,'מיטב דש'!A:G,7,0)+VLOOKUP('תפוקה מצטברת מול אשתקד'!A4,אינפניטי!A:G,7,0) -> 1195708.6 | L4: =VLOOKUP(A4,הכשרה!A:K,8,0)+VLOOKUP('תפוקה מצטברת מול אשתקד'!A4,מגדל!A:K,8,0)+VLOOKUP('תפוקה מצטברת מול אשתקד'!A4,מנורה!A:K,8,0)+VLOOKUP('תפוקה מצטברת מול אשתקד'!A4,איילון!A:K,8,0)+VLOOKUP('תפוקה מצטברת מול אשתקד'!A4,הראל!A:K,8,0)+VLOOKUP('תפוקה מצטברת מול אשתקד'!A4,הפניקס!A:K,8,0)+VLOOKUP('תפוקה מצטברת מול אשתקד'!A4,כלל!A:K,8,0)+VLOOKUP('תפוקה מצטברת מול אשתקד'!A4,מור!A:K,8,0)+VLOOKUP('תפוקה מצטברת מול אשתקד'!A4,'אלטשולר שחם'!A:K,8,0)+VLOOKUP('תפוקה מצטברת מול אשתקד'!A4,'מדיהו '!A:K,8,0)+VLOOKUP('תפוקה מצטברת מול אשתקד'!A4,'אנליסט '!A:K,8,0)+VLOOKUP('תפוקה מצטברת מול אשתקד'!A4,'מיטב דש'!A:K,8,0)+VLOOKUP('תפוקה מצטברת מול אשתקד'!A4,אינפניטי!A:K,8,0) -> 695189.05 | M4: =VLOOKUP(A4,הכשרה!A:K,9,0)+VLOOKUP('תפוקה מצטברת מול אשתקד'!A4,מגדל!A:K,9,0)+VLOOKUP('תפוקה מצטברת מול אשתקד'!A4,מנורה!A:K,9,0)+VLOOKUP('תפוקה מצטברת מול אשתקד'!A4,איילון!A:K,9,0)+VLOOKUP('תפוקה מצטברת מול אשתקד'!A4,הראל!A:K,9,0)+VLOOKUP('תפוקה מצטברת מול אשתקד'!A4,הפניקס!A:K,9,0)+VLOOKUP('תפוקה מצטברת מול אשתקד'!A4,כלל!A:K,9,0)+VLOOKUP('תפוקה מצטברת מול אשתקד'!A4,מור!A:K,9,0)+VLOOKUP('תפוקה מצטברת מול אשתקד'!A4,'אלטשולר שחם'!A:K,9,0)+VLOOKUP('תפוקה מצטברת מול אשתקד'!A4,'מדיהו '!A:K,9,0)+VLOOKUP('תפוקה מצטברת מול אשתקד'!A4,'אנליסט '!A:K,9,0)+VLOOKUP('תפוקה מצטברת מול אשתקד'!A4,'מיטב דש'!A:K,9,0)+VLOOKUP('תפוקה מצטברת מול אשתקד'!A4,אינפניטי!A:K,9,0) -> 4882.1979 | N4: =VLOOKUP(A4,הכשרה!A:K,10,0)+VLOOKUP('תפוקה מצטברת מול אשתקד'!A4,מגדל!A:K,10,0)+VLOOKUP('תפוקה מצטברת מול אשתקד'!A4,מנורה!A:K,10,0)+VLOOKUP('תפוקה מצטברת מול אשתקד'!A4,איילון!A:K,10,0)+VLOOKUP('תפוקה מצטברת מול אשתקד'!A4,הראל!A:K,10,0)+VLOOKUP('תפוקה מצטברת מול אשתקד'!A4,הפניקס!A:K,10,0)+VLOOKUP('תפוקה מצטברת מול אשתקד'!A4,כלל!A:K,10,0)+VLOOKUP('תפוקה מצטברת מול אשתקד'!A4,מור!A:K,10,0)+VLOOKUP('תפוקה מצטברת מול אשתקד'!A4,'אלטשולר שחם'!A:K,10,0)+VLOOKUP('תפוקה מצטברת מול אשתקד'!A4,'מדיהו '!A:K,10,0)+VLOOKUP('תפוקה מצטברת מול אשתקד'!A4,'אנליסט '!A:K,10,0)+VLOOKUP('תפוקה מצטברת מול אשתקד'!A4,'מיטב דש'!A:K,10,0)+VLOOKUP('תפוקה מצטברת מול אשתקד'!A4,אינפניטי!A:K,10,0) -> 5771537 | O4: =VLOOKUP(A4,הכשרה!A:K,11,0)+VLOOKUP('תפוקה מצטברת מול אשתקד'!A4,מגדל!A:K,11,0)+VLOOKUP('תפוקה מצטברת מול אשתקד'!A4,מנורה!A:K,11,0)+VLOOKUP('תפוקה מצטברת מול אשתקד'!A4,איילון!A:K,11,0)+VLOOKUP('תפוקה מצטברת מול אשתקד'!A4,הראל!A:K,11,0)+VLOOKUP('תפוקה מצטברת מול אשתקד'!A4,הפניקס!A:K,11,0)+VLOOKUP('תפוקה מצטברת מול אשתקד'!A4,כלל!A:K,11,0)+VLOOKUP('תפוקה מצטברת מול אשתקד'!A4,מור!A:K,11,0)+VLOOKUP('תפוקה מצטברת מול אשתקד'!A4,'אלטשולר שחם'!A:K,11,0)+VLOOKUP('תפוקה מצטברת מול אשתקד'!A4,'מדיהו '!A:K,11,0)+VLOOKUP('תפוקה מצטברת מול אשתקד'!A4,'אנליסט '!A:K,11,0)+VLOOKUP('תפוקה מצטברת מול אשתקד'!A4,'מיטב דש'!A:K,11,0)+VLOOKUP('תפוקה מצטברת מול אשתקד'!A4,אינפניטי!A:K,11,0) -> 3896426.5
A5: רותי | B5: יוסי אביב | C5: ישירים | D5: =IF(H5=0,0%,IF(L5=0,100%,H5/L5-1)) -> 0 | E5: =IF(I5=0,0%,IF(M5=0,100%,I5/M5-1)) -> 1 | F5: =IF(J5=0,0%,IF(N5=0,100%,J5/N5-1)) -> 0 | G5: =IF(K5=0,0%,IF(O5=H30,100%,K5/O5-1)) -> 0 | H5: =VLOOKUP(A5,הכשרה!A:G,4,0)+VLOOKUP('תפוקה מצטברת מול אשתקד'!A5,מגדל!A:G,4,0)+VLOOKUP('תפוקה מצטברת מול אשתקד'!A5,מנורה!A:G,4,0)+VLOOKUP('תפוקה מצטברת מול אשתקד'!A5,איילון!A:G,4,0)+VLOOKUP('תפוקה מצטברת מול אשתקד'!A5,הראל!A:G,4,0)+VLOOKUP('תפוקה מצטברת מול אשתקד'!A5,הפניקס!A:G,4,0)+VLOOKUP('תפוקה מצטברת מול אשתקד'!A5,כלל!A:G,4,0)+VLOOKUP('תפוקה מצטברת מול אשתקד'!A5,מור!A:G,4,0)+VLOOKUP('תפוקה מצטברת מול אשתקד'!A5,'אלטשולר שחם'!A:G,4,0)+VLOOKUP('תפוקה מצטברת מול אשתקד'!A5,'מדיהו '!A:G,4,0)+VLOOKUP('תפוקה מצטברת מול אשתקד'!A5,'אנליסט '!A:G,4,0)+VLOOKUP('תפוקה מצטברת מול אשתקד'!A5,'מיטב דש'!A:G,4,0)+VLOOKUP('תפוקה מצטברת מול אשתקד'!A5,אינפניטי!A:G,4,0) -> 0 | I5: =VLOOKUP(A5,הכשרה!A:G,5,0)+VLOOKUP('תפוקה מצטברת מול אשתקד'!A5,מגדל!A:G,5,0)+VLOOKUP('תפוקה מצטברת מול אשתקד'!A5,מנורה!A:G,5,0)+VLOOKUP('תפוקה מצטברת מול אשתקד'!A5,איילון!A:G,5,0)+VLOOKUP('תפוקה מצטברת מול אשתקד'!A5,הראל!A:G,5,0)+VLOOKUP('תפוקה מצטברת מול אשתקד'!A5,הפניקס!A:G,5,0)+VLOOKUP('תפוקה מצטברת מול אשתקד'!A5,כלל!A:G,5,0)+VLOOKUP('תפוקה מצטברת מול אשתקד'!A5,מור!A:G,5,0)+VLOOKUP('תפוקה מצטברת מול אשתקד'!A5,'אלטשולר שחם'!A:G,5,0)+VLOOKUP('תפוקה מצטברת מול אשתקד'!A5,'מדיהו '!A:G,5,0)+VLOOKUP('תפוקה מצטברת מול אשתקד'!A5,'אנליסט '!A:G,5,0)+VLOOKUP('תפוקה מצטברת מול אשתקד'!A5,'מיטב דש'!A:G,5,0)+VLOOKUP('תפוקה מצטברת מול אשתקד'!A5,אינפניטי!A:G,5,0) -> 40962.665 | J5: =VLOOKUP(A5,הכשרה!A:G,6,0)+VLOOKUP('תפוקה מצטברת מול אשתקד'!A5,מגדל!A:G,6,0)+VLOOKUP('תפוקה מצטברת מול אשתקד'!A5,מנורה!A:G,6,0)+VLOOKUP('תפוקה מצטברת מול אשתקד'!A5,איילון!A:G,6,0)+VLOOKUP(A5,הראל!A:G,6,0)+VLOOKUP('תפוקה מצטברת מול אשתקד'!A5,הפניקס!A:G,6,0)+VLOOKUP('תפוקה מצטברת מול אשתקד'!A5,כלל!A:G,6,0)+VLOOKUP('תפוקה מצטברת מול אשתקד'!A5,מור!A:G,6,0)+VLOOKUP('תפוקה מצטברת מול אשתקד'!A5,'אלטשולר שחם'!A:G,6,0)+VLOOKUP('תפוקה מצטברת מול אשתקד'!A5,'מדיהו '!A:G,6,0)+VLOOKUP('תפוקה מצטברת מול אשתקד'!A5,'אנליסט '!A:G,6,0)+VLOOKUP('תפוקה מצטברת מול אשתקד'!A5,'מיטב דש'!A:G,6,0)+VLOOKUP('תפוקה מצטברת מול אשתקד'!A5,אינפניטי!A:G,6,0) -> 0 | K5: =VLOOKUP(A5,הכשרה!A:G,7,0)+VLOOKUP('תפוקה מצטברת מול אשתקד'!A5,מגדל!A:G,7,0)+VLOOKUP('תפוקה מצטברת מול אשתקד'!A5,מנורה!A:G,7,0)+VLOOKUP('תפוקה מצטברת מול אשתקד'!A5,איילון!A:G,7,0)+VLOOKUP('תפוקה מצטברת מול אשתקד'!A5,הראל!A:G,7,0)+VLOOKUP('תפוקה מצטברת מול אשתקד'!A5,הפניקס!A:G,7,0)+VLOOKUP('תפוקה מצטברת מול אשתקד'!A5,כלל!A:G,7,0)+VLOOKUP('תפוקה מצטברת מול אשתקד'!A5,מור!A:G,7,0)+VLOOKUP('תפוקה מצטברת מול אשתקד'!A5,'אלטשולר שחם'!A:G,7,0)+VLOOKUP('תפוקה מצטברת מול אשתקד'!A5,'מדיהו '!A:K,7,0)+VLOOKUP(A5,'אנליסט '!A:G,7,0)+VLOOKUP('תפוקה מצטברת מול אשתקד'!A5,'מיטב דש'!A:G,7,0)+VLOOKUP('תפוקה מצטברת מול אשתקד'!A5,אינפניטי!A:G,7,0) -> 0 | L5: =VLOOKUP(A5,הכשרה!A:K,8,0)+VLOOKUP('תפוקה מצטברת מול אשתקד'!A5,מגדל!A:K,8,0)+VLOOKUP('תפוקה מצטברת מול אשתקד'!A5,מנורה!A:K,8,0)+VLOOKUP('תפוקה מצטברת מול אשתקד'!A5,איילון!A:K,8,0)+VLOOKUP('תפוקה מצטברת מול אשתקד'!A5,הראל!A:K,8,0)+VLOOKUP('תפוקה מצטברת מול אשתקד'!A5,הפניקס!A:K,8,0)+VLOOKUP('תפוקה מצטברת מול אשתקד'!A5,כלל!A:K,8,0)+VLOOKUP('תפוקה מצטברת מול אשתקד'!A5,מור!A:K,8,0)+VLOOKUP('תפוקה מצטברת מול אשתקד'!A5,'אלטשולר שחם'!A:K,8,0)+VLOOKUP('תפוקה מצטברת מול אשתקד'!A5,'מדיהו '!A:K,8,0)+VLOOKUP('תפוקה מצטברת מול אשתקד'!A5,'אנליסט '!A:K,8,0)+VLOOKUP('תפוקה מצטברת מול אשתקד'!A5,'מיטב דש'!A:K,8,0)+VLOOKUP('תפוקה מצטברת מול אשתקד'!A5,אינפניטי!A:K,8,0) -> 0 | M5: =VLOOKUP(A5,הכשרה!A:K,9,0)+VLOOKUP('תפוקה מצטברת מול אשתקד'!A5,מגדל!A:K,9,0)+VLOOKUP('תפוקה מצטברת מול אשתקד'!A5,מנורה!A:K,9,0)+VLOOKUP('תפוקה מצטברת מול אשתקד'!A5,איילון!A:K,9,0)+VLOOKUP('תפוקה מצטברת מול אשתקד'!A5,הראל!A:K,9,0)+VLOOKUP('תפוקה מצטברת מול אשתקד'!A5,הפניקס!A:K,9,0)+VLOOKUP('תפוקה מצטברת מול אשתקד'!A5,כלל!A:K,9,0)+VLOOKUP('תפוקה מצטברת מול אשתקד'!A5,מור!A:K,9,0)+VLOOKUP('תפוקה מצטברת מול אשתקד'!A5,'אלטשולר שחם'!A:K,9,0)+VLOOKUP('תפוקה מצטברת מול אשתקד'!A5,'מדיהו '!A:K,9,0)+VLOOKUP('תפוקה מצטברת מול אשתקד'!A5,'אנליסט '!A:K,9,0)+VLOOKUP('תפוקה מצטברת מול אשתקד'!A5,'מיטב דש'!A:K,9,0)+VLOOKUP('תפוקה מצטברת מול אשתקד'!A5,אינפניטי!A:K,9,0) -> 0 | N5: =VLOOKUP(A5,הכשרה!A:K,10,0)+VLOOKUP('תפוקה מצטברת מול אשתקד'!A5,מגדל!A:K,10,0)+VLOOKUP('תפוקה מצטברת מול אשתקד'!A5,מנורה!A:K,10,0)+VLOOKUP('תפוקה מצטברת מול אשתקד'!A5,איילון!A:K,10,0)+VLOOKUP('תפוקה מצטברת מול אשתקד'!A5,הראל!A:K,10,0)+VLOOKUP('תפוקה מצטברת מול אשתקד'!A5,הפניקס!A:K,10,0)+VLOOKUP('תפוקה מצטברת מול אשתקד'!A5,כלל!A:K,10,0)+VLOOKUP('תפוקה מצטברת מול אשתקד'!A5,מור!A:K,10,0)+VLOOKUP('תפוקה מצטברת מול אשתקד'!A5,'אלטשולר שחם'!A:K,10,0)+VLOOKUP('תפוקה מצטברת מול אשתקד'!A5,'מדיהו '!A:K,10,0)+VLOOKUP('תפוקה מצטברת מול אשתקד'!A5,'אנליסט '!A:K,10,0)+VLOOKUP('תפוקה מצטברת מול אשתקד'!A5,'מיטב דש'!A:K,10,0)+VLOOKUP('תפוקה מצטברת מול אשתקד'!A5,אינפניטי!A:K,10,0) -> 0 | O5: =VLOOKUP(A5,הכשרה!A:K,11,0)+VLOOKUP('תפוקה מצטברת מול אשתקד'!A5,מגדל!A:K,11,0)+VLOOKUP('תפוקה מצטברת מול אשתקד'!A5,מנורה!A:K,11,0)+VLOOKUP('תפוקה מצטברת מול אשתקד'!A5,איילון!A:K,11,0)+VLOOKUP('תפוקה מצטברת מול אשתקד'!A5,הראל!A:K,11,0)+VLOOKUP('תפוקה מצטברת מול אשתקד'!A5,הפניקס!A:K,11,0)+VLOOKUP('תפוקה מצטברת מול אשתקד'!A5,כלל!A:K,11,0)+VLOOKUP('תפוקה מצטברת מול אשתקד'!A5,מור!A:K,11,0)+VLOOKUP('תפוקה מצטברת מול אשתקד'!A5,'אלטשולר שחם'!A:K,11,0)+VLOOKUP('תפוקה מצטברת מול אשתקד'!A5,'מדיהו '!A:K,11,0)+VLOOKUP('תפוקה מצטברת מול אשתקד'!A5,'אנליסט '!A:K,11,0)+VLOOKUP('תפוקה מצטברת מול אשתקד'!A5,'מיטב דש'!A:K,11,0)+VLOOKUP('תפוקה מצטברת מול אשתקד'!A5,אינפניטי!A:K,11,0) -> 0
A6: אילנית | B6: יוסי אביב | C6: ישירים | D6: =IF(H6=0,0%,IF(L6=0,100%,H6/L6-1)) -> 1 | E6: =IF(I6=0,0%,IF(M6=0,100%,I6/M6-1)) -> 1 | F6: =IF(J6=0,0%,IF(N6=0,100%,J6/N6-1)) -> 1 | G6: =IF(K6=0,0%,IF(O6=H31,100%,K6/O6-1)) -> #DIV/0! | H6: =VLOOKUP(A6,הכשרה!A:G,4,0)+VLOOKUP('תפוקה מצטברת מול אשתקד'!A6,מגדל!A:G,4,0)+VLOOKUP('תפוקה מצטברת מול אשתקד'!A6,מנורה!A:G,4,0)+VLOOKUP('תפוקה מצטברת מול אשתקד'!A6,איילון!A:G,4,0)+VLOOKUP('תפוקה מצטברת מול אשתקד'!A6,הראל!A:G,4,0)+VLOOKUP('תפוקה מצטברת מול אשתקד'!A6,הפניקס!A:G,4,0)+VLOOKUP('תפוקה מצטברת מול אשתקד'!A6,כלל!A:G,4,0)+VLOOKUP('תפוקה מצטברת מול אשתקד'!A6,מור!A:G,4,0)+VLOOKUP('תפוקה מצטברת מול אשתקד'!A6,'אלטשולר שחם'!A:G,4,0)+VLOOKUP('תפוקה מצטברת מול אשתקד'!A6,'מדיהו '!A:G,4,0)+VLOOKUP('תפוקה מצטברת מול אשתקד'!A6,'אנליסט '!A:G,4,0)+VLOOKUP('תפוקה מצטברת מול אשתקד'!A6,'מיטב דש'!A:G,4,0)+VLOOKUP('תפוקה מצטברת מול אשתקד'!A6,אינפניטי!A:G,4,0) -> 191253.87 | I6: =VLOOKUP(A6,הכשרה!A:G,5,0)+VLOOKUP('תפוקה מצטברת מול אשתקד'!A6,מגדל!A:G,5,0)+VLOOKUP('תפוקה מצטברת מול אשתקד'!A6,מנורה!A:G,5,0)+VLOOKUP('תפוקה מצטברת מול אשתקד'!A6,איילון!A:G,5,0)+VLOOKUP('תפוקה מצטברת מול אשתקד'!A6,הראל!A:G,5,0)+VLOOKUP('תפוקה מצטברת מול אשתקד'!A6,הפניקס!A:G,5,0)+VLOOKUP('תפוקה מצטברת מול אשתקד'!A6,כלל!A:G,5,0)+VLOOKUP('תפוקה מצטברת מול אשתקד'!A6,מור!A:G,5,0)+VLOOKUP('תפוקה מצטברת מול אשתקד'!A6,'אלטשולר שחם'!A:G,5,0)+VLOOKUP('תפוקה מצטברת מול אשתקד'!A6,'מדיהו '!A:G,5,0)+VLOOKUP('תפוקה מצטברת מול אשתקד'!A6,'אנליסט '!A:G,5,0)+VLOOKUP('תפוקה מצטברת מול אשתקד'!A6,'מיטב דש'!A:G,5,0)+VLOOKUP('תפוקה מצטברת מול אשתקד'!A6,אינפניטי!A:G,5,0) -> 31027.561 | J6: =VLOOKUP(A6,הכשרה!A:G,6,0)+VLOOKUP('תפוקה מצטברת מול אשתקד'!A6,מגדל!A:G,6,0)+VLOOKUP('תפוקה מצטברת מול אשתקד'!A6,מנורה!A:G,6,0)+VLOOKUP('תפוקה מצטברת מול אשתקד'!A6,איילון!A:G,6,0)+VLOOKUP(A6,הראל!A:G,6,0)+VLOOKUP('תפוקה מצטברת מול אשתקד'!A6,הפניקס!A:G,6,0)+VLOOKUP('תפוקה מצטברת מול אשתקד'!A6,כלל!A:G,6,0)+VLOOKUP('תפוקה מצטברת מול אשתקד'!A6,מור!A:G,6,0)+VLOOKUP('תפוקה מצטברת מול אשתקד'!A6,'אלטשולר שחם'!A:G,6,0)+VLOOKUP('תפוקה מצטברת מול אשתקד'!A6,'מדיהו '!A:G,6,0)+VLOOKUP('תפוקה מצטברת מול אשתקד'!A6,'אנליסט '!A:G,6,0)+VLOOKUP('תפוקה מצטברת מול אשתקד'!A6,'מיטב דש'!A:G,6,0)+VLOOKUP('תפוקה מצטברת מול אשתקד'!A6,אינפניטי!A:G,6,0) -> 453181.28 | K6: =VLOOKUP(A6,הכשרה!A:G,7,0)+VLOOKUP('תפוקה מצטברת מול אשתקד'!A6,מגדל!A:G,7,0)+VLOOKUP('תפוקה מצטברת מול אשתקד'!A6,מנורה!A:G,7,0)+VLOOKUP('תפוקה מצטברת מול אשתקד'!A6,איילון!A:G,7,0)+VLOOKUP('תפוקה מצטברת מול אשתקד'!A6,הראל!A:G,7,0)+VLOOKUP('תפוקה מצטברת מול אשתקד'!A6,הפניקס!A:G,7,0)+VLOOKUP('תפוקה מצטברת מול אשתקד'!A6,כלל!A:G,7,0)+VLOOKUP('תפוקה מצטברת מול אשתקד'!A6,מור!A:G,7,0)+VLOOKUP('תפוקה מצטברת מול אשתקד'!A6,'אלטשולר שחם'!A:G,7,0)+VLOOKUP('תפוקה מצטברת מול אשתקד'!A6,'מדיהו '!A:K,7,0)+VLOOKUP(A6,'אנליסט '!A:G,7,0)+VLOOKUP('תפוקה מצטברת מול אשתקד'!A6,'מיטב דש'!A:G,7,0)+VLOOKUP('תפוקה מצטברת מול אשתקד'!A6,אינפניטי!A:G,7,0) -> 131217.27 | L6: =VLOOKUP(A6,הכשרה!A:K,8,0)+VLOOKUP('תפוקה מצטברת מול אשתקד'!A6,מגדל!A:K,8,0)+VLOOKUP('תפוקה מצטברת מול אשתקד'!A6,מנורה!A:K,8,0)+VLOOKUP('תפוקה מצטברת מול אשתקד'!A6,איילון!A:K,8,0)+VLOOKUP('תפוקה מצטברת מול אשתקד'!A6,הראל!A:K,8,0)+VLOOKUP('תפוקה מצטברת מול אשתקד'!A6,הפניקס!A:K,8,0)+VLOOKUP('תפוקה מצטברת מול אשתקד'!A6,כלל!A:K,8,0)+VLOOKUP('תפוקה מצטברת מול אשתקד'!A6,מור!A:K,8,0)+VLOOKUP('תפוקה מצטברת מול אשתקד'!A6,'אלטשולר שחם'!A:K,8,0)+VLOOKUP('תפוקה מצטברת מול אשתקד'!A6,'מדיהו '!A:K,8,0)+VLOOKUP('תפוקה מצטברת מול אשתקד'!A6,'אנליסט '!A:K,8,0)+VLOOKUP('תפוקה מצטברת מול אשתקד'!A6,'מיטב דש'!A:K,8,0)+VLOOKUP('תפוקה מצטברת מול אשתקד'!A6,אינפניטי!A:K,8,0) -> 0 | M6: =VLOOKUP(A6,הכשרה!A:K,9,0)+VLOOKUP('תפוקה מצטברת מול אשתקד'!A6,מגדל!A:K,9,0)+VLOOKUP('תפוקה מצטברת מול אשתקד'!A6,מנורה!A:K,9,0)+VLOOKUP('תפוקה מצטברת מול אשתקד'!A6,איילון!A:K,9,0)+VLOOKUP('תפוקה מצטברת מול אשתקד'!A6,הראל!A:K,9,0)+VLOOKUP('תפוקה מצטברת מול אשתקד'!A6,הפניקס!A:K,9,0)+VLOOKUP('תפוקה מצטברת מול אשתקד'!A6,כלל!A:K,9,0)+VLOOKUP('תפוקה מצטברת מול אשתקד'!A6,מור!A:K,9,0)+VLOOKUP('תפוקה מצטברת מול אשתקד'!A6,'אלטשולר שחם'!A:K,9,0)+VLOOKUP('תפוקה מצטברת מול אשתקד'!A6,'מדיהו '!A:K,9,0)+VLOOKUP('תפוקה מצטברת מול אשתקד'!A6,'אנליסט '!A:K,9,0)+VLOOKUP('תפוקה מצטברת מול אשתקד'!A6,'מיטב דש'!A:K,9,0)+VLOOKUP('תפוקה מצטברת מול אשתקד'!A6,אינפניטי!A:K,9,0) -> 0 | N6: =VLOOKUP(A6,הכשרה!A:K,10,0)+VLOOKUP('תפוקה מצטברת מול אשתקד'!A6,מגדל!A:K,10,0)+VLOOKUP('תפוקה מצטברת מול אשתקד'!A6,מנורה!A:K,10,0)+VLOOKUP('תפוקה מצטברת מול אשתקד'!A6,איילון!A:K,10,0)+VLOOKUP('תפוקה מצטברת מול אשתקד'!A6,הראל!A:K,10,0)+VLOOKUP('תפוקה מצטברת מול אשתקד'!A6,הפניקס!A:K,10,0)+VLOOKUP('תפוקה מצטברת מול אשתקד'!A6,כלל!A:K,10,0)+VLOOKUP('תפוקה מצטברת מול אשתקד'!A6,מור!A:K,10,0)+VLOOKUP('תפוקה מצטברת מול אשתקד'!A6,'אלטשולר שחם'!A:K,10,0)+VLOOKUP('תפוקה מצטברת מול אשתקד'!A6,'מדיהו '!A:K,10,0)+VLOOKUP('תפוקה מצטברת מול אשתקד'!A6,'אנליסט '!A:K,10,0)+VLOOKUP('תפוקה מצטברת מול אשתקד'!A6,'מיטב דש'!A:K,10,0)+VLOOKUP('תפוקה מצטברת מול אשתקד'!A6,אינפניטי!A:K,10,0) -> 0 | O6: =VLOOKUP(A6,הכשרה!A:K,11,0)+VLOOKUP('תפוקה מצטברת מול אשתקד'!A6,מגדל!A:K,11,0)+VLOOKUP('תפוקה מצטברת מול אשתקד'!A6,מנורה!A:K,11,0)+VLOOKUP('תפוקה מצטברת מול אשתקד'!A6,איילון!A:K,11,0)+VLOOKUP('תפוקה מצטברת מול אשתקד'!A6,הראל!A:K,11,0)+VLOOKUP('תפוקה מצטברת מול אשתקד'!A6,הפניקס!A:K,11,0)+VLOOKUP('תפוקה מצטברת מול אשתקד'!A6,כלל!A:K,11,0)+VLOOKUP('תפוקה מצטברת מול אשתקד'!A6,מור!A:K,11,0)+VLOOKUP('תפוקה מצטברת מול אשתקד'!A6,'אלטשולר שחם'!A:K,11,0)+VLOOKUP('תפוקה מצטברת מול אשתקד'!A6,'מדיהו '!A:K,11,0)+VLOOKUP('תפוקה מצטברת מול אשתקד'!A6,'אנליסט '!A:K,11,0)+VLOOKUP('תפוקה מצטברת מול אשתקד'!A6,'מיטב דש'!A:K,11,0)+VLOOKUP('תפוקה מצטברת מול אשתקד'!A6,אינפניטי!A:K,11,0) -> 0
A7: דני פחימה | B7: יוסי אביב | C7: ישירים | D7: =IF(H7=0,0%,IF(L7=0,100%,H7/L7-1)) -> -0.50845798 | E7: =IF(I7=0,0%,IF(M7=0,100%,I7/M7-1)) -> 0.65403237 | F7: =IF(J7=0,0%,IF(N7=0,100%,J7/N7-1)) -> 0.18529415 | G7: =IF(K7=0,0%,IF(O7=H71,100%,K7/O7-1)) -> -0.49743581 | H7: =VLOOKUP(A7,הכשרה!A:G,4,0)+VLOOKUP('תפוקה מצטברת מול אשתקד'!A7,מגדל!A:G,4,0)+VLOOKUP('תפוקה מצטברת מול אשתקד'!A7,מנורה!A:G,4,0)+VLOOKUP('תפוקה מצטברת מול אשתקד'!A7,איילון!A:G,4,0)+VLOOKUP('תפוקה מצטברת מול אשתקד'!A7,הראל!A:G,4,0)+VLOOKUP('תפוקה מצטברת מול אשתקד'!A7,הפניקס!A:G,4,0)+VLOOKUP('תפוקה מצטברת מול אשתקד'!A7,כלל!A:G,4,0)+VLOOKUP('תפוקה מצטברת מול אשתקד'!A7,מור!A:G,4,0)+VLOOKUP('תפוקה מצטברת מול אשתקד'!A7,'אלטשולר שחם'!A:G,4,0)+VLOOKUP('תפוקה מצטברת מול אשתקד'!A7,'מדיהו '!A:G,4,0)+VLOOKUP('תפוקה מצטברת מול אשתקד'!A7,'אנליסט '!A:G,4,0)+VLOOKUP('תפוקה מצטברת מול אשתקד'!A7,'מיטב דש'!A:G,4,0)+VLOOKUP('תפוקה מצטברת מול אשתקד'!A7,אינפניטי!A:G,4,0) -> 19299.96 | I7: =VLOOKUP(A7,הכשרה!A:G,5,0)+VLOOKUP('תפוקה מצטברת מול אשתקד'!A7,מגדל!A:G,5,0)+VLOOKUP('תפוקה מצטברת מול אשתקד'!A7,מנורה!A:G,5,0)+VLOOKUP('תפוקה מצטברת מול אשתקד'!A7,איילון!A:G,5,0)+VLOOKUP('תפוקה מצטברת מול אשתקד'!A7,הראל!A:G,5,0)+VLOOKUP('תפוקה מצטברת מול אשתקד'!A7,הפניקס!A:G,5,0)+VLOOKUP('תפוקה מצטברת מול אשתקד'!A7,כלל!A:G,5,0)+VLOOKUP('תפוקה מצטברת מול אשתקד'!A7,מור!A:G,5,0)+VLOOKUP('תפוקה מצטברת מול אשתקד'!A7,'אלטשולר שחם'!A:G,5,0)+VLOOKUP('תפוקה מצטברת מול אשתקד'!A7,'מדיהו '!A:G,5,0)+VLOOKUP('תפוקה מצטברת מול אשתקד'!A7,'אנליסט '!A:G,5,0)+VLOOKUP('תפוקה מצטברת מול אשתקד'!A7,'מיטב דש'!A:G,5,0)+VLOOKUP('תפוקה מצטברת מול אשתקד'!A7,אינפניטי!A:G,5,0) -> 1236.72 | J7: =VLOOKUP(A7,הכשרה!A:G,6,0)+VLOOKUP('תפוקה מצטברת מול אשתקד'!A7,מגדל!A:G,6,0)+VLOOKUP('תפוקה מצטברת מול אשתקד'!A7,מנורה!A:G,6,0)+VLOOKUP('תפוקה מצטברת מול אשתקד'!A7,איילון!A:G,6,0)+VLOOKUP(A7,הראל!A:G,6,0)+VLOOKUP('תפוקה מצטברת מול אשתקד'!A7,הפניקס!A:G,6,0)+VLOOKUP('תפוקה מצטברת מול אשתקד'!A7,כלל!A:G,6,0)+VLOOKUP('תפוקה מצטברת מול אשתקד'!A7,מור!A:G,6,0)+VLOOKUP('תפוקה מצטברת מול אשתקד'!A7,'אלטשולר שחם'!A:G,6,0)+VLOOKUP('תפוקה מצטברת מול אשתקד'!A7,'מדיהו '!A:G,6,0)+VLOOKUP('תפוקה מצטברת מול אשתקד'!A7,'אנליסט '!A:G,6,0)+VLOOKUP('תפוקה מצטברת מול אשתקד'!A7,'מיטב דש'!A:G,6,0)+VLOOKUP('תפוקה מצטברת מול אשתקד'!A7,אינפניטי!A:G,6,0) -> 12098.25 | K7: =VLOOKUP(A7,הכשרה!A:G,7,0)+VLOOKUP('תפוקה מצטברת מול אשתקד'!A7,מגדל!A:G,7,0)+VLOOKUP('תפוקה מצטברת מול אשתקד'!A7,מנורה!A:G,7,0)+VLOOKUP('תפוקה מצטברת מול אשתקד'!A7,איילון!A:G,7,0)+VLOOKUP('תפוקה מצטברת מול אשתקד'!A7,הראל!A:G,7,0)+VLOOKUP('תפוקה מצטברת מול אשתקד'!A7,הפניקס!A:G,7,0)+VLOOKUP('תפוקה מצטברת מול אשתקד'!A7,כלל!A:G,7,0)+VLOOKUP('תפוקה מצטברת מול אשתקד'!A7,מור!A:G,7,0)+VLOOKUP('תפוקה מצטברת מול אשתקד'!A7,'אלטשולר שחם'!A:G,7,0)+VLOOKUP('תפוקה מצטברת מול אשתקד'!A7,'מדיהו '!A:K,7,0)+VLOOKUP(A7,'אנליסט '!A:G,7,0)+VLOOKUP('תפוקה מצטברת מול אשתקד'!A7,'מיטב דש'!A:G,7,0)+VLOOKUP('תפוקה מצטברת מול אשתקד'!A7,אינפניטי!A:G,7,0) -> 52586.07 | L7: =VLOOKUP(A7,הכשרה!A:K,8,0)+VLOOKUP('תפוקה מצטברת מול אשתקד'!A7,מגדל!A:K,8,0)+VLOOKUP('תפוקה מצטברת מול אשתקד'!A7,מנורה!A:K,8,0)+VLOOKUP('תפוקה מצטברת מול אשתקד'!A7,איילון!A:K,8,0)+VLOOKUP('תפוקה מצטברת מול אשתקד'!A7,הראל!A:K,8,0)+VLOOKUP('תפוקה מצטברת מול אשתקד'!A7,הפניקס!A:K,8,0)+VLOOKUP('תפוקה מצטברת מול אשתקד'!A7,כלל!A:K,8,0)+VLOOKUP('תפוקה מצטברת מול אשתקד'!A7,מור!A:K,8,0)+VLOOKUP('תפוקה מצטברת מול אשתקד'!A7,'אלטשולר שחם'!A:K,8,0)+VLOOKUP('תפוקה מצטברת מול אשתקד'!A7,'מדיהו '!A:K,8,0)+VLOOKUP('תפוקה מצטברת מול אשתקד'!A7,'אנליסט '!A:K,8,0)+VLOOKUP('תפוקה מצטברת מול אשתקד'!A7,'מיטב דש'!A:K,8,0)+VLOOKUP('תפוקה מצטברת מול אשתקד'!A7,אינפניטי!A:K,8,0) -> 39264.11 | M7: =VLOOKUP(A7,הכשרה!A:K,9,0)+VLOOKUP('תפוקה מצטברת מול אשתקד'!A7,מגדל!A:K,9,0)+VLOOKUP('תפוקה מצטברת מול אשתקד'!A7,מנורה!A:K,9,0)+VLOOKUP('תפוקה מצטברת מול אשתקד'!A7,איילון!A:K,9,0)+VLOOKUP('תפוקה מצטברת מול אשתקד'!A7,הראל!A:K,9,0)+VLOOKUP('תפוקה מצטברת מול אשתקד'!A7,הפניקס!A:K,9,0)+VLOOKUP('תפוקה מצטברת מול אשתקד'!A7,כלל!A:K,9,0)+VLOOKUP('תפוקה מצטברת מול אשתקד'!A7,מור!A:K,9,0)+VLOOKUP('תפוקה מצטברת מול אשתקד'!A7,'אלטשולר שחם'!A:K,9,0)+VLOOKUP('תפוקה מצטברת מול אשתקד'!A7,'מדיהו '!A:K,9,0)+VLOOKUP('תפוקה מצטברת מול אשתקד'!A7,'אנליסט '!A:K,9,0)+VLOOKUP('תפוקה מצטברת מול אשתקד'!A7,'מיטב דש'!A:K,9,0)+VLOOKUP('תפוקה מצטברת מול אשתקד'!A7,אינפניטי!A:K,9,0) -> 747.7 | N7: =VLOOKUP(A7,הכשרה!A:K,10,0)+VLOOKUP('תפוקה מצטברת מול אשתקד'!A7,מגדל!A:K,10,0)+VLOOKUP('תפוקה מצטברת מול אשתקד'!A7,מנורה!A:K,10,0)+VLOOKUP('תפוקה מצטברת מול אשתקד'!A7,איילון!A:K,10,0)+VLOOKUP('תפוקה מצטברת מול אשתקד'!A7,הראל!A:K,10,0)+VLOOKUP('תפוקה מצטברת מול אשתקד'!A7,הפניקס!A:K,10,0)+VLOOKUP('תפוקה מצטברת מול אשתקד'!A7,כלל!A:K,10,0)+VLOOKUP('תפוקה מצטברת מול אשתקד'!A7,מור!A:K,10,0)+VLOOKUP('תפוקה מצטברת מול אשתקד'!A7,'אלטשולר שחם'!A:K,10,0)+VLOOKUP('תפוקה מצטברת מול אשתקד'!A7,'מדיהו '!A:K,10,0)+VLOOKUP('תפוקה מצטברת מול אשתקד'!A7,'אנליסט '!A:K,10,0)+VLOOKUP('תפוקה מצטברת מול אשתקד'!A7,'מיטב דש'!A:K,10,0)+VLOOKUP('תפוקה מצטברת מול אשתקד'!A7,אינפניטי!A:K,10,0) -> 10206.96 | O7: =VLOOKUP(A7,הכשרה!A:K,11,0)+VLOOKUP('תפוקה מצטברת מול אשתקד'!A7,מגדל!A:K,11,0)+VLOOKUP('תפוקה מצטברת מול אשתקד'!A7,מנורה!A:K,11,0)+VLOOKUP('תפוקה מצטברת מול אשתקד'!A7,איילון!A:K,11,0)+VLOOKUP('תפוקה מצטברת מול אשתקד'!A7,הראל!A:K,11,0)+VLOOKUP('תפוקה מצטברת מול אשתקד'!A7,הפניקס!A:K,11,0)+VLOOKUP('תפוקה מצטברת מול אשתקד'!A7,כלל!A:K,11,0)+VLOOKUP('תפוקה מצטברת מול אשתקד'!A7,מור!A:K,11,0)+VLOOKUP('תפוקה מצטברת מול אשתקד'!A7,'אלטשולר שחם'!A:K,11,0)+VLOOKUP('תפוקה מצטברת מול אשתקד'!A7,'מדיהו '!A:K,11,0)+VLOOKUP('תפוקה מצטברת מול אשתקד'!A7,'אנליסט '!A:K,11,0)+VLOOKUP('תפוקה מצטברת מול אשתקד'!A7,'מיטב דש'!A:K,11,0)+VLOOKUP('תפוקה מצטברת מול אשתקד'!A7,אינפניטי!A:K,11,0) -> 104635.53
A8: סה"כ ישיר | D8: =IF(H8=0,0%,IF(L8=0,100%,H8/L8-1)) -> 0.61202352 | E8: =IF(I8=0,0%,IF(M8=0,100%,I8/M8-1)) -> -0.50690169 | F8: =IF(J8=0,0%,IF(N8=0,100%,J8/N8-1)) -> 0.0062359067 | G8: =IF(K8=0,0%,IF(O8=H72,100%,K8/O8-1)) -> 0.78430941 | H8: =SUM(H3:H7) -> 4971214.4 | I8: =SUM(I3:I7) -> 249721.28 | J8: =SUM(J3:J7) -> 13756636 | K8: =SUM(K3:K7) -> 30552415 | L8: =SUM(L3:L7) -> 3083834.9 | M8: =SUM(M3:M7) -> 506433.04 | N8: =SUM(N3:N7) -> 13671382 | O8: =SUM(O3:O7) -> 17122824
A9: בראשית סוכנות לביטוח | B9: יוסי אביב | C9: שותפים | D9: =IF(H9=0,0%,IF(L9=0,100%,H9/L9-1)) -> 9.1455367 | E9: =IF(I9=0,0%,IF(M9=0,100%,I9/M9-1)) -> 13.335289 | F9: =IF(J9=0,0%,IF(N9=0,100%,J9/N9-1)) -> 0 | G9: =IF(K9=0,0%,IF(O9=H32,100%,K9/O9-1)) -> 2.4051968 | H9: =VLOOKUP(A9,הכשרה!A:G,4,0)+VLOOKUP('תפוקה מצטברת מול אשתקד'!A9,מגדל!A:G,4,0)+VLOOKUP('תפוקה מצטברת מול אשתקד'!A9,מנורה!A:G,4,0)+VLOOKUP('תפוקה מצטברת מול אשתקד'!A9,איילון!A:G,4,0)+VLOOKUP('תפוקה מצטברת מול אשתקד'!A9,הראל!A:G,4,0)+VLOOKUP('תפוקה מצטברת מול אשתקד'!A9,הפניקס!A:G,4,0)+VLOOKUP('תפוקה מצטברת מול אשתקד'!A9,כלל!A:G,4,0)+VLOOKUP('תפוקה מצטברת מול אשתקד'!A9,מור!A:G,4,0)+VLOOKUP('תפוקה מצטברת מול אשתקד'!A9,'אלטשולר שחם'!A:G,4,0)+VLOOKUP('תפוקה מצטברת מול אשתקד'!A9,'מדיהו '!A:G,4,0)+VLOOKUP('תפוקה מצטברת מול אשתקד'!A9,'אנליסט '!A:G,4,0)+VLOOKUP('תפוקה מצטברת מול אשתקד'!A9,'מיטב דש'!A:G,4,0)+VLOOKUP('תפוקה מצטברת מול אשתקד'!A9,אינפניטי!A:G,4,0) -> 24918.94 | I9: =VLOOKUP(A9,הכשרה!A:G,5,0)+VLOOKUP('תפוקה מצטברת מול אשתקד'!A9,מגדל!A:G,5,0)+VLOOKUP('תפוקה מצטברת מול אשתקד'!A9,מנורה!A:G,5,0)+VLOOKUP('תפוקה מצטברת מול אשתקד'!A9,איילון!A:G,5,0)+VLOOKUP('תפוקה מצטברת מול אשתקד'!A9,הראל!A:G,5,0)+VLOOKUP('תפוקה מצטברת מול אשתקד'!A9,הפניקס!A:G,5,0)+VLOOKUP('תפוקה מצטברת מול אשתקד'!A9,כלל!A:G,5,0)+VLOOKUP('תפוקה מצטברת מול אשתקד'!A9,מור!A:G,5,0)+VLOOKUP('תפוקה מצטברת מול אשתקד'!A9,'אלטשולר שחם'!A:G,5,0)+VLOOKUP('תפוקה מצטברת מול אשתקד'!A9,'מדיהו '!A:G,5,0)+VLOOKUP('תפוקה מצטברת מול אשתקד'!A9,'אנליסט '!A:G,5,0)+VLOOKUP('תפוקה מצטברת מול אשתקד'!A9,'מיטב דש'!A:G,5,0)+VLOOKUP('תפוקה מצטברת מול אשתקד'!A9,אינפניטי!A:G,5,0) -> 1160.585 | J9: =VLOOKUP(A9,הכשרה!A:G,6,0)+VLOOKUP('תפוקה מצטברת מול אשתקד'!A9,מגדל!A:G,6,0)+VLOOKUP('תפוקה מצטברת מול אשתקד'!A9,מנורה!A:G,6,0)+VLOOKUP('תפוקה מצטברת מול אשתקד'!A9,איילון!A:G,6,0)+VLOOKUP(A9,הראל!A:G,6,0)+VLOOKUP('תפוקה מצטברת מול אשתקד'!A9,הפניקס!A:G,6,0)+VLOOKUP('תפוקה מצטברת מול אשתקד'!A9,כלל!A:G,6,0)+VLOOKUP('תפוקה מצטברת מול אשתקד'!A9,מור!A:G,6,0)+VLOOKUP('תפוקה מצטברת מול אשתקד'!A9,'אלטשולר שחם'!A:G,6,0)+VLOOKUP('תפוקה מצטברת מול אשתקד'!A9,'מדיהו '!A:G,6,0)+VLOOKUP('תפוקה מצטברת מול אשתקד'!A9,'אנליסט '!A:G,6,0)+VLOOKUP('תפוקה מצטברת מול אשתקד'!A9,'מיטב דש'!A:G,6,0)+VLOOKUP('תפוקה מצטברת מול אשתקד'!A9,אינפניטי!A:G,6,0) -> 0 | K9: =VLOOKUP(A9,הכשרה!A:G,7,0)+VLOOKUP('תפוקה מצטברת מול אשתקד'!A9,מגדל!A:G,7,0)+VLOOKUP('תפוקה מצטברת מול אשתקד'!A9,מנורה!A:G,7,0)+VLOOKUP('תפוקה מצטברת מול אשתקד'!A9,איילון!A:G,7,0)+VLOOKUP('תפוקה מצטברת מול אשתקד'!A9,הראל!A:G,7,0)+VLOOKUP('תפוקה מצטברת מול אשתקד'!A9,הפניקס!A:G,7,0)+VLOOKUP('תפוקה מצטברת מול אשתקד'!A9,כלל!A:G,7,0)+VLOOKUP('תפוקה מצטברת מול אשתקד'!A9,מור!A:G,7,0)+VLOOKUP('תפוקה מצטברת מול אשתקד'!A9,'אלטשולר שחם'!A:G,7,0)+VLOOKUP('תפוקה מצטברת מול אשתקד'!A9,'מדיהו '!A:K,7,0)+VLOOKUP(A9,'אנליסט '!A:G,7,0)+VLOOKUP('תפוקה מצטברת מול אשתקד'!A9,'מיטב דש'!A:G,7,0)+VLOOKUP('תפוקה מצטברת מול אשתקד'!A9,אינפניטי!A:G,7,0) -> -191018.6 | L9: =VLOOKUP(A9,הכשרה!A:K,8,0)+VLOOKUP('תפוקה מצטברת מול אשתקד'!A9,מגדל!A:K,8,0)+VLOOKUP('תפוקה מצטברת מול אשתקד'!A9,מנורה!A:K,8,0)+VLOOKUP('תפוקה מצטברת מול אשתקד'!A9,איילון!A:K,8,0)+VLOOKUP('תפוקה מצטברת מול אשתקד'!A9,הראל!A:K,8,0)+VLOOKUP('תפוקה מצטברת מול אשתקד'!A9,הפניקס!A:K,8,0)+VLOOKUP('תפוקה מצטברת מול אשתקד'!A9,כלל!A:K,8,0)+VLOOKUP('תפוקה מצטברת מול אשתקד'!A9,מור!A:K,8,0)+VLOOKUP('תפוקה מצטברת מול אשתקד'!A9,'אלטשולר שחם'!A:K,8,0)+VLOOKUP('תפוקה מצטברת מול אשתקד'!A9,'מדיהו '!A:K,8,0)+VLOOKUP('תפוקה מצטברת מול אשתקד'!A9,'אנליסט '!A:K,8,0)+VLOOKUP('תפוקה מצטברת מול אשתקד'!A9,'מיטב דש'!A:K,8,0)+VLOOKUP('תפוקה מצטברת מול אשתקד'!A9,אינפניטי!A:K,8,0) -> 2456.148 | M9: =VLOOKUP(A9,הכשרה!A:K,9,0)+VLOOKUP('תפוקה מצטברת מול אשתקד'!A9,מגדל!A:K,9,0)+VLOOKUP('תפוקה מצטברת מול אשתקד'!A9,מנורה!A:K,9,0)+VLOOKUP('תפוקה מצטברת מול אשתקד'!A9,איילון!A:K,9,0)+VLOOKUP('תפוקה מצטברת מול אשתקד'!A9,הראל!A:K,9,0)+VLOOKUP('תפוקה מצטברת מול אשתקד'!A9,הפניקס!A:K,9,0)+VLOOKUP('תפוקה מצטברת מול אשתקד'!A9,כלל!A:K,9,0)+VLOOKUP('תפוקה מצטברת מול אשתקד'!A9,מור!A:K,9,0)+VLOOKUP('תפוקה מצטברת מול אשתקד'!A9,'אלטשולר שחם'!A:K,9,0)+VLOOKUP('תפוקה מצטברת מול אשתקד'!A9,'מדיהו '!A:K,9,0)+VLOOKUP('תפוקה מצטברת מול אשתקד'!A9,'אנליסט '!A:K,9,0)+VLOOKUP('תפוקה מצטברת מול אשתקד'!A9,'מיטב דש'!A:K,9,0)+VLOOKUP('תפוקה מצטברת מול אשתקד'!A9,אינפניטי!A:K,9,0) -> 80.96 | N9: =VLOOKUP(A9,הכשרה!A:K,10,0)+VLOOKUP('תפוקה מצטברת מול אשתקד'!A9,מגדל!A:K,10,0)+VLOOKUP('תפוקה מצטברת מול אשתקד'!A9,מנורה!A:K,10,0)+VLOOKUP('תפוקה מצטברת מול אשתקד'!A9,איילון!A:K,10,0)+VLOOKUP('תפוקה מצטברת מול אשתקד'!A9,הראל!A:K,10,0)+VLOOKUP('תפוקה מצטברת מול אשתקד'!A9,הפניקס!A:K,10,0)+VLOOKUP('תפוקה מצטברת מול אשתקד'!A9,כלל!A:K,10,0)+VLOOKUP('תפוקה מצטברת מול אשתקד'!A9,מור!A:K,10,0)+VLOOKUP('תפוקה מצטברת מול אשתקד'!A9,'אלטשולר שחם'!A:K,10,0)+VLOOKUP('תפוקה מצטברת מול אשתקד'!A9,'מדיהו '!A:K,10,0)+VLOOKUP('תפוקה מצטברת מול אשתקד'!A9,'אנליסט '!A:K,10,0)+VLOOKUP('תפוקה מצטברת מול אשתקד'!A9,'מיטב דש'!A:K,10,0)+VLOOKUP('תפוקה מצטברת מול אשתקד'!A9,אינפניטי!A:K,10,0) -> 0 | O9: =VLOOKUP(A9,הכשרה!A:K,11,0)+VLOOKUP('תפוקה מצטברת מול אשתקד'!A9,מגדל!A:K,11,0)+VLOOKUP('תפוקה מצטברת מול אשתקד'!A9,מנורה!A:K,11,0)+VLOOKUP('תפוקה מצטברת מול אשתקד'!A9,איילון!A:K,11,0)+VLOOKUP('תפוקה מצטברת מול אשתקד'!A9,הראל!A:K,11,0)+VLOOKUP('תפוקה מצטברת מול אשתקד'!A9,הפניקס!A:K,11,0)+VLOOKUP('תפוקה מצטברת מול אשתקד'!A9,כלל!A:K,11,0)+VLOOKUP('תפוקה מצטברת מול אשתקד'!A9,מור!A:K,11,0)+VLOOKUP('תפוקה מצטברת מול אשתקד'!A9,'אלטשולר שחם'!A:K,11,0)+VLOOKUP('תפוקה מצטברת מול אשתקד'!A9,'מדיהו '!A:K,11,0)+VLOOKUP('תפוקה מצטברת מול אשתקד'!A9,'אנליסט '!A:K,11,0)+VLOOKUP('תפוקה מצטברת מול אשתקד'!A9,'מיטב דש'!A:K,11,0)+VLOOKUP('תפוקה מצטברת מול אשתקד'!A9,אינפניטי!A:K,11,0) -> -56096.2
A10: גל אלמגור דאוד סוכ' לב | B10: יוסי אביב | C10: שותפים | D10: =IF(H10=0,0%,IF(L10=0,100%,H10/L10-1)) -> 0.00067828809 | E10: =IF(I10=0,0%,IF(M10=0,100%,I10/M10-1)) -> 1.8176875 | F10: =IF(J10=0,0%,IF(N10=0,100%,J10/N10-1)) -> 3.5936342 | G10: =IF(K10=0,0%,IF(O10=H33,100%,K10/O10-1)) -> 4.9954894 | H10: =VLOOKUP(A10,הכשרה!A:G,4,0)+VLOOKUP('תפוקה מצטברת מול אשתקד'!A10,מגדל!A:G,4,0)+VLOOKUP('תפוקה מצטברת מול אשתקד'!A10,מנורה!A:G,4,0)+VLOOKUP('תפוקה מצטברת מול אשתקד'!A10,איילון!A:G,4,0)+VLOOKUP('תפוקה מצטברת מול אשתקד'!A10,הראל!A:G,4,0)+VLOOKUP('תפוקה מצטברת מול אשתקד'!A10,הפניקס!A:G,4,0)+VLOOKUP('תפוקה מצטברת מול אשתקד'!A10,כלל!A:G,4,0)+VLOOKUP('תפוקה מצטברת מול אשתקד'!A10,מור!A:G,4,0)+VLOOKUP('תפוקה מצטברת מול אשתקד'!A10,'אלטשולר שחם'!A:G,4,0)+VLOOKUP('תפוקה מצטברת מול אשתקד'!A10,'מדיהו '!A:G,4,0)+VLOOKUP('תפוקה מצטברת מול אשתקד'!A10,'אנליסט '!A:G,4,0)+VLOOKUP('תפוקה מצטברת מול אשתקד'!A10,'מיטב דש'!A:G,4,0)+VLOOKUP('תפוקה מצטברת מול אשתקד'!A10,אינפניטי!A:G,4,0) -> 505830.12 | I10: =VLOOKUP(A10,הכשרה!A:G,5,0)+VLOOKUP('תפוקה מצטברת מול אשתקד'!A10,מגדל!A:G,5,0)+VLOOKUP('תפוקה מצטברת מול אשתקד'!A10,מנורה!A:G,5,0)+VLOOKUP('תפוקה מצטברת מול אשתקד'!A10,איילון!A:G,5,0)+VLOOKUP('תפוקה מצטברת מול אשתקד'!A10,הראל!A:G,5,0)+VLOOKUP('תפוקה מצטברת מול אשתקד'!A10,הפניקס!A:G,5,0)+VLOOKUP('תפוקה מצטברת מול אשתקד'!A10,כלל!A:G,5,0)+VLOOKUP('תפוקה מצטברת מול אשתקד'!A10,מור!A:G,5,0)+VLOOKUP('תפוקה מצטברת מול אשתקד'!A10,'אלטשולר שחם'!A:G,5,0)+VLOOKUP('תפוקה מצטברת מול אשתקד'!A10,'מדיהו '!A:G,5,0)+VLOOKUP('תפוקה מצטברת מול אשתקד'!A10,'אנליסט '!A:G,5,0)+VLOOKUP('תפוקה מצטברת מול אשתקד'!A10,'מיטב דש'!A:G,5,0)+VLOOKUP('תפוקה מצטברת מול אשתקד'!A10,אינפניטי!A:G,5,0) -> 556306.61 | J10: =VLOOKUP(A10,הכשרה!A:G,6,0)+VLOOKUP('תפוקה מצטברת מול אשתקד'!A10,מגדל!A:G,6,0)+VLOOKUP('תפוקה מצטברת מול אשתקד'!A10,מנורה!A:G,6,0)+VLOOKUP('תפוקה מצטברת מול אשתקד'!A10,איילון!A:G,6,0)+VLOOKUP(A10,הראל!A:G,6,0)+VLOOKUP('תפוקה מצטברת מול אשתקד'!A10,הפניקס!A:G,6,0)+VLOOKUP('תפוקה מצטברת מול אשתקד'!A10,כלל!A:G,6,0)+VLOOKUP('תפוקה מצטברת מול אשתקד'!A10,מור!A:G,6,0)+VLOOKUP('תפוקה מצטברת מול אשתקד'!A10,'אלטשולר שחם'!A:G,6,0)+VLOOKUP('תפוקה מצטברת מול אשתקד'!A10,'מדיהו '!A:G,6,0)+VLOOKUP('תפוקה מצטברת מול אשתקד'!A10,'אנליסט '!A:G,6,0)+VLOOKUP('תפוקה מצטברת מול אשתקד'!A10,'מיטב דש'!A:G,6,0)+VLOOKUP('תפוקה מצטברת מול אשתקד'!A10,אינפניטי!A:G,6,0) -> 309711.71 | K10: =VLOOKUP(A10,הכשרה!A:G,7,0)+VLOOKUP('תפוקה מצטברת מול אשתקד'!A10,מגדל!A:G,7,0)+VLOOKUP('תפוקה מצטברת מול אשתקד'!A10,מנורה!A:G,7,0)+VLOOKUP('תפוקה מצטברת מול אשתקד'!A10,איילון!A:G,7,0)+VLOOKUP('תפוקה מצטברת מול אשתקד'!A10,הראל!A:G,7,0)+VLOOKUP('תפוקה מצטברת מול אשתקד'!A10,הפניקס!A:G,7,0)+VLOOKUP('תפוקה מצטברת מול אשתקד'!A10,כלל!A:G,7,0)+VLOOKUP('תפוקה מצטברת מול אשתקד'!A10,מור!A:G,7,0)+VLOOKUP('תפוקה מצטברת מול אשתקד'!A10,'אלטשולר שחם'!A:G,7,0)+VLOOKUP('תפוקה מצטברת מול אשתקד'!A10,'מדיהו '!A:K,7,0)+VLOOKUP(A10,'אנליסט '!A:G,7,0)+VLOOKUP('תפוקה מצטברת מול אשתקד'!A10,'מיטב דש'!A:G,7,0)+VLOOKUP('תפוקה מצטברת מול אשתקד'!A10,אינפניטי!A:G,7,0) -> 1110431.1 | L10: =VLOOKUP(A10,הכשרה!A:K,8,0)+VLOOKUP('תפוקה מצטברת מול אשתקד'!A10,מגדל!A:K,8,0)+VLOOKUP('תפוקה מצטברת מול אשתקד'!A10,מנורה!A:K,8,0)+VLOOKUP('תפוקה מצטברת מול אשתקד'!A10,איילון!A:K,8,0)+VLOOKUP('תפוקה מצטברת מול אשתקד'!A10,הראל!A:K,8,0)+VLOOKUP('תפוקה מצטברת מול אשתקד'!A10,הפניקס!A:K,8,0)+VLOOKUP('תפוקה מצטברת מול אשתקד'!A10,כלל!A:K,8,0)+VLOOKUP('תפוקה מצטברת מול אשתקד'!A10,מור!A:K,8,0)+VLOOKUP('תפוקה מצטברת מול אשתקד'!A10,'אלטשולר שחם'!A:K,8,0)+VLOOKUP('תפוקה מצטברת מול אשתקד'!A10,'מדיהו '!A:K,8,0)+VLOOKUP('תפוקה מצטברת מול אשתקד'!A10,'אנליסט '!A:K,8,0)+VLOOKUP('תפוקה מצטברת מול אשתקד'!A10,'מיטב דש'!A:K,8,0)+VLOOKUP('תפוקה מצטברת מול אשתקד'!A10,אינפניטי!A:K,8,0) -> 505487.26 | M10: =VLOOKUP(A10,הכשרה!A:K,9,0)+VLOOKUP('תפוקה מצטברת מול אשתקד'!A10,מגדל!A:K,9,0)+VLOOKUP('תפוקה מצטברת מול אשתקד'!A10,מנורה!A:K,9,0)+VLOOKUP('תפוקה מצטברת מול אשתקד'!A10,איילון!A:K,9,0)+VLOOKUP('תפוקה מצטברת מול אשתקד'!A10,הראל!A:K,9,0)+VLOOKUP('תפוקה מצטברת מול אשתקד'!A10,הפניקס!A:K,9,0)+VLOOKUP('תפוקה מצטברת מול אשתקד'!A10,כלל!A:K,9,0)+VLOOKUP('תפוקה מצטברת מול אשתקד'!A10,מור!A:K,9,0)+VLOOKUP('תפוקה מצטברת מול אשתקד'!A10,'אלטשולר שחם'!A:K,9,0)+VLOOKUP('תפוקה מצטברת מול אשתקד'!A10,'מדיהו '!A:K,9,0)+VLOOKUP('תפוקה מצטברת מול אשתקד'!A10,'אנליסט '!A:K,9,0)+VLOOKUP('תפוקה מצטברת מול אשתקד'!A10,'מיטב דש'!A:K,9,0)+VLOOKUP('תפוקה מצטברת מול אשתקד'!A10,אינפניטי!A:K,9,0) -> 197433.75 | N10: =VLOOKUP(A10,הכשרה!A:K,10,0)+VLOOKUP('תפוקה מצטברת מול אשתקד'!A10,מגדל!A:K,10,0)+VLOOKUP('תפוקה מצטברת מול אשתקד'!A10,מנורה!A:K,10,0)+VLOOKUP('תפוקה מצטברת מול אשתקד'!A10,איילון!A:K,10,0)+VLOOKUP('תפוקה מצטברת מול אשתקד'!A10,הראל!A:K,10,0)+VLOOKUP('תפוקה מצטברת מול אשתקד'!A10,הפניקס!A:K,10,0)+VLOOKUP('תפוקה מצטברת מול אשתקד'!A10,כלל!A:K,10,0)+VLOOKUP('תפוקה מצטברת מול אשתקד'!A10,מור!A:K,10,0)+VLOOKUP('תפוקה מצטברת מול אשתקד'!A10,'אלטשולר שחם'!A:K,10,0)+VLOOKUP('תפוקה מצטברת מול אשתקד'!A10,'מדיהו '!A:K,10,0)+VLOOKUP('תפוקה מצטברת מול אשתקד'!A10,'אנליסט '!A:K,10,0)+VLOOKUP('תפוקה מצטברת מול אשתקד'!A10,'מיטב דש'!A:K,10,0)+VLOOKUP('תפוקה מצטברת מול אשתקד'!A10,אינפניטי!A:K,10,0) -> 67421.936 | O10: =VLOOKUP(A10,הכשרה!A:K,11,0)+VLOOKUP('תפוקה מצטברת מול אשתקד'!A10,מגדל!A:K,11,0)+VLOOKUP('תפוקה מצטברת מול אשתקד'!A10,מנורה!A:K,11,0)+VLOOKUP('תפוקה מצטברת מול אשתקד'!A10,איילון!A:K,11,0)+VLOOKUP('תפוקה מצטברת מול אשתקד'!A10,הראל!A:K,11,0)+VLOOKUP('תפוקה מצטברת מול אשתקד'!A10,הפניקס!A:K,11,0)+VLOOKUP('תפוקה מצטברת מול אשתקד'!A10,כלל!A:K,11,0)+VLOOKUP('תפוקה מצטברת מול אשתקד'!A10,מור!A:K,11,0)+VLOOKUP('תפוקה מצטברת מול אשתקד'!A10,'אלטשולר שחם'!A:K,11,0)+VLOOKUP('תפוקה מצטברת מול אשתקד'!A10,'מדיהו '!A:K,11,0)+VLOOKUP('תפוקה מצטברת מול אשתקד'!A10,'אנליסט '!A:K,11,0)+VLOOKUP('תפוקה מצטברת מול אשתקד'!A10,'מיטב דש'!A:K,11,0)+VLOOKUP('תפוקה מצטברת מול אשתקד'!A10,אינפניטי!A:K,11,0) -> 185211.09
