Workbook

Sheet דוח הנהלה
A1: בס"ד
A3: תפוקה מצטברת לפי קבוצות
A4: קבוצה | B4: תפוקה מצטברת 06/2025 | F4: שינוי מול אשתקד % | J4: השגת יעדים מצטבר %
B5: פנסיוני | C5: סיכונים | D5: פיננסים | E5: ניודי פנסיה | F5: פנסיוני | G5: סיכונים | H5: פיננסים | I5: ניודי פנסיה | J5: פנסיוני | K5: סיכונים | L5: פיננסים | M5: ניודי פנסיה
A6: ישירים | B6: ='תפוקה מצטברת מול אשתקד'!H8 -> 7204918.3 | C6: ='תפוקה מצטברת מול אשתקד'!I8 -> 331810.68 | D6: ='תפוקה מצטברת מול אשתקד'!J8 -> 21403334 | E6: ='תפוקה מצטברת מול אשתקד'!K8 -> 45376087 | F6: ='תפוקה מצטברת מול אשתקד'!D8 -> 0.78289238 | G6: ='תפוקה מצטברת מול אשתקד'!E8 -> -0.56157699 | H6: ='תפוקה מצטברת מול אשתקד'!F8 -> 0.20980712 | I6: ='תפוקה מצטברת מול אשתקד'!G8 -> 0.56240353 | J6: ='תפוקה מצטברת מול יעד מצטבר'!D8 -> -0.26927806 | K6: ='תפוקה מצטברת מול יעד מצטבר'!E8 -> -0.65508246 | L6: ='תפוקה מצטברת מול יעד מצטבר'!F8 -> -0.42352581 | M6: ='תפוקה מצטברת מול יעד מצטבר'!G8 -> -0.21540812
A7: חברות בת | B7: ='תפוקה מצטברת מול אשתקד'!H22 -> 3888390.3 | C7: ='תפוקה מצטברת מול אשתקד'!I22 -> 1454969.7 | D7: ='תפוקה מצטברת מול אשתקד'!J22 -> 12759738 | E7: ='תפוקה מצטברת מול אשתקד'!K22 -> 5828149.4 | F7: ='תפוקה מצטברת מול אשתקד'!D22 -> 0.45095014 | G7: ='תפוקה מצטברת מול אשתקד'!E22 -> 0.36779945 | H7: ='תפוקה מצטברת מול אשתקד'!F22 -> -0.27730744 | I7: ='תפוקה מצטברת מול אשתקד'!G22 -> -0.55658729 | J7: ='תפוקה מצטברת מול יעד מצטבר'!D22 -> 0.011179678 | K7: ='תפוקה מצטברת מול יעד מצטבר'!E22 -> -0.035165993 | L7: ='תפוקה מצטברת מול יעד מצטבר'!F22 -> -0.48449668 | M7: ='תפוקה מצטברת מול יעד מצטבר'!G22 -> -0.59855701
A8: סוכני פרימיום | B8: ='תפוקה מצטברת מול אשתקד'!H75 -> 4773890.1 | C8: ='תפוקה מצטברת מול אשתקד'!I75 -> 768736.04 | D8: ='תפוקה מצטברת מול אשתקד'!J75 -> 33678748 | E8: ='תפוקה מצטברת מול אשתקד'!K75 -> 34335143 | F8: ='תפוקה מצטברת מול אשתקד'!D75 -> 0.34713891 | G8: ='תפוקה מצטברת מול אשתקד'!E75 -> 0.13899521 | H8: ='תפוקה מצטברת מול אשתקד'!F75 -> 0.39575842 | I8: ='תפוקה מצטברת מול אשתקד'!G66 -> 0.85746859 | J8: ='תפוקה מצטברת מול יעד מצטבר'!D66 -> -0.61499731 | K8: ='תפוקה מצטברת מול יעד מצטבר'!E66 -> -0.82120508 | L8: ='תפוקה מצטברת מול יעד מצטבר'!F66 -> -0.089485435 | M8: ='תפוקה מצטברת מול יעד מצטבר'!G66 -> -0.22127836
A9: סוכנים ערן | B9: ='תפוקה מצטברת מול אשתקד'!H56 -> 5287150.4 | C9: ='תפוקה מצטברת מול אשתקד'!I56 -> 736281.58 | D9: ='תפוקה מצטברת מול אשתקד'!J56 -> 10134031 | E9: ='תפוקה מצטברת מול אשתקד'!K56 -> 12164368 | F9: ='תפוקה מצטברת מול אשתקד'!D76 -> 0.20375897 | G9: ='תפוקה מצטברת מול אשתקד'!E76 -> -0.073031128 | H9: ='תפוקה מצטברת מול אשתקד'!F76 -> 0.084798074 | I9: ='תפוקה מצטברת מול אשתקד'!G75 -> 0.35475195 | J9: ='תפוקה מצטברת מול יעד מצטבר'!D75 -> 0.11302839 | K9: ='תפוקה מצטברת מול יעד מצטבר'!E75 -> 0.055956092 | L9: ='תפוקה מצטברת מול יעד מצטבר'!F75 -> 0.42936713 | M9: ='תפוקה מצטברת מול יעד מצטבר'!G75 -> 1.8176817
A10: סוכנים איתי | B10: ='תפוקה מצטברת מול אשתקד'!H66 -> 1442528.1 | C10: ='תפוקה מצטברת מול אשתקד'!I66 -> 104130.16 | D10: ='תפוקה מצטברת מול אשתקד'!J66 -> 9968313.5 | E10: ='תפוקה מצטברת מול אשתקד'!K66 -> 7413430 | F10: ='תפוקה מצטברת מול אשתקד'!D77 -> 0 | G10: ='תפוקה מצטברת מול אשתקד'!E77 -> 0 | H10: ='תפוקה מצטברת מול אשתקד'!F77 -> 0 | I10: ='תפוקה מצטברת מול אשתקד'!G76 -> 0.019712706 | J10: ='תפוקה מצטברת מול יעד מצטבר'!D76 -> -0.16738509 | K10: ='תפוקה מצטברת מול יעד מצטבר'!E76 -> -0.29626821 | L10: ='תפוקה מצטברת מול יעד מצטבר'!F76 -> -0.18609405 | M10: ='תפוקה מצטברת מול יעד מצטבר'!G76 -> -0.0002969496
A11: סה"כ מכירות | B11: =SUM(B6:B10) -> 22596877 | C11: =SUM(C6:C10) -> 3395928.1 | D11: =SUM(D6:D10) -> 87944165 | E11: =SUM(E6:E10) -> 1.0511718e+08 | F11: ='תפוקה מצטברת מול אשתקד'!D76 -> 0.20375897 | G11: ='תפוקה מצטברת מול אשתקד'!E76 -> -0.073031128 | H11: ='תפוקה מצטברת מול אשתקד'!F76 -> 0.084798074 | I11: ='תפוקה מצטברת מול יעד מצטבר'!D75 -> 0.11302839 | J11: ='תפוקה מצטברת מול יעד מצטבר'!D76 -> -0.16738509 | K11: ='תפוקה מצטברת מול יעד מצטבר'!E76 -> -0.29626821 | L11: ='תפוקה מצטברת מול יעד מצטבר'!F76 -> -0.18609405 | M11: ='תפוקה מצטברת מול יעד מצטבר'!G76 -> -0.0002969496
A14: תפוקה מצטברת לפי מפקחים
A15: מפקח | B15: תפוקה מצטברת 06/2025 | F15: שינוי מול אשתקד % | J15: השגת יעדים מצטבר % | N15: תפוקה מצטברת 06/2024 | R15: יעדים מצטבר
B16: פנסיוני | C16: סיכונים | D16: פיננסים | E16: ניודי פנסיה | F16: פנסיוני | G16: סיכונים | H16: פיננסים | I16: ניודי פנסיה | J16: פנסיוני | K16: סיכונים | L16: פיננסים | M16: ניודי פנסיה | N16: פנסיוני | O16: סיכונים | P16: פיננסים | Q16: ניודי פנסיה | R16: פנסיוני | S16: סיכונים | T16: פיננסים | U16: ניודי פנסיה
A17: ערן גירוני | B17: =SUMIF('תפוקה מצטברת מול אשתקד'!B:B,'דוח הנהלה'!A17,'תפוקה מצטברת מול אשתקד'!H:H) -> 9693339.7 | C17: =SUMIF('תפוקה מצטברת מול אשתקד'!B:B,'דוח הנהלה'!A17,'תפוקה מצטברת מול אשתקד'!I:I) -> 1461007.7 | D17: =SUMIF('תפוקה מצטברת מול אשתקד'!B:B,'דוח הנהלה'!A17,'תפוקה מצטברת מול אשתקד'!J:J) -> 39669784 | E17: =SUMIF('תפוקה מצטברת מול אשתקד'!B:B,'דוח הנהלה'!A17,'תפוקה מצטברת מול אשתקד'!K:K) -> 42406947 | F17: =(B17-N17)/N17 -> 0.061847789 | G17: =(C17-O17)/O17 -> -0.048186583 | H17: =(D17-P17)/P17 -> 0.29492834 | I17: =(E17-Q17)/Q17 -> -0.23646333 | J17: =(B17-R17)/R17 -> 0.077366941 | K17: =(C17-S17)/S17 -> -0.11087649 | L17: =(D17-T17)/T17 -> 0.32285529 | M17: =(E17-U17)/U17 -> 1.0766952 | N17: =SUMIF('תפוקה מצטברת מול אשתקד'!B:B,'דוח הנהלה'!A17,'תפוקה מצטברת מול אשתקד'!L:L) -> 9128746.9 | O17: =SUMIF('תפוקה מצטברת מול אשתקד'!B:B,'דוח הנהלה'!A17,'תפוקה מצטברת מול אשתקד'!M:M) -> 1534972.8 | P17: =SUMIF('תפוקה מצטברת מול אשתקד'!B:B,'דוח הנהלה'!A17,'תפוקה מצטברת מול אשתקד'!N:N) -> 30634733 | Q17: =SUMIF('תפוקה מצטברת מול אשתקד'!B:B,'דוח הנהלה'!A17,'תפוקה מצטברת מול אשתקד'!O:O) -> 55540158 | R17: =SUMIF('תפוקה מצטברת מול יעד מצטבר'!B:B,'דוח הנהלה'!A17,'תפוקה מצטברת מול יעד מצטבר'!H:K) -> 8997250 | S17: =SUMIF('תפוקה מצטברת מול יעד מצטבר'!B:B,'דוח הנהלה'!A17,'תפוקה מצטברת מול יעד מצטבר'!I:I) -> 1643200 | T17: =SUMIF('תפוקה מצטברת מול יעד מצטבר'!B:B,'דוח הנהלה'!A17,'תפוקה מצטברת מול יעד מצטבר'!J:J) -> 29988000 | U17: =SUMIF('תפוקה מצטברת מול יעד מצטבר'!B:B,'דוח הנהלה'!A17,'תפוקה מצטברת מול יעד מצטבר'!K:K) -> 20420400
A18: לא מפוקחים | B18: =SUMIF('תפוקה מצטברת מול אשתקד'!B:B,'דוח הנהלה'!A18,'תפוקה מצטברת מול אשתקד'!H:H) -> 29942.03 | C18: =SUMIF('תפוקה מצטברת מול אשתקד'!B:B,'דוח הנהלה'!A18,'תפוקה מצטברת מול אשתקד'!I:I) -> 17842.41 | D18: =SUMIF('תפוקה מצטברת מול אשתקד'!B:B,'דוח הנהלה'!A18,'תפוקה מצטברת מול אשתקד'!J:J) -> 0 | E18: =SUMIF('תפוקה מצטברת מול אשתקד'!B:B,'דוח הנהלה'!A18,'תפוקה מצטברת מול אשתקד'!K:K) -> 0 | F18: =(B18-N18)/N18 -> 85.101777 | G18: =(C18-O18)/O18 -> 4.2386367 | H18: 0 | I18: =(E18-Q18)/Q18 -> -1 | J18: =(B18-R18)/R18 -> -0.84816415 | K18: =(C18-S18)/S18 -> -0.65687673 | L18: =(D18-T18)/T18 -> -1 | M18: =(E18-U18)/U18 -> -1 | N18: =SUMIF('תפוקה מצטברת מול אשתקד'!B:B,'דוח הנהלה'!A18,'תפוקה מצטברת מול אשתקד'!L:L) -> 347.75159 | O18: =SUMIF('תפוקה מצטברת מול אשתקד'!B:B,'דוח הנהלה'!A18,'תפוקה מצטברת מול אשתקד'!M:M) -> 3405.9262 | P18: =SUMIF('תפוקה מצטברת מול אשתקד'!B:B,'דוח הנהלה'!A18,'תפוקה מצטברת מול אשתקד'!N:N) -> 0 | Q18: =SUMIF('תפוקה מצטברת מול אשתקד'!B:B,'דוח הנהלה'!A18,'תפוקה מצטברת מול אשתקד'!O:O) -> -168129.66 | R18: =SUMIF('תפוקה מצטברת מול יעד מצטבר'!B:B,'דוח הנהלה'!A18,'תפוקה מצטברת מול יעד מצטבר'!H:H) -> 197200 | S18: =SUMIF('תפוקה מצטברת מול יעד מצטבר'!B:B,'דוח הנהלה'!A18,'תפוקה מצטברת מול יעד מצטבר'!I:I) -> 52000 | T18: =SUMIF('תפוקה מצטברת מול יעד מצטבר'!B:B,'דוח הנהלה'!A18,'תפוקה מצטברת מול יעד מצטבר'!J:J) -> 476000 | U18: =SUMIF('תפוקה מצטברת מול יעד מצטבר'!B:B,'דוח הנהלה'!A18,'תפוקה מצטברת מול יעד מצטבר'!K:K) -> 476000
A19: יוסי אביב | B19: =SUMIF('תפוקה מצטברת מול אשתקד'!B:B,'דוח הנהלה'!A19,'תפוקה מצטברת מול אשתקד'!H:H) -> 11431067 | C19: =SUMIF('תפוקה מצטברת מול אשתקד'!B:B,'דוח הנהלה'!A19,'תפוקה מצטברת מול אשתקד'!I:I) -> 1812947.8 | D19: =SUMIF('תפוקה מצטברת מול אשתקד'!B:B,'דוח הנהלה'!A19,'תפוקה מצטברת מול אשתקד'!J:J) -> 38306068 | E19: =SUMIF('תפוקה מצטברת מול אשתקד'!B:B,'דוח הנהלה'!A19,'תפוקה מצטברת מול אשתקד'!K:K) -> 55296799 | F19: =(B19-N19)/N19 -> 0.65162459 | G19: =(C19-O19)/O19 -> -0.021725787 | H19: =(D19-P19)/P19 -> -0.058823459 | I19: =(E19-Q19)/Q19 -> 0.26473872 | J19: =(B19-R19)/R19 -> -0.19490454 | K19: =(C19-S19)/S19 -> -0.28848202 | L19: =(D19-T19)/T19 -> -0.42517906 | M19: =(E19-U19)/U19 -> -0.26006531 | N19: =SUMIF('תפוקה מצטברת מול אשתקד'!B:B,'דוח הנהלה'!A19,'תפוקה מצטברת מול אשתקד'!L:L) -> 6921105.1 | O19: =SUMIF('תפוקה מצטברת מול אשתקד'!B:B,'דוח הנהלה'!A19,'תפוקה מצטברת מול אשתקד'!M:M) -> 1853210.3 | P19: =SUMIF('תפוקה מצטברת מול אשתקד'!B:B,'דוח הנהלה'!A19,'תפוקה מצטברת מול אשתקד'!N:N) -> 40700194 | Q19: =SUMIF('תפוקה מצטברת מול אשתקד'!B:B,'דוח הנהלה'!A19,'תפוקה מצטברת מול אשתקד'!O:O) -> 43721915 | R19: =SUMIF('תפוקה מצטברת מול יעד מצטבר'!B:B,'דוח הנהלה'!A19,'תפוקה מצטברת מול יעד מצטבר'!H:H) -> 14198400 | S19: =SUMIF('תפוקה מצטברת מול יעד מצטבר'!B:B,'דוח הנהלה'!A19,'תפוקה מצטברת מול יעד מצטבר'!I:I) -> 2548000 | T19: =SUMIF('תפוקה מצטברת מול יעד מצטבר'!B:B,'דוח הנהלה'!A19,'תפוקה מצטברת מול יעד מצטבר'!J:J) -> 66640000 | U19: =SUMIF('תפוקה מצטברת מול יעד מצטבר'!B:B,'דוח הנהלה'!A19,'תפוקה מצטברת מול יעד מצטבר'!K:K) -> 74732000
A20: איתי אדן | B20: =SUMIF('תפוקה מצטברת מול אשתקד'!B:B,'דוח הנהלה'!A20,'תפוקה מצטברת מול אשתקד'!H:H) -> 1442528.1 | C20: =SUMIF('תפוקה מצטברת מול אשתקד'!B:B,'דוח הנהלה'!A20,'תפוקה מצטברת מול אשתקד'!I:I) -> 104130.16 | D20: =SUMIF('תפוקה מצטברת מול אשתקד'!B:B,'דוח הנהלה'!A20,'תפוקה מצטברת מול אשתקד'!J:J) -> 9968313.5 | E20: =SUMIF('תפוקה מצטברת מול אשתקד'!B:B,'דוח הנהלה'!A20,'תפוקה מצטברת מול אשתקד'!K:K) -> 7413430 | F20: =(B20-N20)/N20 -> -0.46999564 | G20: =(C20-O20)/O20 -> -0.61700924 | H20: =(D20-P20)/P20 -> 0.023998966 | I20: =(E20-Q20)/Q20 -> 0.85746859 | J20: =(B20-R20)/R20 -> -0.61499731 | K20: =(C20-S20)/S20 -> -0.82120508 | L20: =(D20-T20)/T20 -> -0.089485435 | M20: =(E20-U20)/U20 -> -0.22127836 | N20: =SUMIF('תפוקה מצטברת מול אשתקד'!B:B,'דוח הנהלה'!A20,'תפוקה מצטברת מול אשתקד'!L:L) -> 2721728.7 | O20: =SUMIF('תפוקה מצטברת מול אשתקד'!B:B,'דוח הנהלה'!A20,'תפוקה מצטברת מול אשתקד'!M:M) -> 271886.87 | P20: =SUMIF('תפוקה מצטברת מול אשתקד'!B:B,'דוח הנהלה'!A20,'תפוקה מצטברת מול אשתקד'!N:N) -> 9734690.9 | Q20: =SUMIF('תפוקה מצטברת מול אשתקד'!B:B,'דוח הנהלה'!A20,'תפוקה מצטברת מול אשתקד'!O:O) -> 3991146.9 | R20: =SUMIF('תפוקה מצטברת מול יעד מצטבר'!B:B,'דוח הנהלה'!A20,'תפוקה מצטברת מול יעד מצטבר'!H:H) -> 3746800 | S20: =SUMIF('תפוקה מצטברת מול יעד מצטבר'!B:B,'דוח הנהלה'!A20,'תפוקה מצטברת מול יעד מצטבר'!I:I) -> 582400 | T20: =SUMIF('תפוקה מצטברת מול יעד מצטבר'!B:B,'דוח הנהלה'!A20,'תפוקה מצטברת מול יעד מצטבר'!J:J) -> 10948000 | U20: =SUMIF('תפוקה מצטברת מול יעד מצטבר'!B:B,'דוח הנהלה'!A20,'תפוקה מצטברת מול יעד מצטבר'!K:K) -> 9520000
B21: =SUM(B17:B20) -> 22596877 | C21: =SUM(C17:C20) -> 3395928.1 | D21: =SUM(D17:D20) -> 87944165 | E21: =SUM(E17:E20) -> 1.0511718e+08 | F21: =(B21-N21)/N21 -> 0.20375897 | G21: =(C21-O21)/O21 -> -0.073031128 | H21: =(D21-P21)/P21 -> 0.084798074 | I21: =(B21-R21)/R21 -> -0.16738509 | J21: =(B21-R21)/R21 -> -0.16738509 | K21: =(C21-S21)/S21 -> -0.29626821 | L21: =(D21-T21)/T21 -> -0.18609405 | M21: =(E21-U21)/U21 -> -0.0002969496 | N21: =SUM(N17:N20) -> 18771928 | O21: =SUM(O17:O20) -> 3663475.9 | P21: =SUM(P17:P20) -> 81069618 | Q21: =SUM(Q17:Q20) -> 1.0308509e+08 | R21: =SUM(R17:R20) -> 27139650 | S21: =SUM(S17:S20) -> 4825600 | T21: =SUM(T17:T20) -> 108052000 | U21: =SUM(U17:U20) -> 105148400
A25: תפוקה מצטברת לפי חברות | R25: עולים בולטים
A26: קבוצה | B26: תפוקה מצטברת 06/2025 | F26: שינוי מול אשתקד % | R26: סוכן | S26: שינוי % מול תקופה חופפת אשתקד | T26: עליה מול תקופה חופפת אשתקד | U26: תפוקה מצטברת - 2024
B27: פנסיוני | C27: סיכונים | D27: פיננסים | E27: ניודי פנסיה | F27: פנסיוני | G27: סיכונים | H27: פיננסים | I27: ניודי פנסיה | R27: אלרם סוכנות לביטוח | S27: 0.50577806 | T27: 72482.853 | U27: 215792.45
A28: מנורה | B28: =מנורה!D76 -> 3151388.5 | C28: =מנורה!E76 -> 800939.37 | D28: =מנורה!F76 -> 3449865.8 | E28: =מנורה!G76 -> -4300781.8 | F28: =מנורה!D76/מנורה!H76-1 -> 0.14236488 | G28: =מנורה!E76/מנורה!I76-1 -> -0.10480779 | H28: =מנורה!F76/מנורה!J76-1 -> -0.52028454 | I28: =מנורה!G76/מנורה!K76-1 -> -1.3059468 | R28: שלי מזרחי | S28: 0.098120259 | T28: 34397.555 | U28: 384962.83
A29: מגדל | B29: =מגדל!D76 -> 12507529 | C29: =מגדל!E76 -> 618564.33 | D29: =מגדל!F76 -> 35895361 | E29: =מגדל!G76 -> 92537772 | F29: =מגדל!D76/מגדל!H76-1 -> 0.57816086 | G29: =מגדל!E76/מגדל!I76-1 -> 0.20657803 | H29: =מגדל!F76/מגדל!J76-1 -> 0.54842989 | I29: =מגדל!G76/מגדל!K76-1 -> 1.1867395 | R29: רותי | S29: 1 | T29: 47762.664 | U29: 47762.664
A30: כלל | B30: =כלל!D76 -> 3764122.3 | C30: =כלל!E76 -> 1080218.3 | D30: =כלל!F76 -> 14135034 | E30: =כלל!G76 -> 8594073.5 | F30: =כלל!D76/כלל!H76-1 -> -0.25136318 | G30: =כלל!E76/כלל!I76-1 -> 0.23550227 | H30: =כלל!F76/כלל!J76-1 -> 0.19620244 | I30: =כלל!G76/כלל!K76-1 -> -0.76357797 | R30: גל אלמגור דאוד סוכ' לב | S30: 0.69984511 | T30: 330261.05 | U30: 802166.97
A31: אלטשולר שחם | B31: ='אלטשולר שחם'!D76 -> 12000 | C31: ='אלטשולר שחם'!E76 -> 0 | D31: ='אלטשולר שחם'!F76 -> 243273.06 | E31: ='אלטשולר שחם'!G76 -> 0 | F31: 1 | G31: 0 | H31: ='אלטשולר שחם'!F76/'אלטשולר שחם'!J76-1 -> 1.5222712 | I31: 0 | R31: גולדר אבי | S31: 6.3252763 | T31: 52841.261 | U31: 61195.246
A32: מור | B32: =מור!D76 -> 0 | C32: =מור!E76 -> 0 | D32: =מור!F76 -> 1507099.4 | E32: =מור!G76 -> 0 | F32: 0 | G32: 0 | H32: =מור!F76/מור!J76-1 -> -0.56833853 | I32: 0
A33: הראל | B33: =הראל!D76 -> 1258477 | C33: =הראל!E76 -> 434795 | D33: =הראל!F76 -> 2089048 | E33: =הראל!G76 -> 845855 | F33: =הראל!D76/הראל!H76-1 -> -0.44481299 | G33: =הראל!E76/הראל!I76-1 -> -0.40642702 | H33: =הראל!F76/הראל!J76-1 -> -0.67499025 | I33: =הראל!G76/הראל!K76-1 -> -0.84401275
A34: הפניקס | B34: =הפניקס!D76 -> 1902110.6 | C34: =הפניקס!E76 -> 139945.21 | D34: =הפניקס!F76 -> 12507946 | E34: =הפניקס!G76 -> 7440258 | F34: =הפניקס!D76/הפניקס!H76-1 -> 1.401073 | G34: =הפניקס!E76/הפניקס!I76-1 -> -0.41003175 | H34: =הפניקס!F76/הפניקס!J76-1 -> 0.58490611 | I34: =הפניקס!G76/הפניקס!K76-1 -> 0.50705252
A35: איילון | B35: =איילון!D76 -> 1250 | C35: =איילון!E76 -> 301886.92 | D35: =איילון!F76 -> 0 | E35: =איילון!G76 -> 0 | F35: 1 | G35: =איילון!E76/איילון!I76-1 -> -0.25825918 | H35: 0 | I35: 0
A36: הכשרה | B36: =הכשרה!D76 -> 0 | C36: =הכשרה!E76 -> 2710 | D36: =הכשרה!F76 -> 0 | E36: =הכשרה!G76 -> 0 | F36: 0 | G36: =הכשרה!E76/הכשרה!I76-1 -> -0.093645485 | H36: 1 | I36: 0 | R36: יורדים בולטים
A37: מדיהו | B37: ='מדיהו '!D76 -> 0 | C37: ='מדיהו '!E76 -> 16869 | D37: ='מדיהו '!F76 -> 0 | E37: ='מדיהו '!G76 -> 0 | F37: 0 | G37: ='מדיהו '!E76/'מדיהו '!I76-1 -> 7.079023 | H37: 0 | I37: 0 | R37: סוכן | S37: שינוי % מול תקופה חופפת אשתקד | T37: ירידה מול תקופה חופפת אשתקד | U37: תפוקה מצטברת - 2024
A38: אנליסט | B38: ='אנליסט '!D76 -> 0 | C38: ='אנליסט '!E76 -> 0 | D38: ='אנליסט '!F76 -> 18116538 | E38: ='אנליסט '!G76 -> 0 | F38: 0 | G38: 0 | H38: ='אנליסט '!F76/'אנליסט '!J76-1 -> -0.13617071 | I38: 0 | R38: דאי גדי | S38: -0.41942988 | T38: -138690.45 | U38: 191973.76
A39: מיטב דש | B39: ='מיטב דש'!D76 -> 0 | C39: ='מיטב דש'!E76 -> 0 | D39: ='מיטב דש'!F76 -> 0 | E39: ='מיטב דש'!G76 -> 0 | F39: 0 | G39: 0 | H39: 0 | I39: 0 | R39: גל אלמגור סוכ | S39: -0.56 | T39: -502390.89 | U39: 244728.18
A40: אינפניטי | B40: =אינפניטי!D76 -> 0 | C40: =אינפניטי!E76 -> 0 | D40: =אינפניטי!F76 -> 0 | E40: =אינפניטי!G76 -> 0 | F40: 0 | G40: 0 | H40: 0 | I40: 0 | R40: אביב מור יוסף | S40: -0.72531856 | T40: -76929.916 | U40: 29133.71
A41: סה"כ | B41: =SUM(B28:B40) -> 22596877 | C41: =SUM(C28:C40) -> 3395928.1 | D41: =SUM(D28:D40) -> 87944165 | E41: =SUM(E28:E40) -> 1.0511718e+08 | F41: =('תפוקה מצטברת מול אשתקד'!H76-'תפוקה מצטברת מול אשתקד'!L76)/'תפוקה מצטברת מול אשתקד'!L76 -> 0.20375897 | G41: =('תפוקה מצטברת מול אשתקד'!I76-'תפוקה מצטברת מול אשתקד'!M76)/'תפוקה מצטברת מול אשתקד'!M76 -> -0.073031128 | H41: =('תפוקה מצטברת מול אשתקד'!J76-'תפוקה מצטברת מול אשתקד'!N76)/'תפוקה מצטברת מול אשתקד'!N76 -> 0.084798074 | I41: =('תפוקה מצטברת מול אשתקד'!K76-'תפוקה מצטברת מול אשתקד'!O76)/'תפוקה מצטברת מול אשתקד'!O76 -> 0.019712706 | R41: גול זאב | S41: -0.93571864 | T41: -115972.94 | U41: 7967.03
R42: משה שטרן גל אלמגור | S42: -0.3318262 | T42: -68976.856 | U42: 138893.58

Sheet תפוקה מצטברת מול אשתקד
D1: שינוי מול אשתקד % | H1: תפוקה מצטברת 06/2025 | L1: תפוקה מצטברת 06/2024
A2: שם סוכן | B2: מפקח | C2: מחלקה | D2: פנסיוני | E2: סיכונים | F2: פיננסים | G2: ניודי פנסיה | H2: פנסיוני | I2: סיכונים | J2: פיננסים | K2: ניודי פנסיה | L2: פנסיוני | M2: סיכונים | N2: פיננסים | O2: ניודי פנסיה
A3: גל אלמגור סוכ | B3: יוסי אביב | C3: ישירים | D3: =IF(H3=0,0%,IF(L3=0,100%,H3/L3-1)) -> 1.0391678 | E3: =IF(I3=0,0%,IF(M3=0,100%,I3/M3-1)) -> -0.67243752 | F3: =IF(J3=0,0%,IF(N3=G29,100%,J3/N3-1)) -> 0.72840362 | G3: =IF(K3=0,0%,IF(O3=H29,100%,K3/O3-1)) -> 0.97258296 | H3: =VLOOKUP(A3,הכשרה!A:G,4,0)+VLOOKUP('תפוקה מצטברת מול אשתקד'!A3,מגדל!A:G,4,0)+VLOOKUP('תפוקה מצטברת מול אשתקד'!A3,מנורה!A:G,4,0)+VLOOKUP('תפוקה מצטברת מול אשתקד'!A3,איילון!A:G,4,0)+VLOOKUP('תפוקה מצטברת מול אשתקד'!A3,הראל!A:G,4,0)+VLOOKUP('תפוקה מצטברת מול אשתקד'!A3,הפניקס!A:G,4,0)+VLOOKUP('תפוקה מצטברת מול אשתקד'!A3,כלל!A:G,4,0)+VLOOKUP('תפוקה מצטברת מול אשתקד'!A3,מור!A:G,4,0)+VLOOKUP('תפוקה מצטברת מול אשתקד'!A3,'אלטשולר שחם'!A:G,4,0)+VLOOKUP('תפוקה מצטברת מול אשתקד'!A3,'מדיהו '!A:G,4,0)+VLOOKUP('תפוקה מצטברת מול אשתקד'!A3,'אנליסט '!A:G,4,0)+VLOOKUP('תפוקה מצטברת מול אשתקד'!A3,'מיטב דש'!A:G,4,0)+VLOOKUP('תפוקה מצטברת מול אשתקד'!A3,אינפניטי!A:G,4,0) -> 6757134.2 | I3: =VLOOKUP(A3,הכשרה!A:G,5,0)+VLOOKUP('תפוקה מצטברת מול אשתקד'!A3,מגדל!A:G,5,0)+VLOOKUP('תפוקה מצטברת מול אשתקד'!A3,מנורה!A:G,5,0)+VLOOKUP('תפוקה מצטברת מול אשתקד'!A3,איילון!A:G,5,0)+VLOOKUP('תפוקה מצטברת מול אשתקד'!A3,הראל!A:G,5,0)+VLOOKUP('תפוקה מצטברת מול אשתקד'!A3,הפניקס!A:G,5,0)+VLOOKUP('תפוקה מצטברת מול אשתקד'!A3,כלל!A:G,5,0)+VLOOKUP('תפוקה מצטברת מול אשתקד'!A3,מור!A:G,5,0)+VLOOKUP('תפוקה מצטברת מול אשתקד'!A3,'אלטשולר שחם'!A:G,5,0)+VLOOKUP('תפוקה מצטברת מול אשתקד'!A3,'מדיהו '!A:G,5,0)+VLOOKUP('תפוקה מצטברת מול אשתקד'!A3,'אנליסט '!A:G,5,0)+VLOOKUP('תפוקה מצטברת מול אשתקד'!A3,'מיטב דש'!A:G,5,0)+VLOOKUP('תפוקה מצטברת מול אשתקד'!A3,אינפניטי!A:G,5,0) -> 244728.18 | J3: =VLOOKUP(A3,הכשרה!A:G,6,0)+VLOOKUP('תפוקה מצטברת מול אשתקד'!A3,מגדל!A:G,6,0)+VLOOKUP('תפוקה מצטברת מול אשתקד'!A3,מנורה!A:G,6,0)+VLOOKUP('תפוקה מצטברת מול אשתקד'!A3,איילון!A:G,6,0)+VLOOKUP(A3,הראל!A:G,6,0)+VLOOKUP('תפוקה מצטברת מול אשתקד'!A3,הפניקס!A:G,6,0)+VLOOKUP('תפוקה מצטברת מול אשתקד'!A3,כלל!A:G,6,0)+VLOOKUP('תפוקה מצטברת מול אשתקד'!A3,מור!A:G,6,0)+VLOOKUP('תפוקה מצטברת מול אשתקד'!A3,'אלטשולר שחם'!A:G,6,0)+VLOOKUP('תפוקה מצטברת מול אשתקד'!A3,'מדיהו '!A:G,6,0)+VLOOKUP('תפוקה מצטברת מול אשתקד'!A3,'אנליסט '!A:G,6,0)+VLOOKUP('תפוקה מצטברת מול אשתקד'!A3,'מיטב דש'!A:G,6,0)+VLOOKUP('תפוקה מצטברת מול אשתקד'!A3,אינפניטי!A:G,6,0) -> 18040301 | K3: =VLOOKUP(A3,הכשרה!A:G,7,0)+VLOOKUP('תפוקה מצטברת מול אשתקד'!A3,מגדל!A:G,7,0)+VLOOKUP('תפוקה מצטברת מול אשתקד'!A3,מנורה!A:G,7,0)+VLOOKUP('תפוקה מצטברת מול אשתקד'!A3,איילון!A:G,7,0)+VLOOKUP('תפוקה מצטברת מול אשתקד'!A3,הראל!A:G,7,0)+VLOOKUP('תפוקה מצטברת מול אשתקד'!A3,הפניקס!A:G,7,0)+VLOOKUP('תפוקה מצטברת מול אשתקד'!A3,כלל!A:G,7,0)+VLOOKUP('תפוקה מצטברת מול אשתקד'!A3,מור!A:G,7,0)+VLOOKUP('תפוקה מצטברת מול אשתקד'!A3,'אלטשולר שחם'!A:G,7,0)+VLOOKUP('תפוקה מצטברת מול אשתקד'!A3,'מדיהו '!A:K,7,0)+VLOOKUP(A3,'אנליסט '!A:G,7,0)+VLOOKUP('תפוקה מצטברת מול אשתקד'!A3,'מיטב דש'!A:G,7,0)+VLOOKUP('תפוקה מצטברת מול אשתקד'!A3,אינפניטי!A:G,7,0) -> 43938898 | L3: =VLOOKUP(A3,הכשרה!A:K,8,0)+VLOOKUP('תפוקה מצטברת מול אשתקד'!A3,מגדל!A:K,8,0)+VLOOKUP('תפוקה מצטברת מול אשתקד'!A3,מנורה!A:K,8,0)+VLOOKUP('תפוקה מצטברת מול אשתקד'!A3,איילון!A:K,8,0)+VLOOKUP('תפוקה מצטברת מול אשתקד'!A3,הראל!A:K,8,0)+VLOOKUP('תפוקה מצטברת מול אשתקד'!A3,הפניקס!A:K,8,0)+VLOOKUP('תפוקה מצטברת מול אשתקד'!A3,כלל!A:K,8,0)+VLOOKUP('תפוקה מצטברת מול אשתקד'!A3,מור!A:K,8,0)+VLOOKUP('תפוקה מצטברת מול אשתקד'!A3,'אלטשולר שחם'!A:K,8,0)+VLOOKUP('תפוקה מצטברת מול אשתקד'!A3,'מדיהו '!A:K,8,0)+VLOOKUP('תפוקה מצטברת מול אשתקד'!A3,'אנליסט '!A:K,8,0)+VLOOKUP('תפוקה מצטברת מול אשתקד'!A3,'מיטב דש'!A:K,8,0)+VLOOKUP('תפוקה מצטברת מול אשתקד'!A3,אינפניטי!A:K,8,0) -> 3313672.4 | M3: =VLOOKUP(A3,הכשרה!A:K,9,0)+VLOOKUP('תפוקה מצטברת מול אשתקד'!A3,מגדל!A:K,9,0)+VLOOKUP('תפוקה מצטברת מול אשתקד'!A3,מנורה!A:K,9,0)+VLOOKUP('תפוקה מצטברת מול אשתקד'!A3,איילון!A:K,9,0)+VLOOKUP('תפוקה מצטברת מול אשתקד'!A3,הראל!A:K,9,0)+VLOOKUP('תפוקה מצטברת מול אשתקד'!A3,הפניקס!A:K,9,0)+VLOOKUP('תפוקה מצטברת מול אשתקד'!A3,כלל!A:K,9,0)+VLOOKUP('תפוקה מצטברת מול אשתקד'!A3,מור!A:K,9,0)+VLOOKUP('תפוקה מצטברת מול אשתקד'!A3,'אלטשולר שחם'!A:K,9,0)+VLOOKUP('תפוקה מצטברת מול אשתקד'!A3,'מדיהו '!A:K,9,0)+VLOOKUP('תפוקה מצטברת מול אשתקד'!A3,'אנליסט '!A:K,9,0)+VLOOKUP('תפוקה מצטברת מול אשתקד'!A3,'מיטב דש'!A:K,9,0)+VLOOKUP('תפוקה מצטברת מול אשתקד'!A3,אינפניטי!A:K,9,0) -> 747119.06 | N3: =VLOOKUP(A3,הכשרה!A:K,10,0)+VLOOKUP('תפוקה מצטברת מול אשתקד'!A3,מגדל!A:K,10,0)+VLOOKUP('תפוקה מצטברת מול אשתקד'!A3,מנורה!A:K,10,0)+VLOOKUP('תפוקה מצטברת מול אשתקד'!A3,איילון!A:K,10,0)+VLOOKUP('תפוקה מצטברת מול אשתקד'!A3,הראל!A:K,10,0)+VLOOKUP('תפוקה מצטברת מול אשתקד'!A3,הפניקס!A:K,10,0)+VLOOKUP('תפוקה מצטברת מול אשתקד'!A3,כלל!A:K,10,0)+VLOOKUP('תפוקה מצטברת מול אשתקד'!A3,מור!A:K,10,0)+VLOOKUP('תפוקה מצטברת מול אשתקד'!A3,'אלטשולר שחם'!A:K,10,0)+VLOOKUP('תפוקה מצטברת מול אשתקד'!A3,'מדיהו '!A:K,10,0)+VLOOKUP('תפוקה מצטברת מול אשתקד'!A3,'אנליסט '!A:K,10,0)+VLOOKUP('תפוקה מצטברת מול אשתקד'!A3,'מיטב דש'!A:K,10,0)+VLOOKUP('תפוקה מצטברת מול אשתקד'!A3,אינפניטי!A:K,10,0) -> 10437551 | O3: =VLOOKUP(A3,הכשרה!A:K,11,0)+VLOOKUP('תפוקה מצטברת מול אשתקד'!A3,מגדל!A:K,11,0)+VLOOKUP('תפוקה מצטברת מול אשתקד'!A3,מנורה!A:K,11,0)+VLOOKUP('תפוקה מצטברת מול אשתקד'!A3,איילון!A:K,11,0)+VLOOKUP('תפוקה מצטברת מול אשתקד'!A3,הראל!A:K,11,0)+VLOOKUP('תפוקה מצטברת מול אשתקד'!A3,הפניקס!A:K,11,0)+VLOOKUP('תפוקה מצטברת מול אשתקד'!A3,כלל!A:K,11,0)+VLOOKUP('תפוקה מצטברת מול אשתקד'!A3,מור!A:K,11,0)+VLOOKUP('תפוקה מצטברת מול אשתקד'!A3,'אלטשולר שחם'!A:K,11,0)+VLOOKUP('תפוקה מצטברת מול אשתקד'!A3,'מדיהו '!A:K,11,0)+VLOOKUP('תפוקה מצטברת מול אשתקד'!A3,'אנליסט '!A:K,11,0)+VLOOKUP('תפוקה מצטברת מול אשתקד'!A3,'מיטב דש'!A:K,11,0)+VLOOKUP('תפוקה מצטברת מול אשתקד'!A3,אינפניטי!A:K,11,0) -> 22274804
A4: דניאלה אביב | B4: יוסי אביב | C4: ישירים | D4: =IF(H4=0,0%,IF(L4=0,100%,H4/L4-1)) -> -0.39036176 | E4: =IF(I4=0,0%,IF(M4=0,100%,I4/M4-1)) -> -0.42309205 | F4: =IF(J4=0,0%,IF(N4=0,100%,J4/N4-1)) -> -0.64992809 | G4: =IF(K4=0,0%,IF(O4=H30,100%,K4/O4-1)) -> -0.77627579 | H4: =VLOOKUP(A4,הכשרה!A:G,4,0)+VLOOKUP('תפוקה מצטברת מול אשתקד'!A4,מגדל!A:G,4,0)+VLOOKUP('תפוקה מצטברת מול אשתקד'!A4,מנורה!A:G,4,0)+VLOOKUP('תפוקה מצטברת מול אשתקד'!A4,איילון!A:G,4,0)+VLOOKUP('תפוקה מצטברת מול אשתקד'!A4,הראל!A:G,4,0)+VLOOKUP('תפוקה מצטברת מול אשתקד'!A4,הפניקס!A:G,4,0)+VLOOKUP('תפוקה מצטברת מול אשתקד'!A4,כלל!A:G,4,0)+VLOOKUP('תפוקה מצטברת מול אשתקד'!A4,מור!A:G,4,0)+VLOOKUP('תפוקה מצטברת מול אשתקד'!A4,'אלטשולר שחם'!A:G,4,0)+VLOOKUP('תפוקה מצטברת מול אשתקד'!A4,'מדיהו '!A:G,4,0)+VLOOKUP('תפוקה מצטברת מול אשתקד'!A4,'אנליסט '!A:G,4,0)+VLOOKUP('תפוקה מצטברת מול אשתקד'!A4,'מיטב דש'!A:G,4,0)+VLOOKUP('תפוקה מצטברת מול אשתקד'!A4,אינפניטי!A:G,4,0) -> 419302.97 | I4: =VLOOKUP(A4,הכשרה!A:G,5,0)+VLOOKUP('תפוקה מצטברת מול אשתקד'!A4,מגדל!A:G,5,0)+VLOOKUP('תפוקה מצטברת מול אשתקד'!A4,מנורה!A:G,5,0)+VLOOKUP('תפוקה מצטברת מול אשתקד'!A4,איילון!A:G,5,0)+VLOOKUP('תפוקה מצטברת מול אשתקד'!A4,הראל!A:G,5,0)+VLOOKUP('תפוקה מצטברת מול אשתקד'!A4,הפניקס!A:G,5,0)+VLOOKUP('תפוקה מצטברת מול אשתקד'!A4,כלל!A:G,5,0)+VLOOKUP('תפוקה מצטברת מול אשתקד'!A4,מור!A:G,5,0)+VLOOKUP('תפוקה מצטברת מול אשתקד'!A4,'אלטשולר שחם'!A:G,5,0)+VLOOKUP('תפוקה מצטברת מול אשתקד'!A4,'מדיהו '!A:G,5,0)+VLOOKUP('תפוקה מצטברת מול אשתקד'!A4,'אנליסט '!A:G,5,0)+VLOOKUP('תפוקה מצטברת מול אשתקד'!A4,'מיטב דש'!A:G,5,0)+VLOOKUP('תפוקה מצטברת מול אשתקד'!A4,אינפניטי!A:G,5,0) -> 3936.1092 | J4: =VLOOKUP(A4,הכשרה!A:G,6,0)+VLOOKUP('תפוקה מצטברת מול אשתקד'!A4,מגדל!A:G,6,0)+VLOOKUP('תפוקה מצטברת מול אשתקד'!A4,מנורה!A:G,6,0)+VLOOKUP('תפוקה מצטברת מול אשתקד'!A4,איילון!A:G,6,0)+VLOOKUP(A4,הראל!A:G,6,0)+VLOOKUP('תפוקה מצטברת מול אשתקד'!A4,הפניקס!A:G,6,0)+VLOOKUP('תפוקה מצטברת מול אשתקד'!A4,כלל!A:G,6,0)+VLOOKUP('תפוקה מצטברת מול אשתקד'!A4,מור!A:G,6,0)+VLOOKUP('תפוקה מצטברת מול אשתקד'!A4,'אלטשולר שחם'!A:G,6,0)+VLOOKUP('תפוקה מצטברת מול אשתקד'!A4,'מדיהו '!A:G,6,0)+VLOOKUP('תפוקה מצטברת מול אשתקד'!A4,'אנליסט '!A:G,6,0)+VLOOKUP('תפוקה מצטברת מול אשתקד'!A4,'מיטב דש'!A:G,6,0)+VLOOKUP('תפוקה מצטברת מול אשתקד'!A4,אינפניטי!A:G,6,0) -> 2535750.3 | K4: =VLOOKUP(A4,הכשרה!A:G,7,0)+VLOOKUP('תפוקה מצטברת מול אשתקד'!A4,מגדל!A:G,7,0)+VLOOKUP('תפוקה מצטברת מול אשתקד'!A4,מנורה!A:G,7,0)+VLOOKUP('תפוקה מצטברת מול אשתקד'!A4,איילון!A:G,7,0)+VLOOKUP('תפוקה מצטברת מול אשתקד'!A4,הראל!A:G,7,0)+VLOOKUP('תפוקה מצטברת מול אשתקד'!A4,הפניקס!A:G,7,0)+VLOOKUP('תפוקה מצטברת מול אשתקד'!A4,כלל!A:G,7,0)+VLOOKUP('תפוקה מצטברת מול אשתקד'!A4,מור!A:G,7,0)+VLOOKUP('תפוקה מצטברת מול אשתקד'!A4,'אלטשולר שחם'!A:G,7,0)+VLOOKUP('תפוקה מצטברת מול אשתקד'!A4,'מדיהו '!A:K,7,0)+VLOOKUP(A4,'אנליסט '!A:G,7,0)+VLOOKUP('תפוקה מצטברת מול אשתקד'!A4,'מיטב דש'!A:G,7,0)+VLOOKUP('תפוקה מצטברת מול אשתקד'!A4,אינפניטי!A:G,7,0) -> 1490442.5 | L4: =VLOOKUP(A4,הכשרה!A:K,8,0)+VLOOKUP('תפוקה מצטברת מול אשתקד'!A4,מגדל!A:K,8,0)+VLOOKUP('תפוקה מצטברת מול אשתקד'!A4,מנורה!A:K,8,0)+VLOOKUP('תפוקה מצטברת מול אשתקד'!A4,איילון!A:K,8,0)+VLOOKUP('תפוקה מצטברת מול אשתקד'!A4,הראל!A:K,8,0)+VLOOKUP('תפוקה מצטברת מול אשתקד'!A4,הפניקס!A:K,8,0)+VLOOKUP('תפוקה מצטברת מול אשתקד'!A4,כלל!A:K,8,0)+VLOOKUP('תפוקה מצטברת מול אשתקד'!A4,מור!A:K,8,0)+VLOOKUP('תפוקה מצטברת מול אשתקד'!A4,'אלטשולר שחם'!A:K,8,0)+VLOOKUP('תפוקה מצטברת מול אשתקד'!A4,'מדיהו '!A:K,8,0)+VLOOKUP('תפוקה מצטברת מול אשתקד'!A4,'אנליסט '!A:K,8,0)+VLOOKUP('תפוקה מצטברת מול אשתקד'!A4,'מיטב דש'!A:K,8,0)+VLOOKUP('תפוקה מצטברת מול אשתקד'!A4,אינפניטי!A:K,8,0) -> 687789.81 | M4: =VLOOKUP(A4,הכשרה!A:K,9,0)+VLOOKUP('תפוקה מצטברת מול אשתקד'!A4,מגדל!A:K,9,0)+VLOOKUP('תפוקה מצטברת מול אשתקד'!A4,מנורה!A:K,9,0)+VLOOKUP('תפוקה מצטברת מול אשתקד'!A4,איילון!A:K,9,0)+VLOOKUP('תפוקה מצטברת מול אשתקד'!A4,הראל!A:K,9,0)+VLOOKUP('תפוקה מצטברת מול אשתקד'!A4,הפניקס!A:K,9,0)+VLOOKUP('תפוקה מצטברת מול אשתקד'!A4,כלל!A:K,9,0)+VLOOKUP('תפוקה מצטברת מול אשתקד'!A4,מור!A:K,9,0)+VLOOKUP('תפוקה מצטברת מול אשתקד'!A4,'אלטשולר שחם'!A:K,9,0)+VLOOKUP('תפוקה מצטברת מול אשתקד'!A4,'מדיהו '!A:K,9,0)+VLOOKUP('תפוקה מצטברת מול אשתקד'!A4,'אנליסט '!A:K,9,0)+VLOOKUP('תפוקה מצטברת מול אשתקד'!A4,'מיטב דש'!A:K,9,0)+VLOOKUP('תפוקה מצטברת מול אשתקד'!A4,אינפניטי!A:K,9,0) -> 6822.7682 | N4: =VLOOKUP(A4,הכשרה!A:K,10,0)+VLOOKUP('תפוקה מצטברת מול אשתקד'!A4,מגדל!A:K,10,0)+VLOOKUP('תפוקה מצטברת מול אשתקד'!A4,מנורה!A:K,10,0)+VLOOKUP('תפוקה מצטברת מול אשתקד'!A4,איילון!A:K,10,0)+VLOOKUP('תפוקה מצטברת מול אשתקד'!A4,הראל!A:K,10,0)+VLOOKUP('תפוקה מצטברת מול אשתקד'!A4,הפניקס!A:K,10,0)+VLOOKUP('תפוקה מצטברת מול אשתקד'!A4,כלל!A:K,10,0)+VLOOKUP('תפוקה מצטברת מול אשתקד'!A4,מור!A:K,10,0)+VLOOKUP('תפוקה מצטברת מול אשתקד'!A4,'אלטשולר שחם'!A:K,10,0)+VLOOKUP('תפוקה מצטברת מול אשתקד'!A4,'מדיהו '!A:K,10,0)+VLOOKUP('תפוקה מצטברת מול אשתקד'!A4,'אנליסט '!A:K,10,0)+VLOOKUP('תפוקה מצטברת מול אשתקד'!A4,'מיטב דש'!A:K,10,0)+VLOOKUP('תפוקה מצטברת מול אשתקד'!A4,אינפניטי!A:K,10,0) -> 7243512.5 | O4: =VLOOKUP(A4,הכשרה!A:K,11,0)+VLOOKUP('תפוקה מצטברת מול אשתקד'!A4,מגדל!A:K,11,0)+VLOOKUP('תפוקה מצטברת מול אשתקד'!A4,מנורה!A:K,11,0)+VLOOKUP('תפוקה מצטברת מול אשתקד'!A4,איילון!A:K,11,0)+VLOOKUP('תפוקה מצטברת מול אשתקד'!A4,הראל!A:K,11,0)+VLOOKUP('תפוקה מצטברת מול אשתקד'!A4,הפניקס!A:K,11,0)+VLOOKUP('תפוקה מצטברת מול אשתקד'!A4,כלל!A:K,11,0)+VLOOKUP('תפוקה מצטברת מול אשתקד'!A4,מור!A:K,11,0)+VLOOKUP('תפוקה מצטברת מול אשתקד'!A4,'אלטשולר שחם'!A:K,11,0)+VLOOKUP('תפוקה מצטברת מול אשתקד'!A4,'מדיהו '!A:K,11,0)+VLOOKUP('תפוקה מצטברת מול אשתקד'!A4,'אנליסט '!A:K,11,0)+VLOOKUP('תפוקה מצטברת מול אשתקד'!A4,'מיטב דש'!A:K,11,0)+VLOOKUP('תפוקה מצטברת מול אשתקד'!A4,אינפניטי!A:K,11,0) -> 6661963.6
A5: רותי | B5: יוסי אביב | C5: ישירים | D5: =IF(H5=0,0%,IF(L5=0,100%,H5/L5-1)) -> 0 | E5: =IF(I5=0,0%,IF(M5=0,100%,I5/M5-1)) -> 1 | F5: =IF(J5=0,0%,IF(N5=0,100%,J5/N5-1)) -> 1 | G5: =IF(K5=0,0%,IF(O5=H31,100%,K5/O5-1)) -> 0 | H5: =VLOOKUP(A5,הכשרה!A:G,4,0)+VLOOKUP('תפוקה מצטברת מול אשתקד'!A5,מגדל!A:G,4,0)+VLOOKUP('תפוקה מצטברת מול אשתקד'!A5,מנורה!A:G,4,0)+VLOOKUP('תפוקה מצטברת מול אשתקד'!A5,איילון!A:G,4,0)+VLOOKUP('תפוקה מצטברת מול אשתקד'!A5,הראל!A:G,4,0)+VLOOKUP('תפוקה מצטברת מול אשתקד'!A5,הפניקס!A:G,4,0)+VLOOKUP('תפוקה מצטברת מול אשתקד'!A5,כלל!A:G,4,0)+VLOOKUP('תפוקה מצטברת מול אשתקד'!A5,מור!A:G,4,0)+VLOOKUP('תפוקה מצטברת מול אשתקד'!A5,'אלטשולר שחם'!A:G,4,0)+VLOOKUP('תפוקה מצטברת מול אשתקד'!A5,'מדיהו '!A:G,4,0)+VLOOKUP('תפוקה מצטברת מול אשתקד'!A5,'אנליסט '!A:G,4,0)+VLOOKUP('תפוקה מצטברת מול אשתקד'!A5,'מיטב דש'!A:G,4,0)+VLOOKUP('תפוקה מצטברת מול אשתקד'!A5,אינפניטי!A:G,4,0) -> 0 | I5: =VLOOKUP(A5,הכשרה!A:G,5,0)+VLOOKUP('תפוקה מצטברת מול אשתקד'!A5,מגדל!A:G,5,0)+VLOOKUP('תפוקה מצטברת מול אשתקד'!A5,מנורה!A:G,5,0)+VLOOKUP('תפוקה מצטברת מול אשתקד'!A5,איילון!A:G,5,0)+VLOOKUP('תפוקה מצטברת מול אשתקד'!A5,הראל!A:G,5,0)+VLOOKUP('תפוקה מצטברת מול אשתקד'!A5,הפניקס!A:G,5,0)+VLOOKUP('תפוקה מצטברת מול אשתקד'!A5,כלל!A:G,5,0)+VLOOKUP('תפוקה מצטברת מול אשתקד'!A5,מור!A:G,5,0)+VLOOKUP('תפוקה מצטברת מול אשתקד'!A5,'אלטשולר שחם'!A:G,5,0)+VLOOKUP('תפוקה מצטברת מול אשתקד'!A5,'מדיהו '!A:G,5,0)+VLOOKUP('תפוקה מצטברת מול אשתקד'!A5,'אנליסט '!A:G,5,0)+VLOOKUP('תפוקה מצטברת מול אשתקד'!A5,'מיטב דש'!A:G,5,0)+VLOOKUP('תפוקה מצטברת מול אשתקד'!A5,אינפניטי!A:G,5,0) -> 47762.664 | J5: =VLOOKUP(A5,הכשרה!A:G,6,0)+VLOOKUP('תפוקה מצטברת מול אשתקד'!A5,מגדל!A:G,6,0)+VLOOKUP('תפוקה מצטברת מול אשתקד'!A5,מנורה!A:G,6,0)+VLOOKUP('תפוקה מצטברת מול אשתקד'!A5,איילון!A:G,6,0)+VLOOKUP(A5,הראל!A:G,6,0)+VLOOKUP('תפוקה מצטברת מול אשתקד'!A5,הפניקס!A:G,6,0)+VLOOKUP('תפוקה מצטברת מול אשתקד'!A5,כלל!A:G,6,0)+VLOOKUP('תפוקה מצטברת מול אשתקד'!A5,מור!A:G,6,0)+VLOOKUP('תפוקה מצטברת מול אשתקד'!A5,'אלטשולר שחם'!A:G,6,0)+VLOOKUP('תפוקה מצטברת מול אשתקד'!A5,'מדיהו '!A:G,6,0)+VLOOKUP('תפוקה מצטברת מול אשתקד'!A5,'אנליסט '!A:G,6,0)+VLOOKUP('תפוקה מצטברת מול אשתקד'!A5,'מיטב דש'!A:G,6,0)+VLOOKUP('תפוקה מצטברת מול אשתקד'!A5,אינפניטי!A:G,6,0) -> 300000 | K5: =VLOOKUP(A5,הכשרה!A:G,7,0)+VLOOKUP('תפוקה מצטברת מול אשתקד'!A5,מגדל!A:G,7,0)+VLOOKUP('תפוקה מצטברת מול אשתקד'!A5,מנורה!A:G,7,0)+VLOOKUP('תפוקה מצטברת מול אשתקד'!A5,איילון!A:G,7,0)+VLOOKUP('תפוקה מצטברת מול אשתקד'!A5,הראל!A:G,7,0)+VLOOKUP('תפוקה מצטברת מול אשתקד'!A5,הפניקס!A:G,7,0)+VLOOKUP('תפוקה מצטברת מול אשתקד'!A5,כלל!A:G,7,0)+VLOOKUP('תפוקה מצטברת מול אשתקד'!A5,מור!A:G,7,0)+VLOOKUP('תפוקה מצטברת מול אשתקד'!A5,'אלטשולר שחם'!A:G,7,0)+VLOOKUP('תפוקה מצטברת מול אשתקד'!A5,'מדיהו '!A:K,7,0)+VLOOKUP(A5,'אנליסט '!A:G,7,0)+VLOOKUP('תפוקה מצטברת מול אשתקד'!A5,'מיטב דש'!A:G,7,0)+VLOOKUP('תפוקה מצטברת מול אשתקד'!A5,אינפניטי!A:G,7,0) -> 0 | L5: =VLOOKUP(A5,הכשרה!A:K,8,0)+VLOOKUP('תפוקה מצטברת מול אשתקד'!A5,מגדל!A:K,8,0)+VLOOKUP('תפוקה מצטברת מול אשתקד'!A5,מנורה!A:K,8,0)+VLOOKUP('תפוקה מצטברת מול אשתקד'!A5,איילון!A:K,8,0)+VLOOKUP('תפוקה מצטברת מול אשתקד'!A5,הראל!A:K,8,0)+VLOOKUP('תפוקה מצטברת מול אשתקד'!A5,הפניקס!A:K,8,0)+VLOOKUP('תפוקה מצטברת מול אשתקד'!A5,כלל!A:K,8,0)+VLOOKUP('תפוקה מצטברת מול אשתקד'!A5,מור!A:K,8,0)+VLOOKUP('תפוקה מצטברת מול אשתקד'!A5,'אלטשולר שחם'!A:K,8,0)+VLOOKUP('תפוקה מצטברת מול אשתקד'!A5,'מדיהו '!A:K,8,0)+VLOOKUP('תפוקה מצטברת מול אשתקד'!A5,'אנליסט '!A:K,8,0)+VLOOKUP('תפוקה מצטברת מול אשתקד'!A5,'מיטב דש'!A:K,8,0)+VLOOKUP('תפוקה מצטברת מול אשתקד'!A5,אינפניטי!A:K,8,0) -> 0 | M5: =VLOOKUP(A5,הכשרה!A:K,9,0)+VLOOKUP('תפוקה מצטברת מול אשתקד'!A5,מגדל!A:K,9,0)+VLOOKUP('תפוקה מצטברת מול אשתקד'!A5,מנורה!A:K,9,0)+VLOOKUP('תפוקה מצטברת מול אשתקד'!A5,איילון!A:K,9,0)+VLOOKUP('תפוקה מצטברת מול אשתקד'!A5,הראל!A:K,9,0)+VLOOKUP('תפוקה מצטברת מול אשתקד'!A5,הפניקס!A:K,9,0)+VLOOKUP('תפוקה מצטברת מול אשתקד'!A5,כלל!A:K,9,0)+VLOOKUP('תפוקה מצטברת מול אשתקד'!A5,מור!A:K,9,0)+VLOOKUP('תפוקה מצטברת מול אשתקד'!A5,'אלטשולר שחם'!A:K,9,0)+VLOOKUP('תפוקה מצטברת מול אשתקד'!A5,'מדיהו '!A:K,9,0)+VLOOKUP('תפוקה מצטברת מול אשתקד'!A5,'אנליסט '!A:K,9,0)+VLOOKUP('תפוקה מצטברת מול אשתקד'!A5,'מיטב דש'!A:K,9,0)+VLOOKUP('תפוקה מצטברת מול אשתקד'!A5,אינפניטי!A:K,9,0) -> 0 | N5: =VLOOKUP(A5,הכשרה!A:K,10,0)+VLOOKUP('תפוקה מצטברת מול אשתקד'!A5,מגדל!A:K,10,0)+VLOOKUP('תפוקה מצטברת מול אשתקד'!A5,מנורה!A:K,10,0)+VLOOKUP('תפוקה מצטברת מול אשתקד'!A5,איילון!A:K,10,0)+VLOOKUP('תפוקה מצטברת מול אשתקד'!A5,הראל!A:K,10,0)+VLOOKUP('תפוקה מצטברת מול אשתקד'!A5,הפניקס!A:K,10,0)+VLOOKUP('תפוקה מצטברת מול אשתקד'!A5,כלל!A:K,10,0)+VLOOKUP('תפוקה מצטברת מול אשתקד'!A5,מור!A:K,10,0)+VLOOKUP('תפוקה מצטברת מול אשתקד'!A5,'אלטשולר שחם'!A:K,10,0)+VLOOKUP('תפוקה מצטברת מול אשתקד'!A5,'מדיהו '!A:K,10,0)+VLOOKUP('תפוקה מצטברת מול אשתקד'!A5,'אנליסט '!A:K,10,0)+VLOOKUP('תפוקה מצטברת מול אשתקד'!A5,'מיטב דש'!A:K,10,0)+VLOOKUP('תפוקה מצטברת מול אשתקד'!A5,אינפניטי!A:K,10,0) -> 0 | O5: =VLOOKUP(A5,הכשרה!A:K,11,0)+VLOOKUP('תפוקה מצטברת מול אשתקד'!A5,מגדל!A:K,11,0)+VLOOKUP('תפוקה מצטברת מול אשתקד'!A5,מנורה!A:K,11,0)+VLOOKUP('תפוקה מצטברת מול אשתקד'!A5,איילון!A:K,11,0)+VLOOKUP('תפוקה מצטברת מול אשתקד'!A5,הראל!A:K,11,0)+VLOOKUP('תפוקה מצטברת מול אשתקד'!A5,הפניקס!A:K,11,0)+VLOOKUP('תפוקה מצטברת מול אשתקד'!A5,כלל!A:K,11,0)+VLOOKUP('תפוקה מצטברת מול אשתקד'!A5,מור!A:K,11,0)+VLOOKUP('תפוקה מצטברת מול אשתקד'!A5,'אלטשולר שחם'!A:K,11,0)+VLOOKUP('תפוקה מצטברת מול אשתקד'!A5,'מדיהו '!A:K,11,0)+VLOOKUP('תפוקה מצטברת מול אשתקד'!A5,'אנליסט '!A:K,11,0)+VLOOKUP('תפוקה מצטברת מול אשתקד'!A5,'מיטב דש'!A:K,11,0)+VLOOKUP('תפוקה מצטברת מול אשתקד'!A5,אינפניטי!A:K,11,0) -> 0
A6: אילנית | B6: יוסי אביב | C6: ישירים | D6: =IF(H6=0,0%,IF(L6=0,100%,H6/L6-1)) -> 1 | E6: =IF(I6=0,0%,IF(M6=0,100%,I6/M6-1)) -> 1 | F6: =IF(J6=0,0%,IF(N6=0,100%,J6/N6-1)) -> 1 | G6: 1 | H6: =VLOOKUP(A6,הכשרה!A:G,4,0)+VLOOKUP('תפוקה מצטברת מול אשתקד'!A6,מגדל!A:G,4,0)+VLOOKUP('תפוקה מצטברת מול אשתקד'!A6,מנורה!A:G,4,0)+VLOOKUP('תפוקה מצטברת מול אשתקד'!A6,איילון!A:G,4,0)+VLOOKUP('תפוקה מצטברת מול אשתקד'!A6,הראל!A:G,4,0)+VLOOKUP('תפוקה מצטברת מול אשתקד'!A6,הפניקס!A:G,4,0)+VLOOKUP('תפוקה מצטברת מול אשתקד'!A6,כלל!A:G,4,0)+VLOOKUP('תפוקה מצטברת מול אשתקד'!A6,מור!A:G,4,0)+VLOOKUP('תפוקה מצטברת מול אשתקד'!A6,'אלטשולר שחם'!A:G,4,0)+VLOOKUP('תפוקה מצטברת מול אשתקד'!A6,'מדיהו '!A:G,4,0)+VLOOKUP('תפוקה מצטברת מול אשתקד'!A6,'אנליסט '!A:G,4,0)+VLOOKUP('תפוקה מצטברת מול אשתקד'!A6,'מיטב דש'!A:G,4,0)+VLOOKUP('תפוקה מצטברת מול אשתקד'!A6,אינפניטי!A:G,4,0) -> 9117.1363 | I6: =VLOOKUP(A6,הכשרה!A:G,5,0)+VLOOKUP('תפוקה מצטברת מול אשתקד'!A6,מגדל!A:G,5,0)+VLOOKUP('תפוקה מצטברת מול אשתקד'!A6,מנורה!A:G,5,0)+VLOOKUP('תפוקה מצטברת מול אשתקד'!A6,איילון!A:G,5,0)+VLOOKUP('תפוקה מצטברת מול אשתקד'!A6,הראל!A:G,5,0)+VLOOKUP('תפוקה מצטברת מול אשתקד'!A6,הפניקס!A:G,5,0)+VLOOKUP('תפוקה מצטברת מול אשתקד'!A6,כלל!A:G,5,0)+VLOOKUP('תפוקה מצטברת מול אשתקד'!A6,מור!A:G,5,0)+VLOOKUP('תפוקה מצטברת מול אשתקד'!A6,'אלטשולר שחם'!A:G,5,0)+VLOOKUP('תפוקה מצטברת מול אשתקד'!A6,'מדיהו '!A:G,5,0)+VLOOKUP('תפוקה מצטברת מול אשתקד'!A6,'אנליסט '!A:G,5,0)+VLOOKUP('תפוקה מצטברת מול אשתקד'!A6,'מיטב דש'!A:G,5,0)+VLOOKUP('תפוקה מצטברת מול אשתקד'!A6,אינפניטי!A:G,5,0) -> 34130.669 | J6: =VLOOKUP(A6,הכשרה!A:G,6,0)+VLOOKUP('תפוקה מצטברת מול אשתקד'!A6,מגדל!A:G,6,0)+VLOOKUP('תפוקה מצטברת מול אשתקד'!A6,מנורה!A:G,6,0)+VLOOKUP('תפוקה מצטברת מול אשתקד'!A6,איילון!A:G,6,0)+VLOOKUP(A6,הראל!A:G,6,0)+VLOOKUP('תפוקה מצטברת מול אשתקד'!A6,הפניקס!A:G,6,0)+VLOOKUP('תפוקה מצטברת מול אשתקד'!A6,כלל!A:G,6,0)+VLOOKUP('תפוקה מצטברת מול אשתקד'!A6,מור!A:G,6,0)+VLOOKUP('תפוקה מצטברת מול אשתקד'!A6,'אלטשולר שחם'!A:G,6,0)+VLOOKUP('תפוקה מצטברת מול אשתקד'!A6,'מדיהו '!A:G,6,0)+VLOOKUP('תפוקה מצטברת מול אשתקד'!A6,'אנליסט '!A:G,6,0)+VLOOKUP('תפוקה מצטברת מול אשתקד'!A6,'מיטב דש'!A:G,6,0)+VLOOKUP('תפוקה מצטברת מול אשתקד'!A6,אינפניטי!A:G,6,0) -> 515090.01 | K6: =VLOOKUP(A6,הכשרה!A:G,7,0)+VLOOKUP('תפוקה מצטברת מול אשתקד'!A6,מגדל!A:G,7,0)+VLOOKUP('תפוקה מצטברת מול אשתקד'!A6,מנורה!A:G,7,0)+VLOOKUP('תפוקה מצטברת מול אשתקד'!A6,איילון!A:G,7,0)+VLOOKUP('תפוקה מצטברת מול אשתקד'!A6,הראל!A:G,7,0)+VLOOKUP('תפוקה מצטברת מול אשתקד'!A6,הפניקס!A:G,7,0)+VLOOKUP('תפוקה מצטברת מול אשתקד'!A6,כלל!A:G,7,0)+VLOOKUP('תפוקה מצטברת מול אשתקד'!A6,מור!A:G,7,0)+VLOOKUP('תפוקה מצטברת מול אשתקד'!A6,'אלטשולר שחם'!A:G,7,0)+VLOOKUP('תפוקה מצטברת מול אשתקד'!A6,'מדיהו '!A:K,7,0)+VLOOKUP(A6,'אנליסט '!A:G,7,0)+VLOOKUP('תפוקה מצטברת מול אשתקד'!A6,'מיטב דש'!A:G,7,0)+VLOOKUP('תפוקה מצטברת מול אשתקד'!A6,אינפניטי!A:G,7,0) -> -106250.99 | L6: =VLOOKUP(A6,הכשרה!A:K,8,0)+VLOOKUP('תפוקה מצטברת מול אשתקד'!A6,מגדל!A:K,8,0)+VLOOKUP('תפוקה מצטברת מול אשתקד'!A6,מנורה!A:K,8,0)+VLOOKUP('תפוקה מצטברת מול אשתקד'!A6,איילון!A:K,8,0)+VLOOKUP('תפוקה מצטברת מול אשתקד'!A6,הראל!A:K,8,0)+VLOOKUP('תפוקה מצטברת מול אשתקד'!A6,הפניקס!A:K,8,0)+VLOOKUP('תפוקה מצטברת מול אשתקד'!A6,כלל!A:K,8,0)+VLOOKUP('תפוקה מצטברת מול אשתקד'!A6,מור!A:K,8,0)+VLOOKUP('תפוקה מצטברת מול אשתקד'!A6,'אלטשולר שחם'!A:K,8,0)+VLOOKUP('תפוקה מצטברת מול אשתקד'!A6,'מדיהו '!A:K,8,0)+VLOOKUP('תפוקה מצטברת מול אשתקד'!A6,'אנליסט '!A:K,8,0)+VLOOKUP('תפוקה מצטברת מול אשתקד'!A6,'מיטב דש'!A:K,8,0)+VLOOKUP('תפוקה מצטברת מול אשתקד'!A6,אינפניטי!A:K,8,0) -> 0 | M6: =VLOOKUP(A6,הכשרה!A:K,9,0)+VLOOKUP('תפוקה מצטברת מול אשתקד'!A6,מגדל!A:K,9,0)+VLOOKUP('תפוקה מצטברת מול אשתקד'!A6,מנורה!A:K,9,0)+VLOOKUP('תפוקה מצטברת מול אשתקד'!A6,איילון!A:K,9,0)+VLOOKUP('תפוקה מצטברת מול אשתקד'!A6,הראל!A:K,9,0)+VLOOKUP('תפוקה מצטברת מול אשתקד'!A6,הפניקס!A:K,9,0)+VLOOKUP('תפוקה מצטברת מול אשתקד'!A6,כלל!A:K,9,0)+VLOOKUP('תפוקה מצטברת מול אשתקד'!A6,מור!A:K,9,0)+VLOOKUP('תפוקה מצטברת מול אשתקד'!A6,'אלטשולר שחם'!A:K,9,0)+VLOOKUP('תפוקה מצטברת מול אשתקד'!A6,'מדיהו '!A:K,9,0)+VLOOKUP('תפוקה מצטברת מול אשתקד'!A6,'אנליסט '!A:K,9,0)+VLOOKUP('תפוקה מצטברת מול אשתקד'!A6,'מיטב דש'!A:K,9,0)+VLOOKUP('תפוקה מצטברת מול אשתקד'!A6,אינפניטי!A:K,9,0) -> 0 | N6: =VLOOKUP(A6,הכשרה!A:K,10,0)+VLOOKUP('תפוקה מצטברת מול אשתקד'!A6,מגדל!A:K,10,0)+VLOOKUP('תפוקה מצטברת מול אשתקד'!A6,מנורה!A:K,10,0)+VLOOKUP('תפוקה מצטברת מול אשתקד'!A6,איילון!A:K,10,0)+VLOOKUP('תפוקה מצטברת מול אשתקד'!A6,הראל!A:K,10,0)+VLOOKUP('תפוקה מצטברת מול אשתקד'!A6,הפניקס!A:K,10,0)+VLOOKUP('תפוקה מצטברת מול אשתקד'!A6,כלל!A:K,10,0)+VLOOKUP('תפוקה מצטברת מול אשתקד'!A6,מור!A:K,10,0)+VLOOKUP('תפוקה מצטברת מול אשתקד'!A6,'אלטשולר שחם'!A:K,10,0)+VLOOKUP('תפוקה מצטברת מול אשתקד'!A6,'מדיהו '!A:K,10,0)+VLOOKUP('תפוקה מצטברת מול אשתקד'!A6,'אנליסט '!A:K,10,0)+VLOOKUP('תפוקה מצטברת מול אשתקד'!A6,'מיטב דש'!A:K,10,0)+VLOOKUP('תפוקה מצטברת מול אשתקד'!A6,אינפניטי!A:K,10,0) -> 0 | O6: =VLOOKUP(A6,הכשרה!A:K,11,0)+VLOOKUP('תפוקה מצטברת מול אשתקד'!A6,מגדל!A:K,11,0)+VLOOKUP('תפוקה מצטברת מול אשתקד'!A6,מנורה!A:K,11,0)+VLOOKUP('תפוקה מצטברת מול אשתקד'!A6,איילון!A:K,11,0)+VLOOKUP('תפוקה מצטברת מול אשתקד'!A6,הראל!A:K,11,0)+VLOOKUP('תפוקה מצטברת מול אשתקד'!A6,הפניקס!A:K,11,0)+VLOOKUP('תפוקה מצטברת מול אשתקד'!A6,כלל!A:K,11,0)+VLOOKUP('תפוקה מצטברת מול אשתקד'!A6,מור!A:K,11,0)+VLOOKUP('תפוקה מצטברת מול אשתקד'!A6,'אלטשולר שחם'!A:K,11,0)+VLOOKUP('תפוקה מצטברת מול אשתקד'!A6,'מדיהו '!A:K,11,0)+VLOOKUP('תפוקה מצטברת מול אשתקד'!A6,'אנליסט '!A:K,11,0)+VLOOKUP('תפוקה מצטברת מול אשתקד'!A6,'מיטב דש'!A:K,11,0)+VLOOKUP('תפוקה מצטברת מול אשתקד'!A6,אינפניטי!A:K,11,0) -> 0
A7: דני פחימה | B7: יוסי אביב | C7: ישירים | D7: =IF(H7=0,0%,IF(L7=0,100%,H7/L7-1)) -> -0.51197311 | E7: =IF(I7=0,0%,IF(M7=0,100%,I7/M7-1)) -> -0.56579272 | F7: =IF(J7=0,0%,IF(N7=0,100%,J7/N7-1)) -> 0.16538812 | G7: =IF(K7=0,0%,IF(O7=H74,100%,K7/O7-1)) -> -0.49871265 | H7: =VLOOKUP(A7,הכשרה!A:G,4,0)+VLOOKUP('תפוקה מצטברת מול אשתקד'!A7,מגדל!A:G,4,0)+VLOOKUP('תפוקה מצטברת מול אשתקד'!A7,מנורה!A:G,4,0)+VLOOKUP('תפוקה מצטברת מול אשתקד'!A7,איילון!A:G,4,0)+VLOOKUP('תפוקה מצטברת מול אשתקד'!A7,הראל!A:G,4,0)+VLOOKUP('תפוקה מצטברת מול אשתקד'!A7,הפניקס!A:G,4,0)+VLOOKUP('תפוקה מצטברת מול אשתקד'!A7,כלל!A:G,4,0)+VLOOKUP('תפוקה מצטברת מול אשתקד'!A7,מור!A:G,4,0)+VLOOKUP('תפוקה מצטברת מול אשתקד'!A7,'אלטשולר שחם'!A:G,4,0)+VLOOKUP('תפוקה מצטברת מול אשתקד'!A7,'מדיהו '!A:G,4,0)+VLOOKUP('תפוקה מצטברת מול אשתקד'!A7,'אנליסט '!A:G,4,0)+VLOOKUP('תפוקה מצטברת מול אשתקד'!A7,'מיטב דש'!A:G,4,0)+VLOOKUP('תפוקה מצטברת מול אשתקד'!A7,אינפניטי!A:G,4,0) -> 19363.97 | I7: =VLOOKUP(A7,הכשרה!A:G,5,0)+VLOOKUP('תפוקה מצטברת מול אשתקד'!A7,מגדל!A:G,5,0)+VLOOKUP('תפוקה מצטברת מול אשתקד'!A7,מנורה!A:G,5,0)+VLOOKUP('תפוקה מצטברת מול אשתקד'!A7,איילון!A:G,5,0)+VLOOKUP('תפוקה מצטברת מול אשתקד'!A7,הראל!A:G,5,0)+VLOOKUP('תפוקה מצטברת מול אשתקד'!A7,הפניקס!A:G,5,0)+VLOOKUP('תפוקה מצטברת מול אשתקד'!A7,כלל!A:G,5,0)+VLOOKUP('תפוקה מצטברת מול אשתקד'!A7,מור!A:G,5,0)+VLOOKUP('תפוקה מצטברת מול אשתקד'!A7,'אלטשולר שחם'!A:G,5,0)+VLOOKUP('תפוקה מצטברת מול אשתקד'!A7,'מדיהו '!A:G,5,0)+VLOOKUP('תפוקה מצטברת מול אשתקד'!A7,'אנליסט '!A:G,5,0)+VLOOKUP('תפוקה מצטברת מול אשתקד'!A7,'מיטב דש'!A:G,5,0)+VLOOKUP('תפוקה מצטברת מול אשתקד'!A7,אינפניטי!A:G,5,0) -> 1253.06 | J7: =VLOOKUP(A7,הכשרה!A:G,6,0)+VLOOKUP('תפוקה מצטברת מול אשתקד'!A7,מגדל!A:G,6,0)+VLOOKUP('תפוקה מצטברת מול אשתקד'!A7,מנורה!A:G,6,0)+VLOOKUP('תפוקה מצטברת מול אשתקד'!A7,איילון!A:G,6,0)+VLOOKUP(A7,הראל!A:G,6,0)+VLOOKUP('תפוקה מצטברת מול אשתקד'!A7,הפניקס!A:G,6,0)+VLOOKUP('תפוקה מצטברת מול אשתקד'!A7,כלל!A:G,6,0)+VLOOKUP('תפוקה מצטברת מול אשתקד'!A7,מור!A:G,6,0)+VLOOKUP('תפוקה מצטברת מול אשתקד'!A7,'אלטשולר שחם'!A:G,6,0)+VLOOKUP('תפוקה מצטברת מול אשתקד'!A7,'מדיהו '!A:G,6,0)+VLOOKUP('תפוקה מצטברת מול אשתקד'!A7,'אנליסט '!A:G,6,0)+VLOOKUP('תפוקה מצטברת מול אשתקד'!A7,'מיטב דש'!A:G,6,0)+VLOOKUP('תפוקה מצטברת מול אשתקד'!A7,אינפניטי!A:G,6,0) -> 12192.71 | K7: =VLOOKUP(A7,הכשרה!A:G,7,0)+VLOOKUP('תפוקה מצטברת מול אשתקד'!A7,מגדל!A:G,7,0)+VLOOKUP('תפוקה מצטברת מול אשתקד'!A7,מנורה!A:G,7,0)+VLOOKUP('תפוקה מצטברת מול אשתקד'!A7,איילון!A:G,7,0)+VLOOKUP('תפוקה מצטברת מול אשתקד'!A7,הראל!A:G,7,0)+VLOOKUP('תפוקה מצטברת מול אשתקד'!A7,הפניקס!A:G,7,0)+VLOOKUP('תפוקה מצטברת מול אשתקד'!A7,כלל!A:G,7,0)+VLOOKUP('תפוקה מצטברת מול אשתקד'!A7,מור!A:G,7,0)+VLOOKUP('תפוקה מצטברת מול אשתקד'!A7,'אלטשולר שחם'!A:G,7,0)+VLOOKUP('תפוקה מצטברת מול אשתקד'!A7,'מדיהו '!A:K,7,0)+VLOOKUP(A7,'אנליסט '!A:G,7,0)+VLOOKUP('תפוקה מצטברת מול אשתקד'!A7,'מיטב דש'!A:G,7,0)+VLOOKUP('תפוקה מצטברת מול אשתקד'!A7,אינפניטי!A:G,7,0) -> 52996.64 | L7: =VLOOKUP(A7,הכשרה!A:K,8,0)+VLOOKUP('תפוקה מצטברת מול אשתקד'!A7,מגדל!A:K,8,0)+VLOOKUP('תפוקה מצטברת מול אשתקד'!A7,מנורה!A:K,8,0)+VLOOKUP('תפוקה מצטברת מול אשתקד'!A7,איילון!A:K,8,0)+VLOOKUP('תפוקה מצטברת מול אשתקד'!A7,הראל!A:K,8,0)+VLOOKUP('תפוקה מצטברת מול אשתקד'!A7,הפניקס!A:K,8,0)+VLOOKUP('תפוקה מצטברת מול אשתקד'!A7,כלל!A:K,8,0)+VLOOKUP('תפוקה מצטברת מול אשתקד'!A7,מור!A:K,8,0)+VLOOKUP('תפוקה מצטברת מול אשתקד'!A7,'אלטשולר שחם'!A:K,8,0)+VLOOKUP('תפוקה מצטברת מול אשתקד'!A7,'מדיהו '!A:K,8,0)+VLOOKUP('תפוקה מצטברת מול אשתקד'!A7,'אנליסט '!A:K,8,0)+VLOOKUP('תפוקה מצטברת מול אשתקד'!A7,'מיטב דש'!A:K,8,0)+VLOOKUP('תפוקה מצטברת מול אשתקד'!A7,אינפניטי!A:K,8,0) -> 39678.08 | M7: =VLOOKUP(A7,הכשרה!A:K,9,0)+VLOOKUP('תפוקה מצטברת מול אשתקד'!A7,מגדל!A:K,9,0)+VLOOKUP('תפוקה מצטברת מול אשתקד'!A7,מנורה!A:K,9,0)+VLOOKUP('תפוקה מצטברת מול אשתקד'!A7,איילון!A:K,9,0)+VLOOKUP('תפוקה מצטברת מול אשתקד'!A7,הראל!A:K,9,0)+VLOOKUP('תפוקה מצטברת מול אשתקד'!A7,הפניקס!A:K,9,0)+VLOOKUP('תפוקה מצטברת מול אשתקד'!A7,כלל!A:K,9,0)+VLOOKUP('תפוקה מצטברת מול אשתקד'!A7,מור!A:K,9,0)+VLOOKUP('תפוקה מצטברת מול אשתקד'!A7,'אלטשולר שחם'!A:K,9,0)+VLOOKUP('תפוקה מצטברת מול אשתקד'!A7,'מדיהו '!A:K,9,0)+VLOOKUP('תפוקה מצטברת מול אשתקד'!A7,'אנליסט '!A:K,9,0)+VLOOKUP('תפוקה מצטברת מול אשתקד'!A7,'מיטב דש'!A:K,9,0)+VLOOKUP('תפוקה מצטברת מול אשתקד'!A7,אינפניטי!A:K,9,0) -> 2885.8568 | N7: =VLOOKUP(A7,הכשרה!A:K,10,0)+VLOOKUP('תפוקה מצטברת מול אשתקד'!A7,מגדל!A:K,10,0)+VLOOKUP('תפוקה מצטברת מול אשתקד'!A7,מנורה!A:K,10,0)+VLOOKUP('תפוקה מצטברת מול אשתקד'!A7,איילון!A:K,10,0)+VLOOKUP('תפוקה מצטברת מול אשתקד'!A7,הראל!A:K,10,0)+VLOOKUP('תפוקה מצטברת מול אשתקד'!A7,הפניקס!A:K,10,0)+VLOOKUP('תפוקה מצטברת מול אשתקד'!A7,כלל!A:K,10,0)+VLOOKUP('תפוקה מצטברת מול אשתקד'!A7,מור!A:K,10,0)+VLOOKUP('תפוקה מצטברת מול אשתקד'!A7,'אלטשולר שחם'!A:K,10,0)+VLOOKUP('תפוקה מצטברת מול אשתקד'!A7,'מדיהו '!A:K,10,0)+VLOOKUP('תפוקה מצטברת מול אשתקד'!A7,'אנליסט '!A:K,10,0)+VLOOKUP('תפוקה מצטברת מול אשתקד'!A7,'מיטב דש'!A:K,10,0)+VLOOKUP('תפוקה מצטברת מול אשתקד'!A7,אינפניטי!A:K,10,0) -> 10462.36 | O7: =VLOOKUP(A7,הכשרה!A:K,11,0)+VLOOKUP('תפוקה מצטברת מול אשתקד'!A7,מגדל!A:K,11,0)+VLOOKUP('תפוקה מצטברת מול אשתקד'!A7,מנורה!A:K,11,0)+VLOOKUP('תפוקה מצטברת מול אשתקד'!A7,איילון!A:K,11,0)+VLOOKUP('תפוקה מצטברת מול אשתקד'!A7,הראל!A:K,11,0)+VLOOKUP('תפוקה מצטברת מול אשתקד'!A7,הפניקס!A:K,11,0)+VLOOKUP('תפוקה מצטברת מול אשתקד'!A7,כלל!A:K,11,0)+VLOOKUP('תפוקה מצטברת מול אשתקד'!A7,מור!A:K,11,0)+VLOOKUP('תפוקה מצטברת מול אשתקד'!A7,'אלטשולר שחם'!A:K,11,0)+VLOOKUP('תפוקה מצטברת מול אשתקד'!A7,'מדיהו '!A:K,11,0)+VLOOKUP('תפוקה מצטברת מול אשתקד'!A7,'אנליסט '!A:K,11,0)+VLOOKUP('תפוקה מצטברת מול אשתקד'!A7,'מיטב דש'!A:K,11,0)+VLOOKUP('תפוקה מצטברת מול אשתקד'!A7,אינפניטי!A:K,11,0) -> 105721.08
A8: סה"כ ישיר | D8: =IF(H8=0,0%,IF(L8=0,100%,H8/L8-1)) -> 0.78289238 | E8: =IF(I8=0,0%,IF(M8=0,100%,I8/M8-1)) -> -0.56157699 | F8: =IF(J8=0,0%,IF(N8=0,100%,J8/N8-1)) -> 0.20980712 | G8: =IF(K8=0,0%,IF(O8=H75,100%,K8/O8-1)) -> 0.56240353 | H8: =SUM(H3:H7) -> 7204918.3 | I8: =SUM(I3:I7) -> 331810.68 | J8: =SUM(J3:J7) -> 21403334 | K8: =SUM(K3:K7) -> 45376087 | L8: =SUM(L3:L7) -> 4041140.3 | M8: =SUM(M3:M7) -> 756827.69 | N8: =SUM(N3:N7) -> 17691526 | O8: =SUM(O3:O7) -> 29042489
A9: בראשית סוכנות לביטוח | B9: יוסי אביב | C9: שותפים | D9: =IF(H9=0,0%,IF(L9=0,100%,H9/L9-1)) -> 14.734808 | E9: =IF(I9=0,0%,IF(M9=0,100%,I9/M9-1)) -> 0.67362985 | F9: =IF(J9=0,0%,IF(N9=0,100%,J9/N9-1)) -> 0 | G9: =IF(K9=0,0%,IF(O9=H33,100%,K9/O9-1)) -> -0.55518052 | H9: =VLOOKUP(A9,הכשרה!A:G,4,0)+VLOOKUP('תפוקה מצטברת מול אשתקד'!A9,מגדל!A:G,4,0)+VLOOKUP('תפוקה מצטברת מול אשתקד'!A9,מנורה!A:G,4,0)+VLOOKUP('תפוקה מצטברת מול אשתקד'!A9,איילון!A:G,4,0)+VLOOKUP('תפוקה מצטברת מול אשתקד'!A9,הראל!A:G,4,0)+VLOOKUP('תפוקה מצטברת מול אשתקד'!A9,הפניקס!A:G,4,0)+VLOOKUP('תפוקה מצטברת מול אשתקד'!A9,כלל!A:G,4,0)+VLOOKUP('תפוקה מצטברת מול אשתקד'!A9,מור!A:G,4,0)+VLOOKUP('תפוקה מצטברת מול אשתקד'!A9,'אלטשולר שחם'!A:G,4,0)+VLOOKUP('תפוקה מצטברת מול אשתקד'!A9,'מדיהו '!A:G,4,0)+VLOOKUP('תפוקה מצטברת מול אשתקד'!A9,'אנליסט '!A:G,4,0)+VLOOKUP('תפוקה מצטברת מול אשתקד'!A9,'מיטב דש'!A:G,4,0)+VLOOKUP('תפוקה מצטברת מול אשתקד'!A9,אינפניטי!A:G,4,0) -> 42413.4 | I9: =VLOOKUP(A9,הכשרה!A:G,5,0)+VLOOKUP('תפוקה מצטברת מול אשתקד'!A9,מגדל!A:G,5,0)+VLOOKUP('תפוקה מצטברת מול אשתקד'!A9,מנורה!A:G,5,0)+VLOOKUP('תפוקה מצטברת מול אשתקד'!A9,איילון!A:G,5,0)+VLOOKUP('תפוקה מצטברת מול אשתקד'!A9,הראל!A:G,5,0)+VLOOKUP('תפוקה מצטברת מול אשתקד'!A9,הפניקס!A:G,5,0)+VLOOKUP('תפוקה מצטברת מול אשתקד'!A9,כלל!A:G,5,0)+VLOOKUP('תפוקה מצטברת מול אשתקד'!A9,מור!A:G,5,0)+VLOOKUP('תפוקה מצטברת מול אשתקד'!A9,'אלטשולר שחם'!A:G,5,0)+VLOOKUP('תפוקה מצטברת מול אשתקד'!A9,'מדיהו '!A:G,5,0)+VLOOKUP('תפוקה מצטברת מול אשתקד'!A9,'אנליסט '!A:G,5,0)+VLOOKUP('תפוקה מצטברת מול אשתקד'!A9,'מיטב דש'!A:G,5,0)+VLOOKUP('תפוקה מצטברת מול אשתקד'!A9,אינפניטי!A:G,5,0) -> 1169.643 | J9: =VLOOKUP(A9,הכשרה!A:G,6,0)+VLOOKUP('תפוקה מצטברת מול אשתקד'!A9,מגדל!A:G,6,0)+VLOOKUP('תפוקה מצטברת מול אשתקד'!A9,מנורה!A:G,6,0)+VLOOKUP('תפוקה מצטברת מול אשתקד'!A9,איילון!A:G,6,0)+VLOOKUP(A9,הראל!A:G,6,0)+VLOOKUP('תפוקה מצטברת מול אשתקד'!A9,הפניקס!A:G,6,0)+VLOOKUP('תפוקה מצטברת מול אשתקד'!A9,כלל!A:G,6,0)+VLOOKUP('תפוקה מצטברת מול אשתקד'!A9,מור!A:G,6,0)+VLOOKUP('תפוקה מצטברת מול אשתקד'!A9,'אלטשולר שחם'!A:G,6,0)+VLOOKUP('תפוקה מצטברת מול אשתקד'!A9,'מדיהו '!A:G,6,0)+VLOOKUP('תפוקה מצטברת מול אשתקד'!A9,'אנליסט '!A:G,6,0)+VLOOKUP('תפוקה מצטברת מול אשתקד'!A9,'מיטב דש'!A:G,6,0)+VLOOKUP('תפוקה מצטברת מול אשתקד'!A9,אינפניטי!A:G,6,0) -> 0 | K9: =VLOOKUP(A9,הכשרה!A:G,7,0)+VLOOKUP('תפוקה מצטברת מול אשתקד'!A9,מגדל!A:G,7,0)+VLOOKUP('תפוקה מצטברת מול אשתקד'!A9,מנורה!A:G,7,0)+VLOOKUP('תפוקה מצטברת מול אשתקד'!A9,איילון!A:G,7,0)+VLOOKUP('תפוקה מצטברת מול אשתקד'!A9,הראל!A:G,7,0)+VLOOKUP('תפוקה מצטברת מול אשתקד'!A9,הפניקס!A:G,7,0)+VLOOKUP('תפוקה מצטברת מול אשתקד'!A9,כלל!A:G,7,0)+VLOOKUP('תפוקה מצטברת מול אשתקד'!A9,מור!A:G,7,0)+VLOOKUP('תפוקה מצטברת מול אשתקד'!A9,'אלטשולר שחם'!A:G,7,0)+VLOOKUP('תפוקה מצטברת מול אשתקד'!A9,'מדיהו '!A:K,7,0)+VLOOKUP(A9,'אנליסט '!A:G,7,0)+VLOOKUP('תפוקה מצטברת מול אשתקד'!A9,'מיטב דש'!A:G,7,0)+VLOOKUP('תפוקה מצטברת מול אשתקד'!A9,אינפניטי!A:G,7,0) -> -312354.79 | L9: =VLOOKUP(A9,הכשרה!A:K,8,0)+VLOOKUP('תפוקה מצטברת מול אשתקד'!A9,מגדל!A:K,8,0)+VLOOKUP('תפוקה מצטברת מול אשתקד'!A9,מנורה!A:K,8,0)+VLOOKUP('תפוקה מצטברת מול אשתקד'!A9,איילון!A:K,8,0)+VLOOKUP('תפוקה מצטברת מול אשתקד'!A9,הראל!A:K,8,0)+VLOOKUP('תפוקה מצטברת מול אשתקד'!A9,הפניקס!A:K,8,0)+VLOOKUP('תפוקה מצטברת מול אשתקד'!A9,כלל!A:K,8,0)+VLOOKUP('תפוקה מצטברת מול אשתקד'!A9,מור!A:K,8,0)+VLOOKUP('תפוקה מצטברת מול אשתקד'!A9,'אלטשולר שחם'!A:K,8,0)+VLOOKUP('תפוקה מצטברת מול אשתקד'!A9,'מדיהו '!A:K,8,0)+VLOOKUP('תפוקה מצטברת מול אשתקד'!A9,'אנליסט '!A:K,8,0)+VLOOKUP('תפוקה מצטברת מול אשתקד'!A9,'מיטב דש'!A:K,8,0)+VLOOKUP('תפוקה מצטברת מול אשתקד'!A9,אינפניטי!A:K,8,0) -> 2695.5143 | M9: =VLOOKUP(A9,הכשרה!A:K,9,0)+VLOOKUP('תפוקה מצטברת מול אשתקד'!A9,מגדל!A:K,9,0)+VLOOKUP('תפוקה מצטברת מול אשתקד'!A9,מנורה!A:K,9,0)+VLOOKUP('תפוקה מצטברת מול אשתקד'!A9,איילון!A:K,9,0)+VLOOKUP('תפוקה מצטברת מול אשתקד'!A9,הראל!A:K,9,0)+VLOOKUP('תפוקה מצטברת מול אשתקד'!A9,הפניקס!A:K,9,0)+VLOOKUP('תפוקה מצטברת מול אשתקד'!A9,כלל!A:K,9,0)+VLOOKUP('תפוקה מצטברת מול אשתקד'!A9,מור!A:K,9,0)+VLOOKUP('תפוקה מצטברת מול אשתקד'!A9,'אלטשולר שחם'!A:K,9,0)+VLOOKUP('תפוקה מצטברת מול אשתקד'!A9,'מדיהו '!A:K,9,0)+VLOOKUP('תפוקה מצטברת מול אשתקד'!A9,'אנליסט '!A:K,9,0)+VLOOKUP('תפוקה מצטברת מול אשתקד'!A9,'מיטב דש'!A:K,9,0)+VLOOKUP('תפוקה מצטברת מול אשתקד'!A9,אינפניטי!A:K,9,0) -> 698.866 | N9: =VLOOKUP(A9,הכשרה!A:K,10,0)+VLOOKUP('תפוקה מצטברת מול אשתקד'!A9,מגדל!A:K,10,0)+VLOOKUP('תפוקה מצטברת מול אשתקד'!A9,מנורה!A:K,10,0)+VLOOKUP('תפוקה מצטברת מול אשתקד'!A9,איילון!A:K,10,0)+VLOOKUP('תפוקה מצטברת מול אשתקד'!A9,הראל!A:K,10,0)+VLOOKUP('תפוקה מצטברת מול אשתקד'!A9,הפניקס!A:K,10,0)+VLOOKUP('תפוקה מצטברת מול אשתקד'!A9,כלל!A:K,10,0)+VLOOKUP('תפוקה מצטברת מול אשתקד'!A9,מור!A:K,10,0)+VLOOKUP('תפוקה מצטברת מול אשתקד'!A9,'אלטשולר שחם'!A:K,10,0)+VLOOKUP('תפוקה מצטברת מול אשתקד'!A9,'מדיהו '!A:K,10,0)+VLOOKUP('תפוקה מצטברת מול אשתקד'!A9,'אנליסט '!A:K,10,0)+VLOOKUP('תפוקה מצטברת מול אשתקד'!A9,'מיטב דש'!A:K,10,0)+VLOOKUP('תפוקה מצטברת מול אשתקד'!A9,אינפניטי!A:K,10,0) -> 0 | O9: =VLOOKUP(A9,הכשרה!A:K,11,0)+VLOOKUP('תפוקה מצטברת מול אשתקד'!A9,מגדל!A:K,11,0)+VLOOKUP('תפוקה מצטברת מול אשתקד'!A9,מנורה!A:K,11,0)+VLOOKUP('תפוקה מצטברת מול אשתקד'!A9,איילון!A:K,11,0)+VLOOKUP('תפוקה מצטברת מול אשתקד'!A9,הראל!A:K,11,0)+VLOOKUP('תפוקה מצטברת מול אשתקד'!A9,הפניקס!A:K,11,0)+VLOOKUP('תפוקה מצטברת מול אשתקד'!A9,כלל!A:K,11,0)+VLOOKUP('תפוקה מצטברת מול אשתקד'!A9,מור!A:K,11,0)+VLOOKUP('תפוקה מצטברת מול אשתקד'!A9,'אלטשולר שחם'!A:K,11,0)+VLOOKUP('תפוקה מצטברת מול אשתקד'!A9,'מדיהו '!A:K,11,0)+VLOOKUP('תפוקה מצטברת מול אשתקד'!A9,'אנליסט '!A:K,11,0)+VLOOKUP('תפוקה מצטברת מול אשתקד'!A9,'מיטב דש'!A:K,11,0)+VLOOKUP('תפוקה מצטברת מול אשתקד'!A9,אינפניטי!A:K,11,0) -> -702205.74
A10: גל אלמגור דאוד סוכ' לב | B10: יוסי אביב | C10: שותפים | D10: =IF(H10=0,0%,IF(L10=0,100%,H10/L10-1)) -> -0.17296361 | E10: =IF(I10=0,0%,IF(M10=0,100%,I10/M10-1)) -> 0.69984511 | F10: =IF(J10=0,0%,IF(N10=0,100%,J10/N10-1)) -> 0.99759646 | G10: =IF(K10=0,0%,IF(O10=H34,100%,K10/O10-1)) -> 0.90903259 | H10: =VLOOKUP(A10,הכשרה!A:G,4,0)+VLOOKUP('תפוקה מצטברת מול אשתקד'!A10,מגדל!A:G,4,0)+VLOOKUP('תפוקה מצטברת מול אשתקד'!A10,מנורה!A:G,4,0)+VLOOKUP('תפוקה מצטברת מול אשתקד'!A10,איילון!A:G,4,0)+VLOOKUP('תפוקה מצטברת מול אשתקד'!A10,הראל!A:G,4,0)+VLOOKUP('תפוקה מצטברת מול אשתקד'!A10,הפניקס!A:G,4,0)+VLOOKUP('תפוקה מצטברת מול אשתקד'!A10,כלל!A:G,4,0)+VLOOKUP('תפוקה מצטברת מול אשתקד'!A10,מור!A:G,4,0)+VLOOKUP('תפוקה מצטברת מול אשתקד'!A10,'אלטשולר שחם'!A:G,4,0)+VLOOKUP('תפוקה מצטברת מול אשתקד'!A10,'מדיהו '!A:G,4,0)+VLOOKUP('תפוקה מצטברת מול אשתקד'!A10,'אנליסט '!A:G,4,0)+VLOOKUP('תפוקה מצטברת מול אשתקד'!A10,'מיטב דש'!A:G,4,0)+VLOOKUP('תפוקה מצטברת מול אשתקד'!A10,אינפניטי!A:G,4,0) -> 672364.45 | I10: =VLOOKUP(A10,הכשרה!A:G,5,0)+VLOOKUP('תפוקה מצטברת מול אשתקד'!A10,מגדל!A:G,5,0)+VLOOKUP('תפוקה מצטברת מול אשתקד'!A10,מנורה!A:G,5,0)+VLOOKUP('תפוקה מצטברת מול אשתקד'!A10,איילון!A:G,5,0)+VLOOKUP('תפוקה מצטברת מול אשתקד'!A10,הראל!A:G,5,0)+VLOOKUP('תפוקה מצטברת מול אשתקד'!A10,הפניקס!A:G,5,0)+VLOOKUP('תפוקה מצטברת מול אשתקד'!A10,כלל!A:G,5,0)+VLOOKUP('תפוקה מצטברת מול אשתקד'!A10,מור!A:G,5,0)+VLOOKUP('תפוקה מצטברת מול אשתקד'!A10,'אלטשולר שחם'!A:G,5,0)+VLOOKUP('תפוקה מצטברת מול אשתקד'!A10,'מדיהו '!A:G,5,0)+VLOOKUP('תפוקה מצטברת מול אשתקד'!A10,'אנליסט '!A:G,5,0)+VLOOKUP('תפוקה מצטברת מול אשתקד'!A10,'מיטב דש'!A:G,5,0)+VLOOKUP('תפוקה מצטברת מול אשתקד'!A10,אינפניטי!A:G,5,0) -> 802166.97 | J10: =VLOOKUP(A10,הכשרה!A:G,6,0)+VLOOKUP('תפוקה מצטברת מול אשתקד'!A10,מגדל!A:G,6,0)+VLOOKUP('תפוקה מצטברת מול אשתקד'!A10,מנורה!A:G,6,0)+VLOOKUP('תפוקה מצטברת מול אשתקד'!A10,איילון!A:G,6,0)+VLOOKUP(A10,הראל!A:G,6,0)+VLOOKUP('תפוקה מצטברת מול אשתקד'!A10,הפניקס!A:G,6,0)+VLOOKUP('תפוקה מצטברת מול אשתקד'!A10,כלל!A:G,6,0)+VLOOKUP('תפוקה מצטברת מול אשתקד'!A10,מור!A:G,6,0)+VLOOKUP('תפוקה מצטברת מול אשתקד'!A10,'אלטשולר שחם'!A:G,6,0)+VLOOKUP('תפוקה מצטברת מול אשתקד'!A10,'מדיהו '!A:G,6,0)+VLOOKUP('תפוקה מצטברת מול אשתקד'!A10,'אנליסט '!A:G,6,0)+VLOOKUP('תפוקה מצטברת מול אשתקד'!A10,'מיטב דש'!A:G,6,0)+VLOOKUP('תפוקה מצטברת מול אשתקד'!A10,אינפניטי!A:G,6,0) -> 324158.71 | K10: =VLOOKUP(A10,הכשרה!A:G,7,0)+VLOOKUP('תפוקה מצטברת מול אשתקד'!A10,מגדל!A:G,7,0)+VLOOKUP('תפוקה מצטברת מול אשתקד'!A10,מנורה!A:G,7,0)+VLOOKUP('תפוקה מצטברת מול אשתקד'!A10,איילון!A:G,7,0)+VLOOKUP('תפוקה מצטברת מול אשתקד'!A10,הראל!A:G,7,0)+VLOOKUP('תפוקה מצטברת מול אשתקד'!A10,הפניקס!A:G,7,0)+VLOOKUP('תפוקה מצטברת מול אשתקד'!A10,כלל!A:G,7,0)+VLOOKUP('תפוקה מצטברת מול אשתקד'!A10,מור!A:G,7,0)+VLOOKUP('תפוקה מצטברת מול אשתקד'!A10,'אלטשולר שחם'!A:G,7,0)+VLOOKUP('תפוקה מצטברת מול אשתקד'!A10,'מדיהו '!A:K,7,0)+VLOOKUP(A10,'אנליסט '!A:G,7,0)+VLOOKUP('תפוקה מצטברת מול אשתקד'!A10,'מיטב דש'!A:G,7,0)+VLOOKUP('תפוקה מצטברת מול אשתקד'!A10,אינפניטי!A:G,7,0) -> 1237689.2 | L10: =VLOOKUP(A10,הכשרה!A:K,8,0)+VLOOKUP('תפוקה מצטברת מול אשתקד'!A10,מגדל!A:K,8,0)+VLOOKUP('תפוקה מצטברת מול אשתקד'!A10,מנורה!A:K,8,0)+VLOOKUP('תפוקה מצטברת מול אשתקד'!A10,איילון!A:K,8,0)+VLOOKUP('תפוקה מצטברת מול אשתקד'!A10,הראל!A:K,8,0)+VLOOKUP('תפוקה מצטברת מול אשתקד'!A10,הפניקס!A:K,8,0)+VLOOKUP('תפוקה מצטברת מול אשתקד'!A10,כלל!A:K,8,0)+VLOOKUP('תפוקה מצטברת מול אשתקד'!A10,מור!A:K,8,0)+VLOOKUP('תפוקה מצטברת מול אשתקד'!A10,'אלטשולר שחם'!A:K,8,0)+VLOOKUP('תפוקה מצטברת מול אשתקד'!A10,'מדיהו '!A:K,8,0)+VLOOKUP('תפוקה מצטברת מול אשתקד'!A10,'אנליסט '!A:K,8,0)+VLOOKUP('תפוקה מצטברת מול אשתקד'!A10,'מיטב דש'!A:K,8,0)+VLOOKUP('תפוקה מצטברת מול אשתקד'!A10,אינפניטי!A:K,8,0) -> 812980.5 | M10: =VLOOKUP(A10,הכשרה!A:K,9,0)+VLOOKUP('תפוקה מצטברת מול אשתקד'!A10,מגדל!A:K,9,0)+VLOOKUP('תפוקה מצטברת מול אשתקד'!A10,מנורה!A:K,9,0)+VLOOKUP('תפוקה מצטברת מול אשתקד'!A10,איילון!A:K,9,0)+VLOOKUP('תפוקה מצטברת מול אשתקד'!A10,הראל!A:K,9,0)+VLOOKUP('תפוקה מצטברת מול אשתקד'!A10,הפניקס!A:K,9,0)+VLOOKUP('תפוקה מצטברת מול אשתקד'!A10,כלל!A:K,9,0)+VLOOKUP('תפוקה מצטברת מול אשתקד'!A10,מור!A:K,9,0)+VLOOKUP('תפוקה מצטברת מול אשתקד'!A10,'אלטשולר שחם'!A:K,9,0)+VLOOKUP('תפוקה מצטברת מול אשתקד'!A10,'מדיהו '!A:K,9,0)+VLOOKUP('תפוקה מצטברת מול אשתקד'!A10,'אנליסט '!A:K,9,0)+VLOOKUP('תפוקה מצטברת מול אשתקד'!A10,'מיטב דש'!A:K,9,0)+VLOOKUP('תפוקה מצטברת מול אשתקד'!A10,אינפניטי!A:K,9,0) -> 471905.92 | N10: =VLOOKUP(A10,הכשרה!A:K,10,0)+VLOOKUP('תפוקה מצטברת מול אשתקד'!A10,מגדל!A:K,10,0)+VLOOKUP('תפוקה מצטברת מול אשתקד'!A10,מנורה!A:K,10,0)+VLOOKUP('תפוקה מצטברת מול אשתקד'!A10,איילון!A:K,10,0)+VLOOKUP('תפוקה מצטברת מול אשתקד'!A10,הראל!A:K,10,0)+VLOOKUP('תפוקה מצטברת מול אשתקד'!A10,הפניקס!A:K,10,0)+VLOOKUP('תפוקה מצטברת מול אשתקד'!A10,כלל!A:K,10,0)+VLOOKUP('תפוקה מצטברת מול אשתקד'!A10,מור!A:K,10,0)+VLOOKUP('תפוקה מצטברת מול אשתקד'!A10,'אלטשולר שחם'!A:K,10,0)+VLOOKUP('תפוקה מצטברת מול אשתקד'!A10,'מדיהו '!A:K,10,0)+VLOOKUP('תפוקה מצטברת מול אשתקד'!A10,'אנליסט '!A:K,10,0)+VLOOKUP('תפוקה מצטברת מול אשתקד'!A10,'מיטב דש'!A:K,10,0)+VLOOKUP('תפוקה מצטברת מול אשתקד'!A10,אינפניטי!A:K,10,0) -> 162274.37 | O10: =VLOOKUP(A10,הכשרה!A:K,11,0)+VLOOKUP('תפוקה מצטברת מול אשתקד'!A10,מגדל!A:K,11,0)+VLOOKUP('תפוקה מצטברת מול אשתקד'!A10,מנורה!A:K,11,0)+VLOOKUP('תפוקה מצטברת מול אשתקד'!A10,איילון!A:K,11,0)+VLOOKUP('תפוקה מצטברת מול אשתקד'!A10,הראל!A:K,11,0)+VLOOKUP('תפוקה מצטברת מול אשתקד'!A10,הפניקס!A:K,11,0)+VLOOKUP('תפוקה מצטברת מול אשתקד'!A10,כלל!A:K,11,0)+VLOOKUP('תפוקה מצטברת מול אשתקד'!A10,מור!A:K,11,0)+VLOOKUP('תפוקה מצטברת מול אשתקד'!A10,'אלטשולר שחם'!A:K,11,0)+VLOOKUP('תפוקה מצטברת מול אשתקד'!A10,'מדיהו '!A:K,11,0)+VLOOKUP('תפוקה מצטברת מול אשתקד'!A10,'אנליסט '!A:K,11,0)+VLOOKUP('תפוקה מצטברת מול אשתקד'!A10,'מיטב דש'!A:K,11,0)+VLOOKUP('תפוקה מצטברת מול אשתקד'!A10,אינפניטי!A:K,11,0) -> 648333.19
