Workbook

Sheet דוח הנהלה
A1: בס"ד
A3: תפוקה מצטברת לפי קבוצות
A4: קבוצה | B4: תפוקה מצטברת 05/2025 | F4: שינוי מול אשתקד % | J4: השגת יעדים מצטבר %
B5: פנסיוני | C5: סיכונים | D5: פיננסים | E5: ניודי פנסיה | F5: פנסיוני | G5: סיכונים | H5: פיננסים | I5: ניודי פנסיה | J5: פנסיוני | K5: סיכונים | L5: פיננסים | M5: ניודי פנסיה
A6: ישירים | B6: ='תפוקה מצטברת מול אשתקד'!H8 -> 6681566.9 | C6: ='תפוקה מצטברת מול אשתקד'!I8 -> 303337.58 | D6: ='תפוקה מצטברת מול אשתקד'!J8 -> 16401835 | E6: ='תפוקה מצטברת מול אשתקד'!K8 -> 41702394 | F6: ='תפוקה מצטברת מול אשתקד'!D8 -> 0.94235892 | G6: ='תפוקה מצטברת מול אשתקד'!E8 -> -0.5120803 | H6: ='תפוקה מצטברת מול אשתקד'!F8 -> 0.017395754 | I6: ='תפוקה מצטברת מול אשתקד'!G8 -> 0.62047635 | J6: ='תפוקה מצטברת מול יעד מצטבר'!D8 -> -0.18118053 | K6: ='תפוקה מצטברת מול יעד מצטבר'!E8 -> -0.62306607 | L6: ='תפוקה מצטברת מול יעד מצטבר'!F8 -> -0.46899005 | M6: ='תפוקה מצטברת מול יעד מצטבר'!G8 -> -0.13325863
A7: חברות בת | B7: ='תפוקה מצטברת מול אשתקד'!H22 -> 2161478.4 | C7: ='תפוקה מצטברת מול אשתקד'!I22 -> 1207309.2 | D7: ='תפוקה מצטברת מול אשתקד'!J22 -> 11468539 | E7: ='תפוקה מצטברת מול אשתקד'!K22 -> 5348701.1 | F7: ='תפוקה מצטברת מול אשתקד'!D22 -> 0.011118156 | G7: ='תפוקה מצטברת מול אשתקד'!E22 -> 0.59527937 | H7: ='תפוקה מצטברת מול אשתקד'!F22 -> -0.31803464 | I7: ='תפוקה מצטברת מול אשתקד'!G22 -> -0.49366108 | J7: ='תפוקה מצטברת מול יעד מצטבר'!D22 -> -0.32080242 | K7: ='תפוקה מצטברת מול יעד מצטבר'!E22 -> -0.042957396 | L7: ='תפוקה מצטברת מול יעד מצטבר'!F22 -> -0.44305854 | M7: ='תפוקה מצטברת מול יעד מצטבר'!G22 -> -0.55715341
A8: סוכני פרימיום | B8: ='תפוקה מצטברת מול אשתקד'!H75 -> 3975565.7 | C8: ='תפוקה מצטברת מול אשתקד'!I75 -> 652695.64 | D8: ='תפוקה מצטברת מול אשתקד'!J75 -> 27948634 | E8: ='תפוקה מצטברת מול אשתקד'!K75 -> 29592393 | F8: ='תפוקה מצטברת מול אשתקד'!D75 -> 0.40854726 | G8: ='תפוקה מצטברת מול אשתקד'!E75 -> 0.20597974 | H8: ='תפוקה מצטברת מול אשתקד'!F75 -> 0.47274726 | I8: ='תפוקה מצטברת מול אשתקד'!G66 -> 0.71282127 | J8: ='תפוקה מצטברת מול יעד מצטבר'!D66 -> -0.42541301 | K8: ='תפוקה מצטברת מול יעד מצטבר'!E66 -> -0.73504022 | L8: ='תפוקה מצטברת מול יעד מצטבר'!F66 -> -0.084616451 | M8: ='תפוקה מצטברת מול יעד מצטבר'!G66 -> -0.18423831
A9: סוכנים ערן | B9: ='תפוקה מצטברת מול אשתקד'!H56 -> 4675522.4 | C9: ='תפוקה מצטברת מול אשתקד'!I56 -> 652656.54 | D9: ='תפוקה מצטברת מול אשתקד'!J56 -> 8435988 | E9: ='תפוקה מצטברת מול אשתקד'!K56 -> 11766559 | F9: ='תפוקה מצטברת מול אשתקד'!D76 -> 0.28593697 | G9: ='תפוקה מצטברת מול אשתקד'!E76 -> 0.02358863 | H9: ='תפוקה מצטברת מול אשתקד'!F76 -> 0.041488034 | I9: ='תפוקה מצטברת מול אשתקד'!G75 -> 0.37647459 | J9: ='תפוקה מצטברת מול יעד מצטבר'!D75 -> 0.12000385 | K9: ='תפוקה מצטברת מול יעד מצטבר'!E75 -> 0.071749822 | L9: ='תפוקה מצטברת מול יעד מצטבר'!F75 -> 0.42580523 | M9: ='תפוקה מצטברת מול יעד מצטבר'!G75 -> 1.9190729
A10: סוכנים איתי | B10: ='תפוקה מצטברת מול אשתקד'!H66 -> 1781679.3 | C10: ='תפוקה מצטברת מול אשתקד'!I66 -> 129088.41 | D10: ='תפוקה מצטברת מול אשתקד'!J66 -> 8337313.4 | E10: ='תפוקה מצטברת מול אשתקד'!K66 -> 6460832.6 | F10: ='תפוקה מצטברת מול אשתקד'!D77 -> 0 | G10: ='תפוקה מצטברת מול אשתקד'!E77 -> 0 | H10: ='תפוקה מצטברת מול אשתקד'!F77 -> 0 | I10: ='תפוקה מצטברת מול אשתקד'!G76 -> 0.068566129 | J10: ='תפוקה מצטברת מול יעד מצטבר'!D76 -> -0.14178676 | K10: ='תפוקה מצטברת מול יעד מצטבר'!E76 -> -0.2704401 | L10: ='תפוקה מצטברת מול יעד מצטבר'!F76 -> -0.19244972 | M10: ='תפוקה מצטברת מול יעד מצטבר'!G76 -> 0.084531151
A11: סה"כ מכירות | B11: =SUM(B6:B10) -> 19275813 | C11: =SUM(C6:C10) -> 2945087.4 | D11: =SUM(D6:D10) -> 72592310 | E11: =SUM(E6:E10) -> 94870881 | F11: ='תפוקה מצטברת מול אשתקד'!D76 -> 0.28593697 | G11: ='תפוקה מצטברת מול אשתקד'!E76 -> 0.02358863 | H11: ='תפוקה מצטברת מול אשתקד'!F76 -> 0.041488034 | I11: ='תפוקה מצטברת מול יעד מצטבר'!D75 -> 0.12000385 | J11: ='תפוקה מצטברת מול יעד מצטבר'!D76 -> -0.14178676 | K11: ='תפוקה מצטברת מול יעד מצטבר'!E76 -> -0.2704401 | L11: ='תפוקה מצטברת מול יעד מצטבר'!F76 -> -0.19244972 | M11: ='תפוקה מצטברת מול יעד מצטבר'!G76 -> 0.084531151
A14: תפוקה מצטברת לפי מפקחים
A15: מפקח | B15: תפוקה מצטברת 05/2025 | F15: שינוי מול אשתקד % | J15: השגת יעדים מצטבר % | N15: תפוקה מצטברת 03/2024 | R15: יעדים מצטבר
B16: פנסיוני | C16: סיכונים | D16: פיננסים | E16: ניודי פנסיה | F16: פנסיוני | G16: סיכונים | H16: פיננסים | I16: ניודי פנסיה | J16: פנסיוני | K16: סיכונים | L16: פיננסים | M16: ניודי פנסיה | N16: פנסיוני | O16: סיכונים | P16: פיננסים | Q16: ניודי פנסיה | R16: פנסיוני | S16: סיכונים | T16: פיננסים | U16: ניודי פנסיה
A17: ערן גירוני | B17: =SUMIF('תפוקה מצטברת מול אשתקד'!B:B,'דוח הנהלה'!A17,'תפוקה מצטברת מול אשתקד'!H:H) -> 8368137.2 | C17: =SUMIF('תפוקה מצטברת מול אשתקד'!B:B,'דוח הנהלה'!A17,'תפוקה מצטברת מול אשתקד'!I:I) -> 1267553.4 | D17: =SUMIF('תפוקה מצטברת מול אשתקד'!B:B,'דוח הנהלה'!A17,'תפוקה מצטברת מול אשתקד'!J:J) -> 32673072 | E17: =SUMIF('תפוקה מצטברת מול אשתקד'!B:B,'דוח הנהלה'!A17,'תפוקה מצטברת מול אשתקד'!K:K) -> 37609063 | F17: =(B17-N17)/N17 -> 0.13997656 | G17: =(C17-O17)/O17 -> 0.0044952588 | H17: =(D17-P17)/P17 -> 0.31512245 | I17: =(E17-Q17)/Q17 -> -0.21362454 | J17: =(B17-R17)/R17 -> 0.1238433 | K17: =(C17-S17)/S17 -> -0.077874746 | L17: =(D17-T17)/T17 -> 0.30964693 | M17: =(E17-U17)/U17 -> 1.2138084 | N17: =SUMIF('תפוקה מצטברת מול אשתקד'!B:B,'דוח הנהלה'!A17,'תפוקה מצטברת מול אשתקד'!L:L) -> 7340622.1 | O17: =SUMIF('תפוקה מצטברת מול אשתקד'!B:B,'דוח הנהלה'!A17,'תפוקה מצטברת מול אשתקד'!M:M) -> 1261880.9 | P17: =SUMIF('תפוקה מצטברת מול אשתקד'!B:B,'דוח הנהלה'!A17,'תפוקה מצטברת מול אשתקד'!N:N) -> 24844129 | Q17: =SUMIF('תפוקה מצטברת מול אשתקד'!B:B,'דוח הנהלה'!A17,'תפוקה מצטברת מול אשתקד'!O:O) -> 47825835 | R17: =SUMIF('תפוקה מצטברת מול יעד מצטבר'!B:B,'דוח הנהלה'!A17,'תפוקה מצטברת מול יעד מצטבר'!H:K) -> 7446000 | S17: =SUMIF('תפוקה מצטברת מול יעד מצטבר'!B:B,'דוח הנהלה'!A17,'תפוקה מצטברת מול יעד מצטבר'!I:I) -> 1374600 | T17: =SUMIF('תפוקה מצטברת מול יעד מצטבר'!B:B,'דוח הנהלה'!A17,'תפוקה מצטברת מול יעד מצטבר'!J:J) -> 24948000 | U17: =SUMIF('תפוקה מצטברת מול יעד מצטבר'!B:B,'דוח הנהלה'!A17,'תפוקה מצטברת מול יעד מצטבר'!K:K) -> 16988400
A18: לא מפוקחים | B18: =SUMIF('תפוקה מצטברת מול אשתקד'!B:B,'דוח הנהלה'!A18,'תפוקה מצטברת מול אשתקד'!H:H) -> 30082.09 | C18: =SUMIF('תפוקה מצטברת מול אשתקד'!B:B,'דוח הנהלה'!A18,'תפוקה מצטברת מול אשתקד'!I:I) -> 17688.96 | D18: =SUMIF('תפוקה מצטברת מול אשתקד'!B:B,'דוח הנהלה'!A18,'תפוקה מצטברת מול אשתקד'!J:J) -> 0 | E18: =SUMIF('תפוקה מצטברת מול אשתקד'!B:B,'דוח הנהלה'!A18,'תפוקה מצטברת מול אשתקד'!K:K) -> 0 | F18: =(B18-N18)/N18 -> 237.8036 | G18: =(C18-O18)/O18 -> 19.376561 | H18: 0 | I18: =(E18-Q18)/Q18 -> -1 | J18: =(B18-R18)/R18 -> -0.81567347 | K18: =(C18-S18)/S18 -> -0.59335724 | L18: =(D18-T18)/T18 -> -1 | M18: =(E18-U18)/U18 -> -1 | N18: =SUMIF('תפוקה מצטברת מול אשתקד'!B:B,'דוח הנהלה'!A18,'תפוקה מצטברת מול אשתקד'!L:L) -> 125.97 | O18: =SUMIF('תפוקה מצטברת מול אשתקד'!B:B,'דוח הנהלה'!A18,'תפוקה מצטברת מול אשתקד'!M:M) -> 868.10332 | P18: =SUMIF('תפוקה מצטברת מול אשתקד'!B:B,'דוח הנהלה'!A18,'תפוקה מצטברת מול אשתקד'!N:N) -> 0 | Q18: =SUMIF('תפוקה מצטברת מול אשתקד'!B:B,'דוח הנהלה'!A18,'תפוקה מצטברת מול אשתקד'!O:O) -> -115261.94 | R18: =SUMIF('תפוקה מצטברת מול יעד מצטבר'!B:B,'דוח הנהלה'!A18,'תפוקה מצטברת מול יעד מצטבר'!H:H) -> 163200 | S18: =SUMIF('תפוקה מצטברת מול יעד מצטבר'!B:B,'דוח הנהלה'!A18,'תפוקה מצטברת מול יעד מצטבר'!I:I) -> 43500 | T18: =SUMIF('תפוקה מצטברת מול יעד מצטבר'!B:B,'דוח הנהלה'!A18,'תפוקה מצטברת מול יעד מצטבר'!J:J) -> 396000 | U18: =SUMIF('תפוקה מצטברת מול יעד מצטבר'!B:B,'דוח הנהלה'!A18,'תפוקה מצטברת מול יעד מצטבר'!K:K) -> 396000
A19: יוסי אביב | B19: =SUMIF('תפוקה מצטברת מול אשתקד'!B:B,'דוח הנהלה'!A19,'תפוקה מצטברת מול אשתקד'!H:H) -> 9095914.1 | C19: =SUMIF('תפוקה מצטברת מול אשתקד'!B:B,'דוח הנהלה'!A19,'תפוקה מצטברת מול אשתקד'!I:I) -> 1530756.7 | D19: =SUMIF('תפוקה מצטברת מול אשתקד'!B:B,'דוח הנהלה'!A19,'תפוקה מצטברת מול אשתקד'!J:J) -> 31581925 | E19: =SUMIF('תפוקה מצטברת מול אשתקד'!B:B,'דוח הנהלה'!A19,'תפוקה מצטברת מול אשתקד'!K:K) -> 50800985 | F19: =(B19-N19)/N19 -> 0.57004554 | G19: =(C19-O19)/O19 -> 0.088079953 | H19: =(D19-P19)/P19 -> -0.16062852 | I19: =(E19-Q19)/Q19 -> 0.36192985 | J19: =(B19-R19)/R19 -> -0.225906 | K19: =(C19-S19)/S19 -> -0.28184064 | L19: =(D19-T19)/T19 -> -0.43034046 | M19: =(E19-U19)/U19 -> -0.18289608 | N19: =SUMIF('תפוקה מצטברת מול אשתקד'!B:B,'דוח הנהלה'!A19,'תפוקה מצטברת מול אשתקד'!L:L) -> 5793407.8 | O19: =SUMIF('תפוקה מצטברת מול אשתקד'!B:B,'דוח הנהלה'!A19,'תפוקה מצטברת מול אשתקד'!M:M) -> 1406842.1 | P19: =SUMIF('תפוקה מצטברת מול אשתקד'!B:B,'דוח הנהלה'!A19,'תפוקה מצטברת מול אשתקד'!N:N) -> 37625682 | Q19: =SUMIF('תפוקה מצטברת מול אשתקד'!B:B,'דוח הנהלה'!A19,'תפוקה מצטברת מול אשתקד'!O:O) -> 37300735 | R19: =SUMIF('תפוקה מצטברת מול יעד מצטבר'!B:B,'דוח הנהלה'!A19,'תפוקה מצטברת מול יעד מצטבר'!H:H) -> 11750400 | S19: =SUMIF('תפוקה מצטברת מול יעד מצטבר'!B:B,'דוח הנהלה'!A19,'תפוקה מצטברת מול יעד מצטבר'!I:I) -> 2131500 | T19: =SUMIF('תפוקה מצטברת מול יעד מצטבר'!B:B,'דוח הנהלה'!A19,'תפוקה מצטברת מול יעד מצטבר'!J:J) -> 55440000 | U19: =SUMIF('תפוקה מצטברת מול יעד מצטבר'!B:B,'דוח הנהלה'!A19,'תפוקה מצטברת מול יעד מצטבר'!K:K) -> 62172000
A20: איתי אדן | B20: =SUMIF('תפוקה מצטברת מול אשתקד'!B:B,'דוח הנהלה'!A20,'תפוקה מצטברת מול אשתקד'!H:H) -> 1781679.3 | C20: =SUMIF('תפוקה מצטברת מול אשתקד'!B:B,'דוח הנהלה'!A20,'תפוקה מצטברת מול אשתקד'!I:I) -> 129088.41 | D20: =SUMIF('תפוקה מצטברת מול אשתקד'!B:B,'דוח הנהלה'!A20,'תפוקה מצטברת מול אשתקד'!J:J) -> 8337313.4 | E20: =SUMIF('תפוקה מצטברת מול אשתקד'!B:B,'דוח הנהלה'!A20,'תפוקה מצטברת מול אשתקד'!K:K) -> 6460832.6 | F20: =(B20-N20)/N20 -> -0.039808902 | G20: =(C20-O20)/O20 -> -0.37826684 | H20: =(D20-P20)/P20 -> 0.15303434 | I20: =(E20-Q20)/Q20 -> 0.71282127 | J20: =(B20-R20)/R20 -> -0.42541301 | K20: =(C20-S20)/S20 -> -0.73504022 | L20: =(D20-T20)/T20 -> -0.084616451 | M20: =(E20-U20)/U20 -> -0.18423831 | N20: =SUMIF('תפוקה מצטברת מול אשתקד'!B:B,'דוח הנהלה'!A20,'תפוקה מצטברת מול אשתקד'!L:L) -> 1855546.6 | O20: =SUMIF('תפוקה מצטברת מול אשתקד'!B:B,'דוח הנהלה'!A20,'תפוקה מצטברת מול אשתקד'!M:M) -> 207626.7 | P20: =SUMIF('תפוקה מצטברת מול אשתקד'!B:B,'דוח הנהלה'!A20,'תפוקה מצטברת מול אשתקד'!N:N) -> 7230758.9 | Q20: =SUMIF('תפוקה מצטברת מול אשתקד'!B:B,'דוח הנהלה'!A20,'תפוקה מצטברת מול אשתקד'!O:O) -> 3772041.3 | R20: =SUMIF('תפוקה מצטברת מול יעד מצטבר'!B:B,'דוח הנהלה'!A20,'תפוקה מצטברת מול יעד מצטבר'!H:H) -> 3100800 | S20: =SUMIF('תפוקה מצטברת מול יעד מצטבר'!B:B,'דוח הנהלה'!A20,'תפוקה מצטברת מול יעד מצטבר'!I:I) -> 487200 | T20: =SUMIF('תפוקה מצטברת מול יעד מצטבר'!B:B,'דוח הנהלה'!A20,'תפוקה מצטברת מול יעד מצטבר'!J:J) -> 9108000 | U20: =SUMIF('תפוקה מצטברת מול יעד מצטבר'!B:B,'דוח הנהלה'!A20,'תפוקה מצטברת מול יעד מצטבר'!K:K) -> 7920000
B21: =SUM(B17:B20) -> 19275813 | C21: =SUM(C17:C20) -> 2945087.4 | D21: =SUM(D17:D20) -> 72592310 | E21: =SUM(E17:E20) -> 94870881 | F21: =(B21-N21)/N21 -> 0.28593697 | G21: =(C21-O21)/O21 -> 0.02358863 | H21: =(D21-P21)/P21 -> 0.041488034 | I21: =(B21-R21)/R21 -> -0.14178676 | J21: =(B21-R21)/R21 -> -0.14178676 | K21: =(C21-S21)/S21 -> -0.2704401 | L21: =(D21-T21)/T21 -> -0.19244972 | M21: =(E21-U21)/U21 -> 0.084531151 | N21: =SUM(N17:N20) -> 14989703 | O21: =SUM(O17:O20) -> 2877217.8 | P21: =SUM(P17:P20) -> 69700570 | Q21: =SUM(Q17:Q20) -> 88783350 | R21: =SUM(R17:R20) -> 22460400 | S21: =SUM(S17:S20) -> 4036800 | T21: =SUM(T17:T20) -> 89892000 | U21: =SUM(U17:U20) -> 87476400
A25: תפוקה מצטברת לפי חברות | R25: עולים בולטים
A26: קבוצה | B26: תפוקה מצטברת 05/2025 | F26: שינוי מול אשתקד % | R26: סוכן | S26: שינוי % מול תקופה חופפת אשתקד | T26: עליה מול תקופה חופפת אשתקד | U26: תפוקה מצטברת - 2024
B27: פנסיוני | C27: סיכונים | D27: פיננסים | E27: ניודי פנסיה | F27: פנסיוני | G27: סיכונים | H27: פיננסים | I27: ניודי פנסיה | R27: סמיר בלאן | S27: 67.345806 | T27: 207336.19 | U27: 210414.87
A28: מנורה | B28: =מנורה!D76 -> 2630373.3 | C28: =מנורה!E76 -> 713517.97 | D28: =מנורה!F76 -> 2863876 | E28: =מנורה!G76 -> -696662 | F28: =מנורה!D76/מנורה!H76-1 -> 0.081077741 | G28: =מנורה!E76/מנורה!I76-1 -> 0.67210092 | H28: =מנורה!F76/מנורה!J76-1 -> -0.57750655 | I28: =מנורה!G76/מנורה!K76-1 -> -1.0573909 | R28: לילי שרון | S28: 429.18924 | T28: 707042.93 | U28: 708690.32
A29: מגדל | B29: =מגדל!D76 -> 11087931 | C29: =מגדל!E76 -> 539695.35 | D29: =מגדל!F76 -> 29303374 | E29: =מגדל!G76 -> 83012846 | F29: =מגדל!D76/מגדל!H76-1 -> 0.84778542 | G29: =מגדל!E76/מגדל!I76-1 -> 0.18510115 | H29: =מגדל!F76/מגדל!J76-1 -> 0.43202716 | I29: =מגדל!G76/מגדל!K76-1 -> 1.3962181 | R29: מכלול סוכנות לביטוח | S29: 1 | T29: 330170.12 | U29: 330170.12
A30: כלל | B30: =כלל!D76 -> 2735759.9 | C30: =כלל!E76 -> 950020.13 | D30: =כלל!F76 -> 11075255 | E30: =כלל!G76 -> 8594073.5 | F30: =כלל!D76/כלל!H76-1 -> -0.34839322 | G30: =כלל!E76/כלל!I76-1 -> 0.30718987 | H30: =כלל!F76/כלל!J76-1 -> 0.27309131 | I30: =כלל!G76/כלל!K76-1 -> -0.75172378 | R30: דניאלה אביב | S30: 34.352594 | T30: 168203.35 | U30: 173099.73
A31: אלטשולר שחם | B31: ='אלטשולר שחם'!D76 -> 0 | C31: ='אלטשולר שחם'!E76 -> 0 | D31: ='אלטשולר שחם'!F76 -> 206323 | E31: ='אלטשולר שחם'!G76 -> 0 | F31: ='אלטשולר שחם'!D76/'אלטשולר שחם'!H76-1 -> -1 | G31: 0 | H31: ='אלטשולר שחם'!F76/'אלטשולר שחם'!J76-1 -> 1.2899334 | I31: 0 | R31: ריזק חלבי | S31: 3.8491532 | T31: 145538.09 | U31: 183348.51
A32: מור | B32: =מור!D76 -> 0 | C32: =מור!E76 -> 0 | D32: =מור!F76 -> 1480954.4 | E32: =מור!G76 -> 0 | F32: 0 | G32: 0 | H32: =מור!F76/מור!J76-1 -> -0.47876547 | I32: 0
A33: הראל | B33: =הראל!D76 -> 1141283 | C33: =הראל!E76 -> 312138 | D33: =הראל!F76 -> 2038363 | E33: =הראל!G76 -> -1200206 | F33: =הראל!D76/הראל!H76-1 -> -0.37874434 | G33: =הראל!E76/הראל!I76-1 -> -0.48621824 | H33: =הראל!F76/הראל!J76-1 -> -0.61250977 | I33: =הראל!G76/הראל!K76-1 -> -1.4351201
A34: הפניקס | B34: =הפניקס!D76 -> 1679216 | C34: =הפניקס!E76 -> 119729 | D34: =הפניקס!F76 -> 11469936 | E34: =הפניקס!G76 -> 5160829 | F34: =הפניקס!D76/הפניקס!H76-1 -> 2.2478715 | G34: =הפניקס!E76/הפניקס!I76-1 -> -0.58170827 | H34: =הפניקס!F76/הפניקס!J76-1 -> 0.65623155 | I34: =הפניקס!G76/הפניקס!K76-1 -> 0.11516243
A35: איילון | B35: =איילון!D76 -> 1250 | C35: =איילון!E76 -> 293066.96 | D35: =איילון!F76 -> 0 | E35: =איילון!G76 -> 0 | F35: 1 | G35: =איילון!E76/איילון!I76-1 -> -0.20831722 | H35: 0 | I35: 0
A36: הכשרה | B36: =הכשרה!D76 -> 0 | C36: =הכשרה!E76 -> 2975 | D36: =הכשרה!F76 -> 0 | E36: =הכשרה!G76 -> 0 | F36: 0 | G36: =הכשרה!E76/הכשרה!I76-1 -> 0.015705019 | H36: 1 | I36: 0 | R36: יורדים בולטים
A37: מדיהו | B37: ='מדיהו '!D76 -> 0 | C37: ='מדיהו '!E76 -> 13945 | D37: ='מדיהו '!F76 -> 0 | E37: ='מדיהו '!G76 -> 0 | F37: 0 | G37: ='מדיהו '!E76/'מדיהו '!I76-1 -> 8.5644719 | H37: 0%0 | I37: 0 | R37: סוכן | S37: שינוי % מול תקופה חופפת אשתקד | T37: ירידה מול תקופה חופפת אשתקד | U37: תפוקה מצטברת - 2024
A38: אנליסט | B38: ='אנליסט '!D76 -> 0 | C38: ='אנליסט '!E76 -> 0 | D38: ='אנליסט '!F76 -> 14154228 | E38: ='אנליסט '!G76 -> 0 | F38: 0 | G38: 0 | H38: ='אנליסט '!F76/'אנליסט '!J76-1 -> -0.24075934 | I38: 0 | R38: משה שטרן גל אלמגור | S38: -0.87560268 | T38: -176003.3 | U38: 25004.88
A39: מיטב דש | B39: ='מיטב דש'!D76 -> 0 | C39: ='מיטב דש'!E76 -> 0 | D39: ='מיטב דש'!F76 -> 0 | E39: ='מיטב דש'!G76 -> 0 | F39: 0 | G39: 0 | H39: 0 | I39: 0 | R39: דאי גדי | S39: 0 | T39: -270588.35 | U39: 0
A40: אינפניטי | B40: =אינפניטי!D76 -> 0 | C40: =אינפניטי!E76 -> 0 | D40: =אינפניטי!F76 -> 0 | E40: =אינפניטי!G76 -> 0 | F40: 0 | G40: 0 | H40: 0 | I40: 0 | R40: שלי מזרחי | S40: -0.98846228 | T40: -280396.68 | U40: 3272.9
A41: סה"כ | B41: =SUM(B28:B40) -> 19275813 | C41: =SUM(C28:C40) -> 2945087.4 | D41: =SUM(D28:D40) -> 72592310 | E41: =SUM(E28:E40) -> 94870881 | F41: =('תפוקה מצטברת מול אשתקד'!H76-'תפוקה מצטברת מול אשתקד'!L76)/'תפוקה מצטברת מול אשתקד'!L76 -> 0.28593697 | G41: =('תפוקה מצטברת מול אשתקד'!I76-'תפוקה מצטברת מול אשתקד'!M76)/'תפוקה מצטברת מול אשתקד'!M76 -> 0.02358863 | H41: =('תפוקה מצטברת מול אשתקד'!J76-'תפוקה מצטברת מול אשתקד'!N76)/'תפוקה מצטברת מול אשתקד'!N76 -> 0.041488034 | I41: =('תפוקה מצטברת מול אשתקד'!K76-'תפוקה מצטברת מול אשתקד'!O76)/'תפוקה מצטברת מול אשתקד'!O76 -> 0.068566129 | R41: גל אלמגור דאוד סוכ' לב | S41: -1.0012886 | T41: -371533.24 | U41: -478.1235
R42: גל אלמגור סוכ | S42: -0.99658236 | T42: -614691.31 | U42: 2108

Sheet תפוקה מצטברת מול אשתקד
D1: שינוי מול אשתקד % | H1: תפוקה מצטברת 05/2025 | L1: תפוקה מצטברת 05/2024
A2: שם סוכן | B2: מפקח | C2: מחלקה | D2: פנסיוני | E2: סיכונים | F2: פיננסים | G2: ניודי פנסיה | H2: פנסיוני | I2: סיכונים | J2: פיננסים | K2: ניודי פנסיה | L2: פנסיוני | M2: סיכונים | N2: פיננסים | O2: ניודי פנסיה
A3: גל אלמגור סוכ | B3: יוסי אביב | C3: ישירים | D3: =IF(H3=0,0%,IF(L3=0,100%,H3/L3-1)) -> 1.2594934 | E3: =IF(I3=0,0%,IF(M3=0,100%,I3/M3-1)) -> -0.65886008 | F3: =IF(J3=0,0%,IF(N3=G29,100%,J3/N3-1)) -> 0.50910529 | G3: =IF(K3=0,0%,IF(O3=H29,100%,K3/O3-1)) -> 1.0904927 | H3: =VLOOKUP(A3,הכשרה!A:G,4,0)+VLOOKUP('תפוקה מצטברת מול אשתקד'!A3,מגדל!A:G,4,0)+VLOOKUP('תפוקה מצטברת מול אשתקד'!A3,מנורה!A:G,4,0)+VLOOKUP('תפוקה מצטברת מול אשתקד'!A3,איילון!A:G,4,0)+VLOOKUP('תפוקה מצטברת מול אשתקד'!A3,הראל!A:G,4,0)+VLOOKUP('תפוקה מצטברת מול אשתקד'!A3,הפניקס!A:G,4,0)+VLOOKUP('תפוקה מצטברת מול אשתקד'!A3,כלל!A:G,4,0)+VLOOKUP('תפוקה מצטברת מול אשתקד'!A3,מור!A:G,4,0)+VLOOKUP('תפוקה מצטברת מול אשתקד'!A3,'אלטשולר שחם'!A:G,4,0)+VLOOKUP('תפוקה מצטברת מול אשתקד'!A3,'מדיהו '!A:G,4,0)+VLOOKUP('תפוקה מצטברת מול אשתקד'!A3,'אנליסט '!A:G,4,0)+VLOOKUP('תפוקה מצטברת מול אשתקד'!A3,'מיטב דש'!A:G,4,0)+VLOOKUP('תפוקה מצטברת מול אשתקד'!A3,אינפניטי!A:G,4,0) -> 6090018.6 | I3: =VLOOKUP(A3,הכשרה!A:G,5,0)+VLOOKUP('תפוקה מצטברת מול אשתקד'!A3,מגדל!A:G,5,0)+VLOOKUP('תפוקה מצטברת מול אשתקד'!A3,מנורה!A:G,5,0)+VLOOKUP('תפוקה מצטברת מול אשתקד'!A3,איילון!A:G,5,0)+VLOOKUP('תפוקה מצטברת מול אשתקד'!A3,הראל!A:G,5,0)+VLOOKUP('תפוקה מצטברת מול אשתקד'!A3,הפניקס!A:G,5,0)+VLOOKUP('תפוקה מצטברת מול אשתקד'!A3,כלל!A:G,5,0)+VLOOKUP('תפוקה מצטברת מול אשתקד'!A3,מור!A:G,5,0)+VLOOKUP('תפוקה מצטברת מול אשתקד'!A3,'אלטשולר שחם'!A:G,5,0)+VLOOKUP('תפוקה מצטברת מול אשתקד'!A3,'מדיהו '!A:G,5,0)+VLOOKUP('תפוקה מצטברת מול אשתקד'!A3,'אנליסט '!A:G,5,0)+VLOOKUP('תפוקה מצטברת מול אשתקד'!A3,'מיטב דש'!A:G,5,0)+VLOOKUP('תפוקה מצטברת מול אשתקד'!A3,אינפניטי!A:G,5,0) -> 210414.87 | J3: =VLOOKUP(A3,הכשרה!A:G,6,0)+VLOOKUP('תפוקה מצטברת מול אשתקד'!A3,מגדל!A:G,6,0)+VLOOKUP('תפוקה מצטברת מול אשתקד'!A3,מנורה!A:G,6,0)+VLOOKUP('תפוקה מצטברת מול אשתקד'!A3,איילון!A:G,6,0)+VLOOKUP(A3,הראל!A:G,6,0)+VLOOKUP('תפוקה מצטברת מול אשתקד'!A3,הפניקס!A:G,6,0)+VLOOKUP('תפוקה מצטברת מול אשתקד'!A3,כלל!A:G,6,0)+VLOOKUP('תפוקה מצטברת מול אשתקד'!A3,מור!A:G,6,0)+VLOOKUP('תפוקה מצטברת מול אשתקד'!A3,'אלטשולר שחם'!A:G,6,0)+VLOOKUP('תפוקה מצטברת מול אשתקד'!A3,'מדיהו '!A:G,6,0)+VLOOKUP('תפוקה מצטברת מול אשתקד'!A3,'אנליסט '!A:G,6,0)+VLOOKUP('תפוקה מצטברת מול אשתקד'!A3,'מיטב דש'!A:G,6,0)+VLOOKUP('תפוקה מצטברת מול אשתקד'!A3,אינפניטי!A:G,6,0) -> 13779078 | K3: =VLOOKUP(A3,הכשרה!A:G,7,0)+VLOOKUP('תפוקה מצטברת מול אשתקד'!A3,מגדל!A:G,7,0)+VLOOKUP('תפוקה מצטברת מול אשתקד'!A3,מנורה!A:G,7,0)+VLOOKUP('תפוקה מצטברת מול אשתקד'!A3,איילון!A:G,7,0)+VLOOKUP('תפוקה מצטברת מול אשתקד'!A3,הראל!A:G,7,0)+VLOOKUP('תפוקה מצטברת מול אשתקד'!A3,הפניקס!A:G,7,0)+VLOOKUP('תפוקה מצטברת מול אשתקד'!A3,כלל!A:G,7,0)+VLOOKUP('תפוקה מצטברת מול אשתקד'!A3,מור!A:G,7,0)+VLOOKUP('תפוקה מצטברת מול אשתקד'!A3,'אלטשולר שחם'!A:G,7,0)+VLOOKUP('תפוקה מצטברת מול אשתקד'!A3,'מדיהו '!A:K,7,0)+VLOOKUP(A3,'אנליסט '!A:G,7,0)+VLOOKUP('תפוקה מצטברת מול אשתקד'!A3,'מיטב דש'!A:G,7,0)+VLOOKUP('תפוקה מצטברת מול אשתקד'!A3,אינפניטי!A:G,7,0) -> 40437312 | L3: =VLOOKUP(A3,הכשרה!A:K,8,0)+VLOOKUP('תפוקה מצטברת מול אשתקד'!A3,מגדל!A:K,8,0)+VLOOKUP('תפוקה מצטברת מול אשתקד'!A3,מנורה!A:K,8,0)+VLOOKUP('תפוקה מצטברת מול אשתקד'!A3,איילון!A:K,8,0)+VLOOKUP('תפוקה מצטברת מול אשתקד'!A3,הראל!A:K,8,0)+VLOOKUP('תפוקה מצטברת מול אשתקד'!A3,הפניקס!A:K,8,0)+VLOOKUP('תפוקה מצטברת מול אשתקד'!A3,כלל!A:K,8,0)+VLOOKUP('תפוקה מצטברת מול אשתקד'!A3,מור!A:K,8,0)+VLOOKUP('תפוקה מצטברת מול אשתקד'!A3,'אלטשולר שחם'!A:K,8,0)+VLOOKUP('תפוקה מצטברת מול אשתקד'!A3,'מדיהו '!A:K,8,0)+VLOOKUP('תפוקה מצטברת מול אשתקד'!A3,'אנליסט '!A:K,8,0)+VLOOKUP('תפוקה מצטברת מול אשתקד'!A3,'מיטב דש'!A:K,8,0)+VLOOKUP('תפוקה מצטברת מול אשתקד'!A3,אינפניטי!A:K,8,0) -> 2695302.6 | M3: =VLOOKUP(A3,הכשרה!A:K,9,0)+VLOOKUP('תפוקה מצטברת מול אשתקד'!A3,מגדל!A:K,9,0)+VLOOKUP('תפוקה מצטברת מול אשתקד'!A3,מנורה!A:K,9,0)+VLOOKUP('תפוקה מצטברת מול אשתקד'!A3,איילון!A:K,9,0)+VLOOKUP('תפוקה מצטברת מול אשתקד'!A3,הראל!A:K,9,0)+VLOOKUP('תפוקה מצטברת מול אשתקד'!A3,הפניקס!A:K,9,0)+VLOOKUP('תפוקה מצטברת מול אשתקד'!A3,כלל!A:K,9,0)+VLOOKUP('תפוקה מצטברת מול אשתקד'!A3,מור!A:K,9,0)+VLOOKUP('תפוקה מצטברת מול אשתקד'!A3,'אלטשולר שחם'!A:K,9,0)+VLOOKUP('תפוקה מצטברת מול אשתקד'!A3,'מדיהו '!A:K,9,0)+VLOOKUP('תפוקה מצטברת מול אשתקד'!A3,'אנליסט '!A:K,9,0)+VLOOKUP('תפוקה מצטברת מול אשתקד'!A3,'מיטב דש'!A:K,9,0)+VLOOKUP('תפוקה מצטברת מול אשתקד'!A3,אינפניטי!A:K,9,0) -> 616799.31 | N3: =VLOOKUP(A3,הכשרה!A:K,10,0)+VLOOKUP('תפוקה מצטברת מול אשתקד'!A3,מגדל!A:K,10,0)+VLOOKUP('תפוקה מצטברת מול אשתקד'!A3,מנורה!A:K,10,0)+VLOOKUP('תפוקה מצטברת מול אשתקד'!A3,איילון!A:K,10,0)+VLOOKUP('תפוקה מצטברת מול אשתקד'!A3,הראל!A:K,10,0)+VLOOKUP('תפוקה מצטברת מול אשתקד'!A3,הפניקס!A:K,10,0)+VLOOKUP('תפוקה מצטברת מול אשתקד'!A3,כלל!A:K,10,0)+VLOOKUP('תפוקה מצטברת מול אשתקד'!A3,מור!A:K,10,0)+VLOOKUP('תפוקה מצטברת מול אשתקד'!A3,'אלטשולר שחם'!A:K,10,0)+VLOOKUP('תפוקה מצטברת מול אשתקד'!A3,'מדיהו '!A:K,10,0)+VLOOKUP('תפוקה מצטברת מול אשתקד'!A3,'אנליסט '!A:K,10,0)+VLOOKUP('תפוקה מצטברת מול אשתקד'!A3,'מיטב דש'!A:K,10,0)+VLOOKUP('תפוקה מצטברת מול אשתקד'!A3,אינפניטי!A:K,10,0) -> 9130627.1 | O3: =VLOOKUP(A3,הכשרה!A:K,11,0)+VLOOKUP('תפוקה מצטברת מול אשתקד'!A3,מגדל!A:K,11,0)+VLOOKUP('תפוקה מצטברת מול אשתקד'!A3,מנורה!A:K,11,0)+VLOOKUP('תפוקה מצטברת מול אשתקד'!A3,איילון!A:K,11,0)+VLOOKUP('תפוקה מצטברת מול אשתקד'!A3,הראל!A:K,11,0)+VLOOKUP('תפוקה מצטברת מול אשתקד'!A3,הפניקס!A:K,11,0)+VLOOKUP('תפוקה מצטברת מול אשתקד'!A3,כלל!A:K,11,0)+VLOOKUP('תפוקה מצטברת מול אשתקד'!A3,מור!A:K,11,0)+VLOOKUP('תפוקה מצטברת מול אשתקד'!A3,'אלטשולר שחם'!A:K,11,0)+VLOOKUP('תפוקה מצטברת מול אשתקד'!A3,'מדיהו '!A:K,11,0)+VLOOKUP('תפוקה מצטברת מול אשתקד'!A3,'אנליסט '!A:K,11,0)+VLOOKUP('תפוקה מצטברת מול אשתקד'!A3,'מיטב דש'!A:K,11,0)+VLOOKUP('תפוקה מצטברת מול אשתקד'!A3,אינפניטי!A:K,11,0) -> 19343437
A4: דניאלה אביב | B4: יוסי אביב | C4: ישירים | D4: =IF(H4=0,0%,IF(L4=0,100%,H4/L4-1)) -> -0.44559604 | E4: =IF(I4=0,0%,IF(M4=0,100%,I4/M4-1)) -> -0.19611442 | F4: =IF(J4=0,0%,IF(N4=0,100%,J4/N4-1)) -> -0.69743613 | G4: =IF(K4=0,0%,IF(O4=H30,100%,K4/O4-1)) -> -0.80541438 | H4: =VLOOKUP(A4,הכשרה!A:G,4,0)+VLOOKUP('תפוקה מצטברת מול אשתקד'!A4,מגדל!A:G,4,0)+VLOOKUP('תפוקה מצטברת מול אשתקד'!A4,מנורה!A:G,4,0)+VLOOKUP('תפוקה מצטברת מול אשתקד'!A4,איילון!A:G,4,0)+VLOOKUP('תפוקה מצטברת מול אשתקד'!A4,הראל!A:G,4,0)+VLOOKUP('תפוקה מצטברת מול אשתקד'!A4,הפניקס!A:G,4,0)+VLOOKUP('תפוקה מצטברת מול אשתקד'!A4,כלל!A:G,4,0)+VLOOKUP('תפוקה מצטברת מול אשתקד'!A4,מור!A:G,4,0)+VLOOKUP('תפוקה מצטברת מול אשתקד'!A4,'אלטשולר שחם'!A:G,4,0)+VLOOKUP('תפוקה מצטברת מול אשתקד'!A4,'מדיהו '!A:G,4,0)+VLOOKUP('תפוקה מצטברת מול אשתקד'!A4,'אנליסט '!A:G,4,0)+VLOOKUP('תפוקה מצטברת מול אשתקד'!A4,'מיטב דש'!A:G,4,0)+VLOOKUP('תפוקה מצטברת מול אשתקד'!A4,אינפניטי!A:G,4,0) -> 390865.87 | I4: =VLOOKUP(A4,הכשרה!A:G,5,0)+VLOOKUP('תפוקה מצטברת מול אשתקד'!A4,מגדל!A:G,5,0)+VLOOKUP('תפוקה מצטברת מול אשתקד'!A4,מנורה!A:G,5,0)+VLOOKUP('תפוקה מצטברת מול אשתקד'!A4,איילון!A:G,5,0)+VLOOKUP('תפוקה מצטברת מול אשתקד'!A4,הראל!A:G,5,0)+VLOOKUP('תפוקה מצטברת מול אשתקד'!A4,הפניקס!A:G,5,0)+VLOOKUP('תפוקה מצטברת מול אשתקד'!A4,כלל!A:G,5,0)+VLOOKUP('תפוקה מצטברת מול אשתקד'!A4,מור!A:G,5,0)+VLOOKUP('תפוקה מצטברת מול אשתקד'!A4,'אלטשולר שחם'!A:G,5,0)+VLOOKUP('תפוקה מצטברת מול אשתקד'!A4,'מדיהו '!A:G,5,0)+VLOOKUP('תפוקה מצטברת מול אשתקד'!A4,'אנליסט '!A:G,5,0)+VLOOKUP('תפוקה מצטברת מול אשתקד'!A4,'מיטב דש'!A:G,5,0)+VLOOKUP('תפוקה מצטברת מול אשתקד'!A4,אינפניטי!A:G,5,0) -> 3936.1292 | J4: =VLOOKUP(A4,הכשרה!A:G,6,0)+VLOOKUP('תפוקה מצטברת מול אשתקד'!A4,מגדל!A:G,6,0)+VLOOKUP('תפוקה מצטברת מול אשתקד'!A4,מנורה!A:G,6,0)+VLOOKUP('תפוקה מצטברת מול אשתקד'!A4,איילון!A:G,6,0)+VLOOKUP(A4,הראל!A:G,6,0)+VLOOKUP('תפוקה מצטברת מול אשתקד'!A4,הפניקס!A:G,6,0)+VLOOKUP('תפוקה מצטברת מול אשתקד'!A4,כלל!A:G,6,0)+VLOOKUP('תפוקה מצטברת מול אשתקד'!A4,מור!A:G,6,0)+VLOOKUP('תפוקה מצטברת מול אשתקד'!A4,'אלטשולר שחם'!A:G,6,0)+VLOOKUP('תפוקה מצטברת מול אשתקד'!A4,'מדיהו '!A:G,6,0)+VLOOKUP('תפוקה מצטברת מול אשתקד'!A4,'אנליסט '!A:G,6,0)+VLOOKUP('תפוקה מצטברת מול אשתקד'!A4,'מיטב דש'!A:G,6,0)+VLOOKUP('תפוקה מצטברת מול אשתקד'!A4,אינפניטי!A:G,6,0) -> 2112017.2 | K4: =VLOOKUP(A4,הכשרה!A:G,7,0)+VLOOKUP('תפוקה מצטברת מול אשתקד'!A4,מגדל!A:G,7,0)+VLOOKUP('תפוקה מצטברת מול אשתקד'!A4,מנורה!A:G,7,0)+VLOOKUP('תפוקה מצטברת מול אשתקד'!A4,איילון!A:G,7,0)+VLOOKUP('תפוקה מצטברת מול אשתקד'!A4,הראל!A:G,7,0)+VLOOKUP('תפוקה מצטברת מול אשתקד'!A4,הפניקס!A:G,7,0)+VLOOKUP('תפוקה מצטברת מול אשתקד'!A4,כלל!A:G,7,0)+VLOOKUP('תפוקה מצטברת מול אשתקד'!A4,מור!A:G,7,0)+VLOOKUP('תפוקה מצטברת מול אשתקד'!A4,'אלטשולר שחם'!A:G,7,0)+VLOOKUP('תפוקה מצטברת מול אשתקד'!A4,'מדיהו '!A:K,7,0)+VLOOKUP(A4,'אנליסט '!A:G,7,0)+VLOOKUP('תפוקה מצטברת מול אשתקד'!A4,'מיטב דש'!A:G,7,0)+VLOOKUP('תפוקה מצטברת מול אשתקד'!A4,אינפניטי!A:G,7,0) -> 1223104.9 | L4: =VLOOKUP(A4,הכשרה!A:K,8,0)+VLOOKUP('תפוקה מצטברת מול אשתקד'!A4,מגדל!A:K,8,0)+VLOOKUP('תפוקה מצטברת מול אשתקד'!A4,מנורה!A:K,8,0)+VLOOKUP('תפוקה מצטברת מול אשתקד'!A4,איילון!A:K,8,0)+VLOOKUP('תפוקה מצטברת מול אשתקד'!A4,הראל!A:K,8,0)+VLOOKUP('תפוקה מצטברת מול אשתקד'!A4,הפניקס!A:K,8,0)+VLOOKUP('תפוקה מצטברת מול אשתקד'!A4,כלל!A:K,8,0)+VLOOKUP('תפוקה מצטברת מול אשתקד'!A4,מור!A:K,8,0)+VLOOKUP('תפוקה מצטברת מול אשתקד'!A4,'אלטשולר שחם'!A:K,8,0)+VLOOKUP('תפוקה מצטברת מול אשתקד'!A4,'מדיהו '!A:K,8,0)+VLOOKUP('תפוקה מצטברת מול אשתקד'!A4,'אנליסט '!A:K,8,0)+VLOOKUP('תפוקה מצטברת מול אשתקד'!A4,'מיטב דש'!A:K,8,0)+VLOOKUP('תפוקה מצטברת מול אשתקד'!A4,אינפניטי!A:K,8,0) -> 705019.98 | M4: =VLOOKUP(A4,הכשרה!A:K,9,0)+VLOOKUP('תפוקה מצטברת מול אשתקד'!A4,מגדל!A:K,9,0)+VLOOKUP('תפוקה מצטברת מול אשתקד'!A4,מנורה!A:K,9,0)+VLOOKUP('תפוקה מצטברת מול אשתקד'!A4,איילון!A:K,9,0)+VLOOKUP('תפוקה מצטברת מול אשתקד'!A4,הראל!A:K,9,0)+VLOOKUP('תפוקה מצטברת מול אשתקד'!A4,הפניקס!A:K,9,0)+VLOOKUP('תפוקה מצטברת מול אשתקד'!A4,כלל!A:K,9,0)+VLOOKUP('תפוקה מצטברת מול אשתקד'!A4,מור!A:K,9,0)+VLOOKUP('תפוקה מצטברת מול אשתקד'!A4,'אלטשולר שחם'!A:K,9,0)+VLOOKUP('תפוקה מצטברת מול אשתקד'!A4,'מדיהו '!A:K,9,0)+VLOOKUP('תפוקה מצטברת מול אשתקד'!A4,'אנליסט '!A:K,9,0)+VLOOKUP('תפוקה מצטברת מול אשתקד'!A4,'מיטב דש'!A:K,9,0)+VLOOKUP('תפוקה מצטברת מול אשתקד'!A4,אינפניטי!A:K,9,0) -> 4896.3799 | N4: =VLOOKUP(A4,הכשרה!A:K,10,0)+VLOOKUP('תפוקה מצטברת מול אשתקד'!A4,מגדל!A:K,10,0)+VLOOKUP('תפוקה מצטברת מול אשתקד'!A4,מנורה!A:K,10,0)+VLOOKUP('תפוקה מצטברת מול אשתקד'!A4,איילון!A:K,10,0)+VLOOKUP('תפוקה מצטברת מול אשתקד'!A4,הראל!A:K,10,0)+VLOOKUP('תפוקה מצטברת מול אשתקד'!A4,הפניקס!A:K,10,0)+VLOOKUP('תפוקה מצטברת מול אשתקד'!A4,כלל!A:K,10,0)+VLOOKUP('תפוקה מצטברת מול אשתקד'!A4,מור!A:K,10,0)+VLOOKUP('תפוקה מצטברת מול אשתקד'!A4,'אלטשולר שחם'!A:K,10,0)+VLOOKUP('תפוקה מצטברת מול אשתקד'!A4,'מדיהו '!A:K,10,0)+VLOOKUP('תפוקה מצטברת מול אשתקד'!A4,'אנליסט '!A:K,10,0)+VLOOKUP('תפוקה מצטברת מול אשתקד'!A4,'מיטב דש'!A:K,10,0)+VLOOKUP('תפוקה מצטברת מול אשתקד'!A4,אינפניטי!A:K,10,0) -> 6980401.1 | O4: =VLOOKUP(A4,הכשרה!A:K,11,0)+VLOOKUP('תפוקה מצטברת מול אשתקד'!A4,מגדל!A:K,11,0)+VLOOKUP('תפוקה מצטברת מול אשתקד'!A4,מנורה!A:K,11,0)+VLOOKUP('תפוקה מצטברת מול אשתקד'!A4,איילון!A:K,11,0)+VLOOKUP('תפוקה מצטברת מול אשתקד'!A4,הראל!A:K,11,0)+VLOOKUP('תפוקה מצטברת מול אשתקד'!A4,הפניקס!A:K,11,0)+VLOOKUP('תפוקה מצטברת מול אשתקד'!A4,כלל!A:K,11,0)+VLOOKUP('תפוקה מצטברת מול אשתקד'!A4,מור!A:K,11,0)+VLOOKUP('תפוקה מצטברת מול אשתקד'!A4,'אלטשולר שחם'!A:K,11,0)+VLOOKUP('תפוקה מצטברת מול אשתקד'!A4,'מדיהו '!A:K,11,0)+VLOOKUP('תפוקה מצטברת מול אשתקד'!A4,'אנליסט '!A:K,11,0)+VLOOKUP('תפוקה מצטברת מול אשתקד'!A4,'מיטב דש'!A:K,11,0)+VLOOKUP('תפוקה מצטברת מול אשתקד'!A4,אינפניטי!A:K,11,0) -> 6285689.9
A5: רותי | B5: יוסי אביב | C5: ישירים | D5: =IF(H5=0,0%,IF(L5=0,100%,H5/L5-1)) -> 0 | E5: =IF(I5=0,0%,IF(M5=0,100%,I5/M5-1)) -> 1 | F5: =IF(J5=0,0%,IF(N5=0,100%,J5/N5-1)) -> 0 | G5: =IF(K5=0,0%,IF(O5=H31,100%,K5/O5-1)) -> 0 | H5: =VLOOKUP(A5,הכשרה!A:G,4,0)+VLOOKUP('תפוקה מצטברת מול אשתקד'!A5,מגדל!A:G,4,0)+VLOOKUP('תפוקה מצטברת מול אשתקד'!A5,מנורה!A:G,4,0)+VLOOKUP('תפוקה מצטברת מול אשתקד'!A5,איילון!A:G,4,0)+VLOOKUP('תפוקה מצטברת מול אשתקד'!A5,הראל!A:G,4,0)+VLOOKUP('תפוקה מצטברת מול אשתקד'!A5,הפניקס!A:G,4,0)+VLOOKUP('תפוקה מצטברת מול אשתקד'!A5,כלל!A:G,4,0)+VLOOKUP('תפוקה מצטברת מול אשתקד'!A5,מור!A:G,4,0)+VLOOKUP('תפוקה מצטברת מול אשתקד'!A5,'אלטשולר שחם'!A:G,4,0)+VLOOKUP('תפוקה מצטברת מול אשתקד'!A5,'מדיהו '!A:G,4,0)+VLOOKUP('תפוקה מצטברת מול אשתקד'!A5,'אנליסט '!A:G,4,0)+VLOOKUP('תפוקה מצטברת מול אשתקד'!A5,'מיטב דש'!A:G,4,0)+VLOOKUP('תפוקה מצטברת מול אשתקד'!A5,אינפניטי!A:G,4,0) -> 0 | I5: =VLOOKUP(A5,הכשרה!A:G,5,0)+VLOOKUP('תפוקה מצטברת מול אשתקד'!A5,מגדל!A:G,5,0)+VLOOKUP('תפוקה מצטברת מול אשתקד'!A5,מנורה!A:G,5,0)+VLOOKUP('תפוקה מצטברת מול אשתקד'!A5,איילון!A:G,5,0)+VLOOKUP('תפוקה מצטברת מול אשתקד'!A5,הראל!A:G,5,0)+VLOOKUP('תפוקה מצטברת מול אשתקד'!A5,הפניקס!A:G,5,0)+VLOOKUP('תפוקה מצטברת מול אשתקד'!A5,כלל!A:G,5,0)+VLOOKUP('תפוקה מצטברת מול אשתקד'!A5,מור!A:G,5,0)+VLOOKUP('תפוקה מצטברת מול אשתקד'!A5,'אלטשולר שחם'!A:G,5,0)+VLOOKUP('תפוקה מצטברת מול אשתקד'!A5,'מדיהו '!A:G,5,0)+VLOOKUP('תפוקה מצטברת מול אשתקד'!A5,'אנליסט '!A:G,5,0)+VLOOKUP('תפוקה מצטברת מול אשתקד'!A5,'מיטב דש'!A:G,5,0)+VLOOKUP('תפוקה מצטברת מול אשתקד'!A5,אינפניטי!A:G,5,0) -> 48382.235 | J5: =VLOOKUP(A5,הכשרה!A:G,6,0)+VLOOKUP('תפוקה מצטברת מול אשתקד'!A5,מגדל!A:G,6,0)+VLOOKUP('תפוקה מצטברת מול אשתקד'!A5,מנורה!A:G,6,0)+VLOOKUP('תפוקה מצטברת מול אשתקד'!A5,איילון!A:G,6,0)+VLOOKUP(A5,הראל!A:G,6,0)+VLOOKUP('תפוקה מצטברת מול אשתקד'!A5,הפניקס!A:G,6,0)+VLOOKUP('תפוקה מצטברת מול אשתקד'!A5,כלל!A:G,6,0)+VLOOKUP('תפוקה מצטברת מול אשתקד'!A5,מור!A:G,6,0)+VLOOKUP('תפוקה מצטברת מול אשתקד'!A5,'אלטשולר שחם'!A:G,6,0)+VLOOKUP('תפוקה מצטברת מול אשתקד'!A5,'מדיהו '!A:G,6,0)+VLOOKUP('תפוקה מצטברת מול אשתקד'!A5,'אנליסט '!A:G,6,0)+VLOOKUP('תפוקה מצטברת מול אשתקד'!A5,'מיטב דש'!A:G,6,0)+VLOOKUP('תפוקה מצטברת מול אשתקד'!A5,אינפניטי!A:G,6,0) -> 0 | K5: =VLOOKUP(A5,הכשרה!A:G,7,0)+VLOOKUP('תפוקה מצטברת מול אשתקד'!A5,מגדל!A:G,7,0)+VLOOKUP('תפוקה מצטברת מול אשתקד'!A5,מנורה!A:G,7,0)+VLOOKUP('תפוקה מצטברת מול אשתקד'!A5,איילון!A:G,7,0)+VLOOKUP('תפוקה מצטברת מול אשתקד'!A5,הראל!A:G,7,0)+VLOOKUP('תפוקה מצטברת מול אשתקד'!A5,הפניקס!A:G,7,0)+VLOOKUP('תפוקה מצטברת מול אשתקד'!A5,כלל!A:G,7,0)+VLOOKUP('תפוקה מצטברת מול אשתקד'!A5,מור!A:G,7,0)+VLOOKUP('תפוקה מצטברת מול אשתקד'!A5,'אלטשולר שחם'!A:G,7,0)+VLOOKUP('תפוקה מצטברת מול אשתקד'!A5,'מדיהו '!A:K,7,0)+VLOOKUP(A5,'אנליסט '!A:G,7,0)+VLOOKUP('תפוקה מצטברת מול אשתקד'!A5,'מיטב דש'!A:G,7,0)+VLOOKUP('תפוקה מצטברת מול אשתקד'!A5,אינפניטי!A:G,7,0) -> 0 | L5: =VLOOKUP(A5,הכשרה!A:K,8,0)+VLOOKUP('תפוקה מצטברת מול אשתקד'!A5,מגדל!A:K,8,0)+VLOOKUP('תפוקה מצטברת מול אשתקד'!A5,מנורה!A:K,8,0)+VLOOKUP('תפוקה מצטברת מול אשתקד'!A5,איילון!A:K,8,0)+VLOOKUP('תפוקה מצטברת מול אשתקד'!A5,הראל!A:K,8,0)+VLOOKUP('תפוקה מצטברת מול אשתקד'!A5,הפניקס!A:K,8,0)+VLOOKUP('תפוקה מצטברת מול אשתקד'!A5,כלל!A:K,8,0)+VLOOKUP('תפוקה מצטברת מול אשתקד'!A5,מור!A:K,8,0)+VLOOKUP('תפוקה מצטברת מול אשתקד'!A5,'אלטשולר שחם'!A:K,8,0)+VLOOKUP('תפוקה מצטברת מול אשתקד'!A5,'מדיהו '!A:K,8,0)+VLOOKUP('תפוקה מצטברת מול אשתקד'!A5,'אנליסט '!A:K,8,0)+VLOOKUP('תפוקה מצטברת מול אשתקד'!A5,'מיטב דש'!A:K,8,0)+VLOOKUP('תפוקה מצטברת מול אשתקד'!A5,אינפניטי!A:K,8,0) -> 0 | M5: =VLOOKUP(A5,הכשרה!A:K,9,0)+VLOOKUP('תפוקה מצטברת מול אשתקד'!A5,מגדל!A:K,9,0)+VLOOKUP('תפוקה מצטברת מול אשתקד'!A5,מנורה!A:K,9,0)+VLOOKUP('תפוקה מצטברת מול אשתקד'!A5,איילון!A:K,9,0)+VLOOKUP('תפוקה מצטברת מול אשתקד'!A5,הראל!A:K,9,0)+VLOOKUP('תפוקה מצטברת מול אשתקד'!A5,הפניקס!A:K,9,0)+VLOOKUP('תפוקה מצטברת מול אשתקד'!A5,כלל!A:K,9,0)+VLOOKUP('תפוקה מצטברת מול אשתקד'!A5,מור!A:K,9,0)+VLOOKUP('תפוקה מצטברת מול אשתקד'!A5,'אלטשולר שחם'!A:K,9,0)+VLOOKUP('תפוקה מצטברת מול אשתקד'!A5,'מדיהו '!A:K,9,0)+VLOOKUP('תפוקה מצטברת מול אשתקד'!A5,'אנליסט '!A:K,9,0)+VLOOKUP('תפוקה מצטברת מול אשתקד'!A5,'מיטב דש'!A:K,9,0)+VLOOKUP('תפוקה מצטברת מול אשתקד'!A5,אינפניטי!A:K,9,0) -> 0 | N5: =VLOOKUP(A5,הכשרה!A:K,10,0)+VLOOKUP('תפוקה מצטברת מול אשתקד'!A5,מגדל!A:K,10,0)+VLOOKUP('תפוקה מצטברת מול אשתקד'!A5,מנורה!A:K,10,0)+VLOOKUP('תפוקה מצטברת מול אשתקד'!A5,איילון!A:K,10,0)+VLOOKUP('תפוקה מצטברת מול אשתקד'!A5,הראל!A:K,10,0)+VLOOKUP('תפוקה מצטברת מול אשתקד'!A5,הפניקס!A:K,10,0)+VLOOKUP('תפוקה מצטברת מול אשתקד'!A5,כלל!A:K,10,0)+VLOOKUP('תפוקה מצטברת מול אשתקד'!A5,מור!A:K,10,0)+VLOOKUP('תפוקה מצטברת מול אשתקד'!A5,'אלטשולר שחם'!A:K,10,0)+VLOOKUP('תפוקה מצטברת מול אשתקד'!A5,'מדיהו '!A:K,10,0)+VLOOKUP('תפוקה מצטברת מול אשתקד'!A5,'אנליסט '!A:K,10,0)+VLOOKUP('תפוקה מצטברת מול אשתקד'!A5,'מיטב דש'!A:K,10,0)+VLOOKUP('תפוקה מצטברת מול אשתקד'!A5,אינפניטי!A:K,10,0) -> 0 | O5: =VLOOKUP(A5,הכשרה!A:K,11,0)+VLOOKUP('תפוקה מצטברת מול אשתקד'!A5,מגדל!A:K,11,0)+VLOOKUP('תפוקה מצטברת מול אשתקד'!A5,מנורה!A:K,11,0)+VLOOKUP('תפוקה מצטברת מול אשתקד'!A5,איילון!A:K,11,0)+VLOOKUP('תפוקה מצטברת מול אשתקד'!A5,הראל!A:K,11,0)+VLOOKUP('תפוקה מצטברת מול אשתקד'!A5,הפניקס!A:K,11,0)+VLOOKUP('תפוקה מצטברת מול אשתקד'!A5,כלל!A:K,11,0)+VLOOKUP('תפוקה מצטברת מול אשתקד'!A5,מור!A:K,11,0)+VLOOKUP('תפוקה מצטברת מול אשתקד'!A5,'אלטשולר שחם'!A:K,11,0)+VLOOKUP('תפוקה מצטברת מול אשתקד'!A5,'מדיהו '!A:K,11,0)+VLOOKUP('תפוקה מצטברת מול אשתקד'!A5,'אנליסט '!A:K,11,0)+VLOOKUP('תפוקה מצטברת מול אשתקד'!A5,'מיטב דש'!A:K,11,0)+VLOOKUP('תפוקה מצטברת מול אשתקד'!A5,אינפניטי!A:K,11,0) -> 0
A6: אילנית | B6: יוסי אביב | C6: ישירים | D6: =IF(H6=0,0%,IF(L6=0,100%,H6/L6-1)) -> 1 | E6: =IF(I6=0,0%,IF(M6=0,100%,I6/M6-1)) -> 1 | F6: =IF(J6=0,0%,IF(N6=0,100%,J6/N6-1)) -> 1 | G6: =IF(K6=0,0%,IF(O6=H32,100%,K6/O6-1)) -> #DIV/0! | H6: =VLOOKUP(A6,הכשרה!A:G,4,0)+VLOOKUP('תפוקה מצטברת מול אשתקד'!A6,מגדל!A:G,4,0)+VLOOKUP('תפוקה מצטברת מול אשתקד'!A6,מנורה!A:G,4,0)+VLOOKUP('תפוקה מצטברת מול אשתקד'!A6,איילון!A:G,4,0)+VLOOKUP('תפוקה מצטברת מול אשתקד'!A6,הראל!A:G,4,0)+VLOOKUP('תפוקה מצטברת מול אשתקד'!A6,הפניקס!A:G,4,0)+VLOOKUP('תפוקה מצטברת מול אשתקד'!A6,כלל!A:G,4,0)+VLOOKUP('תפוקה מצטברת מול אשתקד'!A6,מור!A:G,4,0)+VLOOKUP('תפוקה מצטברת מול אשתקד'!A6,'אלטשולר שחם'!A:G,4,0)+VLOOKUP('תפוקה מצטברת מול אשתקד'!A6,'מדיהו '!A:G,4,0)+VLOOKUP('תפוקה מצטברת מול אשתקד'!A6,'אנליסט '!A:G,4,0)+VLOOKUP('תפוקה מצטברת מול אשתקד'!A6,'מיטב דש'!A:G,4,0)+VLOOKUP('תפוקה מצטברת מול אשתקד'!A6,אינפניטי!A:G,4,0) -> 181293.87 | I6: =VLOOKUP(A6,הכשרה!A:G,5,0)+VLOOKUP('תפוקה מצטברת מול אשתקד'!A6,מגדל!A:G,5,0)+VLOOKUP('תפוקה מצטברת מול אשתקד'!A6,מנורה!A:G,5,0)+VLOOKUP('תפוקה מצטברת מול אשתקד'!A6,איילון!A:G,5,0)+VLOOKUP('תפוקה מצטברת מול אשתקד'!A6,הראל!A:G,5,0)+VLOOKUP('תפוקה מצטברת מול אשתקד'!A6,הפניקס!A:G,5,0)+VLOOKUP('תפוקה מצטברת מול אשתקד'!A6,כלל!A:G,5,0)+VLOOKUP('תפוקה מצטברת מול אשתקד'!A6,מור!A:G,5,0)+VLOOKUP('תפוקה מצטברת מול אשתקד'!A6,'אלטשולר שחם'!A:G,5,0)+VLOOKUP('תפוקה מצטברת מול אשתקד'!A6,'מדיהו '!A:G,5,0)+VLOOKUP('תפוקה מצטברת מול אשתקד'!A6,'אנליסט '!A:G,5,0)+VLOOKUP('תפוקה מצטברת מול אשתקד'!A6,'מיטב דש'!A:G,5,0)+VLOOKUP('תפוקה מצטברת מול אשתקד'!A6,אינפניטי!A:G,5,0) -> 39350.106 | J6: =VLOOKUP(A6,הכשרה!A:G,6,0)+VLOOKUP('תפוקה מצטברת מול אשתקד'!A6,מגדל!A:G,6,0)+VLOOKUP('תפוקה מצטברת מול אשתקד'!A6,מנורה!A:G,6,0)+VLOOKUP('תפוקה מצטברת מול אשתקד'!A6,איילון!A:G,6,0)+VLOOKUP(A6,הראל!A:G,6,0)+VLOOKUP('תפוקה מצטברת מול אשתקד'!A6,הפניקס!A:G,6,0)+VLOOKUP('תפוקה מצטברת מול אשתקד'!A6,כלל!A:G,6,0)+VLOOKUP('תפוקה מצטברת מול אשתקד'!A6,מור!A:G,6,0)+VLOOKUP('תפוקה מצטברת מול אשתקד'!A6,'אלטשולר שחם'!A:G,6,0)+VLOOKUP('תפוקה מצטברת מול אשתקד'!A6,'מדיהו '!A:G,6,0)+VLOOKUP('תפוקה מצטברת מול אשתקד'!A6,'אנליסט '!A:G,6,0)+VLOOKUP('תפוקה מצטברת מול אשתקד'!A6,'מיטב דש'!A:G,6,0)+VLOOKUP('תפוקה מצטברת מול אשתקד'!A6,אינפניטי!A:G,6,0) -> 501559 | K6: =VLOOKUP(A6,הכשרה!A:G,7,0)+VLOOKUP('תפוקה מצטברת מול אשתקד'!A6,מגדל!A:G,7,0)+VLOOKUP('תפוקה מצטברת מול אשתקד'!A6,מנורה!A:G,7,0)+VLOOKUP('תפוקה מצטברת מול אשתקד'!A6,איילון!A:G,7,0)+VLOOKUP('תפוקה מצטברת מול אשתקד'!A6,הראל!A:G,7,0)+VLOOKUP('תפוקה מצטברת מול אשתקד'!A6,הפניקס!A:G,7,0)+VLOOKUP('תפוקה מצטברת מול אשתקד'!A6,כלל!A:G,7,0)+VLOOKUP('תפוקה מצטברת מול אשתקד'!A6,מור!A:G,7,0)+VLOOKUP('תפוקה מצטברת מול אשתקד'!A6,'אלטשולר שחם'!A:G,7,0)+VLOOKUP('תפוקה מצטברת מול אשתקד'!A6,'מדיהו '!A:K,7,0)+VLOOKUP(A6,'אנליסט '!A:G,7,0)+VLOOKUP('תפוקה מצטברת מול אשתקד'!A6,'מיטב דש'!A:G,7,0)+VLOOKUP('תפוקה מצטברת מול אשתקד'!A6,אינפניטי!A:G,7,0) -> -11177.04 | L6: =VLOOKUP(A6,הכשרה!A:K,8,0)+VLOOKUP('תפוקה מצטברת מול אשתקד'!A6,מגדל!A:K,8,0)+VLOOKUP('תפוקה מצטברת מול אשתקד'!A6,מנורה!A:K,8,0)+VLOOKUP('תפוקה מצטברת מול אשתקד'!A6,איילון!A:K,8,0)+VLOOKUP('תפוקה מצטברת מול אשתקד'!A6,הראל!A:K,8,0)+VLOOKUP('תפוקה מצטברת מול אשתקד'!A6,הפניקס!A:K,8,0)+VLOOKUP('תפוקה מצטברת מול אשתקד'!A6,כלל!A:K,8,0)+VLOOKUP('תפוקה מצטברת מול אשתקד'!A6,מור!A:K,8,0)+VLOOKUP('תפוקה מצטברת מול אשתקד'!A6,'אלטשולר שחם'!A:K,8,0)+VLOOKUP('תפוקה מצטברת מול אשתקד'!A6,'מדיהו '!A:K,8,0)+VLOOKUP('תפוקה מצטברת מול אשתקד'!A6,'אנליסט '!A:K,8,0)+VLOOKUP('תפוקה מצטברת מול אשתקד'!A6,'מיטב דש'!A:K,8,0)+VLOOKUP('תפוקה מצטברת מול אשתקד'!A6,אינפניטי!A:K,8,0) -> 0 | M6: =VLOOKUP(A6,הכשרה!A:K,9,0)+VLOOKUP('תפוקה מצטברת מול אשתקד'!A6,מגדל!A:K,9,0)+VLOOKUP('תפוקה מצטברת מול אשתקד'!A6,מנורה!A:K,9,0)+VLOOKUP('תפוקה מצטברת מול אשתקד'!A6,איילון!A:K,9,0)+VLOOKUP('תפוקה מצטברת מול אשתקד'!A6,הראל!A:K,9,0)+VLOOKUP('תפוקה מצטברת מול אשתקד'!A6,הפניקס!A:K,9,0)+VLOOKUP('תפוקה מצטברת מול אשתקד'!A6,כלל!A:K,9,0)+VLOOKUP('תפוקה מצטברת מול אשתקד'!A6,מור!A:K,9,0)+VLOOKUP('תפוקה מצטברת מול אשתקד'!A6,'אלטשולר שחם'!A:K,9,0)+VLOOKUP('תפוקה מצטברת מול אשתקד'!A6,'מדיהו '!A:K,9,0)+VLOOKUP('תפוקה מצטברת מול אשתקד'!A6,'אנליסט '!A:K,9,0)+VLOOKUP('תפוקה מצטברת מול אשתקד'!A6,'מיטב דש'!A:K,9,0)+VLOOKUP('תפוקה מצטברת מול אשתקד'!A6,אינפניטי!A:K,9,0) -> 0 | N6: =VLOOKUP(A6,הכשרה!A:K,10,0)+VLOOKUP('תפוקה מצטברת מול אשתקד'!A6,מגדל!A:K,10,0)+VLOOKUP('תפוקה מצטברת מול אשתקד'!A6,מנורה!A:K,10,0)+VLOOKUP('תפוקה מצטברת מול אשתקד'!A6,איילון!A:K,10,0)+VLOOKUP('תפוקה מצטברת מול אשתקד'!A6,הראל!A:K,10,0)+VLOOKUP('תפוקה מצטברת מול אשתקד'!A6,הפניקס!A:K,10,0)+VLOOKUP('תפוקה מצטברת מול אשתקד'!A6,כלל!A:K,10,0)+VLOOKUP('תפוקה מצטברת מול אשתקד'!A6,מור!A:K,10,0)+VLOOKUP('תפוקה מצטברת מול אשתקד'!A6,'אלטשולר שחם'!A:K,10,0)+VLOOKUP('תפוקה מצטברת מול אשתקד'!A6,'מדיהו '!A:K,10,0)+VLOOKUP('תפוקה מצטברת מול אשתקד'!A6,'אנליסט '!A:K,10,0)+VLOOKUP('תפוקה מצטברת מול אשתקד'!A6,'מיטב דש'!A:K,10,0)+VLOOKUP('תפוקה מצטברת מול אשתקד'!A6,אינפניטי!A:K,10,0) -> 0 | O6: =VLOOKUP(A6,הכשרה!A:K,11,0)+VLOOKUP('תפוקה מצטברת מול אשתקד'!A6,מגדל!A:K,11,0)+VLOOKUP('תפוקה מצטברת מול אשתקד'!A6,מנורה!A:K,11,0)+VLOOKUP('תפוקה מצטברת מול אשתקד'!A6,איילון!A:K,11,0)+VLOOKUP('תפוקה מצטברת מול אשתקד'!A6,הראל!A:K,11,0)+VLOOKUP('תפוקה מצטברת מול אשתקד'!A6,הפניקס!A:K,11,0)+VLOOKUP('תפוקה מצטברת מול אשתקד'!A6,כלל!A:K,11,0)+VLOOKUP('תפוקה מצטברת מול אשתקד'!A6,מור!A:K,11,0)+VLOOKUP('תפוקה מצטברת מול אשתקד'!A6,'אלטשולר שחם'!A:K,11,0)+VLOOKUP('תפוקה מצטברת מול אשתקד'!A6,'מדיהו '!A:K,11,0)+VLOOKUP('תפוקה מצטברת מול אשתקד'!A6,'אנליסט '!A:K,11,0)+VLOOKUP('תפוקה מצטברת מול אשתקד'!A6,'מיטב דש'!A:K,11,0)+VLOOKUP('תפוקה מצטברת מול אשתקד'!A6,אינפניטי!A:K,11,0) -> 0
A7: דני פחימה | B7: יוסי אביב | C7: ישירים | D7: =IF(H7=0,0%,IF(L7=0,100%,H7/L7-1)) -> -0.5104066 | E7: =IF(I7=0,0%,IF(M7=0,100%,I7/M7-1)) -> 1 | F7: =IF(J7=0,0%,IF(N7=0,100%,J7/N7-1)) -> -0.1140358 | G7: =IF(K7=0,0%,IF(O7=H74,100%,K7/O7-1)) -> -0.49628775 | H7: =VLOOKUP(A7,הכשרה!A:G,4,0)+VLOOKUP('תפוקה מצטברת מול אשתקד'!A7,מגדל!A:G,4,0)+VLOOKUP('תפוקה מצטברת מול אשתקד'!A7,מנורה!A:G,4,0)+VLOOKUP('תפוקה מצטברת מול אשתקד'!A7,איילון!A:G,4,0)+VLOOKUP('תפוקה מצטברת מול אשתקד'!A7,הראל!A:G,4,0)+VLOOKUP('תפוקה מצטברת מול אשתקד'!A7,הפניקס!A:G,4,0)+VLOOKUP('תפוקה מצטברת מול אשתקד'!A7,כלל!A:G,4,0)+VLOOKUP('תפוקה מצטברת מול אשתקד'!A7,מור!A:G,4,0)+VLOOKUP('תפוקה מצטברת מול אשתקד'!A7,'אלטשולר שחם'!A:G,4,0)+VLOOKUP('תפוקה מצטברת מול אשתקד'!A7,'מדיהו '!A:G,4,0)+VLOOKUP('תפוקה מצטברת מול אשתקד'!A7,'אנליסט '!A:G,4,0)+VLOOKUP('תפוקה מצטברת מול אשתקד'!A7,'מיטב דש'!A:G,4,0)+VLOOKUP('תפוקה מצטברת מול אשתקד'!A7,אינפניטי!A:G,4,0) -> 19388.54 | I7: =VLOOKUP(A7,הכשרה!A:G,5,0)+VLOOKUP('תפוקה מצטברת מול אשתקד'!A7,מגדל!A:G,5,0)+VLOOKUP('תפוקה מצטברת מול אשתקד'!A7,מנורה!A:G,5,0)+VLOOKUP('תפוקה מצטברת מול אשתקד'!A7,איילון!A:G,5,0)+VLOOKUP('תפוקה מצטברת מול אשתקד'!A7,הראל!A:G,5,0)+VLOOKUP('תפוקה מצטברת מול אשתקד'!A7,הפניקס!A:G,5,0)+VLOOKUP('תפוקה מצטברת מול אשתקד'!A7,כלל!A:G,5,0)+VLOOKUP('תפוקה מצטברת מול אשתקד'!A7,מור!A:G,5,0)+VLOOKUP('תפוקה מצטברת מול אשתקד'!A7,'אלטשולר שחם'!A:G,5,0)+VLOOKUP('תפוקה מצטברת מול אשתקד'!A7,'מדיהו '!A:G,5,0)+VLOOKUP('תפוקה מצטברת מול אשתקד'!A7,'אנליסט '!A:G,5,0)+VLOOKUP('תפוקה מצטברת מול אשתקד'!A7,'מיטב דש'!A:G,5,0)+VLOOKUP('תפוקה מצטברת מול אשתקד'!A7,אינפניטי!A:G,5,0) -> 1254.24 | J7: =VLOOKUP(A7,הכשרה!A:G,6,0)+VLOOKUP('תפוקה מצטברת מול אשתקד'!A7,מגדל!A:G,6,0)+VLOOKUP('תפוקה מצטברת מול אשתקד'!A7,מנורה!A:G,6,0)+VLOOKUP('תפוקה מצטברת מול אשתקד'!A7,איילון!A:G,6,0)+VLOOKUP(A7,הראל!A:G,6,0)+VLOOKUP('תפוקה מצטברת מול אשתקד'!A7,הפניקס!A:G,6,0)+VLOOKUP('תפוקה מצטברת מול אשתקד'!A7,כלל!A:G,6,0)+VLOOKUP('תפוקה מצטברת מול אשתקד'!A7,מור!A:G,6,0)+VLOOKUP('תפוקה מצטברת מול אשתקד'!A7,'אלטשולר שחם'!A:G,6,0)+VLOOKUP('תפוקה מצטברת מול אשתקד'!A7,'מדיהו '!A:G,6,0)+VLOOKUP('תפוקה מצטברת מול אשתקד'!A7,'אנליסט '!A:G,6,0)+VLOOKUP('תפוקה מצטברת מול אשתקד'!A7,'מיטב דש'!A:G,6,0)+VLOOKUP('תפוקה מצטברת מול אשתקד'!A7,אינפניטי!A:G,6,0) -> 9181.69 | K7: =VLOOKUP(A7,הכשרה!A:G,7,0)+VLOOKUP('תפוקה מצטברת מול אשתקד'!A7,מגדל!A:G,7,0)+VLOOKUP('תפוקה מצטברת מול אשתקד'!A7,מנורה!A:G,7,0)+VLOOKUP('תפוקה מצטברת מול אשתקד'!A7,איילון!A:G,7,0)+VLOOKUP('תפוקה מצטברת מול אשתקד'!A7,הראל!A:G,7,0)+VLOOKUP('תפוקה מצטברת מול אשתקד'!A7,הפניקס!A:G,7,0)+VLOOKUP('תפוקה מצטברת מול אשתקד'!A7,כלל!A:G,7,0)+VLOOKUP('תפוקה מצטברת מול אשתקד'!A7,מור!A:G,7,0)+VLOOKUP('תפוקה מצטברת מול אשתקד'!A7,'אלטשולר שחם'!A:G,7,0)+VLOOKUP('תפוקה מצטברת מול אשתקד'!A7,'מדיהו '!A:K,7,0)+VLOOKUP(A7,'אנליסט '!A:G,7,0)+VLOOKUP('תפוקה מצטברת מול אשתקד'!A7,'מיטב דש'!A:G,7,0)+VLOOKUP('תפוקה מצטברת מול אשתקד'!A7,אינפניטי!A:G,7,0) -> 53154.27 | L7: =VLOOKUP(A7,הכשרה!A:K,8,0)+VLOOKUP('תפוקה מצטברת מול אשתקד'!A7,מגדל!A:K,8,0)+VLOOKUP('תפוקה מצטברת מול אשתקד'!A7,מנורה!A:K,8,0)+VLOOKUP('תפוקה מצטברת מול אשתקד'!A7,איילון!A:K,8,0)+VLOOKUP('תפוקה מצטברת מול אשתקד'!A7,הראל!A:K,8,0)+VLOOKUP('תפוקה מצטברת מול אשתקד'!A7,הפניקס!A:K,8,0)+VLOOKUP('תפוקה מצטברת מול אשתקד'!A7,כלל!A:K,8,0)+VLOOKUP('תפוקה מצטברת מול אשתקד'!A7,מור!A:K,8,0)+VLOOKUP('תפוקה מצטברת מול אשתקד'!A7,'אלטשולר שחם'!A:K,8,0)+VLOOKUP('תפוקה מצטברת מול אשתקד'!A7,'מדיהו '!A:K,8,0)+VLOOKUP('תפוקה מצטברת מול אשתקד'!A7,'אנליסט '!A:K,8,0)+VLOOKUP('תפוקה מצטברת מול אשתקד'!A7,'מיטב דש'!A:K,8,0)+VLOOKUP('תפוקה מצטברת מול אשתקד'!A7,אינפניטי!A:K,8,0) -> 39601.31 | M7: =VLOOKUP(A7,הכשרה!A:K,9,0)+VLOOKUP('תפוקה מצטברת מול אשתקד'!A7,מגדל!A:K,9,0)+VLOOKUP('תפוקה מצטברת מול אשתקד'!A7,מנורה!A:K,9,0)+VLOOKUP('תפוקה מצטברת מול אשתקד'!A7,איילון!A:K,9,0)+VLOOKUP('תפוקה מצטברת מול אשתקד'!A7,הראל!A:K,9,0)+VLOOKUP('תפוקה מצטברת מול אשתקד'!A7,הפניקס!A:K,9,0)+VLOOKUP('תפוקה מצטברת מול אשתקד'!A7,כלל!A:K,9,0)+VLOOKUP('תפוקה מצטברת מול אשתקד'!A7,מור!A:K,9,0)+VLOOKUP('תפוקה מצטברת מול אשתקד'!A7,'אלטשולר שחם'!A:K,9,0)+VLOOKUP('תפוקה מצטברת מול אשתקד'!A7,'מדיהו '!A:K,9,0)+VLOOKUP('תפוקה מצטברת מול אשתקד'!A7,'אנליסט '!A:K,9,0)+VLOOKUP('תפוקה מצטברת מול אשתקד'!A7,'מיטב דש'!A:K,9,0)+VLOOKUP('תפוקה מצטברת מול אשתקד'!A7,אינפניטי!A:K,9,0) -> 0 | N7: =VLOOKUP(A7,הכשרה!A:K,10,0)+VLOOKUP('תפוקה מצטברת מול אשתקד'!A7,מגדל!A:K,10,0)+VLOOKUP('תפוקה מצטברת מול אשתקד'!A7,מנורה!A:K,10,0)+VLOOKUP('תפוקה מצטברת מול אשתקד'!A7,איילון!A:K,10,0)+VLOOKUP('תפוקה מצטברת מול אשתקד'!A7,הראל!A:K,10,0)+VLOOKUP('תפוקה מצטברת מול אשתקד'!A7,הפניקס!A:K,10,0)+VLOOKUP('תפוקה מצטברת מול אשתקד'!A7,כלל!A:K,10,0)+VLOOKUP('תפוקה מצטברת מול אשתקד'!A7,מור!A:K,10,0)+VLOOKUP('תפוקה מצטברת מול אשתקד'!A7,'אלטשולר שחם'!A:K,10,0)+VLOOKUP('תפוקה מצטברת מול אשתקד'!A7,'מדיהו '!A:K,10,0)+VLOOKUP('תפוקה מצטברת מול אשתקד'!A7,'אנליסט '!A:K,10,0)+VLOOKUP('תפוקה מצטברת מול אשתקד'!A7,'מיטב דש'!A:K,10,0)+VLOOKUP('תפוקה מצטברת מול אשתקד'!A7,אינפניטי!A:K,10,0) -> 10363.5 | O7: =VLOOKUP(A7,הכשרה!A:K,11,0)+VLOOKUP('תפוקה מצטברת מול אשתקד'!A7,מגדל!A:K,11,0)+VLOOKUP('תפוקה מצטברת מול אשתקד'!A7,מנורה!A:K,11,0)+VLOOKUP('תפוקה מצטברת מול אשתקד'!A7,איילון!A:K,11,0)+VLOOKUP('תפוקה מצטברת מול אשתקד'!A7,הראל!A:K,11,0)+VLOOKUP('תפוקה מצטברת מול אשתקד'!A7,הפניקס!A:K,11,0)+VLOOKUP('תפוקה מצטברת מול אשתקד'!A7,כלל!A:K,11,0)+VLOOKUP('תפוקה מצטברת מול אשתקד'!A7,מור!A:K,11,0)+VLOOKUP('תפוקה מצטברת מול אשתקד'!A7,'אלטשולר שחם'!A:K,11,0)+VLOOKUP('תפוקה מצטברת מול אשתקד'!A7,'מדיהו '!A:K,11,0)+VLOOKUP('תפוקה מצטברת מול אשתקד'!A7,'אנליסט '!A:K,11,0)+VLOOKUP('תפוקה מצטברת מול אשתקד'!A7,'מיטב דש'!A:K,11,0)+VLOOKUP('תפוקה מצטברת מול אשתקד'!A7,אינפניטי!A:K,11,0) -> 105525.07
A8: סה"כ ישיר | D8: =IF(H8=0,0%,IF(L8=0,100%,H8/L8-1)) -> 0.94235892 | E8: =IF(I8=0,0%,IF(M8=0,100%,I8/M8-1)) -> -0.5120803 | F8: =IF(J8=0,0%,IF(N8=0,100%,J8/N8-1)) -> 0.017395754 | G8: =IF(K8=0,0%,IF(O8=H75,100%,K8/O8-1)) -> 0.62047635 | H8: =SUM(H3:H7) -> 6681566.9 | I8: =SUM(I3:I7) -> 303337.58 | J8: =SUM(J3:J7) -> 16401835 | K8: =SUM(K3:K7) -> 41702394 | L8: =SUM(L3:L7) -> 3439923.9 | M8: =SUM(M3:M7) -> 621695.69 | N8: =SUM(N3:N7) -> 16121392 | O8: =SUM(O3:O7) -> 25734652
A9: בראשית סוכנות לביטוח | B9: יוסי אביב | C9: שותפים | D9: =IF(H9=0,0%,IF(L9=0,100%,H9/L9-1)) -> 15.662419 | E9: =IF(I9=0,0%,IF(M9=0,100%,I9/M9-1)) -> 6.7357732 | F9: =IF(J9=0,0%,IF(N9=0,100%,J9/N9-1)) -> 0 | G9: =IF(K9=0,0%,IF(O9=H33,100%,K9/O9-1)) -> -0.66214523 | H9: =VLOOKUP(A9,הכשרה!A:G,4,0)+VLOOKUP('תפוקה מצטברת מול אשתקד'!A9,מגדל!A:G,4,0)+VLOOKUP('תפוקה מצטברת מול אשתקד'!A9,מנורה!A:G,4,0)+VLOOKUP('תפוקה מצטברת מול אשתקד'!A9,איילון!A:G,4,0)+VLOOKUP('תפוקה מצטברת מול אשתקד'!A9,הראל!A:G,4,0)+VLOOKUP('תפוקה מצטברת מול אשתקד'!A9,הפניקס!A:G,4,0)+VLOOKUP('תפוקה מצטברת מול אשתקד'!A9,כלל!A:G,4,0)+VLOOKUP('תפוקה מצטברת מול אשתקד'!A9,מור!A:G,4,0)+VLOOKUP('תפוקה מצטברת מול אשתקד'!A9,'אלטשולר שחם'!A:G,4,0)+VLOOKUP('תפוקה מצטברת מול אשתקד'!A9,'מדיהו '!A:G,4,0)+VLOOKUP('תפוקה מצטברת מול אשתקד'!A9,'אנליסט '!A:G,4,0)+VLOOKUP('תפוקה מצטברת מול אשתקד'!A9,'מיטב דש'!A:G,4,0)+VLOOKUP('תפוקה מצטברת מול אשתקד'!A9,אינפניטי!A:G,4,0) -> 42413.79 | I9: =VLOOKUP(A9,הכשרה!A:G,5,0)+VLOOKUP('תפוקה מצטברת מול אשתקד'!A9,מגדל!A:G,5,0)+VLOOKUP('תפוקה מצטברת מול אשתקד'!A9,מנורה!A:G,5,0)+VLOOKUP('תפוקה מצטברת מול אשתקד'!A9,איילון!A:G,5,0)+VLOOKUP('תפוקה מצטברת מול אשתקד'!A9,הראל!A:G,5,0)+VLOOKUP('תפוקה מצטברת מול אשתקד'!A9,הפניקס!A:G,5,0)+VLOOKUP('תפוקה מצטברת מול אשתקד'!A9,כלל!A:G,5,0)+VLOOKUP('תפוקה מצטברת מול אשתקד'!A9,מור!A:G,5,0)+VLOOKUP('תפוקה מצטברת מול אשתקד'!A9,'אלטשולר שחם'!A:G,5,0)+VLOOKUP('תפוקה מצטברת מול אשתקד'!A9,'מדיהו '!A:G,5,0)+VLOOKUP('תפוקה מצטברת מול אשתקד'!A9,'אנליסט '!A:G,5,0)+VLOOKUP('תפוקה מצטברת מול אשתקד'!A9,'מיטב דש'!A:G,5,0)+VLOOKUP('תפוקה מצטברת מול אשתקד'!A9,אינפניטי!A:G,5,0) -> 1173.13 | J9: =VLOOKUP(A9,הכשרה!A:G,6,0)+VLOOKUP('תפוקה מצטברת מול אשתקד'!A9,מגדל!A:G,6,0)+VLOOKUP('תפוקה מצטברת מול אשתקד'!A9,מנורה!A:G,6,0)+VLOOKUP('תפוקה מצטברת מול אשתקד'!A9,איילון!A:G,6,0)+VLOOKUP(A9,הראל!A:G,6,0)+VLOOKUP('תפוקה מצטברת מול אשתקד'!A9,הפניקס!A:G,6,0)+VLOOKUP('תפוקה מצטברת מול אשתקד'!A9,כלל!A:G,6,0)+VLOOKUP('תפוקה מצטברת מול אשתקד'!A9,מור!A:G,6,0)+VLOOKUP('תפוקה מצטברת מול אשתקד'!A9,'אלטשולר שחם'!A:G,6,0)+VLOOKUP('תפוקה מצטברת מול אשתקד'!A9,'מדיהו '!A:G,6,0)+VLOOKUP('תפוקה מצטברת מול אשתקד'!A9,'אנליסט '!A:G,6,0)+VLOOKUP('תפוקה מצטברת מול אשתקד'!A9,'מיטב דש'!A:G,6,0)+VLOOKUP('תפוקה מצטברת מול אשתקד'!A9,אינפניטי!A:G,6,0) -> 0 | K9: =VLOOKUP(A9,הכשרה!A:G,7,0)+VLOOKUP('תפוקה מצטברת מול אשתקד'!A9,מגדל!A:G,7,0)+VLOOKUP('תפוקה מצטברת מול אשתקד'!A9,מנורה!A:G,7,0)+VLOOKUP('תפוקה מצטברת מול אשתקד'!A9,איילון!A:G,7,0)+VLOOKUP('תפוקה מצטברת מול אשתקד'!A9,הראל!A:G,7,0)+VLOOKUP('תפוקה מצטברת מול אשתקד'!A9,הפניקס!A:G,7,0)+VLOOKUP('תפוקה מצטברת מול אשתקד'!A9,כלל!A:G,7,0)+VLOOKUP('תפוקה מצטברת מול אשתקד'!A9,מור!A:G,7,0)+VLOOKUP('תפוקה מצטברת מול אשתקד'!A9,'אלטשולר שחם'!A:G,7,0)+VLOOKUP('תפוקה מצטברת מול אשתקד'!A9,'מדיהו '!A:K,7,0)+VLOOKUP(A9,'אנליסט '!A:G,7,0)+VLOOKUP('תפוקה מצטברת מול אשתקד'!A9,'מיטב דש'!A:G,7,0)+VLOOKUP('תפוקה מצטברת מול אשתקד'!A9,אינפניטי!A:G,7,0) -> -220528.51 | L9: =VLOOKUP(A9,הכשרה!A:K,8,0)+VLOOKUP('תפוקה מצטברת מול אשתקד'!A9,מגדל!A:K,8,0)+VLOOKUP('תפוקה מצטברת מול אשתקד'!A9,מנורה!A:K,8,0)+VLOOKUP('תפוקה מצטברת מול אשתקד'!A9,איילון!A:K,8,0)+VLOOKUP('תפוקה מצטברת מול אשתקד'!A9,הראל!A:K,8,0)+VLOOKUP('תפוקה מצטברת מול אשתקד'!A9,הפניקס!A:K,8,0)+VLOOKUP('תפוקה מצטברת מול אשתקד'!A9,כלל!A:K,8,0)+VLOOKUP('תפוקה מצטברת מול אשתקד'!A9,מור!A:K,8,0)+VLOOKUP('תפוקה מצטברת מול אשתקד'!A9,'אלטשולר שחם'!A:K,8,0)+VLOOKUP('תפוקה מצטברת מול אשתקד'!A9,'מדיהו '!A:K,8,0)+VLOOKUP('תפוקה מצטברת מול אשתקד'!A9,'אנליסט '!A:K,8,0)+VLOOKUP('תפוקה מצטברת מול אשתקד'!A9,'מיטב דש'!A:K,8,0)+VLOOKUP('תפוקה מצטברת מול אשתקד'!A9,אינפניטי!A:K,8,0) -> 2545.4762 | M9: =VLOOKUP(A9,הכשרה!A:K,9,0)+VLOOKUP('תפוקה מצטברת מול אשתקד'!A9,מגדל!A:K,9,0)+VLOOKUP('תפוקה מצטברת מול אשתקד'!A9,מנורה!A:K,9,0)+VLOOKUP('תפוקה מצטברת מול אשתקד'!A9,איילון!A:K,9,0)+VLOOKUP('תפוקה מצטברת מול אשתקד'!A9,הראל!A:K,9,0)+VLOOKUP('תפוקה מצטברת מול אשתקד'!A9,הפניקס!A:K,9,0)+VLOOKUP('תפוקה מצטברת מול אשתקד'!A9,כלל!A:K,9,0)+VLOOKUP('תפוקה מצטברת מול אשתקד'!A9,מור!A:K,9,0)+VLOOKUP('תפוקה מצטברת מול אשתקד'!A9,'אלטשולר שחם'!A:K,9,0)+VLOOKUP('תפוקה מצטברת מול אשתקד'!A9,'מדיהו '!A:K,9,0)+VLOOKUP('תפוקה מצטברת מול אשתקד'!A9,'אנליסט '!A:K,9,0)+VLOOKUP('תפוקה מצטברת מול אשתקד'!A9,'מיטב דש'!A:K,9,0)+VLOOKUP('תפוקה מצטברת מול אשתקד'!A9,אינפניטי!A:K,9,0) -> 151.65 | N9: =VLOOKUP(A9,הכשרה!A:K,10,0)+VLOOKUP('תפוקה מצטברת מול אשתקד'!A9,מגדל!A:K,10,0)+VLOOKUP('תפוקה מצטברת מול אשתקד'!A9,מנורה!A:K,10,0)+VLOOKUP('תפוקה מצטברת מול אשתקד'!A9,איילון!A:K,10,0)+VLOOKUP('תפוקה מצטברת מול אשתקד'!A9,הראל!A:K,10,0)+VLOOKUP('תפוקה מצטברת מול אשתקד'!A9,הפניקס!A:K,10,0)+VLOOKUP('תפוקה מצטברת מול אשתקד'!A9,כלל!A:K,10,0)+VLOOKUP('תפוקה מצטברת מול אשתקד'!A9,מור!A:K,10,0)+VLOOKUP('תפוקה מצטברת מול אשתקד'!A9,'אלטשולר שחם'!A:K,10,0)+VLOOKUP('תפוקה מצטברת מול אשתקד'!A9,'מדיהו '!A:K,10,0)+VLOOKUP('תפוקה מצטברת מול אשתקד'!A9,'אנליסט '!A:K,10,0)+VLOOKUP('תפוקה מצטברת מול אשתקד'!A9,'מיטב דש'!A:K,10,0)+VLOOKUP('תפוקה מצטברת מול אשתקד'!A9,אינפניטי!A:K,10,0) -> 0 | O9: =VLOOKUP(A9,הכשרה!A:K,11,0)+VLOOKUP('תפוקה מצטברת מול אשתקד'!A9,מגדל!A:K,11,0)+VLOOKUP('תפוקה מצטברת מול אשתקד'!A9,מנורה!A:K,11,0)+VLOOKUP('תפוקה מצטברת מול אשתקד'!A9,איילון!A:K,11,0)+VLOOKUP('תפוקה מצטברת מול אשתקד'!A9,הראל!A:K,11,0)+VLOOKUP('תפוקה מצטברת מול אשתקד'!A9,הפניקס!A:K,11,0)+VLOOKUP('תפוקה מצטברת מול אשתקד'!A9,כלל!A:K,11,0)+VLOOKUP('תפוקה מצטברת מול אשתקד'!A9,מור!A:K,11,0)+VLOOKUP('תפוקה מצטברת מול אשתקד'!A9,'אלטשולר שחם'!A:K,11,0)+VLOOKUP('תפוקה מצטברת מול אשתקד'!A9,'מדיהו '!A:K,11,0)+VLOOKUP('תפוקה מצטברת מול אשתקד'!A9,'אנליסט '!A:K,11,0)+VLOOKUP('תפוקה מצטברת מול אשתקד'!A9,'מיטב דש'!A:K,11,0)+VLOOKUP('תפוקה מצטברת מול אשתקד'!A9,אינפניטי!A:K,11,0) -> -652731.68
A10: גל אלמגור דאוד סוכ' לב | B10: יוסי אביב | C10: שותפים | D10: =IF(H10=0,0%,IF(L10=0,100%,H10/L10-1)) -> -0.1268804 | E10: =IF(I10=0,0%,IF(M10=0,100%,I10/M10-1)) -> 0.90993276 | F10: =IF(J10=0,0%,IF(N10=0,100%,J10/N10-1)) -> 0.88708546 | G10: =IF(K10=0,0%,IF(O10=H34,100%,K10/O10-1)) -> 1.0180526 | H10: =VLOOKUP(A10,הכשרה!A:G,4,0)+VLOOKUP('תפוקה מצטברת מול אשתקד'!A10,מגדל!A:G,4,0)+VLOOKUP('תפוקה מצטברת מול אשתקד'!A10,מנורה!A:G,4,0)+VLOOKUP('תפוקה מצטברת מול אשתקד'!A10,איילון!A:G,4,0)+VLOOKUP('תפוקה מצטברת מול אשתקד'!A10,הראל!A:G,4,0)+VLOOKUP('תפוקה מצטברת מול אשתקד'!A10,הפניקס!A:G,4,0)+VLOOKUP('תפוקה מצטברת מול אשתקד'!A10,כלל!A:G,4,0)+VLOOKUP('תפוקה מצטברת מול אשתקד'!A10,מור!A:G,4,0)+VLOOKUP('תפוקה מצטברת מול אשתקד'!A10,'אלטשולר שחם'!A:G,4,0)+VLOOKUP('תפוקה מצטברת מול אשתקד'!A10,'מדיהו '!A:G,4,0)+VLOOKUP('תפוקה מצטברת מול אשתקד'!A10,'אנליסט '!A:G,4,0)+VLOOKUP('תפוקה מצטברת מול אשתקד'!A10,'מיטב דש'!A:G,4,0)+VLOOKUP('תפוקה מצטברת מול אשתקד'!A10,אינפניטי!A:G,4,0) -> 548222.68 | I10: =VLOOKUP(A10,הכשרה!A:G,5,0)+VLOOKUP('תפוקה מצטברת מול אשתקד'!A10,מגדל!A:G,5,0)+VLOOKUP('תפוקה מצטברת מול אשתקד'!A10,מנורה!A:G,5,0)+VLOOKUP('תפוקה מצטברת מול אשתקד'!A10,איילון!A:G,5,0)+VLOOKUP('תפוקה מצטברת מול אשתקד'!A10,הראל!A:G,5,0)+VLOOKUP('תפוקה מצטברת מול אשתקד'!A10,הפניקס!A:G,5,0)+VLOOKUP('תפוקה מצטברת מול אשתקד'!A10,כלל!A:G,5,0)+VLOOKUP('תפוקה מצטברת מול אשתקד'!A10,מור!A:G,5,0)+VLOOKUP('תפוקה מצטברת מול אשתקד'!A10,'אלטשולר שחם'!A:G,5,0)+VLOOKUP('תפוקה מצטברת מול אשתקד'!A10,'מדיהו '!A:G,5,0)+VLOOKUP('תפוקה מצטברת מול אשתקד'!A10,'אנליסט '!A:G,5,0)+VLOOKUP('תפוקה מצטברת מול אשתקד'!A10,'מיטב דש'!A:G,5,0)+VLOOKUP('תפוקה מצטברת מול אשתקד'!A10,אינפניטי!A:G,5,0) -> 708690.32 | J10: =VLOOKUP(A10,הכשרה!A:G,6,0)+VLOOKUP('תפוקה מצטברת מול אשתקד'!A10,מגדל!A:G,6,0)+VLOOKUP('תפוקה מצטברת מול אשתקד'!A10,מנורה!A:G,6,0)+VLOOKUP('תפוקה מצטברת מול אשתקד'!A10,איילון!A:G,6,0)+VLOOKUP(A10,הראל!A:G,6,0)+VLOOKUP('תפוקה מצטברת מול אשתקד'!A10,הפניקס!A:G,6,0)+VLOOKUP('תפוקה מצטברת מול אשתקד'!A10,כלל!A:G,6,0)+VLOOKUP('תפוקה מצטברת מול אשתקד'!A10,מור!A:G,6,0)+VLOOKUP('תפוקה מצטברת מול אשתקד'!A10,'אלטשולר שחם'!A:G,6,0)+VLOOKUP('תפוקה מצטברת מול אשתקד'!A10,'מדיהו '!A:G,6,0)+VLOOKUP('תפוקה מצטברת מול אשתקד'!A10,'אנליסט '!A:G,6,0)+VLOOKUP('תפוקה מצטברת מול אשתקד'!A10,'מיטב דש'!A:G,6,0)+VLOOKUP('תפוקה מצטברת מול אשתקד'!A10,אינפניטי!A:G,6,0) -> 312411.71 | K10: =VLOOKUP(A10,הכשרה!A:G,7,0)+VLOOKUP('תפוקה מצטברת מול אשתקד'!A10,מגדל!A:G,7,0)+VLOOKUP('תפוקה מצטברת מול אשתקד'!A10,מנורה!A:G,7,0)+VLOOKUP('תפוקה מצטברת מול אשתקד'!A10,איילון!A:G,7,0)+VLOOKUP('תפוקה מצטברת מול אשתקד'!A10,הראל!A:G,7,0)+VLOOKUP('תפוקה מצטברת מול אשתקד'!A10,הפניקס!A:G,7,0)+VLOOKUP('תפוקה מצטברת מול אשתקד'!A10,כלל!A:G,7,0)+VLOOKUP('תפוקה מצטברת מול אשתקד'!A10,מור!A:G,7,0)+VLOOKUP('תפוקה מצטברת מול אשתקד'!A10,'אלטשולר שחם'!A:G,7,0)+VLOOKUP('תפוקה מצטברת מול אשתקד'!A10,'מדיהו '!A:K,7,0)+VLOOKUP(A10,'אנליסט '!A:G,7,0)+VLOOKUP('תפוקה מצטברת מול אשתקד'!A10,'מיטב דש'!A:G,7,0)+VLOOKUP('תפוקה מצטברת מול אשתקד'!A10,אינפניטי!A:G,7,0) -> 1135424 | L10: =VLOOKUP(A10,הכשרה!A:K,8,0)+VLOOKUP('תפוקה מצטברת מול אשתקד'!A10,מגדל!A:K,8,0)+VLOOKUP('תפוקה מצטברת מול אשתקד'!A10,מנורה!A:K,8,0)+VLOOKUP('תפוקה מצטברת מול אשתקד'!A10,איילון!A:K,8,0)+VLOOKUP('תפוקה מצטברת מול אשתקד'!A10,הראל!A:K,8,0)+VLOOKUP('תפוקה מצטברת מול אשתקד'!A10,הפניקס!A:K,8,0)+VLOOKUP('תפוקה מצטברת מול אשתקד'!A10,כלל!A:K,8,0)+VLOOKUP('תפוקה מצטברת מול אשתקד'!A10,מור!A:K,8,0)+VLOOKUP('תפוקה מצטברת מול אשתקד'!A10,'אלטשולר שחם'!A:K,8,0)+VLOOKUP('תפוקה מצטברת מול אשתקד'!A10,'מדיהו '!A:K,8,0)+VLOOKUP('תפוקה מצטברת מול אשתקד'!A10,'אנליסט '!A:K,8,0)+VLOOKUP('תפוקה מצטברת מול אשתקד'!A10,'מיטב דש'!A:K,8,0)+VLOOKUP('תפוקה מצטברת מול אשתקד'!A10,אינפניטי!A:K,8,0) -> 627889.56 | M10: =VLOOKUP(A10,הכשרה!A:K,9,0)+VLOOKUP('תפוקה מצטברת מול אשתקד'!A10,מגדל!A:K,9,0)+VLOOKUP('תפוקה מצטברת מול אשתקד'!A10,מנורה!A:K,9,0)+VLOOKUP('תפוקה מצטברת מול אשתקד'!A10,איילון!A:K,9,0)+VLOOKUP('תפוקה מצטברת מול אשתקד'!A10,הראל!A:K,9,0)+VLOOKUP('תפוקה מצטברת מול אשתקד'!A10,הפניקס!A:K,9,0)+VLOOKUP('תפוקה מצטברת מול אשתקד'!A10,כלל!A:K,9,0)+VLOOKUP('תפוקה מצטברת מול אשתקד'!A10,מור!A:K,9,0)+VLOOKUP('תפוקה מצטברת מול אשתקד'!A10,'אלטשולר שחם'!A:K,9,0)+VLOOKUP('תפוקה מצטברת מול אשתקד'!A10,'מדיהו '!A:K,9,0)+VLOOKUP('תפוקה מצטברת מול אשתקד'!A10,'אנליסט '!A:K,9,0)+VLOOKUP('תפוקה מצטברת מול אשתקד'!A10,'מיטב דש'!A:K,9,0)+VLOOKUP('תפוקה מצטברת מול אשתקד'!A10,אינפניטי!A:K,9,0) -> 371055.12 | N10: =VLOOKUP(A10,הכשרה!A:K,10,0)+VLOOKUP('תפוקה מצטברת מול אשתקד'!A10,מגדל!A:K,10,0)+VLOOKUP('תפוקה מצטברת מול אשתקד'!A10,מנורה!A:K,10,0)+VLOOKUP('תפוקה מצטברת מול אשתקד'!A10,איילון!A:K,10,0)+VLOOKUP('תפוקה מצטברת מול אשתקד'!A10,הראל!A:K,10,0)+VLOOKUP('תפוקה מצטברת מול אשתקד'!A10,הפניקס!A:K,10,0)+VLOOKUP('תפוקה מצטברת מול אשתקד'!A10,כלל!A:K,10,0)+VLOOKUP('תפוקה מצטברת מול אשתקד'!A10,מור!A:K,10,0)+VLOOKUP('תפוקה מצטברת מול אשתקד'!A10,'אלטשולר שחם'!A:K,10,0)+VLOOKUP('תפוקה מצטברת מול אשתקד'!A10,'מדיהו '!A:K,10,0)+VLOOKUP('תפוקה מצטברת מול אשתקד'!A10,'אנליסט '!A:K,10,0)+VLOOKUP('תפוקה מצטברת מול אשתקד'!A10,'מיטב דש'!A:K,10,0)+VLOOKUP('תפוקה מצטברת מול אשתקד'!A10,אינפניטי!A:K,10,0) -> 165552.5 | O10: =VLOOKUP(A10,הכשרה!A:K,11,0)+VLOOKUP('תפוקה מצטברת מול אשתקד'!A10,מגדל!A:K,11,0)+VLOOKUP('תפוקה מצטברת מול אשתקד'!A10,מנורה!A:K,11,0)+VLOOKUP('תפוקה מצטברת מול אשתקד'!A10,איילון!A:K,11,0)+VLOOKUP('תפוקה מצטברת מול אשתקד'!A10,הראל!A:K,11,0)+VLOOKUP('תפוקה מצטברת מול אשתקד'!A10,הפניקס!A:K,11,0)+VLOOKUP('תפוקה מצטברת מול אשתקד'!A10,כלל!A:K,11,0)+VLOOKUP('תפוקה מצטברת מול אשתקד'!A10,מור!A:K,11,0)+VLOOKUP('תפוקה מצטברת מול אשתקד'!A10,'אלטשולר שחם'!A:K,11,0)+VLOOKUP('תפוקה מצטברת מול אשתקד'!A10,'מדיהו '!A:K,11,0)+VLOOKUP('תפוקה מצטברת מול אשתקד'!A10,'אנליסט '!A:K,11,0)+VLOOKUP('תפוקה מצטברת מול אשתקד'!A10,'מיטב דש'!A:K,11,0)+VLOOKUP('תפוקה מצטברת מול אשתקד'!A10,אינפניטי!A:K,11,0) -> 562633.49
